Workbook
Name \A: #REF!
Name _epmOfflineCondition_: 1
Name _epmOfflineCondition_: 1
Name DATA1: #REF!
Name DATA1: #REF!
Name DATA1: #REF!
Name DATA1: #REF!
Name DATA1: #REF!
Name DATA2: #REF!
Name DATA2: #REF!
Name DATA2: #REF!
Name DATA2: #REF!
Name DATA2: #REF!
Name DATA3: #REF!
Name DATA3: #REF!
Name DATA3: #REF!
Name DATA3: #REF!
Name DATA3: #REF!
Name DATA4: #REF!
Name DATA4: #REF!
Name DATA4: #REF!
Name DATA4: #REF!
Name DATA4: #REF!
Name qykjzdcwbbxjllbxxGridlb_10: #REF!
Name qykjzdcwbbxjllbxxGridlb_19: #REF!
Name qykjzdcwbbxjllbxxGridlb_28: #REF!
Name qykjzdcwbbxjllbxxGridlb_31: #REF!
Name qykjzdcwbbxjllbxxGridlb_52: #REF!
Name qykjzdcwbbxjllbxxGridlb_53: #REF!
Name qykjzdcwbbxjllbxxGridlb_56: #REF!
Name TEST0: #REF!
Name TEST0: #REF!
Name TEST0: #REF!
Name TEST0: #REF!
Name TEST0: #REF!
Name TESTHKEY: #REF!
Name TESTHKEY: #REF!
Name TESTHKEY: #REF!
Name TESTHKEY: #REF!
Name TESTHKEY: #REF!
Name TESTKEYS: #REF!
Name TESTKEYS: #REF!
Name TESTKEYS: #REF!
Name TESTKEYS: #REF!
Name TESTKEYS: #REF!
Name TESTVKEY: #REF!
Name TESTVKEY: #REF!
Name TESTVKEY: #REF!
Name TESTVKEY: #REF!
Name TESTVKEY: #REF!
Name 设备发票明细: #REF!
Name 设备发票明细: #REF!
Name 设备发票明细: #REF!
Name 设备发票明细: #REF!
Name 设备发票明细: #REF!

Sheet 累计税金汇总表
A1: 时间：所属期 单位：元 | C1: 税金缴纳标准 | D1: 202412 | E1: 202501 | F1: 202502 | G1: 202503 | H1: 202504 | I1: 202505 | J1: 202506 | K1: 202507 | L1: 202508 | M1: 202509 | N1: 202510 | O1: 202511 | P1: 202512
A2: 基数 | B2: 账面收入 | D2: 1.5126491e+09 | E2: 4.3116584e+08 | F2: 3.5558408e+08 | G2: 48816138 | H2: 97382183 | I2: 50884270 | J2: 1.2171605e+08 | K2: 1.1081929e+08 | L2: 1.7958369e+08 | M2: 1.7442616e+08 | N2: 1.1709462e+08 | O2: 1.7393182e+09 | P2: 3.9147228e+09
B3: 其他收益
B4: 项目开票 | D4: 1.1262598e+09 | E4: 7.805366e+08 | F4: 5.2620168e+08 | G4: 4.7608694e+08 | H4: 78604519 | I4: 37974761 | J4: 2.3684048e+08 | K4: 1.0914781e+08 | L4: 1.4016733e+08 | M4: 2.3979933e+08 | N4: 3.1389905e+08 | O4: 1.0132121e+09 | P4: 1.094647e+09
B5: 利息开票
B6: 销项税额 | C6: A | D6: 1.5335725e+08 | E6: 54874884 | F6: 45434329 | G6: 4651212.5 | H6: 9372591.2 | I6: 4606639.5 | J6: 10897955 | K6: 9901838.1 | L6: 12579095 | M6: 16661164 | N6: 12198025 | O6: 2.2262931e+08 | P6: 4.7460854e+08
B7: 本期进项税额 | C7: B | D7: 67835873 | E7: 72025452 | F7: 60425055 | G7: 7987426.8 | H7: 7347644.3 | I7: 7003174.4 | J7: 4385018.7 | K7: 6626261.8 | L7: 22887594 | M7: 18893309 | N7: 18347860 | O7: 1.8479839e+08 | P7: 4.0848101e+08
B8: 上期留抵税额 | C8: C | O8: 2228173.5 | P8: 1210358
B9: 进项税额转出 | C9: D | E9: 14956.1 | F9: 3542.11 | G9: 595805.07 | H9: 22641.51 | J9: 272019.39 | K9: 43475.46 | L9: 267177.47 | M9: 82568.81 | P9: 603847.64
B10: 异地预缴税增值税 | C10: E | D10: 11847361 | G10: 29781.96 | H10: 2217866.5 | I10: 655226.71 | J10: 382841.63 | L10: 116982.96 | M10: 2762668.3 | P10: 7694589.5
B11: 应纳增值税额 | C11: A-B-C+D-E | D11: 73674014 | P11: 57826431
A12: 税金 | B12: 增值税 | D12: 73674014 | E12: =E11 -> 0 | F12: =F11 -> 0 | G12: =G11 -> 0 | H12: 0 | I12: =I11 -> 0 | J12: =J11 -> 0 | K12: =K11 -> 0 | L12: =L11 -> 0 | M12: =M11 -> 0 | N12: =N11 -> 0 | O12: =O11 -> 0 | P12: =P11 -> 57826431
B13: 印花税 | D13: 1051983.4 | J13: 330365.58
B14: 城建税 | C14: 增值税额的7% | D14: 5157181 | E14: =E12*0.07 -> 0 | F14: =F12*0.07 -> 0 | G14: =G12*0.07 -> 0 | H14: =H12*0.07 -> 0 | I14: =I12*0.07 -> 0 | J14: =J12*0.07 -> 0 | K14: =K12*0.07 -> 0 | L14: =L12*0.07 -> 0 | ... P14: =P12*0.07 -> 4047850.2
B15: 教育费附加 | C15: 增值税额的3% | D15: 2210220.4 | E15: =E12*0.03 -> 0 | F15: =F12*0.03 -> 0 | G15: =G12*0.03 -> 0 | H15: =H12*0.03 -> 0 | I15: =I12*0.03 -> 0 | J15: =J12*0.03 -> 0 | K15: =K12*0.03 -> 0 | L15: =L12*0.03 -> 0 | ... P15: =P12*0.03 -> 1734792.9
B16: 地方教育费附加 | C16: 增值税额的2% | D16: 1473480.3 | E16: =E12*0.02 -> 0 | F16: =F12*0.02 -> 0 | G16: =G12*0.02 -> 0 | H16: =H12*0.02 -> 0 | I16: =I12*0.02 -> 0 | J16: =J12*0.02 -> 0 | K16: =K12*0.02 -> 0 | L16: =L12*0.02 -> 0 | ... P16: =P12*0.02 -> 1156528.6
B17: 房产税
B18: 城镇土地使用
B19: 企业所得税 | D19: 3.8001788e+08 | J19: 29332502 | M19: 25579909 | P19: 77589714
B20: 个税
B21: 残疾人保障金 | K21: 181635.35
B22: 合计 | D22: =SUM(D12:D21) -> 4.6358476e+08 | E22: =SUM(E12:E21) -> 0 | F22: =SUM(F12:F21) -> 0 | G22: =SUM(G12:G21) -> 0 | H22: =SUM(H12:H21) -> 0 | I22: =SUM(I12:I21) -> 0 | J22: =SUM(J12:J21) -> 29662867 | K22: =SUM(K12:K21) -> 181635.35 | ... P22: =SUM(P12:P21) -> 1.4235532e+08
F26: 异地预缴 | H26: 异地预缴 | I26: 企业所得税
F27: 郎溪景宇风力发电有限公司 | H27: 郎溪
F28: 馆陶县汇恒风电有限公司 | H28: 察哈尔景源
F29: 伊金霍洛旗悦盛新能源有限公司 | H29: 定远纳驰 | I29: 450039.33
H30: 定远纳风 | I30: 734696.74
H31: 哈密博景
F33: 中国石油天然气股份有限公司 吐哈油田分公司 | H33: 吐哈油田 | I33: 136.15
F34: 定远智贮能源科技有限公司 | H34: 远景定远智慧储能共享电站项目 EPC | I34: 61976.18
E37: 45748 | F37: 定边远边汇新能源有限公司 | H37: 定边县红柳沟镇白兴庄 | I37: 443045.39
E39: 45778 | F39: 乌海市远鸿富景新能源科技有限公司 | H39: 乌海市金湖独立储能电站项目EPC总承 | I39: 96963.75
F40: 招银金融租赁有限公司 | H40: 利豪鸡泽县50MW保障类风电场 | I40: 172641.17
E42: 45809 | F42: 滨州远凌新能源有限责任公司 | H42: 滨州北海储能电站项目 | I42: 59826.73
F43: 清水河县云景风力发电有限公 司 | H43: 清水河县城关分散式风电场项目EPC总承包 | I43: 62095.04
E44: 2025.7 | H44: 射阳汇智风电场项目 EPC 总承包采购合同 | I44: 98649.14
E45: 2025.8 | G45: 陕西省榆林市靖边县东南部天赐湾乡 | H45: 靖边县状泽城河100兆瓦风电场项目EPC工程总承包合同 | I45: 364233.03
E46: 2025.9 | G46: 内蒙古自治区乌兰察布市察哈尔右翼后旗 | I46: 288997.39

Sheet 累计项目税收明细表202512
J1: ='累计项目税收明细表2017-202302'!G355 -> 1.1960885e+10 | K1: ='累计项目税收明细表2017-202302'!H355 -> 1.1569549e+10 | L1: =SUBTOTAL(9,L8:L143) -> 4.42397e+08 | M1: =SUBTOTAL(9,M9:M143) -> 5.4813931e+08 | N1: =SUBTOTAL(9,N8:N143) -> 5.2125169e+08 | O1: =SUBTOTAL(9,O8:O143) -> 5.1244236e+08 | P1: =SUBTOTAL(9,P8:P143) -> 6.3590871e+08 | Q1: =SUBTOTAL(9,Q8:Q143) -> 5.4741284e+08 | R1: =SUBTOTAL(9,R8:R150) -> 3.0901827e+08 | S1: =SUBTOTAL(9,S8:S150) -> 3.4998131e+08 | T1: =SUBTOTAL(9,T8:T157) -> 5.5568377e+08 | U1: =SUBTOTAL(9,U8:U150) -> 5.1789361e+08 | V1: =SUBTOTAL(9,V8:V150) -> 6.7448332e+08 | W1: =SUBTOTAL(9,W8:W150) -> 5.424389e+08 | X1: =SUBTOTAL(9,X8:X150) -> 3.3679561e+08 | Y1: =SUBTOTAL(9,Y8:Y150) -> 4.5653185e+08
B2: 项目类型 | C2: 公司代码 或项目号 | D2: 项目名称 | E2: 类别 | F2: 税率 | G2: 累计收入 | H2: 累计开票 | I2: 未开票收入 | J2: 202403之前月度 收入额小计 | K2: 202403之前月度 开票额小计 | L2: 202403账面收入 | M2: 202403开票 | N2: 202404账面收入 | O2: 202404开票 | P2: 202405账面收入 | Q2: 202405开票 | R2: 202406账面收入 | S2: 202406开票 | T2: 202407账面收入 | U2: 202407开票 | V2: 202408账面收入 | W2: 202408开票 | X2: 202409账面收入 | Y2: 202409开票 | Z2: 202410账面收入 | AA2: 202410开票 | AB2: 202411账面收入 | AC2: 202411开票 | AD2: 202412账面收入 | AE2: 202412开票 | AF2: 202501账面收入 | AG2: 202501开票 | AH2: 202502账面收入 | AI2: 202502开票 | AJ2: 202503账面收入 | AK2: 202503开票 | AL2: 202504账面收入 | AM2: 202504开票 | AN2: 202505账面收入 | AO2: 202505开票 | AP2: 202506账面收入 | AQ2: 202506开票 | AR2: 202507账面收入 | AS2: 202507开票 | AT2: 202508预开票金额 | AU2: 202508账面收入 | AV2: 202508开票 | AW2: 202509账面收入 | AX2: 202509开票 | AY2: 202510账面收入 | AZ2: 202510开票 | BA2: 202510预开票 | BB2: 202510预开票冲回 | BC2: 202511账面收入 | BD2: 202511开票 | BE2: 202511预开票 | BF2: 202511预开票冲回 | BG2: 202512账面收入 | BH2: 202512开票 | BI2: 202512预开票 | BJ2: 202512预开票冲回
D3: 202403之前 各月度数据结转 | E3: 商品销售 | F3: 0.16 | G3: =SUM(J3,L3,N3,P3,R3,T3,V3,X3,Z3) -> 467927.48 | H3: =SUM(K3,M3,O3,Q3) -> 88819830 | I3: =G3-H3 -> -88351903 | J3: 467927.48 | K3: 88819830
E4: 工程施工 | F4: 0.1 | G4: =SUM(J4,L4,N4,P4,R4,T4,V4,X4,Z4) -> -1.2564439e+08 | H4: =SUM(K4,M4,O4,Q4) -> -47524533 | I4: =G4-H4 -> -78119852 | J4: -1.2564439e+08 | K4: -47524533
E5: 商品销售 | F5: 0.13 | G5: =SUM(J5,L5,N5,P5,R5,T5,V5,X5,Z5) -> 6.6085485e+09 | H5: =SUM(K5,M5,O5,Q5) -> 6.2670488e+09 | I5: =G5-H5 -> 3.414997e+08 | J5: 6.6085485e+09 | K5: 6.2670488e+09
E6: 工程施工 | F6: 0.09 | G6: =SUM(J6,L6,N6,P6,R6,T6,V6,X6,Z6) -> 5.0145477e+09 | H6: =SUM(K6,M6,O6,Q6) -> 4.892353e+09 | I6: =G6-H6 -> 1.221947e+08 | J6: 5.0145477e+09 | K6: 4.892353e+09
E7: 设计咨询 | F7: 0.06 | G7: =SUM(J7,L7,N7,P7,R7,T7,V7,X7,Z7) -> 4.6296552e+08 | H7: =SUM(K7,M7,O7,Q7) -> 3.6885177e+08 | I7: =G7-H7 -> 94113747 | J7: 4.6296552e+08 | K7: 3.6885177e+08 | Y7: 0
B8: EPC自建 | C8: 2346 | D8: 安徽宣城郎溪 | E8: 商品销售 | F8: 0.13 | G8: =SUM(J8,L8,N8,P8,R8,T8,V8,X8,Z8,AB8,AD8,AF8,AH8,AJ8,AL8,AN8,AP8,AR8,AU8,AW8,AY8,BC8,BG8) -> 32635696 | H8: =SUM(K8,M8,O8,Q8,S8,U8,W8,Y8,AA8,AC8,AE8,AG8,AI8,AK8,AM8,AO8,AQ8,AS8,AV8,AX8,AZ8,BD8,BH8) -> 37275653 | I8: =G8-H8 -> -4639956.4 | N8: 7575879.3 | O8: 11624470 | P8: 17461283 | Q8: 7575879.3 | R8: 2028030.5 | S8: 10476770 | T8: 184101.94 | V8: 5386401.3 | W8: 0 | X8: 0 | Y8: 0 | AJ8: 0 | AK8: 7598533.8
C9: 2346 | E9: 工程施工 | F9: 0.09 | G9: =SUM(J9,L9,N9,P9,R9,T9,V9,X9,Z9,AB9,AD9,AF9,AH9,AJ9,AL9,AN9,AP9,AR9,AU9,AW9,AY9,BC9,BG9) -> 9498435.8 | H9: =SUM(K9,M9,O9,Q9,S9,U9,W9,Y9,AA9,AC9,AE9,AG9,AI9,AK9,AM9,AO9,AQ9,AS9,AV9,AX9,AZ9,BD9,BH9) -> 19399126 | I9: =G9-H9 -> -9900690.2 | L9: 1044857.3 | N9: 2871503.7 | P9: 1423208.3 | Q9: 15363805 | R9: 2364082.2 | S9: 4035321.1 | T9: 1100229.4 | V9: 470183.49 | W9: 0 | X9: 224371.56 | Y9: 0
C10: 2346 | E10: 设计咨询 | F10: 0.06 | G10: =SUM(J10,L10,N10,P10,R10,T10,V10,X10,Z10,AB10,AD10,AF10,AH10,AJ10,AL10,AN10,AP10,AR10,AU10,AW10,AY10,BC10,BG10) -> 1587499.4 | H10: =SUM(K10,M10,O10,Q10,S10,U10,W10,Y10,AA10,AC10,AE10,AG10,AI10,AK10,AM10,AO10,AQ10,AS10,AV10,AX10,AZ10,BD10,BH10) -> 1604523.2 | I10: =G10-H10 -> -17023.79 | L10: 116896.06 | N10: 170311.43 | P10: 316972.4 | Q10: 1050616 | R10: 634803.18 | S10: 362041.83 | T10: 201873.22 | U10: 45222.28 | V10: 68316.87 | W10: 68316.87 | X10: 44486.8 | Y10: 44486.8 | Z10: 33839.49 | AA10: 33839.49
C11: 安新县阔达有色金属熔炼有限公司 | D11: 安徽宣城郎溪 | E11: 商品销售 | F11: 0.13 | G11: =SUM(J11,L11,N11,P11,R11,T11,V11,X11,Z11,AB11,AD11,AF11,AH11,AJ11,AL11,AN11,AP11,AR11,AU11,AW11,AY11,BC11,BG11) -> 0 | H11: =SUM(K11,M11,O11,Q11,S11,U11,W11,Y11,AA11,AC11,AE11,AG11,AI11,AK11,AM11,AO11,AQ11,AS11,AV11,AX11,AZ11,BD11,BH11) -> 81415.93 | BH11: 81415.93
E12: 工程施工 | F12: 0.09 | G12: =SUM(J12,L12,N12,P12,R12,T12,V12,X12,Z12,AB12,AD12,AF12,AH12,AJ12,AL12,AN12,AP12,AR12,AU12,AW12,AY12,BC12,BG12) -> 0 | H12: =SUM(K12,M12,O12,Q12,S12,U12,W12,Y12,AA12,AC12,AE12,AG12,AI12,AK12,AM12,AO12,AQ12,AS12,AV12,AX12,AZ12,BD12,BH12) -> 0
E13: 设计咨询 | F13: 0.06 | G13: =SUM(J13,L13,N13,P13,R13,T13,V13,X13,Z13,AB13,AD13,AF13,AH13,AJ13,AL13,AN13,AP13,AR13,AU13,AW13,AY13,BC13,BG13) -> 0 | H13: =SUM(K13,M13,O13,Q13,S13,U13,W13,Y13,AA13,AC13,AE13,AG13,AI13,AK13,AM13,AO13,AQ13,AS13,AV13,AX13,AZ13,BD13,BH13) -> 0
B14: EPC自建 | C14: 3660 | D14: 巴彦淖尔 | E14: 商品销售 | F14: 0.13 | G14: =SUM(J14,L14,N14,P14,R14,T14,V14,X14,Z14,AB14,AD14,AF14,AH14,AJ14,AL14,AN14,AP14,AR14,AU14,AW14,AY14,BC14,BG14) -> 8211701.3 | H14: =SUM(K14,M14,O14,Q14,S14,U14,W14,Y14,AA14,AC14,AE14,AG14,AI14,AK14,AM14,AO14,AQ14,AS14,AV14,AX14,AZ14,BD14,BH14) -> 11336364 | I14: =G14-H14 -> -3124662.7 | L14: 8130064.1 | M14: 3124662.6 | N14: 81637.17 | V14: 0 | W14: 0 | X14: 0 | Y14: 8211701.4
C15: 3660 | E15: 工程施工 | F15: 0.09 | G15: =SUM(J15,L15,N15,P15,R15,T15,V15,X15,Z15,AB15,AD15,AF15,AH15,AJ15,AL15,AN15,AP15,AR15,AU15,AW15,AY15,BC15,BG15) -> 4.6214846e+08 | H15: =SUM(K15,M15,O15,Q15,S15,U15,W15,Y15,AA15,AC15,AE15,AG15,AI15,AK15,AM15,AO15,AQ15,AS15,AV15,AX15,AZ15,BD15,BH15) -> 4.6214846e+08 | I15: =G15-H15 -> -0.029999912 | L15: 1.8904657e+08 | M15: 1.8348624e+08 | N15: 2.2018349e+08 | O15: 2.2018349e+08 | P15: 1.9266055e+08 | Q15: 1.9266055e+08 | U15: 3981328.1 | V15: 1239039.6 | W15: 0 | X15: 0 | Y15: 2818045.8 | AD15: -1.4098119e+08 | AE15: 0 | AI15: -1.4098119e+08
C16: 3660 | E16: 设计咨询 | F16: 0.06 | G16: =SUM(J16,L16,N16,P16,R16,T16,V16,X16,Z16,AB16,AD16,AF16,AH16,AJ16,AL16,AN16,AP16,AR16,AU16,AW16,AY16,BC16,BG16) -> 5519384.1 | H16: =SUM(K16,M16,O16,Q16,S16,U16,W16,Y16,AA16,AC16,AE16,AG16,AI16,AK16,AM16,AO16,AQ16,AS16,AV16,AX16,AZ16,BD16,BH16) -> 6976051.5 | I16: =G16-H16 -> -1456667.3 | L16: 5238515.3 | M16: 1456667.3 | N16: -81637.17 | T16: 212735.85 | U16: 4216037.7 | V16: 52152 | W16: 0 | X16: 0 | Y16: 1205728.3 | AD16: 97618.11 | AE16: 97618.11
B17: EPC自建 | C17: 4030 | D17: 定边白兴庄 | E17: 商品销售 | F17: 0.13 | G17: =SUM(J17,L17,N17,P17,R17,T17,V17,X17,Z17,AB17,AD17,AF17,AH17,AJ17,AL17,AN17,AP17,AR17,AU17,AW17,AY17,BC17,BG17) -> 2.0329258e+08 | H17: =SUM(K17,M17,O17,Q17,S17,U17,W17,Y17,AA17,AC17,AE17,AG17,AI17,AK17,AM17,AO17,AQ17,AS17,AV17,AX17,AZ17,BD17,BH17) -> 1.1134199e+08 | I17: =G17-H17 -> 91950591 | N17: 3664601.8 | P17: 222234.5 | R17: 18651916 | S17: 0 | T17: 53556348 | V17: 14543776 | W17: 0 | X17: -9581572.7 | Y17: 8347326.5 | Z17: 32102530 | AA17: 11020813 | AB17: 90132743 | AC17: 91973846
C18: 4030 | E18: 工程施工 | F18: 0.09 | G18: =SUM(J18,L18,N18,P18,R18,T18,V18,X18,Z18,AB18,AD18,AF18,AH18,AJ18,AL18,AN18,AP18,AR18,AU18,AW18,AY18,BC18,BG18) -> 2.1309161e+08 | H18: =SUM(K18,M18,O18,Q18,S18,U18,W18,Y18,AA18,AC18,AE18,AG18,AI18,AK18,AM18,AO18,AQ18,AS18,AV18,AX18,AZ18,BD18,BH18) -> 1.8890447e+08 | I18: =G18-H18 -> 24187141 | L18: 489233.5 | N18: 9211423.6 | O18: 45871560 | P18: 10406006 | R18: 14196013 | S18: 0 | T18: 12344910 | V18: 9578080.4 | W18: 0 | X18: 15013767 | Y18: 18679332 | Z18: 37165437 | AA18: 9429091.5 | AB18: 53132537 | AC18: 63370283 | AD18: 51554199 | AE18: 51554199
C19: 4030 | E19: 设计咨询 | F19: 0.06 | G19: =SUM(J19,L19,N19,P19,R19,T19,V19,X19,Z19,AB19,AD19,AF19,AH19,AJ19,AL19,AN19,AP19,AR19,AU19,AW19,AY19,BC19,BG19) -> 8329405.3 | H19: =SUM(K19,M19,O19,Q19,S19,U19,W19,Y19,AA19,AC19,AE19,AG19,AI19,AK19,AM19,AO19,AQ19,AS19,AV19,AX19,AZ19,BD19,BH19) -> 7940431.8 | I19: =G19-H19 -> 388973.51 | L19: 43891.61 | N19: 685280.75 | P19: 64486.14 | R19: 156301.33 | S19: 60092.57 | T19: 3078319.5 | U19: 60296.37 | V19: =563843.01+91089.15 -> 654932.16 | W19: 91089.15 | X19: 165683.66 | Y19: 4427586 | Z19: 3031830.8 | AA19: 474936.19 | AB19: 448679.26 | AC19: 2826431.5
B20: EPC自建 | C20: 4020 | D20: 定边王家梁 | E20: 商品销售 | F20: 0.13 | G20: =SUM(J20,L20,N20,P20,R20,T20,V20,X20,Z20,AB20,AD20,AF20,AH20,AJ20,AL20,AN20,AP20,AR20,AU20,AW20,AY20,BC20,BG20) -> 1.0538136e+08 | H20: =SUM(K20,M20,O20,Q20,S20,U20,W20,Y20,AA20,AC20,AE20,AG20,AI20,AK20,AM20,AO20,AQ20,AS20,AV20,AX20,AZ20,BD20,BH20) -> 1.0767405e+08 | I20: =G20-H20 -> -2292690.1 | M20: 2292690 | N20: 10422345 | R20: 660150.8 | S20: 0 | T20: 27073953 | V20: 3545901.1 | W20: 13168633 | X20: 11705115 | Y20: 3422302.7 | Z20: 51973899 | AA20: 36816530 | AI20: 51973899
C21: 4020 | E21: 工程施工 | F21: 0.09 | G21: =SUM(J21,L21,N21,P21,R21,T21,V21,X21,Z21,AB21,AD21,AF21,AH21,AJ21,AL21,AN21,AP21,AR21,AU21,AW21,AY21,BC21,BG21) -> 2.9721338e+08 | H21: =SUM(K21,M21,O21,Q21,S21,U21,W21,Y21,AA21,AC21,AE21,AG21,AI21,AK21,AM21,AO21,AQ21,AS21,AV21,AX21,AZ21,BD21,BH21) -> 3.2681651e+08 | I21: =G21-H21 -> -29603135 | L21: 5244190.5 | M21: 29823783 | N21: 13660419 | O21: 1.6430483e+08 | P21: 27909442 | R21: 19309601 | S21: 0 | T21: 12545273 | V21: 7283802.8 | W21: 73424735 | X21: 8064138.7 | Y21: 2271099.1 | Z21: 2.0319651e+08 | AA21: 47672842 | AE21: 9319218.1
C22: 4020 | E22: 设计咨询 | F22: 0.06 | G22: =SUM(J22,L22,N22,P22,R22,T22,V22,X22,Z22,AB22,AD22,AF22,AH22,AJ22,AL22,AN22,AP22,AR22,AU22,AW22,AY22,BC22,BG22) -> 15200557 | H22: =SUM(K22,M22,O22,Q22,S22,U22,W22,Y22,AA22,AC22,AE22,AG22,AI22,AK22,AM22,AO22,AQ22,AS22,AV22,AX22,AZ22,BD22,BH22) -> 29092126 | I22: =G22-H22 -> -13891569 | L22: 387382.3 | M22: 6720925.1 | N22: 1991865.6 | O22: 614275.5 | P22: 1033444.8 | R22: 605451.16 | S22: 60092.57 | T22: 3642158.9 | U22: 60296.37 | V22: =451080.26+91089.15 -> 542169.41 | W22: 14187371 | X22: 453844.04 | Y22: 510396 | Z22: 5695184.2 | AA22: 394528.3 | AD22: 849056.6 | AE22: 5695184.2 | AG22: 849056.6
B23: EPC自建 | C23: 2319 | D23: 定远乘风 | E23: 商品销售 | F23: 0.13 | G23: =SUM(J23,L23,N23,P23,R23,T23,V23,X23,Z23,AB23,AD23,AF23,AH23,AJ23,AL23,AN23,AP23,AR23,AU23,AW23,AY23,BC23,BG23) -> 1.2192612e+08 | H23: =SUM(K23,M23,O23,Q23,S23,U23,W23,Y23,AA23,AC23,AE23,AG23,AI23,AK23,AM23,AO23,AQ23,AS23,AV23,AX23,AZ23,BD23,BH23) -> 1.4448884e+08 | I23: =G23-H23 -> -22562720 | L23: 3184412.9 | P23: 3053970.6 | R23: 1591338.1 | S23: 0 | T23: 28616.54 | U23: 30132373 | V23: 22396948 | W23: 0 | X23: 23544881 | Y23: 0 | Z23: 68125955 | AA23: 54847.11 | AC23: 1.1404155e+08 | AD23: 0 | AE23: 260067.96
C24: 2319 | E24: 工程施工 | F24: 0.09 | G24: =SUM(J24,L24,N24,P24,R24,T24,V24,X24,Z24,AB24,AD24,AF24,AH24,AJ24,AL24,AN24,AP24,AR24,AU24,AW24,AY24,BC24,BG24) -> 4.0298493e+08 | H24: =SUM(K24,M24,O24,Q24,S24,U24,W24,Y24,AA24,AC24,AE24,AG24,AI24,AK24,AM24,AO24,AQ24,AS24,AV24,AX24,AZ24,BD24,BH24) -> 4.7599102e+08 | I24: =G24-H24 -> -73006093 | L24: -493692.65 | N24: 11024685 | P24: 9616720.9 | R24: 15488844 | S24: 0 | T24: 5873943.7 | U24: 1.0864265e+08 | V24: 8786601.5 | W24: 0 | X24: 15887463 | Y24: 0 | Z24: 43577732 | AB24: 2.9396666e+08 | AC24: 74125740 | AD24: -744034.87 | AE24: 2.9322263e+08
C25: 2319 | E25: 设计咨询 | F25: 0.06 | G25: =SUM(J25,L25,N25,P25,R25,T25,V25,X25,Z25,AB25,AD25,AF25,AH25,AJ25,AL25,AN25,AP25,AR25,AU25,AW25,AY25,BC25,BG25) -> 12445292 | H25: =SUM(K25,M25,O25,Q25,S25,U25,W25,Y25,AA25,AC25,AE25,AG25,AI25,AK25,AM25,AO25,AQ25,AS25,AV25,AX25,AZ25,BD25,BH25) -> 25072324 | I25: =G25-H25 -> -12627032 | P25: 572632.47 | R25: 1198794.8 | S25: 60092.57 | T25: 1933105.9 | U25: 15442087 | V25: =2056169.38+91089.15 -> 2147258.5 | W25: -1053820.4 | X25: 1316111 | Y25: 59315.74 | Z25: 5207673.3 | AC25: 10494933 | AF25: 69716.4 | AG25: 69716.4
B26: EPC自建 | C26: 2318 | D26: 定远欣月 | E26: 商品销售 | F26: 0.13 | G26: =SUM(J26,L26,N26,P26,R26,T26,V26,X26,Z26,AB26,AD26,AF26,AH26,AJ26,AL26,AN26,AP26,AR26,AU26,AW26,AY26,BC26,BG26) -> 91048578 | H26: =SUM(K26,M26,O26,Q26,S26,U26,W26,Y26,AA26,AC26,AE26,AG26,AI26,AK26,AM26,AO26,AQ26,AS26,AV26,AX26,AZ26,BD26,BH26) -> 94539002 | I26: =G26-H26 -> -3490424.3 | P26: 18248654 | R26: 14223009 | S26: 0 | T26: 24448246 | U26: 35962087 | V26: 6740165.1 | W26: 0 | X26: -3136198 | Y26: 0 | Z26: 30470275 | AB26: 54427.05 | AC26: 58576915
C27: 2318 | E27: 工程施工 | F27: 0.09 | G27: =SUM(J27,L27,N27,P27,R27,T27,V27,X27,Z27,AB27,AD27,AF27,AH27,AJ27,AL27,AN27,AP27,AR27,AU27,AW27,AY27,BC27,BG27) -> 2.385241e+08 | H27: =SUM(K27,M27,O27,Q27,S27,U27,W27,Y27,AA27,AC27,AE27,AG27,AI27,AK27,AM27,AO27,AQ27,AS27,AV27,AX27,AZ27,BD27,BH27) -> 2.7753196e+08 | I27: =G27-H27 -> -39007863 | L27: -634747.7 | N27: 4893183.6 | P27: 1363532.1 | R27: 7882465.7 | S27: 0 | T27: 3424803.4 | U27: 52512297 | V27: 3477768.1 | W27: 0 | X27: -545268.65 | Y27: 0 | Z27: 17266715 | AB27: 1.5728736e+08 | AC27: 1.8091138e+08 | AD27: 44108287 | AE27: 44108287
C28: 2318 | E28: 设计咨询 | F28: 0.06 | G28: =SUM(J28,L28,N28,P28,R28,T28,V28,X28,Z28,AB28,AD28,AF28,AH28,AJ28,AL28,AN28,AP28,AR28,AU28,AW28,AY28,BC28,BG28) -> 9887422.4 | H28: =SUM(K28,M28,O28,Q28,S28,U28,W28,Y28,AA28,AC28,AE28,AG28,AI28,AK28,AM28,AO28,AQ28,AS28,AV28,AX28,AZ28,BD28,BH28) -> 22107136 | I28: =G28-H28 -> -12219713 | L28: 625546.26 | N28: 721744.48 | P28: 1109241.8 | R28: 848738.92 | S28: 45069.41 | T28: 1125155.6 | U28: 16630790 | V28: =1480911.13+68316.91 -> 1549228 | W28: -935850.35 | X28: 281836.92 | Y28: 44486.75 | Z28: 3625930.4 | AC28: 6322639.7
B29: EPC自建 | C29: 2A50 | D29: 定远独立储能 | E29: 商品销售 | F29: 0.13 | G29: =SUM(J29,L29,N29,P29,R29,T29,V29,X29,Z29,AB29,AD29,AF29,AH29,AJ29,AL29,AN29,AP29,AR29,AU29,AW29,AY29,BC29,BG29) -> 0 | H29: =SUM(K29,M29,O29,Q29,S29,U29,W29,Y29,AA29,AC29,AE29,AG29,AI29,AK29,AM29,AO29,AQ29,AS29,AV29,AX29,AZ29,BD29,BH29) -> 9836350.8 | I29: =G29-H29 -> -9836350.8 | V29: 0 | W29: 0 | X29: 0 | Y29: 0 | Z29: 117923.07 | AH29: -117923.07 | AJ29: 0 | AK29: 9836350.8
C30: 2A50 | E30: 工程施工 | F30: 0.09 | G30: =SUM(J30,L30,N30,P30,R30,T30,V30,X30,Z30,AB30,AD30,AF30,AH30,AJ30,AL30,AN30,AP30,AR30,AU30,AW30,AY30,BC30,BG30) -> 2073641.8 | H30: =SUM(K30,M30,O30,Q30,S30,U30,W30,Y30,AA30,AC30,AE30,AG30,AI30,AK30,AM30,AO30,AQ30,AS30,AV30,AX30,AZ30,BD30,BH30) -> 30988092 | I30: =G30-H30 -> -28914451 | V30: 0 | W30: 0 | X30: 0 | Y30: 0 | Z30: 2073641.8 | AI30: 30988092
C31: 2A50 | E31: 设计咨询 | F31: 0.06 | G31: =SUM(J31,L31,N31,P31,R31,T31,V31,X31,Z31,AB31,AD31,AF31,AH31,AJ31,AL31,AN31,AP31,AR31,AU31,AW31,AY31,BC31,BG31) -> 1726122.2 | H31: =SUM(K31,M31,O31,Q31,S31,U31,W31,Y31,AA31,AC31,AE31,AG31,AI31,AK31,AM31,AO31,AQ31,AS31,AV31,AX31,AZ31,BD31,BH31) -> 8077291.4 | I31: =G31-H31 -> -6351169.2 | L31: 1262584.2 | N31: 112007.19 | Q31: 7725760.7 | U31: 0 | V31: 0 | W31: 0 | X31: 0 | Y31: 0 | Z31: 351530.75 | AJ31: 0 | AK31: 351530.74
B32: EPC自建 | C32: 1080 | D32: 丰宁 | E32: 商品销售 | F32: 0.13 | G32: =SUM(J32,L32,N32,P32,R32,T32,V32,X32,Z32,AB32,AD32,AF32,AH32,AJ32,AL32,AN32,AP32,AR32,AU32,AW32,AY32,BC32,BG32) -> 0 | H32: =SUM(K32,M32,O32,Q32,S32,U32,W32,Y32,AA32,AC32,AE32,AG32,AI32,AK32,AM32,AO32,AQ32,AS32,AV32,AX32,AZ32,BD32,BH32) -> 0 | I32: =G32-H32 -> 0
C33: 1080 | E33: 工程施工 | F33: 0.09 | G33: =SUM(J33,L33,N33,P33,R33,T33,V33,X33,Z33,AB33,AD33,AF33,AH33,AJ33,AL33,AN33,AP33,AR33,AU33,AW33,AY33,BC33,BG33) -> 0 | H33: =SUM(K33,M33,O33,Q33,S33,U33,W33,Y33,AA33,AC33,AE33,AG33,AI33,AK33,AM33,AO33,AQ33,AS33,AV33,AX33,AZ33,BD33,BH33) -> 379237.83 | I33: =G33-H33 -> -379237.83 | AI33: 379237.83
C34: 1080 | E34: 设计咨询 | F34: 0.06 | G34: =SUM(J34,L34,N34,P34,R34,T34,V34,X34,Z34,AB34,AD34,AF34,AH34,AJ34,AL34,AN34,AP34,AR34,AU34,AW34,AY34,BC34,BG34) -> 0 | H34: =SUM(K34,M34,O34,Q34,S34,U34,W34,Y34,AA34,AC34,AE34,AG34,AI34,AK34,AM34,AO34,AQ34,AS34,AV34,AX34,AZ34,BD34,BH34) -> 475794.07 | I34: =G34-H34 -> -475794.07 | AI34: 475794.07
B35: EPC自建 | C35: 1080 | D35: 丰宁二期 | E35: 商品销售 | F35: 0.13 | G35: =SUM(J35,L35,N35,P35,R35,T35,V35,X35,Z35,AB35,AD35,AF35,AH35,AJ35,AL35,AN35,AP35,AR35,AU35,AW35,AY35,BC35,BG35) -> 2.1818304e+08 | H35: =SUM(K35,M35,O35,Q35,S35,U35,W35,Y35,AA35,AC35,AE35,AG35,AI35,AK35,AM35,AO35,AQ35,AS35,AV35,AX35,AZ35,BD35,BH35) -> 2.0772881e+08 | I35: =G35-H35 -> 10454224 | N35: 22944611 | P35: 9632042.6 | Q35: 21162439 | R35: 35911880 | S35: 11414215 | T35: 10896695 | V35: 1.0628981e+08 | W35: 36354351 | X35: 4407911.8 | Y35: 83150389 | Z35: 28100089 | AA35: 27533528 | AE35: 4012784.8 | AI35: 24101106
C36: 1080 | E36: 工程施工 | F36: 0.09 | G36: =SUM(J36,L36,N36,P36,R36,T36,V36,X36,Z36,AB36,AD36,AF36,AH36,AJ36,AL36,AN36,AP36,AR36,AU36,AW36,AY36,BC36,BG36) -> 1.1833155e+09 | H36: =SUM(K36,M36,O36,Q36,S36,U36,W36,Y36,AA36,AC36,AE36,AG36,AI36,AK36,AM36,AO36,AQ36,AS36,AV36,AX36,AZ36,BD36,BH36) -> 1.0976805e+09 | I36: =G36-H36 -> 85635052 | L36: 2011104.1 | N36: 16149385 | P36: 24831319 | R36: 29735687 | S36: 49099875 | T36: 1.5868586e+08 | U36: 1.3761468e+08 | V36: 1.7189511e+08 | W36: 2.0677017e+08 | X36: 1.1730584e+08 | Y36: 1.2733723e+08 | Z36: 75373568 | AA36: 28836197 | AD36: 5.8732768e+08 | AE36: 1.4418091e+08 | AG36: 2.7522936e+08 | AI36: 1.2861208e+08 | AN36: -91743119 | AP36: 91743119
C37: 1080 | E37: 设计咨询 | F37: 0.06 | G37: =SUM(J37,L37,N37,P37,R37,T37,V37,X37,Z37,AB37,AD37,AF37,AH37,AJ37,AL37,AN37,AP37,AR37,AU37,AW37,AY37,BC37,BG37) -> 20771259 | H37: =SUM(K37,M37,O37,Q37,S37,U37,W37,Y37,AA37,AC37,AE37,AG37,AI37,AK37,AM37,AO37,AQ37,AS37,AV37,AX37,AZ37,BD37,BH37) -> 22230481 | I37: =G37-H37 -> -1459221.8 | L37: 439078.6 | N37: 1226790.2 | P37: -113038.25 | Q37: 2831283.8 | R37: 60092.57 | S37: 60092.57 | T37: 472894.22 | U37: 60296.37 | V37: =7294630.9+91089.15 -> 7385720 | W37: 684455.55 | X37: 2150705.6 | Y37: 7353946.6 | Z37: 9149015.7 | AA37: 2091389.9 | AE37: 9149015.7
B38: EPC自建 | C38: 1080 | D38: 丰宁三期 | E38: 商品销售 | F38: 0.13 | G38: =SUM(J38,L38,N38,P38,R38,T38,V38,X38,Z38,AB38,AD38,AF38,AH38,AJ38,AL38,AN38,AP38,AR38,AU38,AW38,AY38,BC38,BG38) -> 1.3184584e+08 | H38: =SUM(K38,M38,O38,Q38,S38,U38,W38,Y38,AA38,AC38,AE38,AG38,AI38,AK38,AM38,AO38,AQ38,AS38,AV38,AX38,AZ38,BD38,BH38) -> 1.4230007e+08 | I38: =G38-H38 -> -10454224 | N38: 11498521 | P38: 7347191.1 | Q38: 11498521 | R38: 6781679.1 | S38: 7347191.1 | T38: 0.02 | V38: 80139398 | W38: 17235903 | X38: 4038990.7 | Y38: 0 | Z38: 22040064 | AA38: 84178389 | AE38: 15258591 | AI38: 6781472.8
C39: 1080 | E39: 工程施工 | F39: 0.09 | G39: =SUM(J39,L39,N39,P39,R39,T39,V39,X39,Z39,AB39,AD39,AF39,AH39,AJ39,AL39,AN39,AP39,AR39,AU39,AW39,AY39,BC39,BG39) -> 4.5751058e+08 | H39: =SUM(K39,M39,O39,Q39,S39,U39,W39,Y39,AA39,AC39,AE39,AG39,AI39,AK39,AM39,AO39,AQ39,AS39,AV39,AX39,AZ39,BD39,BH39) -> 4.5996331e+08 | I39: =G39-H39 -> -2452735.4 | L39: 498586.12 | N39: 5439135.9 | P39: 15436790 | R39: 23070803 | S39: 23827247 | T39: 27932492 | V39: 33910823 | W39: 51003294 | X39: 24149722 | Y39: 21902159 | Z39: 25856795 | AA39: 36158386 | AD39: 3.0121543e+08 | AE39: 3.2707223e+08
C40: 1080 | E40: 设计咨询 | F40: 0.06 | G40: =SUM(J40,L40,N40,P40,R40,T40,V40,X40,Z40,AB40,AD40,AF40,AH40,AJ40,AL40,AN40,AP40,AR40,AU40,AW40,AY40,BC40,BG40) -> 16797953 | H40: =SUM(K40,M40,O40,Q40,S40,U40,W40,Y40,AA40,AC40,AE40,AG40,AI40,AK40,AM40,AO40,AQ40,AS40,AV40,AX40,AZ40,BD40,BH40) -> 19963111 | I40: =G40-H40 -> -3165158.3 | L40: 404945.11 | N40: 887361.61 | P40: -78904.76 | Q40: 4197791.7 | R40: 60092.57 | S40: 60092.57 | T40: 652067.3 | U40: 60296.37 | V40: =5996293.68+91089.15 -> 6087382.8 | W40: 863628.63 | X40: 1635477.4 | Y40: 59315.74 | Z40: 7149530.6 | AA40: 7572455.4 | AE40: 7149530.6
...

Sheet 累计项目税收明细表2017-202302
C1: 注意 | D1: 牟平、绿港历史项目须一、二期合并计算 | G1: =SUBTOTAL(9,G3:G349) -> 1.1897425e+10 | H1: =SUBTOTAL(9,H3:H349) -> 1.1509362e+10 | I1: =SUBTOTAL(9,I3:I349) -> 1.3200528e+09 | J1: =SUBTOTAL(9,J3:J349) -> 1.1896884e+10 | K1: =SUBTOTAL(9,K3:K349) -> 3.7949045e+08 | L1: =SUBTOTAL(9,L3:L349) -> -23479405 | M1: =SUBTOTAL(9,M3:M349) -> 1.5664612e+09 | N1: =SUBTOTAL(9,N3:N349) -> 8.5686222e+08 | ... EU1: =SUBTOTAL(9,EU3:EU349) -> 22112371 | EV1: =SUBTOTAL(9,EV3:EV349,EV351:EV354) -> 8.4086634e+08 | EW1: =SUBTOTAL(9,EW3:EW349,EW351:EW354) -> 5.2084957e+08 | EX1: =SUBTOTAL(9,EX3:EX349,EX351:EX354) -> 90002075 | EY1: =SUBTOTAL(9,EY3:EY349,EY351:EY354) -> 8.4086634e+08 | EZ1: =SUBTOTAL(9,EZ3:EZ349,EZ351:EZ354) -> 1.43 | FA1: =SUBTOTAL(9,FA3:FA349,FA351:FA354) -> 5.9911248e+08 | FB1: =SUBTOTAL(9,FB3:FB349,FB351:FB354) -> 5.2499889e+08 | FC1: =SUBTOTAL(9,FC3:FC349,FC351:FC354) -> 72791645 | ... GX1: =SUBTOTAL(9,GX3:GX349,GX351:GX354) -> -0.63000001
C2: 项目分类 | D2: 项目名称 | E2: 类别 | F2: 税率 | G2: 累计收入 | H2: 累计开票 | I2: 累计销项 | J2: 累计申报收入 | K2: 未开票收入 | L2: 预开票统计 | M2: 17-20年累计收入 | N2: 17-20年累计开票 | O2: 17-20年累计销项 | P2: 202013收入 | Q2: 202101收入 | R2: 202101开票 | S2: 202101销项 | T2: 202101申报收入 | U2: 帐税收入差异 | V2: 202102收入 | W2: 202102开票 | X2: 202102销项 | Y2: 202102申报收入 | Z2: 帐税收入差异 | AA2: 202103收入 | AB2: 202103开票 | AC2: 202103销项 | AD2: 202103申报收入 | AE2: 帐税收入差异 | AF2: 202104收入 | AG2: 202104开票 | AH2: 202104销项 | AI2: 202104申报收入 | AJ2: 帐税收入差异 | AK2: 202105收入 | AL2: 202105开票 | AM2: 202105销项 | AN2: 202105申报收入 | AO2: 帐税收入差异 | AP2: 202106收入 | AQ2: 202106开票 | AR2: 202106销项 | AS2: 202106申报收入 | AT2: 帐税收入差异 | AU2: 202107收入 | AV2: 202107开票 | AW2: 202107销项 | AX2: 202107申报收入 | AY2: 帐税收入差异 | AZ2: 202108收入 | BA2: 202108开票 | BB2: 202108销项 | BC2: 202108申报收入 | BD2: 帐税收入差异 | BE2: 202109收入 | BF2: 202109开票 | BG2: 202109销项 | BH2: 202109申报收入 | BI2: 帐税收入差异 | BJ2: 202110收入 | BK2: 202110开票 | BL2: 202110销项 | BM2: 202110申报收入 | BN2: 帐税收入差异 | BO2: 202111收入 | BP2: 202111开票 | BQ2: 202111销项 | BR2: 202111申报收入 | BS2: 帐税收入差异 | BT2: 202112收入 | BU2: 202112开票 | BV2: 202112销项 | BW2: 202112申报收入 | BX2: 帐税收入差异 | BY2: 202201收入 | BZ2: 202201开票 | CA2: 202201销项 | CB2: 202201申报收入 | CC2: 帐税收入差异 | CD2: 202202收入 | CE2: 202202开票 | CF2: 202202销项 | CG2: 202202申报收入 | CH2: 帐税收入差异 | CI2: 202203收入 | CJ2: 202203开票 | CK2: 202203销项 | CL2: 202203申报收入 | CM2: 帐税收入差异 | CN2: 202204收入 | CO2: 202204开票 | CP2: 202204销项 | CQ2: 202204申报收入 | CR2: 帐税收入差异 | CS2: 202205收入 | CT2: 202205开票 | CU2: 202205销项 | CV2: 202205申报收入 | CW2: 帐税收入差异 | CX2: 202206收入 | CY2: 202206开票 | CZ2: 202206销项 | DA2: 202206申报收入 | DB2: 帐税收入差异 | DC2: 202207收入 | DD2: 202207开票 | DE2: 202207销项 | DF2: 202207申报收入 | DG2: 帐税收入差异 | DH2: 202208收入 | DI2: 202208开票 | DJ2: 202208销项 | DK2: 202208申报收入 | DL2: 帐税收入差异 | DM2: 202209收入 | DN2: 202209开票 | DO2: 202209销项 | DP2: 202209申报收入 | DQ2: 帐税收入差异 | DR2: 202210收入 | DS2: 202210开票 | DT2: 202210销项 | DU2: 202210申报收入 | DV2: 帐税收入差异 | DW2: 202211收入 | DX2: 202211开票 | DY2: 202211销项 | DZ2: 202211申报收入 | EA2: 帐税收入差异 | EB2: 202212收入 | EC2: 202212开票 | ED2: 202212销项 | EE2: 202212申报收入 | EF2: 帐税收入差异 | EG2: 202301收入 | EH2: 202301开票 | EI2: 202301销项 | EJ2: 202301申报收入 | EK2: 帐税收入差异 | EL2: 202302收入 | EM2: 202302开票 | EN2: 202302销项 | EO2: 202302申报收入 | EP2: 帐税收入差异 | EQ2: 202303收入 | ER2: 202303开票 | ES2: 202303销项 | ET2: 202303申报收入 | EU2: 帐税收入差异 | EV2: 202304收入 | EW2: 202304开票 | EX2: 202304销项 | EY2: 202304申报收入 | EZ2: 帐税收入差异 | FA2: 202305收入 | FB2: 202305开票 | FC2: 202305销项 | FD2: 202305申报收入 | FE2: 帐税收入差异 | FF2: 202306收入 | FG2: 202306开票 | FH2: 202306销项 | FI2: 202306申报收入 | FJ2: 帐税收入差异 | FK2: 202307收入 | FL2: 202307开票 | FM2: 202307销项 | FN2: 202307申报收入 | FO2: 帐税收入差异 | FP2: 202308收入 | FQ2: 202308开票 | FR2: 202308销项 | FS2: 202308申报收入 | FT2: 帐税收入差异 | FU2: 202309收入 | FV2: 202309开票 | FW2: 202309销项 | FX2: 202309申报收入 | FY2: 帐税收入差异 | FZ2: 202310收入 | GA2: 202310开票 | GB2: 202310销项 | GC2: 202310申报收入 | GD2: 帐税收入差异 | GE2: 202311收入 | GF2: 202311开票 | GG2: 202311销项 | GH2: 202311申报收入 | GI2: 帐税收入差异 | GJ2: 202312收入 | GK2: 202312开票 | GL2: 202312销项 | GM2: 202312申报收入 | GN2: 帐税收入差异 | GO2: 202401收入 | GP2: 202401开票 | GQ2: 202401销项 | GR2: 202401申报收入 | GS2: 帐税收入差异 | GT2: 202402收入 | GU2: 202402开票 | GV2: 202402销项 | GW2: 202402申报收入 | GX2: 帐税收入差异
B3: 1050 | C3: 内部EPC项目 | D3: 1050（智慧能源） | E3: 商品销售 | F3: 0.16 | G3: =SUM(M3,P3:Q3,V3,AA3,AF3,AK3,AP3,AU3,AZ3,BE3,BJ3,BO3,BT3,BY3,CD3,CI3,CN3,CS3,CX3,DC3,DH3,DM3,DR3,DW3,EB3,EG3,EL3,EQ3,EV3,FA3,FF3,FK3,FP3,FU3,FZ3,GE3,GJ3,GO3,GT3) -> 0 | H3: =SUM(N3,R3,W3,AB3,AG3,AL3,AQ3,AV3,BA3,BF3,BK3,BP3,BU3,BZ3,CE3,CJ3,CO3,CT3,CY3,DD3,DI3,DN3,DS3,DX3,EC3,EH3,EM3,ER3,EW3,FB3,FG3,FL3,FQ3,FV3,GA3,GF3,GK3,GP3,GU3) -> 0 | I3: =SUM(O3,S3,X3,AC3,AH3,AM3,AR3,AW3,BB3,BG3,BL3,BQ3,BV3,CA3,CF3,CK3,CP3,CU3,CZ3,DE3,DJ3,DO3,DT3,DY3,ED3,EI3,EN3,ES3,EX3,FC3,FH3,FM3,FR3,FW3,GB3,GG3,GL3,GQ3,GV3) -> 0 | J3: =I3/F3 -> 0 | K3: =I3/F3-H3 -> 0 | L3: =H3-J3 -> 0 | M3: =SUM(S3,V3:W3,AB3,AG3,AL3,AQ3,AV3,BA3,BF3,BK3,BP3,BU3,BZ3,CE3,CJ3,CO3,CT3,CY3,DD3,DI3,DN3,DS3,DX3,EC3,EH3,EM3,ER3,EW3,FB3) -> 0 | N3: =SUM(T3,X3,AC3,AH3,AM3,AR3,AW3,BB3,BG3,BL3,BQ3,BV3,CA3,CF3,CK3,CP3,CU3,CZ3,DE3,DJ3,DO3,DT3,DY3,ED3,EI3,EN3,ES3,EX3,FC3) -> 0 | O3: =SUM(U3,Y3,AD3,AI3,AN3,AS3,AX3,BC3,BH3,BM3,BR3,BW3,CB3,CG3,CL3,CQ3,CV3,DA3,DF3,DK3,DP3,DU3,DZ3,EE3,EJ3,EO3,ET3,EY3,FD3) -> 0 | P3: =SUM(V3,Y3:Z3,AE3,AJ3,AO3,AT3,AY3,BD3,BI3,BN3,BS3,BX3,CC3,CH3,CM3,CR3,CW3,DB3,DG3,DL3,DQ3,DV3,EA3,EF3,EK3,EP3,EU3,EZ3,FE3) -> 0 | Q3: =SUM(W3,AA3,AF3,AK3,AP3,AU3,AZ3,BE3,BJ3,BO3,BT3,BY3,CD3,CI3,CN3,CS3,CX3,DC3,DH3,DM3,DR3,DW3,EB3,EG3,EL3,EQ3,EV3,FA3,FF3) -> 0 | R3: =SUM(X3,AB3,AG3,AL3,AQ3,AV3,BA3,BF3,BK3,BP3,BU3,BZ3,CE3,CJ3,CO3,CT3,CY3,DD3,DI3,DN3,DS3,DX3,EC3,EH3,EM3,ER3,EW3,FB3,FG3) -> 0 | S3: =SUM(Y3,AB3:AC3,AH3,AM3,AR3,AW3,BB3,BG3,BL3,BQ3,BV3,CA3,CF3,CK3,CP3,CU3,CZ3,DE3,DJ3,DO3,DT3,DY3,ED3,EI3,EN3,ES3,EX3,FC3,FH3) -> 0 | T3: =SUM(Z3,AD3,AI3,AN3,AS3,AX3,BC3,BH3,BM3,BR3,BW3,CB3,CG3,CL3,CQ3,CV3,DA3,DF3,DK3,DP3,DU3,DZ3,EE3,EJ3,EO3,ET3,EY3,FD3,FI3) -> 0 | U3: =SUM(AA3,AE3,AJ3,AO3,AT3,AY3,BD3,BI3,BN3,BS3,BX3,CC3,CH3,CM3,CR3,CW3,DB3,DG3,DL3,DQ3,DV3,EA3,EF3,EK3,EP3,EU3,EZ3,FE3,FJ3) -> 0 | V3: =SUM(AB3,AE3:AF3,AK3,AP3,AU3,AZ3,BE3,BJ3,BO3,BT3,BY3,CD3,CI3,CN3,CS3,CX3,DC3,DH3,DM3,DR3,DW3,EB3,EG3,EL3,EQ3,EV3,FA3,FF3,FK3) -> 0 | W3: =SUM(AC3,AG3,AL3,AQ3,AV3,BA3,BF3,BK3,BP3,BU3,BZ3,CE3,CJ3,CO3,CT3,CY3,DD3,DI3,DN3,DS3,DX3,EC3,EH3,EM3,ER3,EW3,FB3,FG3,FL3) -> 0 | X3: =SUM(AD3,AH3,AM3,AR3,AW3,BB3,BG3,BL3,BQ3,BV3,CA3,CF3,CK3,CP3,CU3,CZ3,DE3,DJ3,DO3,DT3,DY3,ED3,EI3,EN3,ES3,EX3,FC3,FH3,FM3) -> 0 | Y3: =SUM(AE3,AH3:AI3,AN3,AS3,AX3,BC3,BH3,BM3,BR3,BW3,CB3,CG3,CL3,CQ3,CV3,DA3,DF3,DK3,DP3,DU3,DZ3,EE3,EJ3,EO3,ET3,EY3,FD3,FI3,FN3) -> 0 | Z3: =SUM(AF3,AJ3,AO3,AT3,AY3,BD3,BI3,BN3,BS3,BX3,CC3,CH3,CM3,CR3,CW3,DB3,DG3,DL3,DQ3,DV3,EA3,EF3,EK3,EP3,EU3,EZ3,FE3,FJ3,FO3) -> 0 | AA3: =SUM(AG3,AK3,AP3,AU3,AZ3,BE3,BJ3,BO3,BT3,BY3,CD3,CI3,CN3,CS3,CX3,DC3,DH3,DM3,DR3,DW3,EB3,EG3,EL3,EQ3,EV3,FA3,FF3,FK3,FP3) -> 0 | AB3: =SUM(AH3,AK3:AL3,AQ3,AV3,BA3,BF3,BK3,BP3,BU3,BZ3,CE3,CJ3,CO3,CT3,CY3,DD3,DI3,DN3,DS3,DX3,EC3,EH3,EM3,ER3,EW3,FB3,FG3,FL3,FQ3) -> 0 | AC3: =SUM(AI3,AM3,AR3,AW3,BB3,BG3,BL3,BQ3,BV3,CA3,CF3,CK3,CP3,CU3,CZ3,DE3,DJ3,DO3,DT3,DY3,ED3,EI3,EN3,ES3,EX3,FC3,FH3,FM3,FR3) -> 0 | AD3: =SUM(AJ3,AN3,AS3,AX3,BC3,BH3,BM3,BR3,BW3,CB3,CG3,CL3,CQ3,CV3,DA3,DF3,DK3,DP3,DU3,DZ3,EE3,EJ3,EO3,ET3,EY3,FD3,FI3,FN3,FS3) -> 0 | AE3: =SUM(AK3,AN3:AO3,AT3,AY3,BD3,BI3,BN3,BS3,BX3,CC3,CH3,CM3,CR3,CW3,DB3,DG3,DL3,DQ3,DV3,EA3,EF3,EK3,EP3,EU3,EZ3,FE3,FJ3,FO3,FT3) -> 0 | AF3: =SUM(AL3,AP3,AU3,AZ3,BE3,BJ3,BO3,BT3,BY3,CD3,CI3,CN3,CS3,CX3,DC3,DH3,DM3,DR3,DW3,EB3,EG3,EL3,EQ3,EV3,FA3,FF3,FK3,FP3,FU3) -> 0 | AG3: =SUM(AM3,AQ3,AV3,BA3,BF3,BK3,BP3,BU3,BZ3,CE3,CJ3,CO3,CT3,CY3,DD3,DI3,DN3,DS3,DX3,EC3,EH3,EM3,ER3,EW3,FB3,FG3,FL3,FQ3,FV3) -> 0 | AH3: =SUM(AN3,AQ3:AR3,AW3,BB3,BG3,BL3,BQ3,BV3,CA3,CF3,CK3,CP3,CU3,CZ3,DE3,DJ3,DO3,DT3,DY3,ED3,EI3,EN3,ES3,EX3,FC3,FH3,FM3,FR3,FW3) -> 0 | AI3: =SUM(AO3,AS3,AX3,BC3,BH3,BM3,BR3,BW3,CB3,CG3,CL3,CQ3,CV3,DA3,DF3,DK3,DP3,DU3,DZ3,EE3,EJ3,EO3,ET3,EY3,FD3,FI3,FN3,FS3,FX3) -> 0 | AJ3: =SUM(AP3,AT3,AY3,BD3,BI3,BN3,BS3,BX3,CC3,CH3,CM3,CR3,CW3,DB3,DG3,DL3,DQ3,DV3,EA3,EF3,EK3,EP3,EU3,EZ3,FE3,FJ3,FO3,FT3,FY3) -> 0 | AK3: =SUM(AQ3,AT3:AU3,AZ3,BE3,BJ3,BO3,BT3,BY3,CD3,CI3,CN3,CS3,CX3,DC3,DH3,DM3,DR3,DW3,EB3,EG3,EL3,EQ3,EV3,FA3,FF3,FK3,FP3,FU3,FZ3) -> 0 | AL3: =SUM(AR3,AV3,BA3,BF3,BK3,BP3,BU3,BZ3,CE3,CJ3,CO3,CT3,CY3,DD3,DI3,DN3,DS3,DX3,EC3,EH3,EM3,ER3,EW3,FB3,FG3,FL3,FQ3,FV3,GA3) -> 0 | AM3: =SUM(AS3,AW3,BB3,BG3,BL3,BQ3,BV3,CA3,CF3,CK3,CP3,CU3,CZ3,DE3,DJ3,DO3,DT3,DY3,ED3,EI3,EN3,ES3,EX3,FC3,FH3,FM3,FR3,FW3,GB3) -> 0 | AN3: =SUM(AT3,AW3:AX3,BC3,BH3,BM3,BR3,BW3,CB3,CG3,CL3,CQ3,CV3,DA3,DF3,DK3,DP3,DU3,DZ3,EE3,EJ3,EO3,ET3,EY3,FD3,FI3,FN3,FS3,FX3,GC3) -> 0 | AO3: =SUM(AU3,AY3,BD3,BI3,BN3,BS3,BX3,CC3,CH3,CM3,CR3,CW3,DB3,DG3,DL3,DQ3,DV3,EA3,EF3,EK3,EP3,EU3,EZ3,FE3,FJ3,FO3,FT3,FY3,GD3) -> 0 | AP3: =SUM(AV3,AZ3,BE3,BJ3,BO3,BT3,BY3,CD3,CI3,CN3,CS3,CX3,DC3,DH3,DM3,DR3,DW3,EB3,EG3,EL3,EQ3,EV3,FA3,FF3,FK3,FP3,FU3,FZ3,GE3) -> 0 | AQ3: =SUM(AW3,AZ3:BA3,BF3,BK3,BP3,BU3,BZ3,CE3,CJ3,CO3,CT3,CY3,DD3,DI3,DN3,DS3,DX3,EC3,EH3,EM3,ER3,EW3,FB3,FG3,FL3,FQ3,FV3,GA3,GF3) -> 0 | AR3: =SUM(AX3,BB3,BG3,BL3,BQ3,BV3,CA3,CF3,CK3,CP3,CU3,CZ3,DE3,DJ3,DO3,DT3,DY3,ED3,EI3,EN3,ES3,EX3,FC3,FH3,FM3,FR3,FW3,GB3,GG3) -> 0 | AS3: =SUM(AY3,BC3,BH3,BM3,BR3,BW3,CB3,CG3,CL3,CQ3,CV3,DA3,DF3,DK3,DP3,DU3,DZ3,EE3,EJ3,EO3,ET3,EY3,FD3,FI3,FN3,FS3,FX3,GC3,GH3) -> 0 | AT3: =SUM(AZ3,BC3:BD3,BI3,BN3,BS3,BX3,CC3,CH3,CM3,CR3,CW3,DB3,DG3,DL3,DQ3,DV3,EA3,EF3,EK3,EP3,EU3,EZ3,FE3,FJ3,FO3,FT3,FY3,GD3,GI3) -> 0 | AU3: =SUM(BA3,BE3,BJ3,BO3,BT3,BY3,CD3,CI3,CN3,CS3,CX3,DC3,DH3,DM3,DR3,DW3,EB3,EG3,EL3,EQ3,EV3,FA3,FF3,FK3,FP3,FU3,FZ3,GE3,GJ3) -> 0 | AV3: =SUM(BB3,BF3,BK3,BP3,BU3,BZ3,CE3,CJ3,CO3,CT3,CY3,DD3,DI3,DN3,DS3,DX3,EC3,EH3,EM3,ER3,EW3,FB3,FG3,FL3,FQ3,FV3,GA3,GF3,GK3) -> 0 | AW3: =SUM(BC3,BF3:BG3,BL3,BQ3,BV3,CA3,CF3,CK3,CP3,CU3,CZ3,DE3,DJ3,DO3,DT3,DY3,ED3,EI3,EN3,ES3,EX3,FC3,FH3,FM3,FR3,FW3,GB3,GG3,GL3) -> 0 | AX3: =SUM(BD3,BH3,BM3,BR3,BW3,CB3,CG3,CL3,CQ3,CV3,DA3,DF3,DK3,DP3,DU3,DZ3,EE3,EJ3,EO3,ET3,EY3,FD3,FI3,FN3,FS3,FX3,GC3,GH3,GM3) -> 0 | AY3: =SUM(BE3,BI3,BN3,BS3,BX3,CC3,CH3,CM3,CR3,CW3,DB3,DG3,DL3,DQ3,DV3,EA3,EF3,EK3,EP3,EU3,EZ3,FE3,FJ3,FO3,FT3,FY3,GD3,GI3,GN3) -> 0 | AZ3: =SUM(BF3,BI3:BJ3,BO3,BT3,BY3,CD3,CI3,CN3,CS3,CX3,DC3,DH3,DM3,DR3,DW3,EB3,EG3,EL3,EQ3,EV3,FA3,FF3,FK3,FP3,FU3,FZ3,GE3,GJ3,GO3) -> 0 | BA3: =SUM(BG3,BK3,BP3,BU3,BZ3,CE3,CJ3,CO3,CT3,CY3,DD3,DI3,DN3,DS3,DX3,EC3,EH3,EM3,ER3,EW3,FB3,FG3,FL3,FQ3,FV3,GA3,GF3,GK3,GP3) -> 0 | BB3: =SUM(BH3,BL3,BQ3,BV3,CA3,CF3,CK3,CP3,CU3,CZ3,DE3,DJ3,DO3,DT3,DY3,ED3,EI3,EN3,ES3,EX3,FC3,FH3,FM3,FR3,FW3,GB3,GG3,GL3,GQ3) -> 0 | BC3: =SUM(BI3,BL3:BM3,BR3,BW3,CB3,CG3,CL3,CQ3,CV3,DA3,DF3,DK3,DP3,DU3,DZ3,EE3,EJ3,EO3,ET3,EY3,FD3,FI3,FN3,FS3,FX3,GC3,GH3,GM3,GR3) -> 0 | BD3: =SUM(BJ3,BN3,BS3,BX3,CC3,CH3,CM3,CR3,CW3,DB3,DG3,DL3,DQ3,DV3,EA3,EF3,EK3,EP3,EU3,EZ3,FE3,FJ3,FO3,FT3,FY3,GD3,GI3,GN3,GS3) -> 0 | BE3: =SUM(BK3,BO3,BT3,BY3,CD3,CI3,CN3,CS3,CX3,DC3,DH3,DM3,DR3,DW3,EB3,EG3,EL3,EQ3,EV3,FA3,FF3,FK3,FP3,FU3,FZ3,GE3,GJ3,GO3,GT3) -> 0 | BF3: =SUM(BL3,BO3:BP3,BU3,BZ3,CE3,CJ3,CO3,CT3,CY3,DD3,DI3,DN3,DS3,DX3,EC3,EH3,EM3,ER3,EW3,FB3,FG3,FL3,FQ3,FV3,GA3,GF3,GK3,GP3,GU3) -> 0 | BG3: =SUM(BM3,BQ3,BV3,CA3,CF3,CK3,CP3,CU3,CZ3,DE3,DJ3,DO3,DT3,DY3,ED3,EI3,EN3,ES3,EX3,FC3,FH3,FM3,FR3,FW3,GB3,GG3,GL3,GQ3,GV3) -> 0 | BH3: =SUM(BN3,BR3,BW3,CB3,CG3,CL3,CQ3,CV3,DA3,DF3,DK3,DP3,DU3,DZ3,EE3,EJ3,EO3,ET3,EY3,FD3,FI3,FN3,FS3,FX3,GC3,GH3,GM3,GR3,GW3) -> 0 | BI3: =SUM(BO3,BR3:BS3,BX3,CC3,CH3,CM3,CR3,CW3,DB3,DG3,DL3,DQ3,DV3,EA3,EF3,EK3,EP3,EU3,EZ3,FE3,FJ3,FO3,FT3,FY3,GD3,GI3,GN3,GS3,GX3) -> 0 | BJ3: =SUM(BP3,BT3,BY3,CD3,CI3,CN3,CS3,CX3,DC3,DH3,DM3,DR3,DW3,EB3,EG3,EL3,EQ3,EV3,FA3,FF3,FK3,FP3,FU3,FZ3,GE3,GJ3,GO3,GT3,GY3) -> 0 | BK3: =SUM(BQ3,BU3,BZ3,CE3,CJ3,CO3,CT3,CY3,DD3,DI3,DN3,DS3,DX3,EC3,EH3,EM3,ER3,EW3,FB3,FG3,FL3,FQ3,FV3,GA3,GF3,GK3,GP3,GU3,GZ3) -> 0 | BL3: =SUM(BR3,BU3:BV3,CA3,CF3,CK3,CP3,CU3,CZ3,DE3,DJ3,DO3,DT3,DY3,ED3,EI3,EN3,ES3,EX3,FC3,FH3,FM3,FR3,FW3,GB3,GG3,GL3,GQ3,GV3,HA3) -> 0 | BM3: =SUM(BS3,BW3,CB3,CG3,CL3,CQ3,CV3,DA3,DF3,DK3,DP3,DU3,DZ3,EE3,EJ3,EO3,ET3,EY3,FD3,FI3,FN3,FS3,FX3,GC3,GH3,GM3,GR3,GW3,HB3) -> 0 | BN3: =SUM(BT3,BX3,CC3,CH3,CM3,CR3,CW3,DB3,DG3,DL3,DQ3,DV3,EA3,EF3,EK3,EP3,EU3,EZ3,FE3,FJ3,FO3,FT3,FY3,GD3,GI3,GN3,GS3,GX3,HC3) -> 0 | BO3: =SUM(BU3,BX3:BY3,CD3,CI3,CN3,CS3,CX3,DC3,DH3,DM3,DR3,DW3,EB3,EG3,EL3,EQ3,EV3,FA3,FF3,FK3,FP3,FU3,FZ3,GE3,GJ3,GO3,GT3,GY3,HD3) -> 0 | BP3: =SUM(BV3,BZ3,CE3,CJ3,CO3,CT3,CY3,DD3,DI3,DN3,DS3,DX3,EC3,EH3,EM3,ER3,EW3,FB3,FG3,FL3,FQ3,FV3,GA3,GF3,GK3,GP3,GU3,GZ3,HE3) -> 0 | BQ3: =SUM(BW3,CA3,CF3,CK3,CP3,CU3,CZ3,DE3,DJ3,DO3,DT3,DY3,ED3,EI3,EN3,ES3,EX3,FC3,FH3,FM3,FR3,FW3,GB3,GG3,GL3,GQ3,GV3,HA3,HF3) -> 0 | BR3: =SUM(BX3,CA3:CB3,CG3,CL3,CQ3,CV3,DA3,DF3,DK3,DP3,DU3,DZ3,EE3,EJ3,EO3,ET3,EY3,FD3,FI3,FN3,FS3,FX3,GC3,GH3,GM3,GR3,GW3,HB3,HG3) -> 0 | BS3: =SUM(BY3,CC3,CH3,CM3,CR3,CW3,DB3,DG3,DL3,DQ3,DV3,EA3,EF3,EK3,EP3,EU3,EZ3,FE3,FJ3,FO3,FT3,FY3,GD3,GI3,GN3,GS3,GX3,HC3,HH3) -> 0 | BT3: =SUM(BZ3,CD3,CI3,CN3,CS3,CX3,DC3,DH3,DM3,DR3,DW3,EB3,EG3,EL3,EQ3,EV3,FA3,FF3,FK3,FP3,FU3,FZ3,GE3,GJ3,GO3,GT3,GY3,HD3,HI3) -> 0 | BU3: =SUM(CA3,CD3:CE3,CJ3,CO3,CT3,CY3,DD3,DI3,DN3,DS3,DX3,EC3,EH3,EM3,ER3,EW3,FB3,FG3,FL3,FQ3,FV3,GA3,GF3,GK3,GP3,GU3,GZ3,HE3,HJ3) -> 0 | BV3: =SUM(CB3,CF3,CK3,CP3,CU3,CZ3,DE3,DJ3,DO3,DT3,DY3,ED3,EI3,EN3,ES3,EX3,FC3,FH3,FM3,FR3,FW3,GB3,GG3,GL3,GQ3,GV3,HA3,HF3,HK3) -> 0 | BW3: =SUM(CC3,CG3,CL3,CQ3,CV3,DA3,DF3,DK3,DP3,DU3,DZ3,EE3,EJ3,EO3,ET3,EY3,FD3,FI3,FN3,FS3,FX3,GC3,GH3,GM3,GR3,GW3,HB3,HG3,HL3) -> 0 | BX3: =SUM(CD3,CG3:CH3,CM3,CR3,CW3,DB3,DG3,DL3,DQ3,DV3,EA3,EF3,EK3,EP3,EU3,EZ3,FE3,FJ3,FO3,FT3,FY3,GD3,GI3,GN3,GS3,GX3,HC3,HH3,HM3) -> 0 | BY3: =SUM(CE3,CI3,CN3,CS3,CX3,DC3,DH3,DM3,DR3,DW3,EB3,EG3,EL3,EQ3,EV3,FA3,FF3,FK3,FP3,FU3,FZ3,GE3,GJ3,GO3,GT3,GY3,HD3,HI3,HN3) -> 0 | BZ3: =SUM(CF3,CJ3,CO3,CT3,CY3,DD3,DI3,DN3,DS3,DX3,EC3,EH3,EM3,ER3,EW3,FB3,FG3,FL3,FQ3,FV3,GA3,GF3,GK3,GP3,GU3,GZ3,HE3,HJ3,HO3) -> 0 | CA3: =SUM(CG3,CJ3:CK3,CP3,CU3,CZ3,DE3,DJ3,DO3,DT3,DY3,ED3,EI3,EN3,ES3,EX3,FC3,FH3,FM3,FR3,FW3,GB3,GG3,GL3,GQ3,GV3,HA3,HF3,HK3,HP3) -> 0 | CB3: =SUM(CH3,CL3,CQ3,CV3,DA3,DF3,DK3,DP3,DU3,DZ3,EE3,EJ3,EO3,ET3,EY3,FD3,FI3,FN3,FS3,FX3,GC3,GH3,GM3,GR3,GW3,HB3,HG3,HL3,HQ3) -> 0 | CC3: =SUM(CI3,CM3,CR3,CW3,DB3,DG3,DL3,DQ3,DV3,EA3,EF3,EK3,EP3,EU3,EZ3,FE3,FJ3,FO3,FT3,FY3,GD3,GI3,GN3,GS3,GX3,HC3,HH3,HM3,HR3) -> 0 | CD3: =SUM(CJ3,CM3:CN3,CS3,CX3,DC3,DH3,DM3,DR3,DW3,EB3,EG3,EL3,EQ3,EV3,FA3,FF3,FK3,FP3,FU3,FZ3,GE3,GJ3,GO3,GT3,GY3,HD3,HI3,HN3,HS3) -> 0 | CE3: =SUM(CK3,CO3,CT3,CY3,DD3,DI3,DN3,DS3,DX3,EC3,EH3,EM3,ER3,EW3,FB3,FG3,FL3,FQ3,FV3,GA3,GF3,GK3,GP3,GU3,GZ3,HE3,HJ3,HO3,HT3) -> 0 | CF3: =SUM(CL3,CP3,CU3,CZ3,DE3,DJ3,DO3,DT3,DY3,ED3,EI3,EN3,ES3,EX3,FC3,FH3,FM3,FR3,FW3,GB3,GG3,GL3,GQ3,GV3,HA3,HF3,HK3,HP3,HU3) -> 0 | CG3: =SUM(CM3,CP3:CQ3,CV3,DA3,DF3,DK3,DP3,DU3,DZ3,EE3,EJ3,EO3,ET3,EY3,FD3,FI3,FN3,FS3,FX3,GC3,GH3,GM3,GR3,GW3,HB3,HG3,HL3,HQ3,HV3) -> 0 | CH3: =SUM(CN3,CR3,CW3,DB3,DG3,DL3,DQ3,DV3,EA3,EF3,EK3,EP3,EU3,EZ3,FE3,FJ3,FO3,FT3,FY3,GD3,GI3,GN3,GS3,GX3,HC3,HH3,HM3,HR3,HW3) -> 0 | CI3: =SUM(CO3,CS3,CX3,DC3,DH3,DM3,DR3,DW3,EB3,EG3,EL3,EQ3,EV3,FA3,FF3,FK3,FP3,FU3,FZ3,GE3,GJ3,GO3,GT3,GY3,HD3,HI3,HN3,HS3,HX3) -> 0 | CJ3: =SUM(CP3,CS3:CT3,CY3,DD3,DI3,DN3,DS3,DX3,EC3,EH3,EM3,ER3,EW3,FB3,FG3,FL3,FQ3,FV3,GA3,GF3,GK3,GP3,GU3,GZ3,HE3,HJ3,HO3,HT3,HY3) -> 0 | CK3: =SUM(CQ3,CU3,CZ3,DE3,DJ3,DO3,DT3,DY3,ED3,EI3,EN3,ES3,EX3,FC3,FH3,FM3,FR3,FW3,GB3,GG3,GL3,GQ3,GV3,HA3,HF3,HK3,HP3,HU3,HZ3) -> 0 | CL3: =SUM(CR3,CV3,DA3,DF3,DK3,DP3,DU3,DZ3,EE3,EJ3,EO3,ET3,EY3,FD3,FI3,FN3,FS3,FX3,GC3,GH3,GM3,GR3,GW3,HB3,HG3,HL3,HQ3,HV3,IA3) -> 0 | CM3: =SUM(CS3,CV3:CW3,DB3,DG3,DL3,DQ3,DV3,EA3,EF3,EK3,EP3,EU3,EZ3,FE3,FJ3,FO3,FT3,FY3,GD3,GI3,GN3,GS3,GX3,HC3,HH3,HM3,HR3,HW3,IB3) -> 0 | CN3: =SUM(CT3,CX3,DC3,DH3,DM3,DR3,DW3,EB3,EG3,EL3,EQ3,EV3,FA3,FF3,FK3,FP3,FU3,FZ3,GE3,GJ3,GO3,GT3,GY3,HD3,HI3,HN3,HS3,HX3,IC3) -> 0 | CO3: =SUM(CU3,CY3,DD3,DI3,DN3,DS3,DX3,EC3,EH3,EM3,ER3,EW3,FB3,FG3,FL3,FQ3,FV3,GA3,GF3,GK3,GP3,GU3,GZ3,HE3,HJ3,HO3,HT3,HY3,ID3) -> 0 | CP3: =SUM(CV3,CY3:CZ3,DE3,DJ3,DO3,DT3,DY3,ED3,EI3,EN3,ES3,EX3,FC3,FH3,FM3,FR3,FW3,GB3,GG3,GL3,GQ3,GV3,HA3,HF3,HK3,HP3,HU3,HZ3,IE3) -> 0 | CQ3: =SUM(CW3,DA3,DF3,DK3,DP3,DU3,DZ3,EE3,EJ3,EO3,ET3,EY3,FD3,FI3,FN3,FS3,FX3,GC3,GH3,GM3,GR3,GW3,HB3,HG3,HL3,HQ3,HV3,IA3,IF3) -> 0 | CR3: =SUM(CX3,DB3,DG3,DL3,DQ3,DV3,EA3,EF3,EK3,EP3,EU3,EZ3,FE3,FJ3,FO3,FT3,FY3,GD3,GI3,GN3,GS3,GX3,HC3,HH3,HM3,HR3,HW3,IB3,IG3) -> 0 | CS3: =SUM(CY3,DB3:DC3,DH3,DM3,DR3,DW3,EB3,EG3,EL3,EQ3,EV3,FA3,FF3,FK3,FP3,FU3,FZ3,GE3,GJ3,GO3,GT3,GY3,HD3,HI3,HN3,HS3,HX3,IC3,IH3) -> 0 | CT3: =SUM(CZ3,DD3,DI3,DN3,DS3,DX3,EC3,EH3,EM3,ER3,EW3,FB3,FG3,FL3,FQ3,FV3,GA3,GF3,GK3,GP3,GU3,GZ3,HE3,HJ3,HO3,HT3,HY3,ID3,II3) -> 0 | CU3: =SUM(DA3,DE3,DJ3,DO3,DT3,DY3,ED3,EI3,EN3,ES3,EX3,FC3,FH3,FM3,FR3,FW3,GB3,GG3,GL3,GQ3,GV3,HA3,HF3,HK3,HP3,HU3,HZ3,IE3,IJ3) -> 0 | CV3: =SUM(DB3,DE3:DF3,DK3,DP3,DU3,DZ3,EE3,EJ3,EO3,ET3,EY3,FD3,FI3,FN3,FS3,FX3,GC3,GH3,GM3,GR3,GW3,HB3,HG3,HL3,HQ3,HV3,IA3,IF3,IK3) -> 0 | CW3: =SUM(DC3,DG3,DL3,DQ3,DV3,EA3,EF3,EK3,EP3,EU3,EZ3,FE3,FJ3,FO3,FT3,FY3,GD3,GI3,GN3,GS3,GX3,HC3,HH3,HM3,HR3,HW3,IB3,IG3,IL3) -> 0 | CX3: =SUM(DD3,DH3,DM3,DR3,DW3,EB3,EG3,EL3,EQ3,EV3,FA3,FF3,FK3,FP3,FU3,FZ3,GE3,GJ3,GO3,GT3,GY3,HD3,HI3,HN3,HS3,HX3,IC3,IH3,IM3) -> 0 | CY3: =SUM(DE3,DH3:DI3,DN3,DS3,DX3,EC3,EH3,EM3,ER3,EW3,FB3,FG3,FL3,FQ3,FV3,GA3,GF3,GK3,GP3,GU3,GZ3,HE3,HJ3,HO3,HT3,HY3,ID3,II3,IN3) -> 0 | CZ3: =SUM(DF3,DJ3,DO3,DT3,DY3,ED3,EI3,EN3,ES3,EX3,FC3,FH3,FM3,FR3,FW3,GB3,GG3,GL3,GQ3,GV3,HA3,HF3,HK3,HP3,HU3,HZ3,IE3,IJ3,IO3) -> 0 | DA3: =SUM(DG3,DK3,DP3,DU3,DZ3,EE3,EJ3,EO3,ET3,EY3,FD3,FI3,FN3,FS3,FX3,GC3,GH3,GM3,GR3,GW3,HB3,HG3,HL3,HQ3,HV3,IA3,IF3,IK3,IP3) -> 0 | DB3: =SUM(DH3,DK3:DL3,DQ3,DV3,EA3,EF3,EK3,EP3,EU3,EZ3,FE3,FJ3,FO3,FT3,FY3,GD3,GI3,GN3,GS3,GX3,HC3,HH3,HM3,HR3,HW3,IB3,IG3,IL3,IQ3) -> 0 | DC3: =SUM(DI3,DM3,DR3,DW3,EB3,EG3,EL3,EQ3,EV3,FA3,FF3,FK3,FP3,FU3,FZ3,GE3,GJ3,GO3,GT3,GY3,HD3,HI3,HN3,HS3,HX3,IC3,IH3,IM3,IR3) -> 0 | DF3: =DE3/F3 -> 0 | DG3: =DC3-DF3 -> 0 | DK3: =DJ3/F3 -> 0 | DL3: =DK3-DH3 -> 0 | DP3: =DO3/F3 -> 0 | DQ3: =DP3-DM3 -> 0 | DU3: =DT3/F3 -> 0 | DV3: =DU3-DR3 -> 0 | DZ3: =ROUND(DY3/F3,2) -> 0 | EA3: =ROUND(DZ3-DW3,2) -> 0 | EF3: =EE3-EB3 -> 0 | EJ3: =ROUND(EI3/F3,2) -> 0 | EK3: =ROUND(EJ3-EG3,2) -> 0 | EO3: =ROUND(EN3/F3,2) -> 0 | EP3: =ROUND(EO3-EL3,2) -> 0 | ET3: =ROUND(ES3/F3,2) -> 0 | EU3: =ROUND(ET3-EQ3,2) -> 0 | EY3: =ROUND(EX3/F3,2) -> 0 | EZ3: =ROUND(EY3-EV3,2) -> 0 | FD3: =ROUND(FC3/F3,2) -> 0 | FE3: =ROUND(FD3-FA3,2) -> 0 | FI3: =FH3/F3 -> 0 | FJ3: =ROUND(FI3-FF3,2) -> 0 | FN3: =ROUND(FM3/F3,2) -> 0 | FO3: =ROUND(FN3-FK3,2) -> 0 | FS3: =ROUND(FR3/F3,2) -> 0 | FT3: =FS3-FP3 -> 0 | FX3: =ROUND(FW3/F3,2) -> 0 | FY3: =FX3-FU3 -> 0 | GC3: =ROUND(GB3/F3,2) -> 0 | GD3: =GC3-FZ3 -> 0 | GH3: =GG3/F3 -> 0 | GI3: =GH3-GE3 -> 0 | GM3: =GL3/F3 -> 0 | GN3: =GM3-GJ3 -> 0 | GR3: =GQ3/F3 -> 0 | GS3: =GR3-GO3 -> 0 | GW3: =ROUND(GV3/F3,2) -> 0 | GX3: =GW3-GT3 -> 0
B4: 1050 | F4: 0.13 | G4: =SUM(M4,P4:Q4,V4,AA4,AF4,AK4,AP4,AU4,AZ4,BE4,BJ4,BO4,BT4,BY4,CD4,CI4,CN4,CS4,CX4,DC4,DH4,DM4,DR4,DW4,EB4,EG4,EL4,EQ4,EV4,FA4,FF4,FK4,FP4,FU4,FZ4,GE4,GJ4,GO4,GT4) -> 3497388.1 | H4: =SUM(N4,R4,W4,AB4,AG4,AL4,AQ4,AV4,BA4,BF4,BK4,BP4,BU4,BZ4,CE4,CJ4,CO4,CT4,CY4,DD4,DI4,DN4,DS4,DX4,EC4,EH4,EM4,ER4,EW4,FB4,FG4,FL4,FQ4,FV4,GA4,GF4,GK4,GP4,GU4) -> 0 | I4: =SUM(O4,S4,X4,AC4,AH4,AM4,AR4,AW4,BB4,BG4,BL4,BQ4,BV4,CA4,CF4,CK4,CP4,CU4,CZ4,DE4,DJ4,DO4,DT4,DY4,ED4,EI4,EN4,ES4,EX4,FC4,FH4,FM4,FR4,FW4,GB4,GG4,GL4,GQ4,GV4) -> 454660.46 | J4: =I4/F4 -> 3497388.1 | K4: =I4/F4-H4 -> 3497388.1 | L4: =H4-J4 -> -3497388.1 | M4: 3497388.1 | N4: 0 | O4: 454660.46 | T4: 0 | U4: =T4-Q4 -> 0 | Z4: =Y4-V4 -> 0 | AD4: =AC4/F4 -> 0 | AE4: =AD4-AA4 -> 0 | AI4: =AH4/F4 -> 0 | AJ4: =AI4-AF4 -> 0 | AN4: =AM4/F4 -> 0 | AO4: =AN4-AK4 -> 0 | AS4: =AR4/F4 -> 0 | AT4: =AS4-AP4 -> 0 | AX4: =AW4/F4 -> 0 | AY4: =AX4-AU4 -> 0 | BC4: =BB4/F4 -> 0 | BH4: =BG4/F4 -> 0 | BI4: =BH4-BE4 -> 0 | BM4: =BL4/F4 -> 0 | BN4: =BM4-BJ4 -> 0 | BR4: =BQ4/F4 -> 0 | BS4: =BR4-BO4 -> 0 | BX4: =BW4-BT4 -> 0 | CB4: =CA4/F4 -> 0 | CC4: =CB4-BY4 -> 0 | CG4: =CF4/F4 -> 0 | CH4: =CG4-CD4 -> 0 | CL4: =CK4/F4 -> 0 | CM4: =CL4-CI4 -> 0 | CR4: =ROUND(CQ4-CN4,2) -> 0 | CW4: =CV4-CS4 -> 0 | DA4: =ROUND(CZ4/F4,2) -> 0 | DB4: =ROUND(DA4-CX4,2) -> 0 | DF4: =DE4/F4 -> 0 | DG4: =DC4-DF4 -> 0 | DK4: =DJ4/F4 -> 0 | DL4: =DK4-DH4 -> 0 | DP4: =DO4/F4 -> 0 | DQ4: =DP4-DM4 -> 0 | DU4: =DT4/F4 -> 0 | DV4: =DU4-DR4 -> 0 | DZ4: =ROUND(DY4/F4,2) -> 0 | EA4: =ROUND(DZ4-DW4,2) -> 0 | EF4: =EE4-EB4 -> 0 | EJ4: =ROUND(EI4/F4,2) -> 0 | EK4: =ROUND(EJ4-EG4,2) -> 0 | EO4: =ROUND(EN4/F4,2) -> 0 | EP4: =ROUND(EO4-EL4,2) -> 0 | ET4: =ROUND(ES4/F4,2) -> 0 | EU4: =ROUND(ET4-EQ4,2) -> 0 | EY4: =ROUND(EX4/F4,2) -> 0 | EZ4: =ROUND(EY4-EV4,2) -> 0 | FD4: =ROUND(FC4/F4,2) -> 0 | FE4: =ROUND(FD4-FA4,2) -> 0 | FI4: =FH4/F4 -> 0 | FJ4: =ROUND(FI4-FF4,2) -> 0 | FN4: =ROUND(FM4/F4,2) -> 0 | FO4: =ROUND(FN4-FK4,2) -> 0 | FS4: =ROUND(FR4/F4,2) -> 0 | FT4: =FS4-FP4 -> 0 | FX4: =ROUND(FW4/F4,2) -> 0 | FY4: =FX4-FU4 -> 0 | GC4: =ROUND(GB4/F4,2) -> 0 | GD4: =GC4-FZ4 -> 0 | GH4: =GG4/F4 -> 0 | GI4: =GH4-GE4 -> 0 | GM4: =GL4/F4 -> 0 | GN4: =GM4-GJ4 -> 0 | GR4: =GQ4/F4 -> 0 | GS4: =GR4-GO4 -> 0 | GW4: =ROUND(GV4/F4,2) -> 0 | GX4: =GW4-GT4 -> 0
B5: 1050 | E5: 工程施工 | F5: 0.1 | G5: =SUM(M5,P5:Q5,V5,AA5,AF5,AK5,AP5,AU5,AZ5,BE5,BJ5,BO5,BT5,BY5,CD5,CI5,CN5,CS5,CX5,DC5,DH5,DM5,DR5,DW5,EB5,EG5,EL5,EQ5,EV5,FA5,FF5,FK5,FP5,FU5,FZ5,GE5,GJ5,GO5,GT5) -> 16159346 | H5: =SUM(N5,R5,W5,AB5,AG5,AL5,AQ5,AV5,BA5,BF5,BK5,BP5,BU5,BZ5,CE5,CJ5,CO5,CT5,CY5,DD5,DI5,DN5,DS5,DX5,EC5,EH5,EM5,ER5,EW5,FB5,FG5,FL5,FQ5,FV5,GA5,GF5,GK5,GP5,GU5) -> 16159346 | I5: =SUM(O5,S5,X5,AC5,AH5,AM5,AR5,AW5,BB5,BG5,BL5,BQ5,BV5,CA5,CF5,CK5,CP5,CU5,CZ5,DE5,DJ5,DO5,DT5,DY5,ED5,EI5,EN5,ES5,EX5,FC5,FH5,FM5,FR5,FW5,GB5,GG5,GL5,GQ5,GV5) -> 1615934.6 | J5: =I5/F5 -> 16159346 | K5: =I5/F5-H5 -> -0.050000001 | L5: =H5-J5 -> 0.050000001 | M5: 16159346 | N5: 16159346 | O5: 1615934.6 | T5: 0 | U5: =T5-Q5 -> 0 | Z5: =Y5-V5 -> 0 | AD5: =AC5/F5 -> 0 | AE5: =AD5-AA5 -> 0 | AI5: =AH5/F5 -> 0 | AJ5: =AI5-AF5 -> 0 | AN5: =AM5/F5 -> 0 | AO5: =AN5-AK5 -> 0 | AS5: =AR5/F5 -> 0 | AT5: =AS5-AP5 -> 0 | AX5: =AW5/F5 -> 0 | AY5: =AX5-AU5 -> 0 | BC5: =BB5/F5 -> 0 | BH5: =BG5/F5 -> 0 | BI5: =BH5-BE5 -> 0 | BM5: =BL5/F5 -> 0 | BN5: =BM5-BJ5 -> 0 | BR5: =BQ5/F5 -> 0 | BS5: =BR5-BO5 -> 0 | BX5: =BW5-BT5 -> 0 | CB5: =CA5/F5 -> 0 | CC5: =CB5-BY5 -> 0 | CG5: =CF5/F5 -> 0 | CH5: =CG5-CD5 -> 0 | CL5: =CK5/F5 -> 0 | CM5: =CL5-CI5 -> 0 | CR5: =ROUND(CQ5-CN5,2) -> 0 | CW5: =CV5-CS5 -> 0 | DA5: =ROUND(CZ5/F5,2) -> 0 | DB5: =ROUND(DA5-CX5,2) -> 0 | DF5: =DE5/F5 -> 0 | DG5: =DC5-DF5 -> 0 | DK5: =DJ5/F5 -> 0 | DL5: =DK5-DH5 -> 0 | DP5: =DO5/F5 -> 0 | DQ5: =DP5-DM5 -> 0 | DU5: =DT5/F5 -> 0 | DV5: =DU5-DR5 -> 0 | DZ5: =ROUND(DY5/F5,2) -> 0 | EA5: =ROUND(DZ5-DW5,2) -> 0 | EF5: =EE5-EB5 -> 0 | EJ5: =ROUND(EI5/F5,2) -> 0 | EK5: =ROUND(EJ5-EG5,2) -> 0 | EO5: =ROUND(EN5/F5,2) -> 0 | EP5: =ROUND(EO5-EL5,2) -> 0 | ET5: =ROUND(ES5/F5,2) -> 0 | EU5: =ROUND(ET5-EQ5,2) -> 0 | EY5: =ROUND(EX5/F5,2) -> 0 | EZ5: =ROUND(EY5-EV5,2) -> 0 | FD5: =ROUND(FC5/F5,2) -> 0 | FE5: =ROUND(FD5-FA5,2) -> 0 | FI5: =FH5/F5 -> 0 | FJ5: =ROUND(FI5-FF5,2) -> 0 | FN5: =ROUND(FM5/F5,2) -> 0 | FO5: =ROUND(FN5-FK5,2) -> 0 | FS5: =ROUND(FR5/F5,2) -> 0 | FT5: =FS5-FP5 -> 0 | FX5: =ROUND(FW5/F5,2) -> 0 | FY5: =FX5-FU5 -> 0 | GC5: =ROUND(GB5/F5,2) -> 0 | GD5: =GC5-FZ5 -> 0 | GH5: =GG5/F5 -> 0 | GI5: =GH5-GE5 -> 0 | GM5: =GL5/F5 -> 0 | GN5: =GM5-GJ5 -> 0 | GR5: =GQ5/F5 -> 0 | GS5: =GR5-GO5 -> 0 | GW5: =ROUND(GV5/F5,2) -> 0 | GX5: =GW5-GT5 -> 0
B6: 1050 | F6: 0.09 | G6: =SUM(M6,P6:Q6,V6,AA6,AF6,AK6,AP6,AU6,AZ6,BE6,BJ6,BO6,BT6,BY6,CD6,CI6,CN6,CS6,CX6,DC6,DH6,DM6,DR6,DW6,EB6,EG6,EL6,EQ6,EV6,FA6,FF6,FK6,FP6,FU6,FZ6,GE6,GJ6,GO6,GT6) -> 5805849.7 | H6: =SUM(N6,R6,W6,AB6,AG6,AL6,AQ6,AV6,BA6,BF6,BK6,BP6,BU6,BZ6,CE6,CJ6,CO6,CT6,CY6,DD6,DI6,DN6,DS6,DX6,EC6,EH6,EM6,ER6,EW6,FB6,FG6,FL6,FQ6,FV6,GA6,GF6,GK6,GP6,GU6) -> 0 | I6: =SUM(O6,S6,X6,AC6,AH6,AM6,AR6,AW6,BB6,BG6,BL6,BQ6,BV6,CA6,CF6,CK6,CP6,CU6,CZ6,DE6,DJ6,DO6,DT6,DY6,ED6,EI6,EN6,ES6,EX6,FC6,FH6,FM6,FR6,FW6,GB6,GG6,GL6,GQ6,GV6) -> 522526.47 | J6: =I6/F6 -> 5805849.7 | K6: =I6/F6-H6 -> 5805849.7 | L6: =H6-J6 -> -5805849.7 | M6: 5805849.7 | N6: 0 | O6: 522526.47 | T6: 0 | U6: =T6-Q6 -> 0 | Z6: =Y6-V6 -> 0 | AD6: =AC6/F6 -> 0 | AE6: =AD6-AA6 -> 0 | AI6: =AH6/F6 -> 0 | AJ6: =AI6-AF6 -> 0 | AN6: =AM6/F6 -> 0 | AO6: =AN6-AK6 -> 0 | AS6: =AR6/F6 -> 0 | AT6: =AS6-AP6 -> 0 | AX6: =AW6/F6 -> 0 | AY6: =AX6-AU6 -> 0 | BC6: =BB6/F6 -> 0 | BH6: =BG6/F6 -> 0 | BI6: =BH6-BE6 -> 0 | BM6: =BL6/F6 -> 0 | BN6: =BM6-BJ6 -> 0 | BR6: =BQ6/F6 -> 0 | BS6: =BR6-BO6 -> 0 | BX6: =BW6-BT6 -> 0 | CB6: =CA6/F6 -> 0 | CC6: =CB6-BY6 -> 0 | CG6: =CF6/F6 -> 0 | CH6: =CG6-CD6 -> 0 | CL6: =CK6/F6 -> 0 | CM6: =CL6-CI6 -> 0 | CR6: =ROUND(CQ6-CN6,2) -> 0 | CW6: =CV6-CS6 -> 0 | DA6: =ROUND(CZ6/F6,2) -> 0 | DB6: =ROUND(DA6-CX6,2) -> 0 | DF6: =DE6/F6 -> 0 | DG6: =DC6-DF6 -> 0 | DK6: =DJ6/F6 -> 0 | DL6: =DK6-DH6 -> 0 | DP6: =DO6/F6 -> 0 | DQ6: =DP6-DM6 -> 0 | DU6: =DT6/F6 -> 0 | DV6: =DU6-DR6 -> 0 | DZ6: =ROUND(DY6/F6,2) -> 0 | EA6: =ROUND(DZ6-DW6,2) -> 0 | EF6: =EE6-EB6 -> 0 | EJ6: =ROUND(EI6/F6,2) -> 0 | EK6: =ROUND(EJ6-EG6,2) -> 0 | EO6: =ROUND(EN6/F6,2) -> 0 | EP6: =ROUND(EO6-EL6,2) -> 0 | ET6: =ROUND(ES6/F6,2) -> 0 | EU6: =ROUND(ET6-EQ6,2) -> 0 | EY6: =ROUND(EX6/F6,2) -> 0 | EZ6: =ROUND(EY6-EV6,2) -> 0 | FD6: =ROUND(FC6/F6,2) -> 0 | FE6: =ROUND(FD6-FA6,2) -> 0 | FI6: =FH6/F6 -> 0 | FJ6: =ROUND(FI6-FF6,2) -> 0 | FN6: =ROUND(FM6/F6,2) -> 0 | FO6: =ROUND(FN6-FK6,2) -> 0 | FS6: =ROUND(FR6/F6,2) -> 0 | FT6: =FS6-FP6 -> 0 | FX6: =ROUND(FW6/F6,2) -> 0 | FY6: =FX6-FU6 -> 0 | GC6: =ROUND(GB6/F6,2) -> 0 | GD6: =GC6-FZ6 -> 0 | GH6: =GG6/F6 -> 0 | GI6: =GH6-GE6 -> 0 | GM6: =GL6/F6 -> 0 | GN6: =GM6-GJ6 -> 0 | GR6: =GQ6/F6 -> 0 | GS6: =GR6-GO6 -> 0 | GW6: =ROUND(GV6/F6,2) -> 0 | GX6: =GW6-GT6 -> 0
B7: 1050 | E7: 设计咨询 | F7: 0.06 | G7: =SUM(M7,P7:Q7,V7,AA7,AF7,AK7,AP7,AU7,AZ7,BE7,BJ7,BO7,BT7,BY7,CD7,CI7,CN7,CS7,CX7,DC7,DH7,DM7,DR7,DW7,EB7,EG7,EL7,EQ7,EV7,FA7,FF7,FK7,FP7,FU7,FZ7,GE7,GJ7,GO7,GT7) -> 275818.22 | H7: =SUM(N7,R7,W7,AB7,AG7,AL7,AQ7,AV7,BA7,BF7,BK7,BP7,BU7,BZ7,CE7,CJ7,CO7,CT7,CY7,DD7,DI7,DN7,DS7,DX7,EC7,EH7,EM7,ER7,EW7,FB7,FG7,FL7,FQ7,FV7,GA7,GF7,GK7,GP7,GU7) -> 139872.96 | I7: =SUM(O7,S7,X7,AC7,AH7,AM7,AR7,AW7,BB7,BG7,BL7,BQ7,BV7,CA7,CF7,CK7,CP7,CU7,CZ7,DE7,DJ7,DO7,DT7,DY7,ED7,EI7,EN7,ES7,EX7,FC7,FH7,FM7,FR7,FW7,GB7,GG7,GL7,GQ7,GV7) -> 16549.083 | J7: =I7/F7 -> 275818.05 | K7: =I7/F7-H7 -> 135945.09 | L7: =H7-J7 -> -135945.09 | M7: 268958.26 | N7: 0 | O7: 16137.492 | T7: 0 | U7: =T7-Q7 -> 0 | Z7: =Y7-V7 -> 0 | AD7: =AC7/F7 -> 0 | AE7: =AD7-AA7 -> 0 | AI7: =AH7/F7 -> 0 | AJ7: =AI7-AF7 -> 0 | AN7: =AM7/F7 -> 0 | AO7: =AN7-AK7 -> 0 | AS7: =AR7/F7 -> 0 | AT7: =AS7-AP7 -> 0 | AU7: 2936.68 | AW7: 176.20092 | AX7: =AW7/F7 -> 2936.682 | AY7: =AX7-AU7 -> 0.002 | AZ7: 3176.41 | BB7: 190.58 | BC7: =BB7/F7 -> 3176.3333 | BH7: =BG7/F7 -> 0 | BI7: =BH7-BE7 -> 0 | BK7: 139872.96 | BM7: =BL7/F7 -> 0 | BN7: =BM7-BJ7 -> 0 | BR7: =BQ7/F7 -> 0 | BS7: =BR7-BO7 -> 0 | BX7: =BW7-BT7 -> 0 | CB7: =CA7/F7 -> 0 | CC7: =CB7-BY7 -> 0 | CG7: =CF7/F7 -> 0 | CH7: =CG7-CD7 -> 0 | CL7: =CK7/F7 -> 0 | CM7: =CL7-CI7 -> 0 | CR7: =ROUND(CQ7-CN7,2) -> 0 | CW7: =CV7-CS7 -> 0 | DA7: =ROUND(CZ7/F7,2) -> 0 | DB7: =ROUND(DA7-CX7,2) -> 0 | DF7: =DE7/F7 -> 0 | DG7: =DC7-DF7 -> 0 | DH7: 746.87 | DJ7: 44.81 | DK7: =DJ7/F7 -> 746.83333 | DL7: =DK7-DH7 -> -0.036666667 | DP7: =DO7/F7 -> 0 | DQ7: =DP7-DM7 -> 0 | DU7: =DT7/F7 -> 0 | DV7: =DU7-DR7 -> 0 | DZ7: =ROUND(DY7/F7,2) -> 0 | EA7: =ROUND(DZ7-DW7,2) -> 0 | EF7: =EE7-EB7 -> 0 | EJ7: =ROUND(EI7/F7,2) -> 0 | EK7: =ROUND(EJ7-EG7,2) -> 0 | EO7: =ROUND(EN7/F7,2) -> 0 | EP7: =ROUND(EO7-EL7,2) -> 0 | ET7: =ROUND(ES7/F7,2) -> 0 | EU7: =ROUND(ET7-EQ7,2) -> 0 | EY7: =ROUND(EX7/F7,2) -> 0 | EZ7: =ROUND(EY7-EV7,2) -> 0 | FD7: =ROUND(FC7/F7,2) -> 0 | FE7: =ROUND(FD7-FA7,2) -> 0 | FI7: =FH7/F7 -> 0 | FJ7: =ROUND(FI7-FF7,2) -> 0 | FN7: =ROUND(FM7/F7,2) -> 0 | FO7: =ROUND(FN7-FK7,2) -> 0 | FS7: =ROUND(FR7/F7,2) -> 0 | FT7: =FS7-FP7 -> 0 | FX7: =ROUND(FW7/F7,2) -> 0 | FY7: =FX7-FU7 -> 0 | GC7: =ROUND(GB7/F7,2) -> 0 | GD7: =GC7-FZ7 -> 0 | GH7: =GG7/F7 -> 0 | GI7: =GH7-GE7 -> 0 | GM7: =GL7/F7 -> 0 | GN7: =GM7-GJ7 -> 0 | GR7: =GQ7/F7 -> 0 | GS7: =GR7-GO7 -> 0 | GW7: =ROUND(GV7/F7,2) -> 0 | GX7: =GW7-GT7 -> 0
B8: 1080 | D8: 1080（丰宁） | E8: 商品销售 | F8: 0.13 | G8: =SUM(M8,P8:Q8,V8,AA8,AF8,AK8,AP8,AU8,AZ8,BE8,BJ8,BO8,BT8,BY8,CD8,CI8,CN8,CS8,CX8,DC8,DH8,DM8,DR8,DW8,EB8,EG8,EL8,EQ8,EV8,FA8,FF8,FK8,FP8,FU8,FZ8,GE8,GJ8,GO8,GT8) -> 1.4159292e+08 | H8: =SUM(N8,R8,W8,AB8,AG8,AL8,AQ8,AV8,BA8,BF8,BK8,BP8,BU8,BZ8,CE8,CJ8,CO8,CT8,CY8,DD8,DI8,DN8,DS8,DX8,EC8,EH8,EM8,ER8,EW8,FB8,FG8,FL8,FQ8,FV8,GA8,GF8,GK8,GP8,GU8) -> 1.4159292e+08 | I8: =SUM(O8,S8,X8,AC8,AH8,AM8,AR8,AW8,BB8,BG8,BL8,BQ8,BV8,CA8,CF8,CK8,CP8,CU8,CZ8,DE8,DJ8,DO8,DT8,DY8,ED8,EI8,EN8,ES8,EX8,FC8,FH8,FM8,FR8,FW8,GB8,GG8,GL8,GQ8,GV8) -> 18407080 | J8: =I8/F8 -> 1.4159292e+08 | K8: =I8/F8-H8 -> 0.46923074 | L8: =H8-J8 -> -0.46923074 | M8: 82650966 | N8: 1.4159292e+08 | O8: 18407080 | P8: 58941955 | T8: 0 | U8: =T8-Q8 -> 0 | Z8: =Y8-V8 -> 0 | AD8: =AC8/F8 -> 0 | AE8: =AD8-AA8 -> 0 | AI8: =AH8/F8 -> 0 | AJ8: =AI8-AF8 -> 0 | AN8: =AM8/F8 -> 0 | AO8: =AN8-AK8 -> 0 | AS8: =AR8/F8 -> 0 | AT8: =AS8-AP8 -> 0 | AX8: =AW8/F8 -> 0 | AY8: =AX8-AU8 -> 0 | BC8: =BB8/F8 -> 0 | BH8: =BG8/F8 -> 0 | BI8: =BH8-BE8 -> 0 | BM8: =BL8/F8 -> 0 | BN8: =BM8-BJ8 -> 0 | BR8: =BQ8/F8 -> 0 | BS8: =BR8-BO8 -> 0 | BX8: =BW8-BT8 -> 0 | CB8: =CA8/F8 -> 0 | CC8: =CB8-BY8 -> 0 | CG8: =CF8/F8 -> 0 | CH8: =CG8-CD8 -> 0 | CL8: =CK8/F8 -> 0 | CM8: =CL8-CI8 -> 0 | CR8: =ROUND(CQ8-CN8,2) -> 0 | CW8: =CV8-CS8 -> 0 | DA8: =ROUND(CZ8/F8,2) -> 0 | DB8: =ROUND(DA8-CX8,2) -> 0 | DF8: =DE8/F8 -> 0 | DG8: =DC8-DF8 -> 0 | DK8: =DJ8/F8 -> 0 | DL8: =DK8-DH8 -> 0 | DP8: =DO8/F8 -> 0 | DQ8: =DP8-DM8 -> 0 | DU8: =DT8/F8 -> 0 | DV8: =DU8-DR8 -> 0 | DZ8: =ROUND(DY8/F8,2) -> 0 | EA8: =ROUND(DZ8-DW8,2) -> 0 | EF8: =EE8-EB8 -> 0 | EJ8: =ROUND(EI8/F8,2) -> 0 | EK8: =ROUND(EJ8-EG8,2) -> 0 | EO8: =ROUND(EN8/F8,2) -> 0 | EP8: =ROUND(EO8-EL8,2) -> 0 | ET8: =ROUND(ES8/F8,2) -> 0 | EU8: =ROUND(ET8-EQ8,2) -> 0 | EY8: =ROUND(EX8/F8,2) -> 0 | EZ8: =ROUND(EY8-EV8,2) -> 0 | FD8: =ROUND(FC8/F8,2) -> 0 | FE8: =ROUND(FD8-FA8,2) -> 0 | FI8: =FH8/F8 -> 0 | FJ8: =ROUND(FI8-FF8,2) -> 0 | FN8: =ROUND(FM8/F8,2) -> 0 | FO8: =ROUND(FN8-FK8,2) -> 0 | FS8: =ROUND(FR8/F8,2) -> 0 | FT8: =FS8-FP8 -> 0 | FX8: =ROUND(FW8/F8,2) -> 0 | FY8: =FX8-FU8 -> 0 | GC8: =ROUND(GB8/F8,2) -> 0 | GD8: =GC8-FZ8 -> 0 | GH8: =GG8/F8 -> 0 | GI8: =GH8-GE8 -> 0 | GM8: =GL8/F8 -> 0 | GN8: =GM8-GJ8 -> 0 | GR8: =GQ8/F8 -> 0 | GS8: =GR8-GO8 -> 0 | GW8: =ROUND(GV8/F8,2) -> 0 | GX8: =GW8-GT8 -> 0
B9: 1080 | E9: 工程施工 | F9: 0.09 | G9: =SUM(M9,P9:Q9,V9,AA9,AF9,AK9,AP9,AU9,AZ9,BE9,BJ9,BO9,BT9,BY9,CD9,CI9,CN9,CS9,CX9,DC9,DH9,DM9,DR9,DW9,EB9,EG9,EL9,EQ9,EV9,FA9,FF9,FK9,FP9,FU9,FZ9,GE9,GJ9,GO9,GT9) -> 52351181 | H9: =SUM(N9,R9,W9,AB9,AG9,AL9,AQ9,AV9,BA9,BF9,BK9,BP9,BU9,BZ9,CE9,CJ9,CO9,CT9,CY9,DD9,DI9,DN9,DS9,DX9,EC9,EH9,EM9,ER9,EW9,FB9,FG9,FL9,FQ9,FV9,GA9,GF9,GK9,GP9,GU9) -> 51971943 | I9: =SUM(O9,S9,X9,AC9,AH9,AM9,AR9,AW9,BB9,BG9,BL9,BQ9,BV9,CA9,CF9,CK9,CP9,CU9,CZ9,DE9,DJ9,DO9,DT9,DY9,ED9,EI9,EN9,ES9,EX9,FC9,FH9,FM9,FR9,FW9,GB9,GG9,GL9,GQ9,GV9) -> 4711606.3 | J9: =I9/F9 -> 52351181 | K9: =I9/F9-H9 -> 379237.89 | L9: =H9-J9 -> -379237.89 | M9: 1.0939348e+08 | N9: 0 | O9: 9845413.6 | P9: =-52921541.4-4500000 -> -57421541 | S9: -1360542.6 | T9: -15117140 | U9: =T9-Q9 -> -15117140 | Z9: =Y9-V9 -> 0 | AC9: -170884.6 | AD9: =AC9/F9 -> -1898717.8 | AE9: =AD9-AA9 -> -1898717.8 | AH9: -289580.32 | AI9: =AH9/F9 -> -3217559.1 | AJ9: =AI9-AF9 -> -3217559.1 | AL9: 51971943 | AM9: -2821202.9 | AN9: =AM9/F9 -> -31346699 | AO9: =AN9-AK9 -> -31346699 | AR9: -525728.34 | AS9: =AR9/F9 -> -5841426 | AT9: =AS9-AP9 -> -5841426 | AV9: =AP9*0.09 -> 0 | AX9: =AW9/F9 -> 0 | AY9: =AX9-AU9 -> 0 | BC9: =BB9/F9 -> 0 | BH9: =BG9/F9 -> 0 | BI9: =BH9-BE9 -> 0 | BM9: =BL9/F9 -> 0 | BN9: =BM9-BJ9 -> 0 | BR9: =BQ9/F9 -> 0 | BS9: =BR9-BO9 -> 0 | BX9: =BW9-BT9 -> 0 | BY9: 1261555.8 | CA9: 113540.02 | CB9: =CA9/F9 -> 1261555.8 | CC9: =CB9-BY9 -> -0.022222222 | CG9: =CF9/F9 -> 0 | CH9: =CG9-CD9 -> 0 | CL9: =CK9/F9 -> 0 | CM9: =CL9-CI9 -> 0 | CR9: =ROUND(CQ9-CN9,2) -> 0 | CW9: =CV9-CS9 -> 0 | CX9: -882317.97 | CZ9: -79408.61 | DA9: =ROUND(CZ9/F9,2) -> -882317.89 | DB9: =ROUND(DA9-CX9,2) -> 0.08 | DF9: =DE9/F9 -> 0 | DG9: =DC9-DF9 -> 0 | DK9: =DJ9/F9 -> 0 | DL9: =DK9-DH9 -> 0 | DP9: =DO9/F9 -> 0 | DQ9: =DP9-DM9 -> 0 | DU9: =DT9/F9 -> 0 | DV9: =DU9-DR9 -> 0 | DZ9: =ROUND(DY9/F9,2) -> 0 | EA9: =ROUND(DZ9-DW9,2) -> 0 | EF9: =EE9-EB9 -> 0 | EJ9: =ROUND(EI9/F9,2) -> 0 | EK9: =ROUND(EJ9-EG9,2) -> 0 | EO9: =ROUND(EN9/F9,2) -> 0 | EP9: =ROUND(EO9-EL9,2) -> 0 | ET9: =ROUND(ES9/F9,2) -> 0 | EU9: =ROUND(ET9-EQ9,2) -> 0 | EY9: =ROUND(EX9/F9,2) -> 0 | EZ9: =ROUND(EY9-EV9,2) -> 0 | FD9: =ROUND(FC9/F9,2) -> 0 | FE9: =ROUND(FD9-FA9,2) -> 0 | FI9: =FH9/F9 -> 0 | FJ9: =ROUND(FI9-FF9,2) -> 0 | FN9: =ROUND(FM9/F9,2) -> 0 | FO9: =ROUND(FN9-FK9,2) -> 0 | FS9: =ROUND(FR9/F9,2) -> 0 | FT9: =FS9-FP9 -> 0 | FX9: =ROUND(FW9/F9,2) -> 0 | FY9: =FX9-FU9 -> 0 | GC9: =ROUND(GB9/F9,2) -> 0 | GD9: =GC9-FZ9 -> 0 | GH9: =GG9/F9 -> 0 | GI9: =GH9-GE9 -> 0 | GM9: =GL9/F9 -> 0 | GN9: =GM9-GJ9 -> 0 | GR9: =GQ9/F9 -> 0 | GS9: =GR9-GO9 -> 0 | GW9: =ROUND(GV9/F9,2) -> 0 | GX9: =GW9-GT9 -> 0
