Workbook
Name _epmOfflineCondition_: 1
Name _epmOfflineCondition_: 1

Sheet 10月BS
B1: 资产负债表-单体
B2: 编制单位：五河新茂风力发电有限公司
B3: 编制时间：2025.07
B4: 项目 | C4: 行 | D4: 年初数 | E4: 累计发生数 | F4: 项目 | G4: 行 | H4: 年初数 | I4: 累计发生数
B5: 流动资产： | C5: 1 | F5: 流动负债：
B6: 货币资金 | C6: 2 | D6: 0 | E6: 2696447.8 | F6: 短期借款 | G6: 50 | H6: 0 | I6: 0
B7: 交易性金融资产 | C7: 3 | D7: 0 | E7: 0 | F7: 衍生金融负债 | G7: 51 | H7: 0 | I7: 0
B8: 衍生金融资产 | C8: 4 | D8: 0 | E8: 0 | F8: 应付票据 | G8: 52 | H8: 0 | I8: 0
B9: 应收票据 | C9: 5 | D9: 0 | E9: 0 | F9: 应付账款 | G9: 53 | H9: 0 | I9: 29686827
B10: 应收账款 | C10: 6 | D10: 0 | E10: 0 | F10: 预收款项 | G10: 54 | H10: 0 | I10: 0
B11: 应收款项融资 | C11: 7 | D11: 0 | E11: 0 | F11: 合同负债 | G11: 55 | H11: 0 | I11: 0
B12: 预付款项 | C12: 8 | D12: 0 | E12: 0 | F12: 应付职工薪酬 | G12: 56 | H12: 0 | I12: 0
B13: 应收利息 | C13: 9 | D13: 0 | E13: 0 | F13: 应交税费 | G13: 57 | H13: 0 | I13: -1515953.1
B14: 应收股利 | C14: 10 | D14: 0 | E14: 0 | F14: 应付利息 | G14: 58 | H14: 0 | I14: 0
B15: 其他应收款 | C15: 11 | D15: 0 | E15: 0 | G15: 59
B16: 存货 | C16: 12 | D16: 0 | E16: 0 | F16: 应付股利 | G16: 60 | H16: 0 | I16: 0
B17: 合同资产 | C17: 13 | D17: 0 | E17: 0 | F17: 其他应付款 | G17: 61 | H17: 0 | I17: 5029578
B18: 一年内到期的非流动资产 | C18: 14 | D18: 0 | E18: 0 | F18: 递延收益 | G18: 62 | H18: 0 | I18: 0
B19: 其他流动资产 | C19: 15 | D19: 0 | E19: 201612.91 | F19: 一年内到期的非流动负债 | G19: 63 | H19: 0 | I19: 0
B20: 流动资产合计 | C20: 16 | D20: 0 | E20: 2898060.7 | F20: 其他流动负债 | G20: 64 | H20: 0 | I20: 0
B21: 非流动资产： | C21: 17 | F21: 流动负债合计 | G21: 65 | H21: 0 | I21: 33200452
B22: 其他权益工具投资 | C22: 18 | D22: 0 | E22: 0 | F22: 非流动负债： | G22: 66
B23: 债权投资 | C23: 19 | D23: 0 | E23: 0 | F23: 长期借款 | G23: 67 | H23: 0 | I23: 0
B24: 长期应收款 | C24: 20 | D24: 0 | E24: 0 | F24: 应付债券 | G24: 68 | H24: 0 | I24: 0
B25: 长期股权投资 | C25: 21 | D25: 0 | E25: 0 | F25: 租赁负债 | G25: 69 | H25: 0 | I25: 0
B26: 其他非流动金融资产 | C26: 22 | D26: 0 | E26: 0 | F26: 长期应付款 | G26: 70 | H26: 0 | I26: 0
B27: 投资性房地产 | C27: 23 | D27: 0 | E27: 0 | F27: 专项应付款 | G27: 71 | H27: 0 | I27: 0
B28: 固定资产-原值 | C28: 24 | D28: 0 | E28: 0 | F28: 预计负债 | G28: 72 | H28: 0 | I28: 0
B29: 减：累计折旧 | C29: 25 | D29: 0 | E29: 0 | F29: 递延所得税负债 | G29: 73 | H29: 0 | I29: 0
B30: 减：固定资产减值准备 | C30: 26 | D30: 0 | E30: 0 | F30: 其他非流动负债 | G30: 74 | H30: 0 | I30: 0
B31: 固定资产净值 | C31: 27 | D31: 0 | E31: 0 | F31: 非流动负债合计 | G31: 75 | H31: 0 | I31: 0
B32: 在建工程 | C32: 28 | D32: 0 | E32: 30302391 | G32: 76
B33: 使用权资产-原值 | C33: 29 | D33: 0 | E33: 0 | G33: 77
B34: 减：使用权资产-累计折旧 | C34: 30 | D34: 0 | E34: 0 | F34: 负债合计 | G34: 78 | H34: 0 | I34: 33200452
B35: 使用权资产-净值 | C35: 31 | D35: 0 | E35: 0 | G35: 79
B36: 无形资产 | C36: 32 | D36: 0 | E36: 0 | F36: 所有者权益（股东权益） | G36: 80
B37: 开发支出 | C37: 33 | D37: 0 | E37: 0 | F37: 实收资本 | G37: 81 | H37: 0 | I37: 0
B38: 商誉 | C38: 34 | D38: 0 | E38: 0 | F38: 资本公积 | G38: 82 | H38: 0 | I38: 0
B39: 长期待摊费用 | C39: 35 | D39: 0 | E39: 0 | F39: 盈余公积 | G39: 83 | H39: 0 | I39: 0
B40: 递延所得税资产 | C40: 36 | D40: 0 | E40: 0 | F40: 其他综合收益 | G40: 84 | H40: 0 | I40: 0
...

Sheet 10月PL
B1: 利润表-单体
A2: 当期时间 | B2: 编制单位：五河新茂风力发电有限公司
B3: 编制时间：2025.07
A4: 2025.07 | B4: 项目 | D4: 本期发生额 | E4: 累计发生额 | F4: 上月累计发生额
A5: 当前月份 | B5: 一、营业收入 | C5: 1 | D5: =IF(RIGHT($B$3,2)="01",E5,E5-F5) -> 0 | E5: 0 | F5: 0
A6: =RIGHT(A4,2) -> 07 | B6: 其中：营业收入 | C6: 2 | D6: =IF(RIGHT($B$3,2)="01",E6,E6-F6) -> 0 | E6: 0 | F6: 0
B7: 主营业务收入 | C7: 3 | D7: =IF(RIGHT($B$3,2)="01",E7,E7-F7) -> 0 | E7: 0 | F7: 0
B8: 其他业务收入 | C8: 4 | D8: =IF(RIGHT($B$3,2)="01",E8,E8-F8) -> 0 | E8: 0 | F8: 0
B9: 二：营业总成本 | C9: 5 | D9: =IF(RIGHT($B$3,2)="01",E9,E9-F9) -> 0 | E9: =E10+E13+E14+E15+E16+E17+E20+E21+E22+E23+E24 -> 0 | F9: =F10+F13+F14+F15+F16+F17+F20+F21+F22+F23+F24 -> 0
B10: 其中：营业成本 | C10: 6 | D10: =IF(RIGHT($B$3,2)="01",E10,E10-F10) -> 0 | E10: 0 | F10: 0
B11: 主营业务成本 | C11: 7 | D11: =IF(RIGHT($B$3,2)="01",E11,E11-F11) -> 0 | E11: 0 | F11: 0
B12: 其他业务成本 | C12: 8 | D12: =IF(RIGHT($B$3,2)="01",E12,E12-F12) -> 0 | E12: 0 | F12: 0
B13: 营业税金及附加 | C13: 9 | D13: =IF(RIGHT($B$3,2)="01",E13,E13-F13) -> 0 | E13: 0 | F13: 0
B14: 销售费用 | C14: 10 | D14: =IF(RIGHT($B$3,2)="01",E14,E14-F14) -> 0 | E14: 0 | F14: 0
B15: 管理费用 | C15: 11 | D15: =IF(RIGHT($B$3,2)="01",E15,E15-F15) -> 0 | E15: 0 | F15: 0
B16: 研发费用 | C16: 12 | D16: =IF(RIGHT($B$3,2)="01",E16,E16-F16) -> 0 | E16: 0 | F16: 0
B17: 财务费用 | C17: 13 | D17: =IF(RIGHT($B$3,2)="01",E17,E17-F17) -> 0 | E17: 0 | F17: 0
B18: 其他收益 | C18: 14 | D18: =IF(RIGHT($B$3,2)="01",E18,E18-F18) -> 0 | E18: 0 | F18: 0
B19: 投资收益（损失以“-”号填列） | C19: 15 | D19: =IF(RIGHT($B$3,2)="01",E19,E19-F19) -> 0 | E19: 0 | F19: 0
B20: 净敞口套期收益（亏损以“－”号填列） | C20: 16 | D20: =IF(RIGHT($B$3,2)="01",E20,E20-F20) -> 0 | E20: 0 | F20: 0
B21: 公允价值变动收益 | C21: 17 | D21: =IF(RIGHT($B$3,2)="01",E21,E21-F21) -> 0 | E21: 0 | F21: 0
... B30: 五、净利润（净亏损以“－”号填列） | C30: 26 | D30: =IF(RIGHT($B$3,2)="01",E30,E30-F30) -> 0 | E30: 0 | F30: 0
B32: 利润表-单体
A33: 当期时间 | B33: 编制单位：五河新茂风力发电有限公司
B34: 编制时间：2025.08
A35: 2025.08 | B35: 项目 | D35: 本期发生额 | E35: 累计发生额 | F35: 上月累计发生额
A36: 当前月份 | B36: 一、营业收入 | C36: 1 | D36: =IF(RIGHT($B$3,2)="01",E36,E36-F36) -> 0 | E36: 0 | F36: 0
A37: =RIGHT(A35,2) -> 08 | B37: 其中：营业收入 | C37: 2 | D37: =IF(RIGHT($B$3,2)="01",E37,E37-F37) -> 0 | E37: 0 | F37: 0
B38: 主营业务收入 | C38: 3 | D38: =IF(RIGHT($B$3,2)="01",E38,E38-F38) -> 0 | E38: 0 | F38: 0
B39: 其他业务收入 | C39: 4 | D39: =IF(RIGHT($B$3,2)="01",E39,E39-F39) -> 0 | E39: 0 | F39: 0
B40: 二：营业总成本 | C40: 5 | D40: =IF(RIGHT($B$3,2)="01",E40,E40-F40) -> 0 | E40: =E41+E44+E45+E46+E47+E48+E51+E52+E53+E54+E55 -> 0 | F40: =F41+F44+F45+F46+F47+F48+F51+F52+F53+F54+F55 -> 0
B41: 其中：营业成本 | C41: 6 | D41: =IF(RIGHT($B$3,2)="01",E41,E41-F41) -> 0 | E41: 0 | F41: 0
B42: 主营业务成本 | C42: 7 | D42: =IF(RIGHT($B$3,2)="01",E42,E42-F42) -> 0 | E42: 0 | F42: 0
B43: 其他业务成本 | C43: 8 | D43: =IF(RIGHT($B$3,2)="01",E43,E43-F43) -> 0 | E43: 0 | F43: 0
B44: 营业税金及附加 | C44: 9 | D44: =IF(RIGHT($B$3,2)="01",E44,E44-F44) -> 0 | E44: 0 | F44: 0
B45: 销售费用 | C45: 10 | D45: =IF(RIGHT($B$3,2)="01",E45,E45-F45) -> 0 | E45: 0 | F45: 0
B46: 管理费用 | C46: 11 | D46: =IF(RIGHT($B$3,2)="01",E46,E46-F46) -> 0 | E46: 0 | F46: 0
B47: 研发费用 | C47: 12 | D47: =IF(RIGHT($B$3,2)="01",E47,E47-F47) -> 0 | E47: 0 | F47: 0
B48: 财务费用 | C48: 13 | D48: =IF(RIGHT($B$3,2)="01",E48,E48-F48) -> 0 | E48: 0 | F48: 0
B49: 其他收益 | C49: 14 | D49: =IF(RIGHT($B$3,2)="01",E49,E49-F49) -> 0 | E49: 0 | F49: 0
...

Sheet 销项明细

Sheet 进项明细
A1: 公司代码 | B1: 财年 | C1: 年度/月份 | D1: 科目 | E1: 凭证编号 | F1: 凭证类型 | G1: 凭证日期 | H1: 过账日期 | I1: 本币金额 | J1: 本币 | K1: 显示货币的金额 | L1: 凭证货币 | M1: 文本 | N1: 凭证抬头文本 | O1: 付款参考 | P1: 贸易伙伴 | Q1: 客户 | R1: 供应商 | S1: 成本中心 | T1: WBS 要素 | U1: 参照 | V1: 冲销清帐 | W1: 采购凭证 | X1: 参考代码 1 | Y1: 分配 | Z1: 用户名 | AA1: 特别总账标识
A2: 2342 | B2: 2025 | C2: 2025/10 | D2: 2221010100 | E2: 4000000143 | F2: RE | G2: 45944 | H2: 45945 | I2: 1161.26 | J2: RMB | K2: 1161.26 | L2: RMB | M2: CGDD011617-9720012771 | N2: CGDD011617-9720012771 | U2: 25112*218814297 | Y2: 25112*218814297 | Z2: JT_SRM_SERV
A3: 2342 | B3: 2025 | C3: 2025/10 | D3: 2221010100 | E3: 4000000144 | F3: RE | G3: 45944 | H3: 45945 | I3: 580.63 | J3: RMB | K3: 580.63 | L3: RMB | M3: CGDD011752-9720012828 | N3: CGDD011752-9720012828 | U3: 25112*218775108 | Y3: 25112*218775108 | Z3: JT_SRM_SERV
A4: 2342 | B4: 2025 | C4: 2025/10 | D4: 2221010100 | E4: 4000000145 | F4: RE | G4: 45945 | H4: 45945 | I4: 18127.36 | J4: RMB | K4: 18127.36 | L4: RMB | M4: CGDD012464-9720013026 | N4: CGDD012464-9720013026 | U4: 25322*477236947 | Y4: 25322*477236947 | Z4: JT_SRM_SERV
A5: 2342 | B5: 2025 | C5: 2025/10 | D5: 2221010100 | E5: 4000000146 | F5: RE | G5: 45945 | H5: 45946 | I5: 219.76 | J5: RMB | K5: 219.76 | L5: RMB | M5: CGDD011492-9210210662 | N5: CGDD011492-9210210662 | U5: 25347*120397457 | Y5: 25347*120397457 | Z5: JT_SRM_SERV
A6: 2342 | B6: 2025 | C6: 2025/10 | D6: 2221010100 | E6: 4000000147 | F6: RE | G6: 45945 | H6: 45946 | I6: 315.51 | J6: RMB | K6: 315.51 | L6: RMB | M6: CGDD011113-9720012632 | N6: CGDD011113-9720012632 | U6: 25347*120397458 | Y6: 25347*120397458 | Z6: JT_SRM_SERV
A7: 2342 | B7: 2025 | C7: 2025/10 | D7: 2221010100 | E7: 4000000151 | F7: KR | G7: 45957 | H7: 45959 | I7: 61.74 | J7: RMB | K7: 61.74 | L7: RMB | M7: 25312000000344893988计景泰8月及9月运维部携程差旅费 | N7: 2531200000034489398820251 | P7: 2450 | U7: SGJTZX | Y7: SGJTZX | Z7: JT_SRM_SERV
A8: 2342 | B8: 2025 | C8: 2025/10 | D8: 2221010100 | E8: 4000000162 | F8: RE | G8: 45960 | H8: 45960 | I8: 5126.74 | J8: RMB | K8: 5126.74 | L8: RMB | M8: 25312000000349849361五河彩舟_10月收咨询服务-在建发票 | N8: 五河彩舟_10月收咨询服务-在建发票 | O8: 咨询服务-在建 | P8: 2320 | U8: SGRJZX | Y8: NE-1453 | Z8: JIE.HU
A9: 2342 | B9: 2025 | C9: 2025/10 | D9: 2221010100 | E9: 4000000163 | F9: RE | G9: 45960 | H9: 45960 | I9: 199.51 | J9: RMB | K9: 199.51 | L9: RMB | M9: 25312000000349848792五河彩舟_10月收设计服务发票 | N9: 五河彩舟_10月收设计服务发票 | O9: XNCN23202025081900543 | P9: 2320 | U9: SGZZFJSJ | Y9: NE-1453 | Z9: JIE.HU
A10: 2342 | B10: 2025 | C10: 2025/10 | D10: 2221010100 | E10: 4000000164 | F10: RE | G10: 45960 | H10: 45960 | I10: 77382.52 | J10: RMB | K10: 77382.52 | L10: RMB | M10: 25312000000349849513五河彩舟_10月收建安发票 | N10: 五河彩舟_10月收建安发票 | O10: CPACN23202025070700008 | P10: 2320 | U10: SGZZFJJA | Y10: NE-1453 | Z10: JIE.HU
A11: 2342 | B11: 2025 | C11: 2025/10 | D11: 2221010100 | E11: 4000000152 | F11: RE | G11: 45961 | H11: 45961 | I11: 39562.6 | J11: RMB | K11: 39562.6 | L11: RMB | M11: 远景五河彩舟风电场项目项目_10月收到中央分摊发票25312000000351492020 | N11: 25312000000351492020 | O11: 咨询服务-在建 | P11: 2320 | U11: SGRJZX | Y11: NE-1453 | Z11: IT_PEGA_800
A12: 2342 | B12: 2025 | C12: 2025/10 | D12: 2221010100 | E12: 4000000153 | F12: RE | G12: 45961 | H12: 45961 | I12: 10408.58 | J12: RMB | K12: 10408.58 | L12: RMB | M12: 远景五河彩舟风电场项目项目_10月收到设计服务发票25312000000351491562 | N12: 25312000000351491562 | O12: XNCN23202025080600097 | P12: 2320 | U12: SGZZFJSJ | Y12: NE-1453 | Z12: IT_PEGA_800
A13: 2342 | B13: 2025 | C13: 2025/10 | D13: 2221010100 | E13: 4000000154 | F13: RE | G13: 45961 | H13: 45961 | I13: 10575.76 | J13: RMB | K13: 10575.76 | L13: RMB | M13: 远景五河彩舟风电场项目项目_10月收到设计服务发票25312000000351491827 | N13: 25312000000351491827 | O13: XNCN23202025091700543 | P13: 2320 | U13: SGZZFJSJ | Y13: NE-1453 | Z13: IT_PEGA_800
A14: 2342 | B14: 2025 | C14: 2025/10 | D14: 2221010100 | E14: 4000000155 | F14: RE | G14: 45961 | H14: 45961 | I14: 1176613.6 | J14: RMB | K14: 1176613.6 | L14: RMB | M14: 远景五河彩舟风电场项目项目_10月收到前期技术服务发票25312000000351491962 | N14: 25312000000351491962 | O14: 远景前期技术服务费 | P14: 2320 | U14: SGYJQQZX | Y14: NE-1453 | Z14: IT_PEGA_800
A15: 2342 | B15: 2025 | C15: 2025/10 | D15: 2221010100 | E15: 4000000156 | F15: RE | G15: 45961 | H15: 45961 | I15: 196746.55 | J15: RMB | K15: 196746.55 | L15: RMB | M15: 远景五河彩舟风电场项目项目_10月收到前期技术服务发票25312000000351492051 | N15: 25312000000351492051 | O15: 景泰前期技术服务费 | P15: 2320 | U15: SGJTQQZX | Y15: NE-1453 | Z15: IT_PEGA_800
A16: 2342 | B16: 2025 | C16: 2025/10 | D16: 2221010100 | E16: 4000000157 | F16: RE | G16: 45961 | H16: 45961 | I16: 225115.82 | J16: RMB | K16: 225115.82 | L16: RMB | M16: 远景五河彩舟风电场项目项目_10月收到中央分摊发票25312000000351492165 | N16: 25312000000351492165 | O16: 景泰中央分摊 | P16: 2320 | U16: SGJTZX | Y16: NE-1453 | Z16: IT_PEGA_800
A17: 2342 | B17: 2025 | C17: 2025/10 | D17: 2221010100 | E17: 4000000158 | F17: RE | G17: 45961 | H17: 45961 | I17: 188.78 | J17: RMB | K17: 188.78 | L17: RMB | M17: 远景五河彩舟风电场项目项目_10月收到设计服务发票25312000000351492267 | N17: 25312000000351492267 | O17: 费用报销单 | P17: 2320 | U17: SGZZFJSJ | Y17: NE-1453 | Z17: IT_PEGA_800
A18: 2342 | B18: 2025 | C18: 2025/10 | D18: 2221010100 | E18: 4000000159 | F18: RE | G18: 45961 | H18: 45961 | I18: 5979.43 | J18: RMB | K18: 5979.43 | L18: RMB | M18: 25312000000352074636_10月睿景咨询服务费_蚌埠五河 | N18: 2531200000035207463620251 | O18: 咨询服务-在建 | P18: 2320 | U18: SGRJZX | Y18: NE-1453 | Z18: JT_SRM_SERV
K21: =SUM(K2:K20) -> 1768366.1

Sheet 所得税明细

Sheet 印花税明细
A1: 2342-五河新茂风力发电有限公司 | D1: 所属期 | E1: 45838 | F1: 2025年第二季度 | H1: 单位：元
A2: 序号 | B2: 税目 | C2: 计税依据 | D2: 税率 | E2: 应纳税额 | F2: 减免税额 | G2: 已缴税额 | H2: 应补（退）税额
A3: 1 | B3: 借款合同 | C3: 0 | D3: 5e-05 | E3: 0 | F3: 0 | H3: 0
A4: 2 | B4: 融资租赁合同 | C4: 0 | D4: 5e-05 | E4: 0 | F4: 0 | H4: 0
A5: 3 | B5: 买卖合同 | C5: 0 | D5: 0.0003 | E5: 0 | F5: 0 | H5: 0
A6: 4 | B6: 承揽合同 | C6: 0 | D6: 0.0003 | E6: 0 | F6: 0 | H6: 0
A7: 5 | B7: 建设工程合同 | C7: 0 | D7: 0.0003 | E7: 0 | F7: 0 | H7: 0
A8: 6 | B8: 运输合同 | C8: 0 | D8: 0.0003 | E8: 0 | F8: 0 | H8: 0
A9: 7 | B9: 技术合同 | C9: 21253143 | D9: 0.0003 | E9: 6375.9428 | F9: 3187.9714 | H9: 3187.97
A10: 8 | B10: 租赁合同 | C10: 0 | D10: 0.001 | E10: 0 | F10: 0 | H10: 0
A11: 9 | B11: 保管合同 | C11: 0 | D11: 0.001 | E11: 0 | F11: 0 | H11: 0
A12: 10 | B12: 仓储合同 | C12: 0 | D12: 0.001 | E12: 0 | F12: 0 | H12: 0
A13: 11 | B13: 财产保险合同 | C13: 81022.16 | D13: 0.001 | E13: 81.02216 | F13: 40.51108 | H13: 40.51
A14: 12 | B14: 土地使用权 出让书据 | C14: 0 | D14: 0.0005 | E14: 0 | F14: 0 | H14: 0
... A19: 17 | B19: 证券交易 | C19: 0 | D19: 0.001 | E19: 0 | F19: 0 | H19: 0
B20: 合计 | C20: 21334165 | E20: 6456.965 | F20: 3228.4825 | G20: 0 | H20: 3228.48
A24: 2342-五河新茂风力发电有限公司 | D24: 所属期 | E24: 2025Q3 | F24: 2025年第三季度 | H24: 单位：元
A25: 序号 | B25: 税目 | C25: 计税依据 | D25: 税率 | E25: 应纳税额 | F25: 减免税额 | G25: 已缴税额 | H25: 应补（退）税额
A26: 1 | B26: 借款合同 | C26: 0 | D26: 5e-05 | E26: 0 | F26: 0 | H26: 0
A27: 2 | B27: 融资租赁合同 | C27: 0 | D27: 5e-05 | E27: 0 | F27: 0 | H27: 0
A28: 3 | B28: 买卖合同 | C28: 3.3248115e+08 | D28: 0.0003 | E28: 99744.345 | F28: 49872.173 | H28: 49872.17
A29: 4 | B29: 承揽合同 | C29: 0 | D29: 0.0003 | E29: 0 | F29: 0 | H29: 0
A30: 5 | B30: 建设工程合同 | C30: 2.8617382e+08 | D30: 0.0003 | E30: 85852.145 | F30: 42926.073 | H30: 42926.07
A31: 6 | B31: 运输合同 | C31: 0 | D31: 0.0003 | E31: 0 | F31: 0 | H31: 0
A32: 7 | B32: 技术合同 | C32: 174528.3 | D32: 0.0003 | E32: 52.35849 | F32: 26.179245 | H32: 26.18
A33: 8 | B33: 租赁合同 | C33: 67129.74 | D33: 0.001 | E33: 67.12974 | F33: 33.56487 | H33: 33.56
A34: 9 | B34: 保管合同 | C34: 0 | D34: 0.001 | E34: 0 | F34: 0 | H34: 0
A35: 10 | B35: 仓储合同 | C35: 0 | D35: 0.001 | E35: 0 | F35: 0 | H35: 0
A36: 11 | B36: 财产保险合同 | C36: 0 | D36: 0.001 | E36: 0 | F36: 0 | H36: 0
A37: 12 | B37: 土地使用权 出让书据 | C37: 0 | D37: 0.0005 | E37: 0 | F37: 0 | H37: 0
... A42: 17 | B42: 证券交易 | C42: 0 | D42: 0.001 | E42: 0 | F42: 0 | H42: 0
B43: 合计 | C43: 6.1889663e+08 | E43: 185715.98 | F43: 92857.989 | G43: 0 | H43: 92857.98

Sheet Ref 1_202510_Summary
A1: 五河新茂风力发电有限公司2025年10月（税务所属期）税费申报明细
H2: 45931
A3: 序号 | B3: 申报税种 | C3: 税目 | D3: 计税依据（记账科目/计税表格） | E3: 计税金额 (A)-季度 | F3: 征收比例 (B) | G3: 税率 (C) | H3: 实际应纳税额 (D) | I3: 计税金额-2025年10月 | J3: 计税金额-2025年11月 | K3: 计税金额-2025年12月 | L3: 差异原因 | M3: 指引
B4: 印花税 | C4: 买卖合同 | D4: 主营业务收入&财务提供 | F4: 1 | G4: 0.0003 | H4: =ROUND(E4*F4*G4,2) -> 0 | I4: ='10月PL'!D5 -> 0 | J4: ='10月PL'!D36 -> 0 | K4: ='10月PL'!D67 -> 0 | M4: PL
C5: 产权转移书据 | D5: 财务提供 | F5: 1 | G5: 0.0005 | H5: =ROUND(E5*F5*G5,2) -> 0 | M5: Ref 1
C6: 借款合同 | F6: 1 | G6: 5e-05 | H6: =ROUND(E6*F6*G6,2) -> 0 | M6: Ref 1
C7: 承揽合同 | F7: 1 | G7: 0.0003 | H7: =ROUND(E7*F7*G7,2) -> 0 | M7: Ref 1
C8: 建设工程合同 | F8: 1 | G8: 0.0003 | H8: =ROUND(E8*F8*G8,2) -> 0 | M8: Ref 1
C9: 运输合同 | F9: 1 | G9: 0.0003 | H9: =ROUND(E9*F9*G9,2) -> 0 | M9: Ref 1
C10: 技术合同 | F10: 1 | G10: 0.0003 | H10: =ROUND(E10*F10*G10,2) -> 0 | M10: Ref 1
C11: 租赁合同 | F11: 1 | G11: 0.001 | H11: =ROUND(E11*F11*G11,2) -> 0 | M11: Ref 1
C12: 保管合同 | F12: 1 | G12: 0.001 | H12: =ROUND(E12*F12*G12,2) -> 0 | M12: Ref 1
C13: 仓储合同 | F13: 1 | G13: 0.001 | H13: =ROUND(E13*F13*G13,2) -> 0 | M13: Ref 1
C14: 财产保险合同 | F14: 1 | G14: 0.001 | H14: =ROUND(E14*F14*G14,2) -> 0 | M14: Ref 1
C15: 营业账簿 | F15: 1 | G15: 0.00025 | H15: =ROUND(E15*F15*G15,2) -> 0 | M15: Ref 1
A16: 1 | B16: 印花税合计 | E16: =SUM(E4:E15) -> 0 | H16: =SUM(H4:H15)*50% -> 0 | I16: 60000200000001 | K16: =H16-J16 -> 0
A17: 序号 | B17: 申报税种 | C17: 税目 | D17: 计税依据（记账科目/计税表格） | E17: 计税金额 | F17: 征收比例 (B) | G17: 税率 (C) | H17: 实际应纳税额 (D) | I17: 记账科目 | J17: 账面金额 | K17: 差异 | L17: 差异原因
B18: 增值税 | C18: 销项税额-主营业务收入 | D18: 主营业务收入 | E18: ='10月PL'!D36 -> 0 | F18: 1 | G18: 0.13 | H18: =E18*G18 -> 0 | I18: 2221010200 | J18: =销项明细!E3 -> 0 | K18: =H18-J18 -> 0 | M18: PL
C19: 销项税额-固定资产处置收入 | D19: 固定资产销售收入 | E19: ='Ref 4_202510 增值税变动表'!F3 -> 0 | F19: 1 | G19: 0.02 | H19: =E19*G19 -> 0
C20: 销项税额-财务费用-利息收入 | D20: 利息收入 | E20: ='Ref 4_202510 增值税变动表'!F4 -> 0 | F20: 1 | G20: 0.06 | H20: =E20*G20 -> 0
C21: 销项税额-其他收益 | D21: 个税手续费返还 | E21: ='Ref 4_202510 增值税变动表'!F5 -> 0 | F21: 1 | G21: 0.06 | H21: =E21*G21 -> 0
C22: 增值税进项税额 | D22: 见表-增值税进项认证清单 | E22: ='Ref 3_202510增值税进项认证清单'!K20 -> 28927576 | F22: 1 | G22: 不适用 | H22: ='Ref 3_202510增值税进项认证清单'!M20 -> 1762386.7 | I22: 2221010100 | J22: =进项明细!K21 -> 1768366.1 | K22: =H22-J22 -> -5979.43 | L22: 此差异是已入账，进项发票不勾选，下个月调整 | M22: Ref 3 | R22: 0.09
C23: 期初进项留抵金额 | D23: 见表-增值税变动表 | F23: 1 | H23: ='Ref 4_202510 增值税变动表'!F11 -> 1538561.5 | M23: Ref 4
C24: 期末进项留抵金额 | D24: 见表-增值税变动表 | F24: 1 | G24: 不适用 | H24: ='Ref 4_202510 增值税变动表'!F12 -> 2354342.5 | J24: ='10月BS'!K145 -> 2360322 | K24: =H24-J24 -> -5979.43 | M24: Ref 4
A25: 2 | B25: 增值税合计 | I25: 61400200000001
B26: 企业所得税 | C26: 项目名称 | D26: 所处优惠期 | E26: 应纳税所得额 | F26: 征收税率 | G26: 当年应缴税额 | H26: Q4应缴税额 | I26: Q3已缴税额 | J26: Q2已缴税额 | K26: Q1已缴税额
E27: ='10月PL'!E121 -> 0 | F27: =25%*20% -> 0.05 | G27: 0 | H27: =G27 -> 0 | I27: 0 | J27: 0 | K27: 0
A28: 3 | B28: 企业所得税合计 | E28: =SUM(E27) -> 0 | G28: =SUM(G27) -> 0 | H28: =SUM(H27) -> 0 | I28: 2221050000
A29: 4 | B29: 城镇土地使用税 | C29: 县城、建制镇、工矿区 | D29: 建设用地面积 | H29: =(ROUND(E29*G29/12*1*50%,2)) -> 0 | I29: 61408220000001 | K29: =H29-J29 -> 0
A30: 5 | B30: 房产税 | C30: 从价计征 | D30: 房产原值 | H30: =E30*0.7*G30/4/3 -> 0 | I30: 61409210000000
A31: 6 | B31: 耕地占用税 | C31: 耕地（非基本农田） | E31: 0 | F31: 26.25 | H31: =E31*F31*50% -> 0
C32: 其他 | E32: 0 | F32: 21 | H32: =E32*F32*50% -> 0
A33: 7 | B33: 水利基金
A34: 8 | B34: 个人所得税 | D34: 实发工资
C35: 劳务报酬所得 | F35: 0.8 | G35: 0.2 | H35: =ROUND(IF(D35<=800,0,IF(D35<=3360,(D35-800)/4,IF(D35<=21000,0.16*D35/0.84,IF(D35<=49500,(0.24*D35-2000)/0.76,(0.32*D35-7000)/0.68)))),2) -> 0 | I35: 6600020002 | J35: 0 | K35: =H35-J35 -> 0
C36: 财产租赁所得 | F36: 0.8 | G36: 0.2
C37: 财产租赁所得（倒算） | F37: 0.8 | G37: 0.2
A38: 9 | B38: =B34 -> 个人所得税 | H38: =SUM(H35:H37) -> 0
A39: 10 | B39: 契税 | C39: 土地使用权出让 | D39: 金额 | G39: 0.03 | H39: =E39*G39 -> 0
A40: 10月应申报合计 | H40: =H16+H25+H28+H29+H30+H31+H32+H38+H39 -> 0 | J40: =J16+J25+J28+J29+J30+J38 -> 0

Sheet Ref 2_202510增值税销项 （样式）

Sheet Ref 3_202510增值税进项认证清单
A1: 发票清单 | B1: 发票清单 | C1: 发票清单 | D1: 发票清单 | E1: 发票清单 | F1: 发票清单 | G1: 发票清单 | H1: 发票清单 | I1: 发票清单 | J1: 发票清单 | K1: 发票清单 | L1: 发票清单 | M1: 发票清单 | N1: 发票清单 | O1: 发票清单 | P1: 发票清单 | Q1: 发票清单 | R1: 发票清单 | S1: 发票清单
A2: 纳税人识别号 | B2: 91340322MA8P9Y1B29 | E2: 税款所属期 | F2: 202510 | H2: 纳税人名称 | I2: 五河新茂风力发电有限公司
A3: 序号 | B3: 勾选状态 | C3: 发票来源 | D3: 转内销证明编号 | E3: 数电发票号码 | F3: 发票代码 | G3: 发票号码 | H3: 开票日期 | I3: 销售方纳税人识别号 | J3: 销售方纳税人名称 | K3: 金额 | L3: 税额 | M3: 有效抵扣税额 | N3: 票种 | O3: 票种标签 | P3: 发票状态 | Q3: 勾选时间 | R3: 发票风险等级 | S3: 风险状态
A4: 1 | B4: 已勾选 | C4: 电子发票服务平台 | E4: 25347000000120397458 | H4: 2025-10-15 14:24:28 | I4: 91340700MA8PUEPEXD | J4: 薪班班（安徽）网络科技有限公司 | K4: 5258.48 | L4: 315.51 | M4: 315.51 | N4: 数电发票（增值税专用发票） | O4: 增值税专用发票 | P4: 正常 | Q4: 2025-11-10 13:47:18 | R4: 正常 | S4: 无风险
A5: 2 | B5: 已勾选 | C5: 电子发票服务平台 | E5: 25347000000120397457 | H5: 2025-10-15 14:24:28 | I5: 91340700MA8PUEPEXD | J5: 薪班班（安徽）网络科技有限公司 | K5: 3662.71 | L5: 219.76 | M5: 219.76 | N5: 数电发票（增值税专用发票） | O5: 增值税专用发票 | P5: 正常 | Q5: 2025-11-10 13:47:18 | R5: 正常 | S5: 无风险
A6: 3 | B6: 已勾选 | C6: 电子发票服务平台 | E6: 25322000000477236947 | H6: 2025-10-15 13:57:54 | I6: 913201183023341889 | J6: 江苏苏安电力工程管理有限公司 | K6: 302122.64 | L6: 18127.36 | M6: 18127.36 | N6: 数电发票（增值税专用发票） | O6: 增值税专用发票 | P6: 正常 | Q6: 2025-11-10 13:47:18 | R6: 正常 | S6: 无风险
A7: 4 | B7: 已勾选 | C7: 电子发票服务平台 | E7: 25312000000344893988 | H7: 2025-10-27 17:38:30 | I7: 91310105MA1FWAC869 | J7: 景泰新能源（上海）有限公司 | K7: 1029 | L7: 61.74 | M7: 61.74 | N7: 数电发票（增值税专用发票） | O7: 增值税专用发票 | P7: 正常 | Q7: 2025-11-10 13:47:18 | R7: 正常 | S7: 无风险
A8: 5 | B8: 已勾选 | C8: 电子发票服务平台 | E8: 25312000000351492267 | H8: 2025-10-31 13:59:14 | I8: 91310105MA1FW25C2F | J8: 上海睿景能源科技有限公司 | K8: 3146.31 | L8: 188.78 | M8: 188.78 | N8: 数电发票（增值税专用发票） | O8: 增值税专用发票 | P8: 正常 | Q8: 2025-11-10 13:47:18 | R8: 正常 | S8: 无风险
A9: 6 | B9: 已勾选 | C9: 电子发票服务平台 | E9: 25312000000351492165 | H9: 2025-10-31 13:59:11 | I9: 91310105MA1FW25C2F | J9: 上海睿景能源科技有限公司 | K9: 3751930.3 | L9: 225115.82 | M9: 225115.82 | N9: 数电发票（增值税专用发票） | O9: 增值税专用发票 | P9: 正常 | Q9: 2025-11-10 13:47:18 | R9: 正常 | S9: 无风险
A10: 7 | B10: 已勾选 | C10: 电子发票服务平台 | E10: 25312000000351492051 | H10: 2025-10-31 13:59:06 | I10: 91310105MA1FW25C2F | J10: 上海睿景能源科技有限公司 | K10: 3279109.2 | L10: 196746.55 | M10: 196746.55 | N10: 数电发票（增值税专用发票） | O10: 增值税专用发票 | P10: 正常 | Q10: 2025-11-10 13:47:18 | R10: 正常 | S10: 无风险
A11: 8 | B11: 已勾选 | C11: 电子发票服务平台 | E11: 25312000000351492020 | H11: 2025-10-31 13:58:59 | I11: 91310105MA1FW25C2F | J11: 上海睿景能源科技有限公司 | K11: 659376.66 | L11: 39562.6 | M11: 39562.6 | N11: 数电发票（增值税专用发票） | O11: 增值税专用发票 | P11: 正常 | Q11: 2025-11-10 13:47:18 | R11: 正常 | S11: 无风险
A12: 9 | B12: 已勾选 | C12: 电子发票服务平台 | E12: 25312000000351491962 | H12: 2025-10-31 13:59:09 | I12: 91310105MA1FW25C2F | J12: 上海睿景能源科技有限公司 | K12: 19610226 | L12: 1176613.6 | M12: 1176613.6 | N12: 数电发票（增值税专用发票） | O12: 增值税专用发票 | P12: 正常 | Q12: 2025-11-10 13:47:18 | R12: 正常 | S12: 无风险
A13: 10 | B13: 已勾选 | C13: 电子发票服务平台 | E13: 25312000000351491827 | H13: 2025-10-31 13:59:01 | I13: 91310105MA1FW25C2F | J13: 上海睿景能源科技有限公司 | K13: 176262.64 | L13: 10575.76 | M13: 10575.76 | N13: 数电发票（增值税专用发票） | O13: 增值税专用发票 | P13: 正常 | Q13: 2025-11-10 13:47:18 | R13: 正常 | S13: 无风险
A14: 11 | B14: 已勾选 | C14: 电子发票服务平台 | E14: 25312000000351491562 | H14: 2025-10-31 13:59:04 | I14: 91310105MA1FW25C2F | J14: 上海睿景能源科技有限公司 | K14: 173476.41 | L14: 10408.58 | M14: 10408.58 | N14: 数电发票（增值税专用发票） | O14: 增值税专用发票 | P14: 正常 | Q14: 2025-11-10 13:47:18 | R14: 正常 | S14: 无风险
A15: 12 | B15: 已勾选 | C15: 电子发票服务平台 | E15: 25312000000349849513 | H15: 2025-10-30 14:28:32 | I15: 91310105MA1FW25C2F | J15: 上海睿景能源科技有限公司 | K15: 859805.82 | L15: 77382.52 | M15: 77382.52 | N15: 数电发票（增值税专用发票） | O15: 增值税专用发票 | P15: 正常 | Q15: 2025-11-10 13:47:18 | R15: 正常 | S15: 无风险
... A19: 16 | B19: 已勾选 | C19: 电子发票服务平台 | E19: 25112000000218775108 | H19: 2025-10-14 16:51:56 | I19: 91110105667530069X | J19: 北京神州汽车租赁有限公司 | K19: 4466.37 | L19: 580.63 | M19: 580.63 | N19: 数电发票（增值税专用发票） | O19: 增值税专用发票 | P19: 正常 | Q19: 2025-11-10 13:47:18 | R19: 正常 | S19: 无风险
A20: 合计 | K20: 28927576 | L20: 1762386.7 | M20: 1762386.7

Sheet Ref 4_202510 增值税变动表
C1: 未开票金额 | D1: 当月开票金额 | E1: 以前月度开票金额 | F1: 合计
B2: 当月利润表主营业务收入 | C2: 0 | D2: ='Ref 2_202510增值税销项 （样式）'!I8 -> 0 | E2: 0 | F2: =C2+D2+E2 -> 0
B3: 销项税额-固定资产处置收入 | F3: =C3+D3+E3 -> 0
B4: 销项税额-财务费用-利息收入 | F4: =C4+D4+E4 -> 0
B5: 销项税额-其他收益 | F5: =C5+D5+E5 -> 0
F6: =C6+D6+E6 -> 0
B7: 应交增值税-销项税 | C7: =F7-D7 -> 0 | D7: ='Ref 2_202510增值税销项 （样式）'!J8 -> 0 | E7: =E2*13%+E3*2%+E4*6%+E5*6% -> 0 | F7: ='Ref 2_202510增值税销项 （样式）'!J8 -> 0
B8: 预开票（未确认收入）-应交增值税 | F8: =C8+D8+E8 -> 0
B9: 增值税已认证进项税 | F9: ='Ref 3_202510增值税进项认证清单'!M20 -> 1762386.7
B10: 进项转出 | F10: 946605.64
B11: 期初留抵进项税-即征即退项目 | F11: 1538561.5
B12: 期末留抵进项税-即征即退项目 | F12: =IF(F11+F9-F7-F10>0,F11+F9-F7-F10,0) -> 2354342.5
B13: 应交增值税 | F13: =IF(F12>0,0,F7+F10-F9-F11) -> 0

Sheet 未开票数监控
A1: 所属期 | B1: 申报账面数 | F1: 开票数 | H1: 未开票数
B2: 营业收入 | C2: 利息收入 | D2: 其他收益 | E2: 销项税额 | F2: 销售收入 | G2: 销项税额 | H2: 销售收入 | I2: 销项税额
A3: 2025-1 | H3: =B3+C3+D3-F3 -> 0 | I3: =E3-G3 -> 0
A4: 2025-2 | H4: =B4+C4+D4-F4 -> 0 | I4: =E4-G4 -> 0
A5: 2025-3 | H5: =B5+C5+D5-F5 -> 0 | I5: =E5-G5 -> 0
A6: 2025-4 | H6: =B6+C6+D6-F6 -> 0 | I6: =E6-G6 -> 0
A7: 2025-5 | H7: =B7+C7+D7-F7 -> 0 | I7: =E7-G7 -> 0
A8: 2025-6 | H8: =B8+C8+D8-F8 -> 0 | I8: =E8-G8 -> 0
A9: 2025-7 | H9: =B9+C9+D9-F9 -> 0 | I9: =E9-G9 -> 0
A10: 2025-8 | B10: 0 | E10: 0 | F10: 0 | G10: 0 | H10: =B10+C10+D10-F10 -> 0 | I10: =E10-G10 -> 0
A11: 2025-9 | B11: 0 | E11: 0 | F11: 0 | G11: 0 | H11: =B11+C11+D11-F11 -> 0 | I11: =E11-G11 -> 0
A12: 2025-10 | B12: 0 | E12: 0 | F12: 0 | G12: 0 | H12: =B12+C12+D12-F12 -> 0 | I12: =E12-G12 -> 0
A13: 2025-11 | B13: 0 | E13: 0 | F13: 0 | G13: 0 | H13: =B13+C13+D13-F13 -> 0 | I13: =E13-G13 -> 0
A14: 2025-12 | B14: 0 | E14: 0 | F14: 0 | G14: 0 | H14: =B14+C14+D14-F14 -> 0 | I14: =E14-G14 -> 0
A15: 合计数 | B15: =SUM(B3:B14) -> 0 | C15: =SUM(C3:C14) -> 0 | D15: =SUM(D3:D14) -> 0 | E15: =SUM(E3:E14) -> 0 | F15: =SUM(F3:F14) -> 0 | G15: =SUM(G3:G14) -> 0 | H15: =SUM(H3:H14) -> 0 | I15: =SUM(I3:I14) -> 0

Sheet 五河新茂项目累计申报
B1: 申报税费汇总表
B2: 五河新茂风力发电有限公司 | M2: 残疾人保证金 | P2: 单位：元
B3: 所属期 | C3: 所得税 | D3: 增值税 | E3: 增值税附加税 | F3: 印花税 | G3: 工会经费 | H3: 房产税 | I3: 个人所得税 | J3: 耕地占用税 | K3: 土地使用税 | L3: 垃圾费 | M3: 水利基金 | N3: 滞纳金 | O3: 契税 | P3: 税款合计
B4: 45658 | P4: =SUM(C4:O4) -> 0
B5: 45689 | P5: =SUM(C5:O5) -> 0
B6: 45717 | P6: =SUM(C6:O6) -> 0
B7: 45748 | P7: =SUM(C7:O7) -> 0
B8: 45778 | J8: 940332.74 | P8: =SUM(C8:O8) -> 940332.74
B9: 45809 | F9: 3228.48 | J9: 181710.37 | P9: =SUM(C9:O9) -> 184938.85
B10: 45839 | P10: =SUM(C10:O10) -> 0
B11: 45870 | P11: =SUM(C11:O11) -> 0
B12: 45901 | F12: 92857.995 | J12: 28031.06 | P12: =SUM(C12:O12) -> 120889.05
B13: 45931 | P13: =SUM(C13:O13) -> 0
B14: 45962 | P14: =SUM(C14:O14) -> 0
B15: 45992 | P15: =SUM(C15:O15) -> 0
B16: 合计 | C16: =SUM(C4:C15) -> 0 | D16: =SUM(D4:D15) -> 0 | E16: =SUM(E4:E15) -> 0 | F16: =SUM(F4:F15) -> 96086.475 | G16: =SUM(G4:G15) -> 0 | H16: =SUM(H4:H15) -> 0 | I16: =SUM(I4:I15) -> 0 | J16: =SUM(J4:J15) -> 1150074.2 | ... O16: =SUM(O4:O15) -> 0 | P16: =SUM(C16:O16) -> 1246160.6

Sheet 五河新茂项目累计缴纳
B1: 实缴税费汇总表
B2: 五河新茂风力发电有限公司 | M2: 残疾人保证金 | P2: 单位：元
B3: 所属期 | C3: 所得税 | D3: 增值税 | E3: 增值税附加税 | F3: 印花税 | G3: 工会经费 | H3: 房产税 | I3: 个人所得税 | J3: 耕地占用税 | K3: 土地使用税 | L3: 垃圾费 | M3: 水利基金 | N3: 滞纳金 | O3: 契税 | P3: 实缴税金 | Q3: 申请税金 | R3: 差异 | S3: 原因
B4: 45658 | P4: =SUM(C4:O4) -> 0 | Q4: =五河新茂项目累计申报!P4 -> 0 | R4: =P4-Q4 -> 0
B5: 45689 | P5: =SUM(C5:O5) -> 0 | Q5: =五河新茂项目累计申报!P5 -> 0 | R5: =P5-Q5 -> 0
B6: 45717 | P6: =SUM(C6:O6) -> 0 | Q6: =五河新茂项目累计申报!P6 -> 0 | R6: =P6-Q6 -> 0
B7: 45748 | P7: =SUM(C7:O7) -> 0 | Q7: =五河新茂项目累计申报!P7 -> 0 | R7: =P7-Q7 -> 0
B8: 45778 | J8: 940332.74 | P8: =SUM(C8:O8) -> 940332.74 | Q8: =五河新茂项目累计申报!P8 -> 940332.74 | R8: =P8-Q8 -> 0
B9: 45809 | F9: 3228.48 | J9: 181710.37 | P9: =SUM(C9:O9) -> 184938.85 | Q9: =五河新茂项目累计申报!P9 -> 184938.85 | R9: =P9-Q9 -> 0
B10: 45839 | P10: =SUM(C10:O10) -> 0 | Q10: =五河新茂项目累计申报!P10 -> 0 | R10: =P10-Q10 -> 0
B11: 45870 | P11: =SUM(C11:O11) -> 0 | Q11: =五河新茂项目累计申报!P11 -> 0 | R11: =P11-Q11 -> 0
B12: 45901 | J12: 28031.06 | P12: =SUM(C12:O12) -> 28031.06 | Q12: =五河新茂项目累计申报!P12 -> 120889.05 | R12: =P12-Q12 -> -92857.995
B13: 45931 | P13: =SUM(C13:O13) -> 0 | Q13: =五河新茂项目累计申报!P13 -> 0 | R13: =P13-Q13 -> 0
B14: 45962 | P14: =SUM(C14:O14) -> 0 | Q14: =五河新茂项目累计申报!P14 -> 0 | R14: =P14-Q14 -> 0
B15: 45992 | P15: =SUM(C15:O15) -> 0 | Q15: =五河新茂项目累计申报!P15 -> 0 | R15: =P15-Q15 -> 0
B16: 合计 | C16: =SUM(C4:C15) -> 0 | D16: =SUM(D4:D15) -> 0 | E16: =SUM(E4:E15) -> 0 | F16: =SUM(F4:F15) -> 3228.48 | G16: =SUM(G4:G15) -> 0 | H16: =SUM(H4:H15) -> 0 | I16: =SUM(I4:I15) -> 0 | J16: =SUM(J4:J15) -> 1150074.2 | ... O16: =SUM(O4:O15) -> 0 | P16: =SUM(C16:O16) -> 1153302.6 | Q16: =SUM(Q4:Q15) -> 1246160.6 | R16: =SUM(R4:R15) -> -92857.995
