Workbook
Name _epmOfflineCondition_: 1
Name _epmOfflineCondition_: 1

Sheet 02月BS
B1: 资产负债表-单体
B2: 编制单位：伊金霍洛旗悦盛新能源有限公司
B3: 编制时间：2025.01
B4: 项目 | C4: 行 | D4: 年初数 | E4: 累计发生数 | F4: 项目 | G4: 行 | H4: 年初数 | I4: 累计发生数
B5: 流动资产： | C5: 1 | F5: 流动负债：
B6: 货币资金 | C6: 2 | D6: 305592.95 | E6: 4642887.7 | F6: 短期借款 | G6: 50 | H6: 0 | I6: 0
B7: 交易性金融资产 | C7: 3 | D7: 0 | E7: 0 | F7: 衍生金融负债 | G7: 51 | H7: 0 | I7: 0
B8: 衍生金融资产 | C8: 4 | D8: 0 | E8: 0 | F8: 应付票据 | G8: 52 | H8: 0 | I8: 0
B9: 应收票据 | C9: 5 | D9: 0 | E9: 0 | F9: 应付账款 | G9: 53 | H9: 80954845 | I9: 81076223
B10: 应收账款 | C10: 6 | D10: 45946754 | E10: 62250914 | F10: 预收款项 | G10: 54 | H10: 0 | I10: 0
B11: 应收款项融资 | C11: 7 | D11: 0 | E11: 0 | F11: 合同负债 | G11: 55 | H11: 0 | I11: 0
B12: 预付款项 | C12: 8 | D12: 3.4780292e+08 | E12: 3.3681871e+08 | F12: 应付职工薪酬 | G12: 56 | H12: 0 | I12: 0
B13: 应收利息 | C13: 9 | D13: 0 | E13: 0 | F13: 应交税费 | G13: 57 | H13: -1.9480895e+08 | I13: -1.9248279e+08
B14: 应收股利 | C14: 10 | D14: 0 | E14: 0 | F14: 应付利息 | G14: 58 | H14: 1922871.5 | I14: 7341873
B15: 其他应收款 | C15: 11 | D15: 40000 | E15: 40000 | G15: 59
B16: 存货 | C16: 12 | D16: 0 | E16: 0 | F16: 应付股利 | G16: 60 | H16: 0 | I16: 0
B17: 合同资产 | C17: 13 | D17: 0 | E17: 0 | F17: 其他应付款 | G17: 61 | H17: 48600700 | I17: 50600700
B18: 一年内到期的非流动资产 | C18: 14 | D18: 0 | E18: 0 | F18: 递延收益 | G18: 62 | H18: 0 | I18: 0
B19: 其他流动资产 | C19: 15 | D19: 16285254 | E19: 17223966 | F19: 一年内到期的非流动负债 | G19: 63 | H19: 1.2183232e+08 | I19: 1.2183232e+08
B20: 流动资产合计 | C20: 16 | D20: 4.1038052e+08 | E20: 4.2097648e+08 | F20: 其他流动负债 | G20: 64 | H20: 0 | I20: 0
B21: 非流动资产： | C21: 17 | F21: 流动负债合计 | G21: 65 | H21: 58501784 | I21: 68368332
B22: 其他权益工具投资 | C22: 18 | D22: 0 | E22: 0 | F22: 非流动负债： | G22: 66
B23: 债权投资 | C23: 19 | D23: 0 | E23: 0 | F23: 长期借款 | G23: 67 | H23: 1.5932477e+09 | I23: 1.5932477e+09
B24: 长期应收款 | C24: 20 | D24: 0 | E24: 0 | F24: 应付债券 | G24: 68 | H24: 0 | I24: 0 | Q24: 788747.51 | R24: 转出数据
B25: 长期股权投资 | C25: 21 | D25: 0 | E25: 0 | F25: 租赁负债 | G25: 69 | H25: 0 | I25: 0
B26: 其他非流动金融资产 | C26: 22 | D26: 0 | E26: 0 | F26: 长期应付款 | G26: 70 | H26: 0 | I26: 0
B27: 投资性房地产 | C27: 23 | D27: 0 | E27: 0 | F27: 专项应付款 | G27: 71 | H27: 0 | I27: 0
B28: 固定资产-原值 | C28: 24 | D28: 1.6220084e+09 | E28: 1.6220084e+09 | F28: 预计负债 | G28: 72 | H28: 0 | I28: 0
B29: 减：累计折旧 | C29: 25 | D29: -11566607 | E29: -17987057 | F29: 递延所得税负债 | G29: 73 | H29: 0 | I29: 0
B30: 减：固定资产减值准备 | C30: 26 | D30: 0 | E30: 0 | F30: 其他非流动负债 | G30: 74 | H30: 0 | I30: 0
B31: 固定资产净值 | C31: 27 | D31: 1.6104418e+09 | E31: 1.6040213e+09 | F31: 非流动负债合计 | G31: 75 | H31: 1.5932477e+09 | I31: 1.5932477e+09
B32: 在建工程 | C32: 28 | D32: 2.416989e+08 | E32: 2.5426721e+08 | G32: 76
B33: 使用权资产-原值 | C33: 29 | D33: 0 | E33: 0 | G33: 77
B34: 减：使用权资产-累计折旧 | C34: 30 | D34: 0 | E34: 0 | F34: 负债合计 | G34: 78 | H34: 1.6517495e+09 | I34: 1.661616e+09
B35: 使用权资产-净值 | C35: 31 | D35: 0 | E35: 0 | G35: 79
B36: 无形资产 | C36: 32 | D36: 12298070 | E36: 12246474 | F36: 所有者权益（股东权益） | G36: 80
B37: 开发支出 | C37: 33 | D37: 0 | E37: 0 | F37: 实收资本 | G37: 81 | H37: 591690000 | I37: 591690000
B38: 商誉 | C38: 34 | D38: 0 | E38: 0 | F38: 资本公积 | G38: 82 | H38: 0 | I38: 0
B39: 长期待摊费用 | C39: 35 | D39: 0 | E39: 0 | F39: 盈余公积 | G39: 83 | H39: 3137978.8 | I39: 3137978.8
B40: 递延所得税资产 | C40: 36 | D40: 0 | E40: 0 | F40: 其他综合收益 | G40: 84 | H40: 0 | I40: 0
...

Sheet 02月PL
B1: 利润表-单体
A2: 当期时间 | B2: 编制单位：伊金霍洛旗悦盛新能源有限公司
B3: 编制时间：2025.01
A4: 2024.1 | B4: 项目 | D4: 本期发生额 | E4: 累计发生额 | I4: 收入 | J4: 销项
A5: 当前月份 | B5: 一、营业收入 | C5: 1 | D5: =IF(RIGHT($B$3,2)="01",E5,E5-F5) -> 18613557 | E5: 18613557 | H5: 光伏 | I5: 73719.56 | J5: 9583.55
A6: =RIGHT(A4,2) -> .1 | B6: 其中：营业收入 | C6: 2 | D6: =IF(RIGHT($B$3,2)="01",E6,E6-F6) -> 18613557 | E6: 18613557 | H6: 风电 | I6: 18539837 | J6: 2410178.8
B7: 主营业务收入 | C7: 3 | D7: =IF(RIGHT($B$3,2)="01",E7,E7-F7) -> 18613557 | E7: 18613557 | I7: =SUM(I5:I6) -> 18613557 | J7: =J5+J6 -> 2419762.4
B8: 其他业务收入 | C8: 4 | D8: =IF(RIGHT($B$3,2)="01",E8,E8-F8) -> 0 | E8: 0
B9: 二：营业总成本 | C9: 5 | D9: =IF(RIGHT($B$3,2)="01",E9,E9-F9) -> 11787882 | E9: =E10+E13+E14+E15+E16+E17+E20+E21+E22+E23+E24 -> 11787882
B10: 其中：营业成本 | C10: 6 | D10: =IF(RIGHT($B$3,2)="01",E10,E10-F10) -> 6947743.1 | E10: 6947743.1
B11: 主营业务成本 | C11: 7 | D11: =IF(RIGHT($B$3,2)="01",E11,E11-F11) -> 6947743.1 | E11: 6947743.1
B12: 其他业务成本 | C12: 8 | D12: =IF(RIGHT($B$3,2)="01",E12,E12-F12) -> 0 | E12: 0
B13: 营业税金及附加 | C13: 9 | D13: =IF(RIGHT($B$3,2)="01",E13,E13-F13) -> 37307.89 | E13: 37307.89
B14: 销售费用 | C14: 10 | D14: =IF(RIGHT($B$3,2)="01",E14,E14-F14) -> 0 | E14: 0
B15: 管理费用 | C15: 11 | D15: =IF(RIGHT($B$3,2)="01",E15,E15-F15) -> 30593.09 | E15: 30593.09
B16: 研发费用 | C16: 12 | D16: =IF(RIGHT($B$3,2)="01",E16,E16-F16) -> 0 | E16: 0
B17: 财务费用 | C17: 13 | D17: =IF(RIGHT($B$3,2)="01",E17,E17-F17) -> 4772237.5 | E17: 4772237.5
B18: 其他收益 | C18: 14 | D18: =IF(RIGHT($B$3,2)="01",E18,E18-F18) -> 0 | E18: 0
B19: 投资收益（损失以“-”号填列） | C19: 15 | D19: =IF(RIGHT($B$3,2)="01",E19,E19-F19) -> 0 | E19: 0
B20: 净敞口套期收益（亏损以“－”号填列） | C20: 16 | D20: =IF(RIGHT($B$3,2)="01",E20,E20-F20) -> 0 | E20: 0
B21: 公允价值变动收益 | C21: 17 | D21: =IF(RIGHT($B$3,2)="01",E21,E21-F21) -> 0 | E21: 0
... B30: 五、净利润（净亏损以“－”号填列） | C30: 26 | D30: =IF(RIGHT($B$3,2)="01",E30,E30-F30) -> 6825675 | E30: 6825675
B32: 利润表-单体
B33: 编制单位：伊金霍洛旗悦盛新能源有限公司
B34: 编制时间：2025.02
B35: 项目 | D35: 本期发生额 | E35: 累计发生额
B36: 一、营业收入 | C36: 1 | D36: 15885357 | E36: 34498913
B37: 其中：营业收入 | C37: 2 | D37: 15885357 | E37: 34498913 | I37: 收入 | J37: 销项
B38: 主营业务收入 | C38: 3 | D38: 15885357 | E38: 34498913 | H38: 光伏 | I38: 75907.57 | J38: 9867.98
B39: 其他业务收入 | C39: 4 | D39: 0 | E39: 0 | H39: 风电 | I39: 15809449 | J39: 2055228.4
B40: 二：营业总成本 | C40: 5 | D40: 11385683 | E40: =E41+E44+E45+E46+E47+E48+E51+E52+E53+E54+E55 -> 23173564 | I40: =SUM(I38:I39) -> 15885357 | J40: =J38+J39 -> 2065096.4
B41: 其中：营业成本 | C41: 6 | D41: 7010582.4 | E41: 13958326
B42: 主营业务成本 | C42: 7 | D42: 7010582.4 | E42: 13958326
B43: 其他业务成本 | C43: 8 | D43: 0 | E43: 0
B44: 营业税金及附加 | C44: 9 | D44: 0 | E44: 37307.89
B45: 销售费用 | C45: 10 | D45: 0 | E45: 0
B46: 管理费用 | C46: 11 | D46: 64860.01 | E46: 95453.1
B47: 研发费用 | C47: 12 | D47: 0 | E47: 0
B48: 财务费用 | C48: 13 | D48: 4310240.3 | E48: 9082477.8
B49: 其他收益 | C49: 14 | D49: 0 | E49: 0
...

Sheet 销项明细
A1: 公司代码 | B1: 财年 | C1: 过账期间 | D1: 凭证编号 | E1: 凭证日期 | F1: 凭证类型 | G1: 过账日期 | H1: 年度/月份 | I1: 分配 | J1: 总帐帐目 | K1: 本币金额 | L1: 本币 | M1: 物料 | N1: 显示货币的金额 | O1: 凭证货币 | P1: 贸易伙伴 | Q1: 记帐代码 | R1: 税码 | S1: 数量 | T1: 采购凭证 | U1: 参照 | V1: 清帐凭证 | W1: 文本 | X1: 凭证抬头文本 | Y1: 客户 | Z1: 供应商 | AA1: WBS 要素 | AB1: 成本中心 | AC1: 订单 | AD1: 清帐日期
A2: 4470 | B2: 2025 | C2: 2 | D2: 3000000007 | E2: 45716 | F2: DR | G2: 45716 | H2: 2025/02 | I2: 暂估02月电费收入 | J2: 2221010200 | K2: -163973.19 | L2: RMB | N2: -163973.19 | O2: RMB | P2: B012 | Q2: 50 | S2: 0 | U2: 暂估02月电费收入 | W2: 暂估2025年02月电费收入-远景动力（风电） | X2: 暂估2025年02月电费收入-远景动力
A3: 4470 | B3: 2025 | C3: 2 | D3: 3000000007 | E3: 45716 | F3: DR | G3: 45716 | H3: 2025/02 | I3: 暂估02月电费收入 | J3: 2221010200 | K3: 5856.19 | L3: RMB | N3: 5856.19 | O3: RMB | P3: B012 | Q3: 40 | S3: 0 | U3: 暂估02月电费收入 | W3: 政策性交叉补贴 | X3: 暂估2025年02月电费收入-远景动力
A4: 4470 | B4: 2025 | C4: 2 | D4: 3000000007 | E4: 45716 | F4: DR | G4: 45716 | H4: 2025/02 | I4: 暂估02月电费收入 | J4: 2221010200 | K4: 18154.17 | L4: RMB | N4: 18154.17 | O4: RMB | P4: B012 | Q4: 40 | S4: 0 | U4: 暂估02月电费收入 | W4: 系统备用费用 | X4: 暂估2025年02月电费收入-远景动力
A5: 4470 | B5: 2025 | C5: 2 | D5: 3000000008 | E5: 45716 | F5: DR | G5: 45716 | H5: 2025/02 | I5: 暂估02月电费收入 | J5: 2221010200 | K5: -11560.82 | L5: RMB | N5: -11560.82 | O5: RMB | P5: B012 | Q5: 50 | S5: 0 | U5: 暂估02月电费收入 | W5: 暂估2025年02月电费收入-远景动力（光伏） | X5: 暂估2025年02月电费收入-远景动力（光伏）
A6: 4470 | B6: 2025 | C6: 2 | D6: 3000000008 | E6: 45716 | F6: DR | G6: 45716 | H6: 2025/02 | I6: 暂估02月电费收入 | J6: 2221010200 | K6: 412.89 | L6: RMB | N6: 412.89 | O6: RMB | P6: B012 | Q6: 40 | S6: 0 | U6: 暂估02月电费收入 | W6: 政策性交叉补贴 | X6: 暂估2025年02月电费收入-远景动力（光伏）
A7: 4470 | B7: 2025 | C7: 2 | D7: 3000000008 | E7: 45716 | F7: DR | G7: 45716 | H7: 2025/02 | I7: 暂估02月电费收入 | J7: 2221010200 | K7: 1279.95 | L7: RMB | N7: 1279.95 | O7: RMB | P7: B012 | Q7: 40 | S7: 0 | U7: 暂估02月电费收入 | W7: 系统备用费用 | X7: 暂估2025年02月电费收入-远景动力（光伏）
A8: 4470 | B8: 2025 | C8: 2 | D8: 3000000009 | E8: 45716 | F8: DR | G8: 45716 | H8: 2025/02 | I8: 02月电费收入 | J8: 2221010200 | K8: -1915265.6 | L8: RMB | N8: -1915265.6 | O8: RMB | Q8: 50 | S8: 0 | U8: 02月电费收入 | W8: 暂估02月电费收入 | X8: 暂估46万零碳电费收入
N10: =SUM(N2:N8) -> -2065096.4

Sheet 进项明细
A1: 公司代码 | B1: 财年 | C1: 过账期间 | D1: 凭证编号 | E1: 凭证日期 | F1: 凭证类型 | G1: 过账日期 | H1: 年度/月份 | I1: 分配 | J1: 总帐帐目 | K1: 本币金额 | L1: 本币 | M1: 物料 | N1: 显示货币的金额 | O1: 凭证货币 | P1: 贸易伙伴 | Q1: 记帐代码 | R1: 税码 | S1: 数量 | T1: 采购凭证 | U1: 参照 | V1: 清帐凭证 | W1: 文本 | X1: 凭证抬头文本 | Y1: 客户 | Z1: 供应商 | AA1: WBS 要素 | AB1: 成本中心 | AC1: 订单 | AD1: 清帐日期
A2: 4470 | B2: 2025 | C2: 2 | D2: 1000000096 | E2: 45667 | F2: SA | G2: 45689 | H2: 2025/02 | J2: 2221010100 | K2: 6949.21 | L2: RMB | N2: 6949.21 | O2: RMB | Q2: 40 | S2: 0 | V2: 1000000096 | W2: 调整4-12，下网电费税号开错，进项调整。 | X2: 调整4-12 | AD2: 45689
A3: 4470 | B3: 2025 | C3: 2 | D3: 1000000097 | E3: 45667 | F3: SA | G3: 45689 | H3: 2025/02 | J3: 2221010100 | K3: 13397.9 | L3: RMB | N3: 13397.9 | O3: RMB | Q3: 40 | S3: 0 | V3: 1000000097 | W3: 调整4-10 ，下网电费税号开错，进项调整。 | X3: 调整4-10 | AD3: 45689
A4: 4470 | B4: 2025 | C4: 2 | D4: 1000000098 | E4: 45667 | F4: SA | G4: 45689 | H4: 2025/02 | J4: 2221010100 | K4: 4828.4 | L4: RMB | N4: 4828.4 | O4: RMB | Q4: 40 | S4: 0 | V4: 1000000098 | W4: 调整4-11，下网电费税号开错，进项调整。 | X4: 调整4-11 | AD4: 45689
A5: 4470 | B5: 2025 | C5: 2 | D5: 4000000035 | E5: 45696 | F5: KR | G5: 45696 | H5: 2025/02 | I5: 447002 | J5: 2221010100 | K5: 1185.61 | L5: RMB | N5: 1185.61 | O5: RMB | Q5: 40 | R5: J2 | S5: 0 | U5: 25157*18271151/1 | W5: 25157*18271151/152762,ATJT20241000704/202501001 | X5: ATJT20241000704/202501001
A6: 4470 | B6: 2025 | C6: 2 | D6: 4000000035 | E6: 45696 | F6: KR | G6: 45696 | H6: 2025/02 | I6: 447002 | J6: 2221010100 | K6: 1079.19 | L6: RMB | N6: 1079.19 | O6: RMB | Q6: 40 | R6: J2 | S6: 0 | U6: 25157*18271151/1 | W6: 25157*18271151/152762,ATJT20241000704/202501001 | X6: ATJT20241000704/202501001
A7: 4470 | B7: 2025 | C7: 2 | D7: 4000000036 | E7: 45698 | F7: KR | G7: 45698 | H7: 2025/02 | I7: E-1246 | J7: 2221010100 | K7: 1041.13 | L7: RMB | N7: 1041.13 | O7: RMB | Q7: 40 | R7: J2 | S7: 0 | U7: 04127570 | W7: 04127570,ATJT20241200199,加油卡预付回票 | X7: ATJT20241200199,加油卡预付回票
A8: 4470 | B8: 2025 | C8: 2 | D8: 4000000037 | E8: 45698 | F8: KR | G8: 45698 | H8: 2025/02 | I8: 447002-生产部-碳4万(自运维 | J8: 2221010100 | K8: 10691.72 | L8: RMB | N8: 10691.72 | O8: RMB | P8: 1000 | Q8: 40 | R8: J4 | S8: 0 | U8: APJT20250200056 | W8: APJT20250200056,25322*26402336 | X8: 25322*26402336
A9: 4470 | B9: 2025 | C9: 2 | D9: 4000000038 | E9: 45698 | F9: KR | G9: 45698 | H9: 2025/02 | I9: 447004-生产部-零碳46万(昌 | J9: 2221010100 | K9: 16540.84 | L9: RMB | N9: 16540.84 | O9: RMB | P9: 1000 | Q9: 40 | R9: J4 | S9: 0 | U9: APJT20250200060 | W9: APJT20250200060,25322*26461738 | X9: 25322*26461738
A10: 4470 | B10: 2025 | C10: 2 | D10: 4000000039 | E10: 45696 | F10: RE | G10: 45699 | H10: 2025/02 | I10: 25342*21849078 | J10: 2221010100 | K10: 346.32 | L10: RMB | N10: 346.32 | O10: RMB | Q10: 40 | R10: J4 | S10: 0 | U10: 25342*21849078 | W10: CGDD010053-9720012445 | X10: CGDD010053-9720012445
A11: 4470 | B11: 2025 | C11: 2 | D11: 4000000043 | E11: 45678 | F11: RE | G11: 45702 | H11: 2025/02 | I11: 25671188 | J11: 2221010100 | K11: 49031.62 | L11: RMB | N11: 49031.62 | O11: RMB | Q11: 40 | R11: J4 | S11: 0 | U11: 25671188 | W11: CGDD010200-9210183322 | X11: CGDD010200-9210183322
A12: 4470 | B12: 2025 | C12: 2 | D12: 4000000044 | E12: 45702 | F12: KR | G12: 45702 | H12: 2025/02 | I12: 447002-生产部-碳4万(自运维 | J12: 2221010100 | K12: 456.45 | L12: RMB | N12: 456.45 | O12: RMB | Q12: 40 | R12: J4 | S12: 0 | U12: APJT20250200097 | W12: APJT20250200097,05281350 | X12: 05281350
A13: 4470 | B13: 2025 | C13: 2 | D13: 4000000047 | E13: 45712 | F13: KR | G13: 45712 | H13: 2025/02 | I13: E-1246 | J13: 2221010100 | K13: 4726.56 | L13: RMB | N13: 4726.56 | O13: RMB | Q13: 40 | R13: J4 | S13: 0 | U13: APJT20250200244 | W13: APJT20250200244,25312*49452397 | X13: 25312*49452397
A14: 4470 | B14: 2025 | C14: 2 | D14: 4000000049 | E14: 45713 | F14: RE | G14: 45715 | H14: 2025/02 | I14: 25112*36466812 | J14: 2221010100 | K14: 1193.24 | L14: RMB | N14: 1193.24 | O14: RMB | Q14: 40 | R14: J2 | S14: 0 | U14: 25112*36466812 | W14: CGDD010616-9720012486 | X14: CGDD010616-9720012486
A15: 4470 | B15: 2025 | C15: 2 | D15: 4000000053 | E15: 45667 | F15: KR | G15: 45689 | H15: 2025/02 | I15: 447002 | J15: 2221010100 | K15: -13397.9 | L15: RMB | N15: -13397.9 | O15: RMB | Q15: 50 | R15: J2 | S15: 0 | U15: 25157*14158360 | V15: 4000000053 | W15: 25157*14158360,ATJT20241000078，24年12月下网电 | X15: ATJT20241000078，24年12月下网电 | AD15: 45689
A16: 4470 | B16: 2025 | C16: 2 | D16: 4000000054 | E16: 45667 | F16: KR | G16: 45689 | H16: 2025/02 | I16: 447002 | J16: 2221010100 | K16: -4828.4 | L16: RMB | N16: -4828.4 | O16: RMB | Q16: 50 | R16: J2 | S16: 0 | U16: 24157*20742238 | V16: 4000000054 | W16: 24157*20742238,ATJT20241000078，11月下网电费回票 | X16: ATJT20241000078，11月下网电费回票 | AD16: 45689
A17: 4470 | B17: 2025 | C17: 2 | D17: 4000000055 | E17: 45667 | F17: KR | G17: 45689 | H17: 2025/02 | I17: 447002 | J17: 2221010100 | K17: -6949.21 | L17: RMB | N17: -6949.21 | O17: RMB | Q17: 50 | R17: J2 | S17: 0 | U17: 25157*14158350 | V17: 4000000055 | W17: 25157*14158350,ATJT20241000078，11月下网需量电费 | X17: ATJT20241000078，11月下网需量电费 | AD17: 45689
A18: 4470 | B18: 2025 | C18: 2 | D18: 4000000056 | E18: 45714 | F18: KR | G18: 45714 | H18: 2025/02 | I18: 447002 | J18: 2221010100 | K18: 4828.4 | L18: RMB | N18: 4828.4 | O18: RMB | Q18: 40 | R18: J2 | S18: 0 | U18: 25157*18424906 | W18: 25157*18424906,ATJT20241000078，11月下网电费回票 | X18: ATJT20241000078，11月下网电费回票
A19: 4470 | B19: 2025 | C19: 2 | D19: 4000000057 | E19: 45714 | F19: KR | G19: 45714 | H19: 2025/02 | I19: 447002 | J19: 2221010100 | K19: 20346.97 | L19: RMB | N19: 20346.97 | O19: RMB | Q19: 40 | R19: J2 | S19: 0 | U19: 25157*18424916 | W19: 25157*18424916,ATJT20241000078，12月下网电费 | X19: ATJT20241000078，12月下网电费
A20: 4470 | B20: 2025 | C20: 2 | D20: 4000000058 | E20: 45715 | F20: KR | G20: 45715 | H20: 2025/02 | I20: 447005 | J20: 2221010100 | K20: 2028.35 | L20: RMB | N20: 2028.35 | O20: RMB | Q20: 40 | R20: J2 | S20: 0 | U20: 25157*18424917 | W20: 25157*18424917,ATJT20250100442/202410000 | X20: ATJT20250100442/202410000
A21: 4470 | B21: 2025 | C21: 2 | D21: 4000000058 | E21: 45715 | F21: KR | G21: 45715 | H21: 2025/02 | I21: 447002 | J21: 2221010100 | K21: 12728.54 | L21: RMB | N21: 12728.54 | O21: RMB | Q21: 40 | R21: J2 | S21: 0 | U21: 25157*18424917 | W21: 25157*18424917,ATJT20250100442/202410000 | X21: ATJT20250100442/202410000
A22: 4470 | B22: 2025 | C22: 2 | D22: 4000000059 | E22: 45715 | F22: KR | G22: 45715 | H22: 2025/02 | I22: 447002-生产部-碳4万(自运维 | J22: 2221010100 | K22: 1023.1 | L22: RMB | N22: 1023.1 | O22: RMB | P22: 1000 | Q22: 40 | R22: J4 | S22: 0 | U22: APJT20250200475 | W22: APJT20250200475,25322*73754460 | X22: 25322*73754460
A23: 4470 | B23: 2025 | C23: 2 | D23: 4000000060 | E23: 45715 | F23: KR | G23: 45715 | H23: 2025/02 | I23: 447004-生产部-零碳46万(昌 | J23: 2221010100 | K23: 11530.5 | L23: RMB | N23: 11530.5 | O23: RMB | P23: 1000 | Q23: 40 | R23: J4 | S23: 0 | U23: APJT20250200477 | W23: APJT20250200477,25322*73656142 | X23: 25322*73656142
A24: 4470 | B24: 2025 | C24: 2 | D24: 4000000061 | E24: 45716 | F24: KR | G24: 45716 | H24: 2025/02 | I24: SGJTZX | J24: 2221010100 | K24: 1389.5 | L24: RMB | N24: 1389.5 | O24: RMB | P24: 2450 | Q24: 40 | S24: 0 | U24: SGJTZX | W24: 计景泰2月咨询服务费-零碳产业园41W风+5W光25312*61175368 | X24: 25312*6117536820250228000
A25: 4470 | B25: 2025 | C25: 2 | D25: 4000000062 | E25: 45716 | F25: KR | G25: 45716 | H25: 2025/02 | I25: SGJTZX | J25: 2221010100 | K25: 233.86 | L25: RMB | N25: 233.86 | O25: RMB | P25: 2450 | Q25: 40 | S25: 0 | U25: SGJTZX | W25: 计景泰2月咨询服务费-零碳4MW25312*61167361 | X25: 25312*6116736120250228000
A26: 4470 | B26: 2025 | C26: 2 | D26: 4000000063 | E26: 45716 | F26: KR | G26: 45716 | H26: 2025/02 | I26: SGJTZX | J26: 2221010100 | K26: 2268.24 | L26: RMB | N26: 2268.24 | O26: RMB | P26: 2450 | Q26: 40 | S26: 0 | U26: SGJTZX | W26: 计景泰2月咨询服务费-零碳产业园41W风+5W光25312*61167362 | X26: 25312*6116736220250228000
N28: =SUM(N2:N26) -> 142670.14

Sheet 所得税明细

Sheet 印花税明细

Sheet Ref 1_202502_Summary
A1: 伊金霍洛旗悦盛新能源有限公司2025年02月（税务所属期）税费申报明细
H2: 45689
A3: 序号 | B3: 申报税种 | C3: 税目 | D3: 计税依据（记账科目/计税表格） | E3: 计税金额 (A)-季度 | F3: 征收比例 (B) | G3: 税率 (C) | H3: 实际应纳税额 (D) | I3: 计税金额-2025年01月 | J3: 计税金额-2025年02月 | K3: 计税金额-2025年03月 | L3: 差异原因 | M3: 指引
B4: 印花税 | C4: 买卖合同 | D4: 主营业务收入&财务提供 | E4: 0 | F4: 1 | G4: 0.0003 | H4: =ROUND(E4*F4*G4,2) -> 0 | I4: ='02月PL'!D6 -> 18613557 | J4: ='02月PL'!D37 -> 15885357 | K4: ='02月PL'!D69 -> 0 | M4: PL
C5: 融资租赁合同 | D5: 财务提供 | F5: 1 | G5: 5e-05 | H5: =ROUND(E5*F5*G5,2) -> 0 | M5: Ref 1
C6: 借款合同 | F6: 1 | G6: 5e-05 | H6: =ROUND(E6*F6*G6,2) -> 0 | M6: Ref 1
C7: 承揽合同 | E7: 0 | F7: 1 | G7: 0.0003 | H7: =ROUND(E7*F7*G7,2) -> 0 | M7: Ref 1
C8: 建设工程合同 | E8: 0 | F8: 1 | G8: 0.0003 | H8: =ROUND(E8*F8*G8,2) -> 0 | M8: Ref 1
C9: 运输合同 | F9: 1 | G9: 0.0003 | H9: =ROUND(E9*F9*G9,2) -> 0 | M9: Ref 1
C10: 技术合同 | E10: 0 | F10: 1 | G10: 0.0003 | H10: =ROUND(E10*F10*G10,2) -> 0 | M10: Ref 1
C11: 租赁合同 | E11: 0 | F11: 1 | G11: 0.001 | H11: =ROUND(E11*F11*G11,2) -> 0 | M11: Ref 1
C12: 保管合同 | F12: 1 | G12: 0.001 | H12: =ROUND(E12*F12*G12,2) -> 0 | M12: Ref 1
C13: 仓储合同 | F13: 1 | G13: 0.001 | H13: =ROUND(E13*F13*G13,2) -> 0 | M13: Ref 1
C14: 财产保险合同 | F14: 1 | G14: 0.001 | H14: =ROUND(E14*F14*G14,2) -> 0 | M14: Ref 1
C15: 营业账簿 | F15: 1 | G15: 0.00025 | H15: =ROUND(E15*F15*G15,2) -> 0 | M15: Ref 1
C16: 产权转移书据 | F16: 1 | G16: 0.0005 | H16: =ROUND(E16*F16*G16,2) -> 0
A17: 1 | B17: 印花税合计 | E17: =SUM(E4:E16) -> 0 | H17: =SUM(H4:H16) -> 0 | I17: 60000200000001 | K17: =H17-J17 -> 0 | N17: 自行判断：申报期上月末资产总额不超过5000万元
A18: 序号 | B18: 申报税种 | C18: 税目 | D18: 计税依据（记账科目/计税表格） | E18: 计税金额 | F18: 征收比例 (B) | G18: 税率 (C) | H18: 实际应纳税额 (D) | I18: 记账科目 | J18: 账面金额 | K18: 差异 | L18: 差异原因
B19: 增值税 | C19: 销项税额-主营业务收入 | D19: 主营业务收入 | E19: ='02月PL'!D36 -> 15885357 | F19: 1 | G19: 0.13 | H19: =ROUND(E19*G19,2) -> 2065096.4 | I19: 2221010200 | J19: =-销项明细!N10 -> 2065096.4 | K19: =H19-J19 -> 0 | L19: 尾差，以账面计提申报为准 | M19: PL
C20: 销项税额-固定资产处置收入 | D20: 固定资产销售收入 | E20: ='Ref 4_202502 增值税变动表'!F4 -> 0 | F20: 1 | G20: 0.09 | H20: =E20*G20 -> 0
C21: 销项税额-财务费用-利息收入 | D21: 利息收入 | E21: ='Ref 4_202502 增值税变动表'!F5 -> 0 | F21: 1 | G21: 0.06 | H21: =E21*G21 -> 0
C22: 销项税额-其他收益 | D22: 个税手续费返还 | E22: ='Ref 4_202502 增值税变动表'!F6 -> 0 | F22: 1 | G22: 0.06 | H22: =E22*G22 -> 0
C23: 增值税进项税额 | D23: 见表-增值税进项认证清单 | E23: ='Ref 3_202502 增值税进项认证清单'!K22 -> 1979092.2 | F23: 1 | G23: 不适用 | H23: ='Ref 3_202502 增值税进项认证清单'!L22 -> 142670.14 | I23: 2221010100 | J23: =进项明细!N28 -> 142670.14 | K23: =H23-J23 -> 0 | M23: Ref 3 | N23: 当期 | R23: 0.09
C24: 期初进项留抵金额 | D24: 见表-增值税变动表 | F24: 1 | H24: ='Ref 4_202502 增值税变动表'!F15+'Ref 4_202502 增值税变动表'!F16 -> 1.9248279e+08 | M24: Ref 4
C25: 期末进项留抵金额 | D25: 见表-增值税变动表 | F25: 1 | G25: 不适用 | H25: ='Ref 4_202502 增值税变动表'!F17+'Ref 4_202502 增值税变动表'!F18 -> 1.9056036e+08 | J25: =-'02月BS'!I58 -> 1.9056036e+08 | K25: =H25-J25 -> 0 | M25: Ref 4
A26: 2 | B26: 增值税合计 | H26: 0 | I26: 61400200000001
B27: 企业所得税 | C27: 项目名称 | D27: 所处优惠期 | E27: 应纳税所得额 | F27: 征收税率 | G27: 当年应缴税额 | H27: Q1已缴税额 | I27: Q2应缴税额 | J27: Q3应缴税额 | K27: Q4应缴税额
C28: 鄂尔多斯（2023-2025三免期） | D28: 减免期 | E28: ='02月PL'!E91 -> 0 | F28: =25% -> 0.25 | G28: =E28*F28*0 -> 0 | H28: 0 | I28: =G28-H28 -> 0
A29: 3 | B29: 企业所得税合计 | E29: =SUM(E28:E28) -> 0 | G29: =SUM(G28:G28) -> 0 | H29: =I28 -> 0 | I29: 2221050000
A30: 4 | B30: 城镇土地使用税 | C30: 县城、建制镇、工矿区 | D30: 建设用地面积 | F30: 5月、11月缴纳 | G30: 2.4 | H30: =(E30*G30/12*6) -> 0 | I30: 61408220000001 | K30: =H30-J30 -> 0
A31: 5 | B31: 房产税 | C31: 从价计征 | D31: 房产原值 | I31: 61409210000000
B32: 个人所得税 | D32: 实发工资
C33: 劳务报酬所得 | F33: 0.8 | G33: 0.2 | H33: =ROUND(IF(D33<=800,0,IF(D33<=3360,(D33-800)/4,IF(D33<=21000,0.16*D33/0.84,IF(D33<=49500,(0.24*D33-2000)/0.76,(0.32*D33-7000)/0.68)))),2) -> 0 | I33: 6600020002 | J33: 0 | K33: =H33-J33 -> 0
C34: 劳务报酬所得（倒算） | E34: =ROUND(IF(D34<=800,0,IF(D34<=3360,(D34-800)/4,IF(D34<=21000,0.16*D34/0.84,IF(D34<=49500,(0.24*D34-2000)/0.76,(0.32*D34-7000)/0.68)))),2)+D34 -> 0 | F34: 0.8 | G34: 0.4 | H34: =IF(AND(E34=0),0,IF(AND(E34<=4000),E34-800,IF(AND(E34>4000),E34*F34*G34-7000))) -> 0 | I34: 6600020002 | J34: 0
C35: 财产租赁所得 | F35: 0.8 | G35: 0.2
C36: 财产租赁所得（倒算） | F36: 0.8 | G36: 0.2
A37: 6 | B37: =B32 -> 个人所得税 | I37: 代扣代缴个税
A38: 7 | B38: 水利建设专项收入 | C38: 地方水利建设基金 | E38: =伊金悦盛项目累计缴纳!D5 -> 0 | G38: 0.01 | H38: =E38*G38 -> 0
A39: 8 | B39: 耕地占用税 | C39: 林地、草地 | F39: 1 | G39: 27
A40: 9 | B40: 契税 | C40: 国有土地使用权出让（非居住用地） | F40: 1 | G40: 0.03
...

Sheet Ref 2_202502 增值税销项 （样式）

Sheet Ref 3_202502 增值税进项认证清单
A1: 发票清单 | B1: 发票清单 | C1: 发票清单 | D1: 发票清单 | E1: 发票清单 | F1: 发票清单 | G1: 发票清单 | H1: 发票清单 | I1: 发票清单 | J1: 发票清单 | K1: 发票清单 | L1: 发票清单 | M1: 发票清单 | N1: 发票清单 | O1: 发票清单 | P1: 发票清单 | Q1: 发票清单 | R1: 发票清单 | S1: 发票清单
A2: 纳税人识别号 | B2: 91150627MA7JDD6F4F | E2: 税款所属期 | F2: 202502 | H2: 纳税人名称 | I2: 伊金霍洛旗悦盛新能源有限公司
A3: 序号 | B3: 勾选状态 | C3: 发票来源 | D3: 转内销证明编号 | E3: 数电票号码 | F3: 发票代码 | G3: 发票号码 | H3: 开票日期 | I3: 销售方纳税人识别号 | J3: 销售方纳税人名称 | K3: 金额 | L3: 税额 | M3: 有效抵扣税额 | N3: 票种 | O3: 票种标签 | P3: 发票状态 | Q3: 勾选时间 | R3: 发票风险等级 | S3: 风险状态
A4: 1 | B4: 已勾选 | C4: 电子发票服务平台 | E4: 25342000000021849078 | H4: 2025-02-08 18:05:42 | I4: 91340700MA8PUEPEXD | J4: 薪班班（安徽）网络科技有限公司 | K4: 5771.94 | L4: 346.32 | M4: 346.32 | N4: 数电票(增值税专用发票) | O4: 增值税专用发票 | P4: 正常 | Q4: 2025-03-10 14:11:27 | R4: 正常 | S4: 无风险
A5: 2 | B5: 已勾选 | C5: 电子发票服务平台 | E5: 25322000000073754460 | H5: 2025-02-20 09:44:50 | I5: 91320281673004487B | J5: 远景能源有限公司 | K5: 17051.68 | L5: 1023.1 | M5: 1023.1 | N5: 数电票(增值税专用发票) | O5: 增值税专用发票 | P5: 正常 | Q5: 2025-03-10 14:11:27 | R5: 正常 | S5: 无风险
A6: 3 | B6: 已勾选 | C6: 电子发票服务平台 | E6: 25322000000073656142 | H6: 2025-02-20 09:44:52 | I6: 91320281673004487B | J6: 远景能源有限公司 | K6: 192174.95 | L6: 11530.5 | M6: 11530.5 | N6: 数电票(增值税专用发票) | O6: 增值税专用发票 | P6: 正常 | Q6: 2025-03-10 14:11:27 | R6: 正常 | S6: 无风险
A7: 4 | B7: 已勾选 | C7: 电子发票服务平台 | E7: 25322000000026461738 | H7: 2025-01-15 14:53:49 | I7: 91320281673004487B | J7: 远景能源有限公司 | K7: 275680.66 | L7: 16540.84 | M7: 16540.84 | N7: 数电票(增值税专用发票) | O7: 增值税专用发票 | P7: 正常 | Q7: 2025-03-10 14:11:27 | R7: 正常 | S7: 无风险
A8: 5 | B8: 已勾选 | C8: 电子发票服务平台 | E8: 25322000000026402336 | H8: 2025-01-15 14:53:45 | I8: 91320281673004487B | J8: 远景能源有限公司 | K8: 178195.28 | L8: 10691.72 | M8: 10691.72 | N8: 数电票(增值税专用发票) | O8: 增值税专用发票 | P8: 正常 | Q8: 2025-03-10 14:11:27 | R8: 正常 | S8: 无风险
A9: 6 | B9: 已勾选 | C9: 电子发票服务平台 | E9: 25312000000049452397 | H9: 2025-02-19 09:53:20 | I9: 91310230MA1JTEYM9N | J9: 上海峙雄新能源科技有限公司 | K9: 78776.08 | L9: 4726.56 | M9: 4726.56 | N9: 数电票(增值税专用发票) | O9: 增值税专用发票 | P9: 正常 | Q9: 2025-03-10 14:11:27 | R9: 正常 | S9: 无风险
A10: 7 | B10: 已勾选 | C10: 电子发票服务平台 | E10: 25312000000061175368 | H10: 2025-02-28 10:29:55 | I10: 91310105MA1FWAC869 | J10: 景泰新能源（上海）有限公司 | K10: 23158.41 | L10: 1389.5 | M10: 1389.5 | N10: 数电票(增值税专用发票) | O10: 增值税专用发票 | P10: 正常 | Q10: 2025-03-10 14:11:27 | R10: 正常 | S10: 无风险
A11: 8 | B11: 已勾选 | C11: 电子发票服务平台 | E11: 25312000000061167362 | H11: 2025-02-28 10:27:06 | I11: 91310105MA1FWAC869 | J11: 景泰新能源（上海）有限公司 | K11: 37804 | L11: 2268.24 | M11: 2268.24 | N11: 数电票(增值税专用发票) | O11: 增值税专用发票 | P11: 正常 | Q11: 2025-03-10 14:11:27 | R11: 正常 | S11: 无风险
A12: 9 | B12: 已勾选 | C12: 电子发票服务平台 | E12: 25312000000061167361 | H12: 2025-02-28 10:27:06 | I12: 91310105MA1FWAC869 | J12: 景泰新能源（上海）有限公司 | K12: 3897.6 | L12: 233.86 | M12: 233.86 | N12: 数电票(增值税专用发票) | O12: 增值税专用发票 | P12: 正常 | Q12: 2025-03-10 14:11:27 | R12: 正常 | S12: 无风险
A13: 10 | B13: 已勾选 | C13: 增值税发票管理系统 | F13: 3100231130 | G13: 25671188 | H13: 2025-01-21 16:56:22 | I13: 913100008322367537 | J13: 中国人民财产保险股份有限公司上海市分公司 | K13: 817193.81 | L13: 49031.62 | M13: 49031.62 | N13: 增值税专用发票 | O13: 增值税专用发票 | P13: 正常 | Q13: 2025-03-10 14:11:27 | R13: 正常 | S13: 无风险
A14: 11 | B14: 已勾选 | C14: 增值税发票管理系统 | F14: 1500231130 | G14: 04127570 | H14: 2025-01-15 10:10:01 | I14: 91150691701494963W | J14: 中国石油天然气股份有限公司内蒙古鄂尔多斯市销售分公司 | K14: 8008.66 | L14: 1041.13 | M14: 1041.13 | N14: 增值税专用发票 | O14: 增值税专用发票 | P14: 正常 | Q14: 2025-03-10 14:11:27 | R14: 正常 | S14: 无风险
A15: 12 | B15: 已勾选 | C15: 电子发票服务平台 | E15: 25157000000018424917 | H15: 2025-02-10 18:17:05 | I15: 911506911169612847 | J15: 内蒙古电力（集团）有限责任公司鄂尔多斯供电分公司 | K15: 113514.53 | L15: 14756.89 | M15: 14756.89 | N15: 数电票(增值税专用发票) | O15: 增值税专用发票 | P15: 正常 | Q15: 2025-03-10 14:11:27 | R15: 正常 | S15: 无风险
A16: 13 | B16: 已勾选 | C16: 电子发票服务平台 | E16: 25157000000018424916 | H16: 2025-02-10 18:14:31 | I16: 911506911169612847 | J16: 内蒙古电力（集团）有限责任公司鄂尔多斯供电分公司 | K16: 156515.17 | L16: 20346.97 | M16: 20346.97 | N16: 数电票(增值税专用发票) | O16: 增值税专用发票 | P16: 正常 | Q16: 2025-03-10 14:11:27 | R16: 正常 | S16: 无风险
A17: 14 | B17: 已勾选 | C17: 电子发票服务平台 | E17: 25157000000018424906 | H17: 2025-02-10 18:07:48 | I17: 911506911169612847 | J17: 内蒙古电力（集团）有限责任公司鄂尔多斯供电分公司 | K17: 37141.58 | L17: 4828.4 | M17: 4828.4 | N17: 数电票(增值税专用发票) | O17: 增值税专用发票 | P17: 正常 | Q17: 2025-03-10 14:11:27 | R17: 正常 | S17: 无风险
A18: 15 | B18: 已勾选 | C18: 电子发票服务平台 | E18: 25157000000018271151 | H18: 2025-02-07 14:46:54 | I18: 911506911169612847 | J18: 内蒙古电力（集团）有限责任公司鄂尔多斯供电分公司 | K18: 16735.27 | L18: 2175.59 | M18: 2175.59 | N18: 数电票(增值税专用发票) | O18: 增值税专用发票 | P18: 正常 | Q18: 2025-03-10 14:11:27 | R18: 正常 | S18: 无风险
A19: 16 | B19: 已勾选 | C19: 电子发票服务平台 | E19: 25157000000018152762 | H19: 2025-02-07 14:46:08 | I19: 911506911169612847 | J19: 内蒙古电力（集团）有限责任公司鄂尔多斯供电分公司 | K19: 686.27 | L19: 89.21 | M19: 89.21 | N19: 数电票(增值税专用发票) | O19: 增值税专用发票 | P19: 正常 | Q19: 2025-03-10 14:11:27 | R19: 正常 | S19: 无风险
A20: 17 | B20: 已勾选 | C20: 增值税发票管理系统 | F20: 1500221130 | G20: 05281350 | H20: 2025-02-06 18:17:23 | I20: 91150600701412139Q | J20: 中国移动通信集团内蒙古有限公司鄂尔多斯分公司 | K20: 7607.55 | L20: 456.45 | M20: 456.45 | N20: 增值税专用发票 | O20: 增值税专用发票 | P20: 正常 | Q20: 2025-03-10 14:11:27 | R20: 正常 | S20: 无风险
A21: 18 | B21: 已勾选 | C21: 电子发票服务平台 | E21: 25112000000036466812 | H21: 2025-02-25 09:57:02 | I21: 91110105667530069X | J21: 北京神州汽车租赁有限公司 | K21: 9178.76 | L21: 1193.24 | M21: 1193.24 | N21: 数电票(增值税专用发票) | O21: 增值税专用发票 | P21: 正常 | Q21: 2025-03-10 14:11:27 | R21: 正常 | S21: 无风险
A22: 合计 | K22: 1979092.2 | L22: 142670.14 | M22: 142670.14

Sheet Ref 4_202502 增值税变动表
C1: 未开票金额 | D1: 当月开票金额 | E1: 以前月度开票金额 | F1: 合计
B2: 当月利润表主营业务收入-光伏收入 | C2: ='02月PL'!I38-D2-E2 -> 75907.57 | D2: ='Ref 2_202502 增值税销项 （样式）'!Q8 -> 0 | E2: 0 | F2: =C2+D2+E2 -> 75907.57
B3: 当月利润表主营业务收入-风电收入 | C3: ='02月PL'!I39-D3-E3 -> 15809449 | D3: ='Ref 2_202502 增值税销项 （样式）'!Q9 -> 0 | F3: =C3+D3+E3 -> 15809449
B4: 销项税额-固定资产处置收入 | F4: =C4+D4+E4 -> 0
B5: 销项税额-财务费用-利息收入 | F5: =C5+D5+E5 -> 0
B6: 销项税额-其他收益 | F6: =C6+D6+E6 -> 0
F7: =C7+D7+E7 -> 0
B8: 应交增值税-销项税-一般项目（光伏） | C8: 9867.98 | D8: ='Ref 2_202502 增值税销项 （样式）'!S8 -> 0 | E8: =E2*13%+E4*2%+E5*6%+E6*6% -> 0 | F8: ='02月PL'!J38 -> 9867.98
B9: 应交增值税-销项税-即征即退项目（风电） | C9: 2055228.4 | D9: ='Ref 2_202502 增值税销项 （样式）'!S9 -> 0 | E9: =E3*13%+E5*2%+E6*6%+E7*6% -> 0 | F9: ='02月PL'!J39 -> 2055228.4
B10: 预开票（未确认收入）-应交增值税 | F10: =C10+D10+E10 -> 0
B11: 增值税已认证进项税-一般项目（光伏） | F11: ='Ref 3_202502 增值税进项认证清单'!L88 -> 0
B12: 增值税已认证进项税-即征即退项目（风电） | F12: ='Ref 3_202502 增值税进项认证清单'!L22 -> 142670.14
B13: 进项转出-一般
B14: 进项转出-即征即退
B15: 期初留抵进项税-一般项目（光伏） | F15: 2219434 | G15: 上月末
B16: 期初留抵进项税-即征即退项目（风电） | F16: 1.9026335e+08 | G16: 上月末
B17: 期末留抵进项税-一般项目（光伏） | F17: =IF(F8-(F11+F15-F13)>0,0,ABS(F8-(F11+F15-F13))) -> 2209566.1 | G17: 本月末
B18: 期末留抵进项税-即征即退项目（风电） | F18: =IF(F9-(F12+F16-F14)>0,0,ABS(F9-(F12+F16-F14))) -> 1.8835079e+08 | G18: 本月末
B19: 应交增值税-一般项目（光伏）
B20: 应交增值税-即征即退项目（风电） | F20: =IF(F17>0,0,F8+F13-F11-F15) -> 0

Sheet 未开票数监控
A1: 所属期 | B1: 申报账面数 | F1: 开票数 | H1: 未开票数
B2: 营业收入 | C2: 利息收入 | D2: 其他收益 | E2: 销项税额 | F2: 销售收入 | G2: 销项税额 | H2: 销售收入 | I2: 销项税额
B3: 在前序税务台账此页的基础上新增本次台账期数据 取本台账期【PL表】主营业收入 行的本期发生额 | C3: 默认空 | D3: 默认空 | E3: 在前序税务台账此页的基础上新增本次台账期数据 取本台账期【销项明细】货币金额字段合计*-1 | F3: 在前序税务台账此页的基础上新增本次台账期数据 取本台账期【增值税销项表-按税率（征收率）统计表】合计行实际开具发票金额 | G3: 在前序税务台账此页的基础上新增本次台账期数据 取本台账期【增值税销项表-按税率（征收率）统计表】合计行实际开具发票税额 | H3: =B列+C列+D列-F列 | I3: =E列-F列
A4: 2025-1 | B4: 18613557 | E4: 2419762.4 | H4: =B4+C4+D4-F4 -> 18613557 | I4: =E4-G4 -> 2419762.4
A5: 2025-2 | B5: 15885357 | E5: 2065096.4 | H5: =B5+C5+D5-F5 -> 15885357 | I5: =E5-G5 -> 2065096.4
A6: 2025-3 | H6: =B6+C6+D6-F6 -> 0 | I6: =E6-G6 -> 0
A7: 2025-4 | H7: =B7+C7+D7-F7 -> 0 | I7: =E7-G7 -> 0
A8: 2025-5 | H8: =B8+C8+D8-F8 -> 0 | I8: =E8-G8 -> 0
A9: 2025-6 | H9: =B9+C9+D9-F9 -> 0 | I9: =E9-G9 -> 0
A10: 2025-7 | H10: =B10+C10+D10-F10 -> 0 | I10: =E10-G10 -> 0
A11: 2025-8 | H11: =B11+C11+D11-F11 -> 0 | I11: =E11-G11 -> 0
A12: 2025-9 | H12: =B12+C12+D12-F12 -> 0 | I12: =E12-G12 -> 0
A13: 2025-10 | H13: =B13+C13+D13-F13 -> 0 | I13: =E13-G13 -> 0
A14: 2025-11 | H14: =B14+C14+D14-F14 -> 0 | I14: =E14-G14 -> 0
A15: 2025-12 | H15: =B15+C15+D15-F15 -> 0 | I15: =E15-G15 -> 0
A16: 合计数 | B16: =SUM(B4:B15) -> 34498913 | C16: =SUM(C4:C15) -> 0 | D16: =SUM(D4:D15) -> 0 | E16: =SUM(E4:E15) -> 4484858.8 | F16: =SUM(F4:F15) -> 0 | G16: =SUM(G4:G15) -> 0 | H16: =SUM(H4:H15) -> 34498913 | I16: =SUM(I4:I15) -> 4484858.8

Sheet 伊金悦盛项目累计申报
B1: 申报税费汇总表
B2: 伊金霍洛旗悦盛新能源有限公司 | M2: 残疾人保证金 | P2: 单位：元
B3: 所属期 | C3: 所得税 | D3: 增值税 | E3: 增值税附加税 | F3: 印花税 | G3: 工会经费 | H3: 房产税 | I3: 个人所得税 | J3: 耕地占用税 | K3: 土地使用税 | L3: 垃圾费 | M3: 水利基金 | N3: 滞纳金 | O3: 契税 | P3: 税款合计
B4: 45658 | P4: =SUM(C4:O4) -> 0
B5: 45689 | P5: =SUM(C5:O5) -> 0
B6: 45717 | P6: =SUM(C6:O6) -> 0
B7: 45748 | P7: =SUM(C7:O7) -> 0
B8: 45778 | P8: =SUM(C8:O8) -> 0
B9: 45809 | P9: =SUM(C9:O9) -> 0
B10: 45839 | P10: =SUM(C10:O10) -> 0
B11: 45870 | P11: =SUM(C11:O11) -> 0
B12: 45901 | P12: =SUM(C12:O12) -> 0
B13: 45931 | P13: =SUM(C13:O13) -> 0
B14: 45962 | P14: =SUM(C14:O14) -> 0
B15: 45992 | P15: =SUM(C15:O15) -> 0
B16: 合计 | C16: =SUM(C4:C15) -> 0 | D16: =SUM(D4:D15) -> 0 | E16: =SUM(E4:E15) -> 0 | F16: =SUM(F4:F15) -> 0 | G16: =SUM(G4:G15) -> 0 | H16: =SUM(H4:H15) -> 0 | I16: =SUM(I4:I15) -> 0 | J16: =SUM(J4:J15) -> 0 | ... O16: =SUM(O4:O15) -> 0 | P16: =SUM(C16:O16) -> 0

Sheet 伊金悦盛项目累计缴纳
B1: 实缴税费汇总表
B2: 伊金霍洛旗悦盛新能源有限公司 | M2: 残疾人保证金 | P2: 单位：元
B3: 所属期 | C3: 所得税 | D3: 增值税 | E3: 增值税附加税 | F3: 印花税 | G3: 工会经费 | H3: 房产税 | I3: 个人所得税 | J3: 耕地占用税 | K3: 土地使用税 | L3: 垃圾费 | M3: 水利基金 | N3: 滞纳金 | O3: 契税 | P3: 实缴税金 | Q3: 申请税金 | R3: 差异 | S3: 原因
B4: 45658 | P4: =SUM(C4:O4) -> 0 | Q4: =伊金悦盛项目累计申报!P4 -> 0 | R4: =P4-Q4 -> 0
B5: 45689 | P5: =SUM(C5:O5) -> 0 | Q5: =伊金悦盛项目累计申报!P5 -> 0 | R5: =P5-Q5 -> 0
B6: 45717 | P6: =SUM(C6:O6) -> 0 | Q6: =伊金悦盛项目累计申报!P6 -> 0 | R6: =P6-Q6 -> 0
B7: 45748 | P7: =SUM(C7:O7) -> 0 | Q7: =伊金悦盛项目累计申报!P7 -> 0 | R7: =P7-Q7 -> 0
B8: 45778 | P8: =SUM(C8:O8) -> 0 | Q8: =伊金悦盛项目累计申报!P8 -> 0 | R8: =P8-Q8 -> 0
B9: 45809 | P9: =SUM(C9:O9) -> 0 | Q9: =伊金悦盛项目累计申报!P9 -> 0 | R9: =P9-Q9 -> 0
B10: 45839 | P10: =SUM(C10:O10) -> 0 | Q10: =伊金悦盛项目累计申报!P10 -> 0 | R10: =P10-Q10 -> 0
B11: 45870 | P11: =SUM(C11:O11) -> 0 | Q11: =伊金悦盛项目累计申报!P11 -> 0 | R11: =P11-Q11 -> 0
B12: 45901 | P12: =SUM(C12:O12) -> 0 | Q12: =伊金悦盛项目累计申报!P12 -> 0 | R12: =P12-Q12 -> 0
B13: 45931 | P13: =SUM(C13:O13) -> 0 | Q13: =伊金悦盛项目累计申报!P13 -> 0 | R13: =P13-Q13 -> 0
B14: 45962 | P14: =SUM(C14:O14) -> 0 | Q14: =伊金悦盛项目累计申报!P14 -> 0 | R14: =P14-Q14 -> 0
B15: 45992 | P15: =SUM(C15:O15) -> 0 | Q15: =伊金悦盛项目累计申报!P15 -> 0 | R15: =P15-Q15 -> 0
B16: 合计 | C16: =SUM(C4:C15) -> 0 | D16: =SUM(D4:D15) -> 0 | E16: =SUM(E4:E15) -> 0 | F16: =SUM(F4:F15) -> 0 | G16: =SUM(G4:G15) -> 0 | H16: =SUM(H4:H15) -> 0 | I16: =SUM(I4:I15) -> 0 | J16: =SUM(J4:J15) -> 0 | ... O16: =SUM(O4:O15) -> 0 | P16: =SUM(C16:O16) -> 0 | Q16: =SUM(Q4:Q15) -> 0 | R16: =SUM(R4:R15) -> 0
