Workbook
Name \A: #REF!
Name \A: #REF!
Name \A: #REF!
Name \A: #REF!
Name \A: #REF!
Name \A: #REF!
Name \A: #REF!
Name \e: #REF!
Name \p: #REF!
Name \s: #N/A
Name _: #REF!
Name _.xls: #REF!
Name _?: #N/A
Name _??????: #N/A
Name __: #REF!
Name __?: #N/A
Name __??????: #N/A
Name __aaa5: [2]六纺!#REF!
Name __k3: #REF!
Name __sc13: #REF!
Name _00104gz: #REF!
Name _002报表: #REF!
Name _002科目余额表: #REF!
Name _003报表: #REF!
Name _003科目余额表: #REF!
Name _003年12月辅料库: #REF!
Name _01.xls: #REF!
Name _010104501: #REF!
Name _02.xls: #REF!
Name _03.xls: #REF!
Name _1_?: #N/A
Name _11.xls: #REF!
Name _12.xls: #REF!
Name _121.dbf: #REF!
Name _1212002.dbf: #REF!
Name _13: #REF!
Name _17103.dbf: #REF!
Name _171032002.dbf: #REF!
Name _2: #REF!
Name _2_??????: #N/A
Name _2009: #REF!
Name _3¸ß¼ÛÖÜ×ª¼þ_¨º½²Ä¹ý¶É: #REF!
Name _3年12月: #REF!
Name _3年12月后勤库: #REF!
Name _4_04标准价: #REF!
Name _5_20011225: #REF!
Name _55154: #REF!
Name _8未还DB_查询: #REF!
Name _9_12_mo_cost: #REF!
Name _999年12月31日股份应收帐款.dbf: #REF!
Name _aaa5: [2]六纺!#REF!
Name _act411: #REF!
Name _act412: #REF!
Name _act413: #REF!
Name _act414: #REF!
Name _DAT1: #REF!
Name _DAT10: #REF!
Name _DAT11: #REF!
Name _DAT12: #REF!
Name _DAT13: [12]Sheet1!#REF!

Sheet Ref 1_202502_Summary
A1: 伊金霍洛旗悦盛新能源有限公司2025年02月（税务所属期）税费申报明细
H2: 45689
A3: 序号 | B3: 申报税种 | C3: 税目 | D3: 计税依据（记账科目/计税表格） | E3: 计税金额 (A)-季度 | F3: 征收比例 (B) | G3: 税率 (C) | H3: 实际应纳税额 (D) | I3: 计税金额-2025年01月 | J3: 计税金额-2025年02月 | K3: 计税金额-2025年03月 | L3: 差异原因 | M3: 指引
B4: 印花税 | C4: 买卖合同 | D4: 主营业务收入&财务提供 | E4: 0 | F4: 1 | G4: 0.0003 | H4: =ROUND(E4*F4*G4,2) -> 0 | I4: ='[112]02月PL'!D6 -> 18613557 | J4: ='[112]02月PL'!D37 -> 15885357 | K4: ='[112]02月PL'!D69 -> 0 | M4: PL
C5: 融资租赁合同 | D5: 财务提供 | F5: 1 | G5: 5e-05 | H5: =ROUND(E5*F5*G5,2) -> 0 | M5: Ref 1
C6: 借款合同 | F6: 1 | G6: 5e-05 | H6: =ROUND(E6*F6*G6,2) -> 0 | M6: Ref 1
C7: 承揽合同 | E7: 0 | F7: 1 | G7: 0.0003 | H7: =ROUND(E7*F7*G7,2) -> 0 | M7: Ref 1
C8: 建设工程合同 | E8: 0 | F8: 1 | G8: 0.0003 | H8: =ROUND(E8*F8*G8,2) -> 0 | M8: Ref 1
C9: 运输合同 | F9: 1 | G9: 0.0003 | H9: =ROUND(E9*F9*G9,2) -> 0 | M9: Ref 1
C10: 技术合同 | E10: 0 | F10: 1 | G10: 0.0003 | H10: =ROUND(E10*F10*G10,2) -> 0 | M10: Ref 1
C11: 租赁合同 | E11: 0 | F11: 1 | G11: 0.001 | H11: =ROUND(E11*F11*G11,2) -> 0 | M11: Ref 1
C12: 保管合同 | F12: 1 | G12: 0.001 | H12: =ROUND(E12*F12*G12,2) -> 0 | M12: Ref 1
C13: 仓储合同 | F13: 1 | G13: 0.001 | H13: =ROUND(E13*F13*G13,2) -> 0 | M13: Ref 1
C14: 财产保险合同 | F14: 1 | G14: 0.001 | H14: =ROUND(E14*F14*G14,2) -> 0 | M14: Ref 1
C15: 营业账簿 | F15: 1 | G15: 0.00025 | H15: =ROUND(E15*F15*G15,2) -> 0 | M15: Ref 1
C16: 产权转移书据 | F16: 1 | G16: 0.0005 | H16: =ROUND(E16*F16*G16,2) -> 0
A17: 1 | B17: 印花税合计 | E17: =SUM(E4:E16) -> 0 | H17: =SUM(H4:H16) -> 0 | I17: 60000200000001 | K17: =H17-J17 -> 0 | N17: 自行判断：申报期上月末资产总额不超过5000万元
A18: 序号 | B18: 申报税种 | C18: 税目 | D18: 计税依据（记账科目/计税表格） | E18: 计税金额 | F18: 征收比例 (B) | G18: 税率 (C) | H18: 实际应纳税额 (D) | I18: 记账科目 | J18: 账面金额 | K18: 差异 | L18: 差异原因
B19: 增值税 | C19: 销项税额-主营业务收入 | D19: 主营业务收入 | E19: ='[112]02月PL'!D36 -> 15885357 | F19: 1 | G19: 0.13 | H19: =ROUND(E19*G19,2) -> 2065096.4 | I19: 2221010200 | J19: =-[112]销项明细!N10 -> 2065096.4 | K19: =H19-J19 -> 0 | L19: 尾差，以账面计提申报为准 | M19: PL
C20: 销项税额-固定资产处置收入 | D20: 固定资产销售收入 | E20: ='[112]Ref 4_202502 增值税变动表'!F4 -> 0 | F20: 1 | G20: 0.09 | H20: =E20*G20 -> 0
C21: 销项税额-财务费用-利息收入 | D21: 利息收入 | E21: ='[112]Ref 4_202502 增值税变动表'!F5 -> 0 | F21: 1 | G21: 0.06 | H21: =E21*G21 -> 0
C22: 销项税额-其他收益 | D22: 个税手续费返还 | E22: ='[112]Ref 4_202502 增值税变动表'!F6 -> 0 | F22: 1 | G22: 0.06 | H22: =E22*G22 -> 0
C23: 增值税进项税额 | D23: 见表-增值税进项认证清单 | E23: ='[112]Ref 3_202502 增值税进项认证清单'!K22 -> 1979092.2 | F23: 1 | G23: 不适用 | H23: ='[112]Ref 3_202502 增值税进项认证清单'!L22 -> 142670.14 | I23: 2221010100 | J23: =[112]进项明细!N28 -> 142670.14 | K23: =H23-J23 -> 0 | M23: Ref 3 | N23: 当期 | R23: 0.09
C24: 期初进项留抵金额 | D24: 见表-增值税变动表 | F24: 1 | H24: ='[112]Ref 4_202502 增值税变动表'!F15+'[112]Ref 4_202502 增值税变动表'!F16 -> 1.9248279e+08 | M24: Ref 4
C25: 期末进项留抵金额 | D25: 见表-增值税变动表 | F25: 1 | G25: 不适用 | H25: ='[112]Ref 4_202502 增值税变动表'!F17+'[112]Ref 4_202502 增值税变动表'!F18 -> 1.9056036e+08 | J25: =-'[112]02月BS'!I58 -> 1.9056036e+08 | K25: =H25-J25 -> 0 | M25: Ref 4
A26: 2 | B26: 增值税合计 | H26: 0 | I26: 61400200000001
B27: 企业所得税 | C27: 项目名称 | D27: 所处优惠期 | E27: 应纳税所得额 | F27: 征收税率 | G27: 当年应缴税额 | H27: Q1已缴税额 | I27: Q2应缴税额 | J27: Q3应缴税额 | K27: Q4应缴税额
C28: 鄂尔多斯（2023-2025三免期） | D28: 减免期 | E28: ='[112]02月PL'!E91 -> 0 | F28: =25% -> 0.25 | G28: =E28*F28*0 -> 0 | H28: 0 | I28: =G28-H28 -> 0
A29: 3 | B29: 企业所得税合计 | E29: =SUM(E28:E28) -> 0 | G29: =SUM(G28:G28) -> 0 | H29: =I28 -> 0 | I29: 2221050000
A30: 4 | B30: 城镇土地使用税 | C30: 县城、建制镇、工矿区 | D30: 建设用地面积 | F30: 5月、11月缴纳 | G30: 2.4 | H30: =(E30*G30/12*6) -> 0 | I30: 61408220000001 | K30: =H30-J30 -> 0
A31: 5 | B31: 房产税 | C31: 从价计征 | D31: 房产原值 | I31: 61409210000000
B32: 个人所得税 | D32: 实发工资
C33: 劳务报酬所得 | F33: 0.8 | G33: 0.2 | H33: =ROUND(IF(D33<=800,0,IF(D33<=3360,(D33-800)/4,IF(D33<=21000,0.16*D33/0.84,IF(D33<=49500,(0.24*D33-2000)/0.76,(0.32*D33-7000)/0.68)))),2) -> 0 | I33: 6600020002 | J33: 0 | K33: =H33-J33 -> 0
C34: 劳务报酬所得（倒算） | E34: =ROUND(IF(D34<=800,0,IF(D34<=3360,(D34-800)/4,IF(D34<=21000,0.16*D34/0.84,IF(D34<=49500,(0.24*D34-2000)/0.76,(0.32*D34-7000)/0.68)))),2)+D34 -> 0 | F34: 0.8 | G34: 0.4 | H34: =IF(AND(E34=0),0,IF(AND(E34<=4000),E34-800,IF(AND(E34>4000),E34*F34*G34-7000))) -> 0 | I34: 6600020002 | J34: 0
C35: 财产租赁所得 | F35: 0.8 | G35: 0.2
C36: 财产租赁所得（倒算） | F36: 0.8 | G36: 0.2
A37: 6 | B37: =B32 -> 个人所得税 | I37: 代扣代缴个税
A38: 7 | B38: 水利建设专项收入 | C38: 地方水利建设基金 | E38: =[112]伊金悦盛项目累计缴纳!D5 -> 0 | G38: 0.01 | H38: =E38*G38 -> 0
A39: 8 | B39: 耕地占用税 | C39: 林地、草地 | F39: 1 | G39: 27
A40: 9 | B40: 契税 | C40: 国有土地使用权出让（非居住用地） | F40: 1 | G40: 0.03
...

Sheet 说明
A1: 排序 | B1: 表名 | C1: 表名逻辑 | D1: 取值逻辑 | E1: 公司代码 | F1: 备注 | L1: 标黄 | M1: 需要计算的页签
A2: 1 | B2: 累计税金汇总表 | D2: 在上期台账数据基础上计算生成本期数据 | E2: 2320、2355 | L2: 标绿 | M2: 数据集捞取数据
A3: 2 | B3: 累计项目税收明细表 | D3: 手工上传 | E3: 2320、2355 | L3: 标蓝 | M3: 用户手工上传
A4: 3 | B4: 增值税表一 累计销项 | D4: 在上期台账数据基础上计算生成本期数据 | E4: 2320、2355 | L4: 标紫 | M4: 取上月台账导出
A5: 4 | B5: 账税差异监控 | D5: 在上期台账数据基础上计算生成本期数据 | E5: 2320、2355 | L5: 标橙色 | M5: 配置表
A6: 5 | B6: BS表 | C6: 台账月份&“BS表”，例如：12月BS表 | D6: 拼接上传的本年资产负债表&BS表附表 | E6: all
A7: 6 | B7: PL表 | D7: 拼接上传的本年利润表&PL表附表，如果公司代码=2320、2355那么PL表附表是计算的，如果公司代码≠2320、2355那么PL表附表不是必须上传 | E7: all
A8: 7 | B8: 收入明细 | E8: all
A9: 8 | B9: 销项明细 | E9: all
A10: 9 | B10: 进项明细 | E10: all
A11: 10 | B11: 所得税明细 | E11: all
A12: 11 | B12: summary表 | C12: “Ref 1”&_&台账年度台账月份&_&“summary表”，例如：Ref 1_202602_summary表 | E12: all
A13: 12 | B13: 增值税销项表 | C13: “Ref 2”&_&台账年度台账月份&_&“增值税销项（样式）”，例如：Ref 2_202602_增值税销项（样式） | E13: all
A14: 13 | B14: 增值税进项认证清单 | C14: “Ref 3”&_&台账年度台账月份&_&“增值税进项认证清单”，例如：Ref 3_202602_增值税进项认证清单 | E14: all
A15: 14 | B15: 增值税变动表 | C15: “Ref 4”&_&台账年度台账月份&_&“增值税变动表”，例如：Ref 4_202602_增值税变动表 | D15: 拼接增值税变动表&增值税变动表附表 | E15: all
A16: 15 | B16: 预开票收入计提及冲回统计 | E16: 2320、2355
A17: 16 | B17: 未开票数监控 | D17: 在上期台账数据基础上计算生成本期数据 | E17: all
A18: 17 | B18: 项目累计申报 | D18: 在上期台账数据基础上计算生成本期数据 | E18: all
A19: 18 | B19: 项目累计缴纳 | D19: 在上期台账数据基础上计算生成本期数据 | E19: all
A20: 19 | B20: 睿景景程月结数据表-报税 | F20: 只用于PL表附表取数，不实际在台账中显示
A21: 20 | B21: 其他科目明细 | F21: 只用于取数，不实际在台账中显示
A22: 21 | B22: 合同印花税明细台账 | F22: 只用于取数，不实际在台账中显示

Sheet 增值税变动表
B1: 基础条目 | C1: 拆分依据 | D1: 条目 | E1: 未开票金额 | F1: 当月开票金额 | G1: 以前月度开票金额 | H1: 合计
B2: 不显示此列 | C2: 不显示此列 | D2: 显示 | E2: 显示 | F2: 显示 | G2: 显示 | H2: 显示
B3: 取【增值税变动表基础条目配置表】中公司代码=台账公司或空，是否显示=Y，的基础条目字段，按照条目序号升序排列。 | C3: --若台账公司=2320/2450： 此字段默认为空 --若台账公司≠2320/2450： 1.在【增值税变动表基础条目配置表】表中取基础条目对应的是否拆分字段，若是否拆分=N，此字段默认为空，若是否拆分=Y，此字段取【PL附表】拆分依据列示。 | D3: ’--若台账公司=2320/2355： 取【睿景、景程增值税变动表特殊条目配置表】中公司代码=2320、2450或空，是否显示=Y的行，由取到行的条目序号=基础条目的条目序号，将【睿景、景程增值税变动表特殊条目配置表】中对应的特殊条目替换基础条目 --若台账公司≠2320/2450： 1.若拆分依据为空，此字段=基础条目 2.若拆分依据不为空，此条目=基础条目&“-”&拆分依据 | E3: ‘=合计-当月开票金额-以前月度开票金额 | F3: ’--若台账公司=2320/2355： 1.当条目=当月利润表主营业务收入（商品销售13%），此字段取【增值税销项表-按税率（征收率）统计表】中税率/征收率字段=0.13、发票类型=电子发票（增值税专用发票）对应数据行的实际开具发票金额 2.当条目=当月利润表主营业务收入（建安收入9%），此字段取【增值税销项表-按税率（征收率）统计表】中税率/征收率字段=0.09、发票类型=电子发票（增值税专用发票）对应数据行的实际开具发票金额 3.当条目=当月利润表主营业务收入（设计服务6%），此字段取【增值税销项表-按税率（征收率）统计表】中税率/征收率字段=0.06、发票类型=电子发票（增值税专用发票）对应数据行的实际开具发票金额 4.当条目=当月利润表主营业务收入（商品销售13%-普票），此字段取【增值税销项表-按税率（征收率）统计表】中税率/征收率字段=0.13、发票类型=电子发票（普通发票）对应数据行的实际开具发票金额 5.当条目=当月利润表主营业务收入（建安收入9%-普票），此字段取【增值税销项表-按税率（征收率）统计表】中税率/征收率字段=0.09、发票类型=电子发票（普通发票）对应数据行的实际开具发票金额 6.当条目=当月利润表主营业务收入（设计服务6%-普票），此字段取【增值税销项表-按税率（征收率）统计表】中税率/征收率字段=0.06、发票类型=电子发票（普通发票）对应数据行的实际开具发票金额 7.当条目=应交增值税-销项税（商品销售13%），此字段取【增值税销项表-按税率（征收率）统计表】中税率/征收率字段=0.13、发票类型=电子发票（增值税专用发票）对应数据行的实际开具发票税额 8.当条目=应交增值税-销项税（建安收入9%），此字段取【增值税销项表-按税率（征收率）统计表】中税率/征收率字段=0.09、发票类型=电子发票（增值税专用发票）对应数据行的实际开具发票税额 9.当条目=应交增值税-销项税（设计服务6%），此字段取【增值税销项表-按税率（征收率）统计表】中税率/征收率字段=0.06、发票类型=电子发票（增值税专用发票）对应数据行的实际开具发票税额 10.当条目=应交增值税-销项税（商品销售13%-普票），此字段取【增值税销项表-按税率（征收率）统计表】中税率/征收率字段=0.13、发票类型=电子发票（普通发票）对应数据行的实际开具发票税额 11.当条目=应交增值税-销项税（建安收入9%-普票），此字段取【增值税销项表-按税率（征收率）统计表】中税率/征收率字段=0.09、发票类型=电子发票（普通发票）对应数据行的实际开具发票税额 12.当条目=应交增值税-销项税（设计服务6%-普票），此字段取【增值税销项表-按税率（征收率）统计表】中税率/征收率字段=0.06、发票类型=电子发票（普通发票）对应数据行的实际开具发票税额 其他情况，此字段为空 --若台账公司≠2320/2450： 1.当基础条目=当月利润表主营业务收入，此字段取【增值税销项表-按税率（征收率）统计表】合计行实际开具发票金额 2.当基础条目=应交增值税-销项税，此字段取【增值税销项表-按税率（征收率）统计表】合计行实际开具发票税额 3.其他情况，此字段默认为空 | G3: 取基础条目=当月利润表主营业务收入 从上往下数第一行填入【收入明细表】中总账科目=6001000010的货币金额合计，其他数据行此字段默认为空 ---默认为空，由用户手工维护 | H3: ’--若台账公司=2320/2355： 1.当条目=当月利润表主营业务收入（商品销售13%），此字段取【PL表附表】中拆分依据=专票-13%对应数据行的申报金额 2.当条目=当月利润表主营业务收入（建安收入9%），此字段取【PL表附表】中拆分依据=专票-9%对应数据行的申报金额 3.当条目=当月利润表主营业务收入（设计服务6%），此字段取【PL表附表】中拆分依据=专票-6%对应数据行的申报金额 4.当条目=当月利润表主营业务收入（商品销售13%-普票），此字段取【PL表附表】中拆分依据=普票-13%对应数据行的申报金额 5.当条目=当月利润表主营业务收入（建安收入9%-普票），此字段取【PL表附表】中拆分依据=普票-9%对应数据行的申报金额 6.当条目=当月利润表主营业务收入（设计服务6%-普票），此字段取【PL表附表】中拆分依据=普票-6%对应数据行的申报金额 7.当条目=应交增值税-销项税（商品销售13%），此字段取【【PL表附表】中拆分依据=专票-13%对应数据行的申报税额 8.当条目=应交增值税-销项税（建安收入9%），此字段取【PL表附表】中拆分依据=专票-9%对应数据行的申报税额 9.当条目=应交增值税-销项税（设计服务6%），此字段取【PL表附表】中拆分依据=专票-6%对应数据行的申报税额 10.当条目=应交增值税-销项税（商品销售13%-普票），此字段取【PL表附表】中拆分依据=普票-13%对应数据行的申报税额 11.当条目=应交增值税-销项税（建安收入9%-普票），此字段取【PL表附表】中拆分依据=普票-9%对应数据行的申报税额 12.当条目=应交增值税-销项税（设计服务6%-普票），此字段取【【PL表附表】中拆分依据=普票-6%对应数据行的申报税额 13.当条目=增值税已认证进项税，此字段取【增值税进项认证清单】税额合计 14.当条目=期初留抵进项税，此字段取系统中台账公司、台账月份-1的【税务台账表-增值税变动表】页签期末留抵进项税行合计金额字段，如台账月份为1月，此字段取上年度12月期末留抵进项税 15.当条目=期末留抵进项税，此字段等于同一拆分依据下【应交增值税-销项税】-（【增值税已认证进项税】+【期初留抵进项税】-进项转出）小于0部分的绝对值，若【应交增值税-销项税】-（【增值税已认证进项税】+【期初留抵进项税】-进项转出）大于0.此字段默认为0 16.当条目=应交增值税，若【期末留抵进项税】合计>0，此字段为0，若【期末留抵进项税】合计<0，此字段=【销项税额*】合计+【应交增值税-销项税*】合计+【进项转出】合计-【增值税已认证进项税】合计-【期初留抵进项税】合计 17.当条目=本期应交增值税，此字段=【应交增值税】合计-【异地预缴抵减】合计 18.当条目=异地预缴递减，此字段=【增值税变动表附表】本期递减预缴 其他情况，此字段为空 --若台账公司≠2320/2450： 1.当基础条目=当月利润表主营业务收入，此字段取【PL表附表】拆分依据对应的主营业务收入字段。如无【PL附表】，取[PL表]主营业务收入本期发生数。 2.当基础条目=应交增值税-销项税，此字段取【PL表附表】拆分依据对应的销项字段，如无【PL附表】，取[BS表]应交税费（累计发生数-年初数）*-1。 3.当基础条目=增值税已认证进项税，此字段取【增值税进项认证清单】税额合计 4.当基础条目=期初留抵进项税，此字段取系统中台账公司、台账月份-1的【税务台账表-增值税变动表】页签期末留抵进项税行合计金额字段，如台账月份为1月，此字段取上年度12月期末留抵进项税 5.当基础条目=期末留抵进项税，此字段等于同一拆分依据下【应交增值税-销项税】-（【增值税已认证进项税】+【期初留抵进项税】-进项转出）小于0部分的绝对值，若【应交增值税-销项税】-（【增值税已认证进项税】+【期初留抵进项税】-进项转出）大于0.此字段默认为0 6.当条目=应交增值税，若【期末留抵进项税】合计>0，此字段为0，若【期末留抵进项税】合计<0，此字段=【销项税额*】合计+【应交增值税-销项税*】合计+【进项转出】合计-【增值税已认证进项税】合计-【期初留抵进项税】合计 7.其他情况，此字段默认为空
D4: 当月利润表主营业务收入-光伏收入
D5: 当月利润表主营业务收入-风电收入
D6: 销项税额-固定资产处置收入
D7: 销项税额-财务费用-利息收入
D8: 销项税额-其他收益
D10: 应交增值税-销项税-一般项目（光伏）
D11: 应交增值税-销项税-即征即退项目（风电）
D12: 预开票（未确认收入）-应交增值税
D13: 增值税已认证进项税-一般项目（光伏）
D14: 增值税已认证进项税-即征即退项目（风电）
D15: 进项转出-一般 | H15: ？
D16: 进项转出-即征即退
D17: 期初留抵进项税-一般项目（光伏）
D18: 期初留抵进项税-即征即退项目（风电）
D19: 期末留抵进项税-一般项目（光伏）
D20: 期末留抵进项税-即征即退项目（风电）
D21: 应交增值税-一般项目（光伏）
D22: 应交增值税-即征即退项目（风电）

Sheet Summary 
A1: 伊金霍洛旗悦盛新能源有限公司2025年02月（税务所属期）税费申报明细 | N1: 表头逻辑：由公司代码在【公司代码配置表】取到公司名称，按照示例拼接公司名称、台账年度、月份
B2: 申报税种取值逻辑：除印花税、增值税、企业所得税外，由【税目配置表】-公司代码=此表公司代码或空，取【税目配置表】-税种按照序号升序列示 | H2: 45689
A3: 序号 | B3: 申报税种 | C3: 税目 | D3: 计税依据（记账科目/计税表格） | E3: 计税金额 (A)-季度 | F3: 征收比例 (B) | G3: 税率 (C) | H3: 实际应纳税额 (D) | I3: 计税金额-2025年01月 | J3: 计税金额-2025年02月 | K3: 计税金额-2025年03月 | L3: 差异原因 | M3: 指引
B4: 印花税 | C4: 由【税目配置表】-税种=印花税，【税目配置表】-公司代码=此表公司代码或空，取【税目配置表】的税目列示。 | D4: 由【税目配置表】-税种="印花税"，【税目配置表】-公司代码=此表公司代码或空，【税目配置表】-税目=此表C列税目，取【税目配置表】-计税依据 | E4: 当税目=买卖合同，如台账月份为3、6、9、12，此字段取【印花税明细表】税目对应计税依据字段值+summary表计税金额当前季度计税金额 当税目≠买卖合同，如台账月份为3、6、9、12，此字段取【印花税明细表】税目对应计税依据字段值，反之此字段默认为0 | F4: 由【税目配置表】-税种="印花税"，【税目配置表】-公司代码=此表公司代码或空，【税目配置表】-税目=此表C列税目，取【税目配置表】-征收比例 | G4: 由【税目配置表】-税种="印花税"，【税目配置表】-公司代码=此表公司代码或空，【税目配置表】-税目=此表C列税目，取【税目配置表】-税率 | H4: 计税金额（A）-季度*征收比例（B）*税率（C） 保留两位小数 | I4: I3、J3、K3分别取台账月份对应季度的三个月，例如：台账月份为26年4月，则I3、J3、K3分别为计税金额-2026年04月、计税金额-2026年05月、计税金额-2026年06月 计税金额取值：当税目="买卖合同"，此字段取对应公司代码、I3、J3、K3单元格月份【PL表】-其中：营业收入的本期发生额，反之，此字段为空
C5: 融资租赁合同 | D5: 财务提供 | F5: 1 | G5: 5e-05 | H5: =ROUND(E5*F5*G5,2) -> 0
C6: 借款合同 | F6: 1 | G6: 5e-05 | H6: =ROUND(E6*F6*G6,2) -> 0 | I6: ='[112]02月PL'!D8 -> 0
C7: 承揽合同 | E7: 0 | F7: 1 | G7: 0.0003 | H7: =ROUND(E7*F7*G7,2) -> 0
C8: 建设工程合同 | E8: 0 | F8: 1 | G8: 0.0003 | H8: =ROUND(E8*F8*G8,2) -> 0
C9: 运输合同 | F9: 1 | G9: 0.0003 | H9: =ROUND(E9*F9*G9,2) -> 0
C10: 技术合同 | E10: 0 | F10: 1 | G10: 0.0003 | H10: =ROUND(E10*F10*G10,2) -> 0
C11: 租赁合同 | E11: 0 | F11: 1 | G11: 0.001 | H11: =ROUND(E11*F11*G11,2) -> 0
C12: 保管合同 | F12: 1 | G12: 0.001 | H12: =ROUND(E12*F12*G12,2) -> 0
C13: 仓储合同 | F13: 1 | G13: 0.001
C14: 财产保险合同 | F14: 1 | G14: 0.001 | H14: =ROUND(E14*F14*G14,2) -> 0
C15: 营业账簿 | F15: 1 | G15: 0.00025 | H15: =ROUND(E15*F15*G15,2) -> 0
C16: 产权转移书据 | F16: 1 | G16: 0.0005 | H16: =ROUND(E16*F16*G16,2) -> 0
A17: 1 | B17: 印花税合计 | H17: =SUM(H4:H16) 取印花税实际应纳税额（D）的合计
A18: 序号 | B18: 申报税种 | C18: 税目 | D18: 计税依据（记账科目/计税表格） | E18: 计税金额 | F18: 征收比例 (B) | G18: 税率 (C) | H18: 实际应纳税额 (D) | I18: 记账科目 | J18: 账面金额 | K18: 差异 | L18: 差异原因 | M18: 指引
B19: 增值税 | C19: 由【税目配置表】-税种=此表税种，【税目配置表】-公司代码=此表公司代码或空，取【税目配置表】的税目列示。 | D19: 由【税目配置表】-税种=此表税种，【税目配置表】-公司代码=此表公司代码或空，【税目配置表】-税目=此表C列税目，取【税目配置表】-计税依据 | E19: 当税种=增值税，税目="销项税额-主营业务收入*",取对应公司代码、台账月份【PL表附表】拆分依据对应申报金额 当税种=增值税，税目="销项税额-固定资产处置收入",取对应公司代码、台账月份【增值税变动表】-销项税额-固定资产处置收入的合计金额 当税种=增值税，税目="销项税额-财务费用-利息收入",取对应公司代码、台账月份【增值税变动表】-销项税额-财务费用-利息收入的合计金额 当税种=增值税，税目="销项税额-其他收益",取对应公司代码、台账月份【增值税变动表】-销项税额-其他收益的合计金额 当税种=增值税，税目="增值税进项税额",取对应公司代码、台账月份【增值税进项认证清单】-金额的合计 当税种=增值税，税目="期末进项留抵金额"、”期初进项留抵金额“,此字段默认为空 | F19: 由【税目配置表】-税种=此表税种，【税目配置表】-公司代码=此表公司代码或空，【税目配置表】-税目=此表C列税目，取【税目配置表】-征收比例 | G19: 由【税目配置表】-税种=此表税种，【税目配置表】-公司代码=此表公司代码或空，【税目配置表】-税目=此表C列税目，取【税目配置表】-税率 | H19: 若税种=增值税，税目=“销项税额*”，此字段=计税金额（A）*税率（C） 若税种=增值税，税目=“增值税进项税额”，此字段取【进项认证清单】税额合计 若税种=增值税，税目=“期初进项留抵金额”，此字段取【增值税变动表】期初留抵进项税*合计金额汇总 若税种=增值税，税目=“期末进项留抵金额”，此字段取【增值税变动表】期末留抵进项税*合计金额汇总 | I19: 由【税目配置表】-公司代码=此表公司代码/空，【税目配置表】-税目=此表税目取得对应会计科目 | J19: 当公司代码≠2320、2355 当税种=增值税，税目="销项税额-主营业务收入",取对应公司代码、台账月份【销项明细】-货币金额字段合计*-1； 当税种=增值税，税目="增值税进项税额",取对应公司代码、台账月份【进项明细】-货币金额字段合计； 当税种=增值税，税目="期末进项留抵金额",取对应公司代码、台账月份【BS表-附表】应交税费-增值税*科目累计余额合计。 反之，此字段为空 当公司代码=2330、2355 当税种=增值税，税目="销项税额-主营业务收入*",取对应公司代码、台账月份【PL表-附表】中拆分依据对应的申报税额； 当税种=增值税，税目="增值税进项税额",取对应公司代码、台账月份【进项明细】-货币金额字段合计； 当税种=增值税，税目="期末进项留抵金额",取对应公司代码、台账月份【BS表-附表】应交税费-增值税*科目累计余额合计。 反之，此字段为空 | K19: 实际应纳税额(D)-账面金额 | L19: 尾差，以账面计提申报为准
C20: 销项税额-固定资产处置收入 | D20: 固定资产销售收入 | E20: ='[112]Ref 4_202502 增值税变动表'!F4 -> 0 | F20: 1 | G20: 0.09 | H20: =E20*G20 -> 0
C21: 销项税额-财务费用-利息收入 | D21: 利息收入 | E21: ='[112]Ref 4_202502 增值税变动表'!F5 -> 0 | F21: 1 | G21: 0.06 | H21: =E21*G21 -> 0
C22: 销项税额-其他收益 | D22: 个税手续费返还 | E22: ='[112]Ref 4_202502 增值税变动表'!F6 -> 0 | F22: 1 | G22: 0.06 | H22: =E22*G22 -> 0
C23: 增值税进项税额 | D23: 见表-增值税进项认证清单 | E23: ='[112]Ref 3_202502 增值税进项认证清单'!K22 -> 1979092.2 | F23: 1 | G23: 不适用 | H23: ='[112]Ref 3_202502 增值税进项认证清单'!L22 -> 142670.14 | I23: 2221010100 | J23: =[112]进项明细!N28 -> 142670.14 | K23: =H23-J23 -> 0
C24: 期初进项留抵金额 | D24: 见表-增值税变动表 | F24: 1 | H24: ='[112]Ref 4_202502 增值税变动表'!F15+'[112]Ref 4_202502 增值税变动表'!F16 -> 1.9248279e+08
C25: 期末进项留抵金额 | D25: 见表-增值税变动表 | F25: 1 | G25: 不适用 | H25: ='[112]Ref 4_202502 增值税变动表'!F17+'[112]Ref 4_202502 增值税变动表'!F18 -> 1.9056036e+08 | J25: =-'[112]02月BS'!I58 -> 1.9056036e+08 | K25: =H25-J25 -> 0
A26: 2 | B26: 增值税合计 | H26: 取对应公司代码、台账月份【增值税变动表】应交增值税合计字段；
B27: 增值税附加 | C27: 城建税 | H27: ‘=G27*H26
C28: 教育费附加 | H28: ‘=G28*H26
C29: 地方教育费附加 | H29: ‘=G29*H26
B30: 增值税附加合计 | H30: =SUM(H27:H29)
B31: 企业所得税 | C31: 项目名称 | D31: 所处优惠期 | E31: 应纳税所得额 | F31: 征收税率 | G31: 当年应缴税额 | H31: Q1已缴税额 | I31: Q2应缴税额 | J31: Q3应缴税额 | K31: Q4应缴税额
C32: 由【项目配置表】-税种=企业所得税，【项目配置表】-公司代码=此表公司代码或空，取【项目配置表】的项目名称列示。 | D32: 由【项目配置表】-税种=企业所得税，【项目配置表】-公司代码=此表公司代码或空，取【项目配置表】项目名称对应的所属优惠期。 | E32: 第一行取对应公司代码、台账月份【PL表】利润总额累计发生额，其他行该字段为空 | F32: 由【税目配置表】-税种="企业所得税"，【税目配置表】-公司代码=此表公司代码或空，【税目配置表】-税目="企业所得税"，取【税目配置表】-税率 | G32: 如所处优惠期为“减免期”此字段默认为0；如所处优惠期为“减半期”此字段=应纳税所得额*征收税率*0.5；如所处优惠期为“非风场项目，无优惠期”此字段=应纳税所得额*征收税率 | H32: 取台账当前年度第一季度数据，如当前为26年2月，26年第一季度还未结束，表头为“应缴”，如当前为26年3月，26年第一季度已结束，表头为“已缴”，则此字段按如下逻辑从数据集中取值 由公司代码=company_code、fiscal_year_period=年度1月到3月、account=2221050000 ，从数据集finance_electronicarchives_accounting_document_print中取debit_amount_in_document_currency+credit_amount_in_document_currency*-1 | I32: 取第二季度数据，逻辑同Q1已缴税额 | J32: 取第三季度数据，逻辑同Q1已缴税额 | K32: 取第四季度数据，逻辑同Q1已缴税额
A33: 3 | B33: 企业所得税合计 | E33: 企业所得税应纳税所得额合计 | H33: 判断台账期为几季度，在对应季度列下显示当季度应交税额合计
A34: 4 | B34: 城镇土地使用税 | C34: 县城、建制镇、工矿区 | D34: 建设用地面积 | E34: 手工维护 | F34: 取配置表需缴税月份 | G34: 2.4 | H34: ‘=(E34*G34/12*6) | K34: =H34-J34 -> #VALUE!
A35: 5 | B35: 房产税 | C35: 从价计征 | D35: 房产原值 | E35: 手工维护 | H35: =E35*G35/12*6
B36: 个人所得税 | D36: 实发工资 | E36: 手工维护 | H36: 手工维护
C37: 劳务报酬所得 | E37: 手工维护 | F37: 0.8 | G37: 0.2 | H37: 手工维护 | I37: 6600020002 | J37: 0 | K37: =H37-J37 -> #VALUE!
C38: 劳务报酬所得（倒算） | E38: 手工维护 | F38: 0.8 | G38: 0.4 | H38: 手工维护 | I38: 6600020002 | J38: 0
C39: 财产租赁所得 | E39: 手工维护 | F39: 0.8 | G39: 0.2 | H39: 手工维护
C40: 财产租赁所得（倒算） | E40: 手工维护 | F40: 0.8 | G40: 0.2 | H40: 手工维护
...

Sheet Summary 表样
A1: 伊金霍洛旗悦盛新能源有限公司2025年02月（税务所属期）税费申报明细
A2: 45689
A3: 序号 | B3: 申报税种 | C3: 税目 | D3: 计税依据（记账科目/计税表格） | E3: 计税金额 (A)-季度 | F3: 征收比例 (B) | G3: 税率 (C) | H3: 实际应纳税额 (D) | I3: 计税金额-2025年01月 | J3: 计税金额-2025年02月 | K3: 计税金额-2025年03月 | L3: 差异原因 | M3: 指引
B4: 印花税 | C4: 买卖合同 | D4: 主营业务收入&财务提供 | F4: 1 | G4: 0.0003
C5: 融资租赁合同 | D5: 财务提供 | F5: 1 | G5: 5e-05
C6: 借款合同 | F6: 1 | G6: 5e-05
C7: 承揽合同 | F7: 1 | G7: 0.0003
C8: 建设工程合同 | F8: 1 | G8: 0.0003
C9: 运输合同 | F9: 1 | G9: 0.0003
C10: 技术合同 | F10: 1 | G10: 0.0003
C11: 租赁合同 | F11: 1 | G11: 0.001
C12: 保管合同 | F12: 1 | G12: 0.001
C13: 仓储合同 | F13: 1 | G13: 0.001
C14: 财产保险合同 | F14: 1 | G14: 0.001
C15: 营业账簿 | F15: 1 | G15: 0.00025
C16: 产权转移书据 | F16: 1 | G16: 0.0005
A17: 1 | B17: 印花税合计
A18: 序号 | B18: 申报税种 | C18: 税目 | D18: 计税依据（记账科目/计税表格） | E18: 计税金额 | F18: 征收比例 (B) | G18: 税率 (C) | H18: 实际应纳税额 (D) | I18: 记账科目 | J18: 账面金额 | K18: 差异 | L18: 差异原因 | M18: 指引
B19: 增值税 | C19: 销项税额-主营业务收入 | D19: 主营业务收入 | F19: 1 | G19: 0.13 | I19: 2221010200
C20: 销项税额-固定资产处置收入 | D20: 固定资产销售收入 | F20: 1 | G20: 0.09
C21: 销项税额-财务费用-利息收入 | D21: 利息收入 | F21: 1 | G21: 0.06
C22: 销项税额-其他收益 | D22: 个税手续费返还 | F22: 1 | G22: 0.06
C23: 增值税进项税额 | D23: 见表-增值税进项认证清单 | F23: 1 | G23: 不适用 | I23: 2221010100
C24: 期初进项留抵金额 | D24: 见表-增值税变动表 | F24: 1
C25: 期末进项留抵金额 | D25: 见表-增值税变动表 | F25: 1 | G25: 不适用
A26: 2 | B26: 增值税合计
B27: 企业所得税 | C27: 项目名称 | D27: 所处优惠期 | E27: 应纳税所得额 | F27: 征收税率 | G27: 当年应缴税额 | H27: Q1已缴税额 | I27: Q2应缴税额 | J27: Q3应缴税额 | K27: Q4应缴税额
F28: =25% -> 0.25
A29: 3 | B29: 企业所得税合计 | I29: 2221050000
A30: 4 | B30: 城镇土地使用税 | C30: 县城、建制镇、工矿区 | D30: 建设用地面积 | F30: 5月、11月缴纳 | G30: 2.4
A31: 5 | B31: 房产税 | C31: 从价计征 | D31: 房产原值
B32: 个人所得税 | D32: 实发工资
C33: 劳务报酬所得 | F33: 0.8 | G33: 0.2
C34: 劳务报酬所得（倒算） | F34: 0.8 | G34: 0.4
C35: 财产租赁所得 | F35: 0.8 | G35: 0.2
C36: 财产租赁所得（倒算） | F36: 0.8 | G36: 0.2
A37: 6 | B37: =B32 -> 个人所得税 | I37: 代扣代缴个税
A38: 7 | B38: 水利建设专项收入 | C38: 地方水利建设基金 | G38: 0.01
A39: 8 | B39: 耕地占用税 | C39: 林地、草地 | F39: 1 | G39: 27
A40: 9 | B40: 契税 | C40: 国有土地使用权出让（非居住用地） | F40: 1 | G40: 0.03
...

Sheet 未开票数监控
A1: 所属期 | B1: 申报账面数 | F1: 开票数 | H1: 未开票数
B2: 营业收入 | C2: 利息收入 | D2: 其他收益 | E2: 销项税额 | F2: 销售收入 | G2: 销项税额 | H2: 销售收入 | I2: 销项税额 | K2: 在前序税务台账此页的基础上新增本次台账期数据
B3: 取本台账期【PL表】主营业收入 行的本期发生额 | C3: 取【其他科目明细表】科目=6603020011货币金额合计 | D3: 取【其他科目明细表】科目=6702000010货币金额合计 | E3: 取本台账期【销项明细】货币金额字段合计*-1 | F3: 取本台账期【增值税销项表-按税率（征收率）统计表】合计行实际开具发票金额 | G3: 取本台账期【增值税销项表-按税率（征收率）统计表】合计行实际开具发票税额 | H3: =B列+C列+D列-F列 | I3: =E列-F列
A4: 2025-1 | B4: 18613557 | E4: 2419762.4 | H4: =B4+C4+D4-F4 -> 18613557 | I4: =E4-G4 -> 2419762.4
A5: 2025-2 | B5: 15885357 | E5: 2065096.4 | H5: =B5+C5+D5-F5 -> 15885357 | I5: =E5-G5 -> 2065096.4
A6: 2025-3 | H6: =B6+C6+D6-F6 -> 0 | I6: =E6-G6 -> 0
A7: 2025-4 | H7: =B7+C7+D7-F7 -> 0 | I7: =E7-G7 -> 0
A8: 2025-5 | H8: =B8+C8+D8-F8 -> 0 | I8: =E8-G8 -> 0
A9: 2025-6 | H9: =B9+C9+D9-F9 -> 0 | I9: =E9-G9 -> 0
A10: 2025-7 | H10: =B10+C10+D10-F10 -> 0 | I10: =E10-G10 -> 0
A11: 2025-8 | H11: =B11+C11+D11-F11 -> 0 | I11: =E11-G11 -> 0
A12: 2025-9 | H12: =B12+C12+D12-F12 -> 0 | I12: =E12-G12 -> 0
A13: 2025-10 | H13: =B13+C13+D13-F13 -> 0 | I13: =E13-G13 -> 0
A14: 2025-11 | H14: =B14+C14+D14-F14 -> 0 | I14: =E14-G14 -> 0
A15: 2025-12 | H15: =B15+C15+D15-F15 -> 0 | I15: =E15-G15 -> 0
A16: 合计数 | B16: =SUM(B4:B15) -> 34498913 | C16: =SUM(C4:C15) -> 0 | D16: =SUM(D4:D15) -> 0 | E16: =SUM(E4:E15) -> 4484858.8 | F16: =SUM(F4:F15) -> 0 | G16: =SUM(G4:G15) -> 0 | H16: =SUM(H4:H15) -> 34498913 | I16: =SUM(I4:I15) -> 4484858.8

Sheet PL附表-2320、2355
A2: 睿景、景程PL附表
A3: 拆分依据 | B3: 未开票收入 | C3: 销项 | D3: 已开票收入 | E3: 已开票销项
A4: 专票-13% | B4: 申报金额-已开票收入 | C4: 申报税额-已开票销项 | D4: 取【睿景月结数据表】报税页签设备区域已开票收入列合计 | E4: 取【睿景月结数据表】报税页签设备区域已开票税额列合计
A5: 专票-9% | B5: 申报金额-已开票收入 | C5: 申报税额-已开票销项 | D5: 取【睿景月结数据表】报税页签建安区域已开票收入列合计 | E5: 取【睿景月结数据表】报税页签建安区域已开票税额列合计
A6: 专票-6% | B6: 申报金额-已开票收入 | C6: 申报税额-已开票销项 | D6: 取【睿景月结数据表】报税页签建安区域除设备、建安区域外其他区域已开票收入列合计 | E6: 取【睿景月结数据表】报税页签建安区域除设备、建安区域外其他区域已开票税额列合计
A7: 普票-13%
A8: 普票-9%
A9: 普票-6%
B10: =SUM(B4:B9) -> 0 | C10: =SUM(C4:C9) -> 0 | D10: =SUM(D4:D9) -> 0 | E10: =SUM(E4:E9) -> 0
A14: 拆分依据 | B14: 申报金额 | C14: 申报税额
A15: 专票-13% | B15: 取【睿景月结数据表】报税页签设备区域收入列合计 | C15: 取【睿景月结数据表】报税页签设备区域销项列合计
A16: 专票-9% | B16: 取【睿景月结数据表】报税页签建安区域收入列合计 | C16: 取【睿景月结数据表】报税页签建安区域销项列合计
A17: 专票-6% | B17: 取【睿景月结数据表】报税页签建安区域除设备、建安区域外其他区域收入列合计 | C17: 取【睿景月结数据表】报税页签建安区域除设备、建安区域外其他区域销项列合计
A18: 普票-13%
A19: 普票-9%
A20: 普票-6%
A21: 合计： | B21: =SUM(B15:B20) -> 0 | C21: =SUM(C15:C20) -> 0

Sheet 累计税金汇总表-2320、2355
A1: 时间：所属期 单位：元 | C1: 税金缴纳标准 | D1: 202412 | E1: 202501 | F1: 202502 | G1: 202503 | H1: 202504 | I1: 202505 | J1: 202506 | K1: 202507 | L1: 202508 | M1: 202509 | N1: 202510 | O1: 202511 | P1: 202512
A2: 基数 | B2: 账面收入 | D2: 1.5126491e+09 | E2: 4.3116584e+08 | F2: 3.5558408e+08 | G2: 48816138 | H2: 97382183 | I2: 50884270 | J2: 1.2171605e+08 | K2: 1.1081929e+08 | L2: 1.7958369e+08 | M2: 1.7442616e+08 | N2: 1.1709462e+08 | O2: 1.7393182e+09 | P2: 取台账期【增值税变动表】条目=当月利润表主营业务收入*合计列相加 | R2: 在前序税务台账此页的基础上新增本次台账期数据
B3: 其他收益 | P3: 取【其他科目明细表】科目=6702000010货币金额合计
B4: 项目开票 | D4: 1.1262598e+09 | E4: 7.805366e+08 | F4: 5.2620168e+08 | G4: 4.7608694e+08 | H4: 78604519 | I4: 37974761 | J4: 2.3684048e+08 | K4: 1.0914781e+08 | L4: 1.4016733e+08 | M4: 2.3979933e+08 | N4: 3.1389905e+08 | O4: 1.0132121e+09 | P4: 取台账期【增值税变动表】条目=当月利润表主营业务收入*当月开票金额列相加
B5: 利息开票 | P5: 取【其他科目明细表】科目=6603020011货币金额合计
B6: 销项税额 | C6: A | D6: 1.5335725e+08 | E6: 54874884 | F6: 45434329 | G6: 4651212.5 | H6: 9372591.2 | I6: 4606639.5 | J6: 10897955 | K6: 9901838.1 | L6: 12579095 | M6: 16661164 | N6: 12198025 | O6: 2.2262931e+08 | P6: 取台账期【增值税变动表】条目=条目=应交增值税-销项税*合计列相加
B7: 本期进项税额 | C7: B | D7: 67835873 | E7: 72025452 | F7: 60425055 | G7: 7987426.8 | H7: 7347644.3 | I7: 7003174.4 | J7: 4385018.7 | K7: 6626261.8 | L7: 22887594 | M7: 18893309 | N7: 18347860 | O7: 1.8479839e+08 | P7: 取台账期【增值税变动表】条目=应交增值税-增值税已认证进项税合计字段值
B8: 上期留抵税额 | C8: C | O8: 2228173.5 | P8: 取台账期【增值税变动表】条目=期初留抵进项税合计字段值
B9: 进项税额转出 | C9: D | E9: 14956.1 | F9: 3542.11 | G9: 595805.07 | H9: 22641.51 | J9: 272019.39 | K9: 43475.46 | L9: 267177.47 | M9: 82568.81 | P9: 取台账期【增值税变动表】条目=进项转出合计字段值
B10: 异地预缴税增值税 | C10: E | D10: 11847361 | G10: 29781.96 | H10: 2217866.5 | I10: 655226.71 | J10: 382841.63 | L10: 116982.96 | M10: 2762668.3 | P10: 取台账期【增值税变动表】条目=异地预缴抵减合计字段值
B11: 应纳增值税额 | C11: A-B-C+D-E | D11: 73674014 | P11: 取台账期【增值税变动表】条目=本期应交增值税合计字段值
B12: 增值税 | D12: 73674014 | E12: =E11 -> 0 | F12: =F11 -> 0 | G12: =G11 -> 0 | H12: 0 | I12: =I11 -> 0 | J12: =J11 -> 0 | K12: =K11 -> 0 | L12: =L11 -> 0 | M12: =M11 -> 0 | N12: =N11 -> 0 | O12: =O11 -> 0 | P12: ‘=P11
B13: 印花税 | D13: 1051983.4 | J13: 330365.58 | P13: 取summary表，税种=印花税合计，取实际应缴税额
B14: 城建税 | C14: 增值税额的7% | D14: 5157181 | E14: =E12*0.07 -> 0 | F14: =F12*0.07 -> 0 | G14: =G12*0.07 -> 0 | H14: =H12*0.07 -> 0 | I14: =I12*0.07 -> 0 | J14: =J12*0.07 -> 0 | K14: =K12*0.07 -> 0 | L14: =L12*0.07 -> 0 | ... O14: =O12*0.07 -> 0 | P14: =P12*税目配置表对应税率
B15: 教育费附加 | C15: 增值税额的3% | D15: 2210220.4 | E15: =E12*0.03 -> 0 | F15: =F12*0.03 -> 0 | G15: =G12*0.03 -> 0 | H15: =H12*0.03 -> 0 | I15: =I12*0.03 -> 0 | J15: =J12*0.03 -> 0 | K15: =K12*0.03 -> 0 | L15: =L12*0.03 -> 0 | ... O15: =O12*0.03 -> 0 | P15: =P12*税目配置表对应税率
B16: 地方教育费附加 | C16: 增值税额的2% | D16: 1473480.3 | E16: =E12*0.02 -> 0 | F16: =F12*0.02 -> 0 | G16: =G12*0.02 -> 0 | H16: =H12*0.02 -> 0 | I16: =I12*0.02 -> 0 | J16: =J12*0.02 -> 0 | K16: =K12*0.02 -> 0 | L16: =L12*0.02 -> 0 | ... O16: =O12*0.02 -> 0 | P16: =P12*税目配置表对应税率
B17: 房产税 | P17: 取summary表，税种=房产税，取实际应缴税额
B18: 城镇土地使用 | P18: 取summary表，税种=城镇土地使用税，取实际应缴税额
B19: 企业所得税 | D19: 3.8001788e+08 | J19: 29332502 | M19: 25579909 | P19: 取summary表，税种=企业所得税合计，取本季度应缴税额
B20: 个税 | P20: 取summary表，税种=城镇土地使用税，取实际应缴税额
B21: 残疾人保障金 | K21: 181635.35 | P21: 取summary表，税种=残疾人保障金，取实际应缴税额
B22: 合计 | D22: =SUM(D12:D21) -> 4.6358476e+08 | E22: =SUM(E12:E21) -> 0 | F22: =SUM(F12:F21) -> 0 | G22: =SUM(G12:G21) -> 0 | H22: =SUM(H12:H21) -> 0 | I22: =SUM(I12:I21) -> 0 | J22: =SUM(J12:J21) -> 29662867 | K22: =SUM(K12:K21) -> 181635.35 | ... P22: =SUM(P12:P21) -> 0
F26: 异地预缴 | H26: 异地预缴 | I26: 企业所得税
F27: 郎溪景宇风力发电有限公司 | H27: 郎溪
F28: 馆陶县汇恒风电有限公司 | H28: 察哈尔景源
F29: 伊金霍洛旗悦盛新能源有限公司 | H29: 定远纳驰 | I29: 450039.33
H30: 定远纳风 | I30: 734696.74
H31: 哈密博景
F33: 中国石油天然气股份有限公司 吐哈油田分公司 | H33: 吐哈油田 | I33: 136.15
F34: 定远智贮能源科技有限公司 | H34: 远景定远智慧储能共享电站项目 EPC | I34: 61976.18
E37: 45748 | F37: 定边远边汇新能源有限公司 | H37: 定边县红柳沟镇白兴庄 | I37: 443045.39
E39: 45778 | F39: 乌海市远鸿富景新能源科技有限公司 | H39: 乌海市金湖独立储能电站项目EPC总承 | I39: 96963.75
F40: 招银金融租赁有限公司 | H40: 利豪鸡泽县50MW保障类风电场 | I40: 172641.17
E42: 45809 | F42: 滨州远凌新能源有限责任公司 | H42: 滨州北海储能电站项目 | I42: 59826.73
F43: 清水河县云景风力发电有限公 司 | H43: 清水河县城关分散式风电场项目EPC总承包 | I43: 62095.04
E44: 2025.7 | H44: 射阳汇智风电场项目 EPC 总承包采购合同 | I44: 98649.14
E45: 2025.8 | G45: 陕西省榆林市靖边县东南部天赐湾乡 | H45: 靖边县状泽城河100兆瓦风电场项目EPC工程总承包合同 | I45: 364233.03
E46: 2025.9 | G46: 内蒙古自治区乌兰察布市察哈尔右翼后旗 | I46: 288997.39

Sheet 账税差异监控-2320、2355
B2: 日期 | C2: 商品销售（13%） | E2: 建筑安装（9%） | G2: 设计服务（6%） | I2: 汇总 | K2: 帐税差异 | L2: 差异分析 | N2: 在前序税务台账此页的基础上新增本次台账期数据
C3: 账面收入 | D3: 申报收入 | E3: 账面收入 | F3: 申报收入 | G3: 账面收入 | H3: 申报收入 | I3: 账面收入 | J3: 增值税申报收入
B4: 202501 | C4: 4.0460338e+08 | D4: 4.0460338e+08 | E4: 22756563 | F4: 22756563 | G4: 3805898.1 | H4: 3805898.1 | I4: =C4+E4+G4 -> 4.3116584e+08 | J4: =D4+F4+H4 -> 4.3116584e+08 | K4: =I4-J4 -> 0
B5: 202502 | C5: 3.4233211e+08 | D5: 3.4233211e+08 | E5: 4534546.6 | F5: 4534546.6 | G5: 8717422.1 | H5: 8717422.1 | I5: =C5+E5+G5 -> 3.5558408e+08 | J5: =D5+F5+H5 -> 3.5558408e+08 | K5: =I5-J5 -> 0
B6: 202503 | C6: 9263829.2 | D6: 9263829.2 | E6: 35792541 | F6: 35792541 | G6: 3759768 | H6: 3759768 | I6: =C6+E6+G6 -> 48816138 | J6: =D6+F6+H6 -> 48816138 | K6: =I6-J6 -> 0
B7: 202504 | C7: 21323842 | D7: 21323842 | E7: 67899709 | F7: 67899709 | G7: 8158632 | H7: 8158632 | I7: =C7+E7+G7 -> 97382183 | J7: =D7+F7+H7 -> 97382183 | K7: =I7-J7 -> 0
B8: 202505 | C8: 28632006 | D8: 28632006 | E8: -15021903 | F8: -15021903 | G8: 37274167 | H8: 37274167 | I8: =C8+E8+G8 -> 50884270 | J8: =D8+F8+H8 -> 50884270 | K8: =I8-J8 -> 0
B9: 202506 | C9: 5217250.7 | D9: 5217250.7 | E9: 15916344 | F9: 1.0765946e+08 | G9: 8839340.7 | H9: 8839340.7 | I9: =C9+E9+G9 -> 29972935 | J9: =D9+F9+H9 -> 1.2171605e+08 | K9: =I9-J9 -> -91743119 | L9: 调整5月数据，为了全年累计收入和销项税金额和账面对上
B10: 202507 | C10: 10527136 | D10: 10527136 | E10: 83859377 | F10: 83859377 | G10: 16432773 | H10: 16432773 | I10: =C10+E10+G10 -> 1.1081929e+08 | J10: =D10+F10+H10 -> 1.1081929e+08 | K10: =I10-J10 -> 0
B11: 202508 | C11: 36101207 | D11: 1.7123491e+08 | E11: 1.2087632e+08 | F11: 1.2100853e+08 | G11: 22606165 | H11: 22669790 | I11: =C11+E11+G11 -> 1.7958369e+08 | J11: =D11+F11+H11 -> 3.1491323e+08 | K11: =I11-J11 -> -1.3532954e+08 | L11: DHL项目8月只确认了销项，没确认收入，和大业项目预开票金额确认申报
B12: 202509 | C12: 38059869 | D12: 38059869 | E12: 1.1771344e+08 | F12: 1.1771344e+08 | G12: 18652850 | H12: 18652850 | I12: =C12+E12+G12 -> 1.7442616e+08 | J12: =D12+F12+H12 -> 1.7442616e+08 | K12: =I12-J12 -> 0
B13: 202510 | C13: 50555058 | D13: 1.9887533e+08 | E13: 53264485 | F13: 53659589 | G13: 13275081 | H13: 13275081 | I13: =C13+E13+G13 -> 1.1709462e+08 | J13: =D13+F13+H13 -> 2.6581e+08 | K13: =I13-J13 -> -1.4871537e+08 | L13: 大业项目预开票金额冲回10730530.06，综能项目预开票收入申报395103.89，五河项目融资设备预开票金额159050800.11
B14: 202511 | C14: 1.6361222e+09 | D14: 1.3529404e+09 | E14: 1.2590767e+08 | F14: 1.2551256e+08 | G14: -22711643 | H14: -22711643 | I14: =C14+E14+G14 -> 1.7393182e+09 | J14: =D14+F14+H14 -> 1.4557413e+09 | K14: =I14-J14 -> 2.8357688e+08 | L14: 大业项目预开票金额冲回124130974.37，综能项目预开票收入冲回395103.89，五河项目融资设备预开票冲回159050800.11
B15: 202512 | C15: 取【增值税变动表 】条目=当月利润表主营业务收入（商品销售13%）的合计金额 | D15: 默认为空 | E15: 取【增值税变动表 】条目=当月利润表主营业务收入（建安收入9%）的合计金额 | F15: 默认为空 | G15: 取【增值税变动表 】条目=当月利润表主营业务收入（设计服务6%）的合计金额 | H15: 默认为空 | I15: ’=C15+E15+G15 | J15: ‘=D15+F15+H15 | K15: ‘=I15-J15

Sheet 增值税表一 累计销项-2320、2355
A2: 所属期 | B2: 涉税类别 | C2: 已开票 | F2: 未开票 | I2: 合计 | M2: 在前序税务台账此页的基础上新增本次台账期数据
C3: 不含税金额 | D3: 税额 | E3: 税率 | F3: 不含税金额 | G3: 税额 | H3: 税率 | I3: 不含税金额 | J3: 税额
A4: 202501 | B4: 商品销售 | C4: 4.7777895e+08 | D4: =C4*E4 -> 62111263 | E4: 0.13 | F4: -73175570 | G4: =F4*H4 -> -9512824.1 | H4: 0.13 | I4: =C4+F4 -> 4.0460338e+08 | J4: =D4+G4 -> 52598439
B5: 工程建设 | C5: 2.8243024e+08 | D5: =C5*E5 -> 25418722 | E5: 0.09 | F5: -2.5967368e+08 | G5: =F5*H5 -> -23370631 | H5: 0.09 | I5: =C5+F5 -> 22756563 | J5: =D5+G5 -> 2048090.7
B6: 设计服务 | C6: 20327408 | D6: =C6*E6 -> 1219644.5 | E6: 0.06 | F6: -16521510 | G6: =F6*H6 -> -991290.58 | H6: 0.06 | I6: =C6+F6 -> 3805898.1 | J6: =D6+G6 -> 228353.89
A7: 202502 | B7: 商品销售 | C7: 4.4148457e+08 | D7: =C7*E7-0.04 -> 57392994 | E7: 0.13 | F7: -99152456 | G7: =F7*H7+0.04 -> -12889819 | H7: 0.13 | I7: =C7+F7 -> 3.4233211e+08 | J7: =D7+G7 -> 44503175
B8: 工程建设 | C8: 65474783 | D8: =C8*E8+0.02 -> 5892730.5 | E8: 0.09 | F8: -60940237 | G8: =F8*H8-0.03 -> -5484621.3 | H8: 0.09 | I8: =C8+F8 -> 4534546.6 | J8: =D8+G8 -> 408109.18
B9: 设计服务 | C9: 19242331 | D9: =C9*E9+0.05 -> 1154539.9 | E9: 0.06 | F9: -10524909 | G9: =F9*H9-0.03 -> -631494.55 | H9: 0.06 | I9: =C9+F9 -> 8717422.1 | J9: =D9+G9 -> 523045.35
A10: 202503 | B10: 商品销售 | C10: 3.5947726e+08 | D10: 46732044 | E10: 0.13 | F10: -3.5021343e+08 | G10: -45527746 | H10: 0.13 | I10: =C10+F10 -> 9263829.1 | J10: =D10+G10 -> 1204297.8
B11: 工程建设 | C11: 65827968 | D11: 5924517.1 | E11: 0.09 | F11: -30035427 | G11: -2703188.5 | H11: 0.09 | I11: =C11+F11 -> 35792541 | J11: =D11+G11 -> 3221328.7
B12: 设计服务 | C12: 50781714 | D12: 3046902.8 | E12: 0.06 | F12: -47021946 | G12: -2821316.7 | H12: 0.06 | I12: =C12+F12 -> 3759768 | J12: =D12+G12 -> 225586.09
A13: 202504 | B13: 商品销售 | C13: 17534647 | D13: =C13*E13+0.02 -> 2279504.2 | E13: 0.13 | F13: 3789194.8 | G13: =F13*H13-0.01 -> 492595.32 | H13: 0.13 | I13: =C13+F13 -> 21323842 | J13: =D13+G13 -> 2772099.5
B14: 工程建设 | C14: 60452779 | D14: =C14*E14-0.01 -> 5440750.1 | E14: 0.09 | F14: 7446930 | G14: =F14*H14 -> 670223.7 | H14: 0.09 | I14: =C14+F14 -> 67899709 | J14: =D14+G14 -> 6110973.8
B15: 设计服务 | C15: 617092.61 | D15: =C15*E15 -> 37025.557 | E15: 0.06 | F15: 7541539.4 | G15: =F15*H15 -> 452492.36 | H15: 0.06 | I15: =C15+F15 -> 8158632 | J15: =D15+G15 -> 489517.92
A16: 202505 | B16: 商品销售 | C16: 33522209 | D16: =C16*E16-0.01 -> 4357887.2 | E16: 0.13 | F16: -4890202.6 | G16: =F16*H16+0.01 -> -635726.33 | H16: 0.13 | I16: =C16+F16 -> 28632006 | J16: =D16+G16 -> 3722160.8
B17: 工程建设 | C17: 2703065 | D17: =C17*E17-0.01 -> 243275.84 | E17: 0.09 | F17: -17724968 | G17: =F17*H17-0.01 -> -1595247.1 | H17: 0.09 | I17: =C17+F17 -> -15021903 | J17: =D17+G17 -> -1351971.3
B18: 设计服务 | C18: 1749486.8 | D18: =C18*E18-0.03 -> 104969.18 | E18: 0.06 | F18: 35524680 | G18: =F18*H18-0.01 -> 2131480.8 | H18: 0.06 | I18: =C18+F18 -> 37274167 | J18: =D18+G18+0.01 -> 2236450
A19: 202506 | B19: 商品销售 | C19: 1.1092236e+08 | D19: =C19*E19+0.08 -> 14419907 | E19: 0.13 | F19: -1.0570511e+08 | G19: =F19*H19-0.08 -> -13741665 | H19: 0.13 | I19: =C19+F19 -> 5217250.7 | J19: =D19+G19 -> 678242.59
B20: 工程建设 | C20: 79949926 | D20: =C20*E20-0.03 -> 7195493.3 | E20: 0.09 | F20: 27709538 | G20: =F20*H20+0.05 -> 2493858.4 | H20: 0.09 | I20: =C20+F20 -> 1.0765946e+08 | J20: =D20+G20 -> 9689351.7
B21: 设计服务 | C21: 45968194 | D21: =C21*E21-0.02 -> 2758091.6 | E21: 0.06 | F21: -37128853 | G21: =F21*H21+0.02 -> -2227731.2 | H21: 0.06 | I21: =C21+F21 -> 8839340.7 | J21: =D21+G21 -> 530360.44
A22: 202507 | B22: 商品销售 | C22: 21068171 | D22: =C22*E22+0.07 -> 2738862.3 | E22: 0.13 | F22: -10541035 | G22: =F22*H22-0.08 -> -1370334.6 | H22: 0.13 | I22: =C22+F22 -> 10527136 | J22: =D22+G22-0.01 -> 1368527.7
B23: 工程建设 | C23: 74348075 | D23: =C23*E23-0.01 -> 6691326.8 | E23: 0.09 | F23: 9511301.3 | G23: =F23*H23-0.02 -> 856017.1 | H23: 0.09 | I23: =C23+F23 -> 83859377 | J23: =D23+G23+0.01 -> 7547343.9
B24: 设计服务 | C24: 13731566 | D24: =C24*E24+0.05 -> 823894.03 | E24: 0.06 | F24: 2701206.9 | G24: =F24*H24+0.02 -> 162072.44 | H24: 0.06 | I24: =C24+F24 -> 16432773 | J24: =D24+G24 -> 985966.47
A25: 202508 | B25: 商品销售 | C25: 1.3644534e+08 | D25: =C25*E25 -> 17737895 | E25: 0.13 | F25: 34789570 | G25: 4522644 | H25: 0.13 | I25: =C25+F25 -> 1.7123491e+08 | J25: =D25+G25 -> 22260539
B26: 工程建设 | C26: 866835.23 | D26: 78015.15 | E26: 0.09 | F26: 1.2014169e+08 | G26: 10812752 | H26: 0.09 | I26: =C26+F26 -> 1.2100853e+08 | J26: =D26+G26 -> 10890768
B27: 设计服务 | C27: 2855156.3 | D27: 171309.36 | E27: 0.06 | F27: 19814633 | G27: 1188878 | H27: 0.06 | I27: =C27+F27 -> 22669790 | J27: =D27+G27 -> 1360187.4
A28: 202509 | B28: 商品销售 | C28: 7446608.4 | D28: =C28*E28-0.01 -> 968059.09 | E28: 0.13 | F28: 30613261 | G28: =F28*H28 -> 3979723.9 | H28: 0.13 | I28: =C28+F28 -> 38059869 | J28: =D28+G28 -> 4947783
B29: 工程建设 | C29: 2.2254209e+08 | D29: =C29*E29+0.01 -> 20028788 | E29: 0.09 | F29: -1.0482864e+08 | G29: =F29*H29 -> -9434578 | H29: 0.09 | I29: =C29+F29 -> 1.1771344e+08 | J29: =D29+G29 -> 10594210
B30: 设计服务 | C30: 9810630.4 | D30: =C30*E30 -> 588637.82 | E30: 0.06 | F30: 8842219.5 | G30: =F30*H30+0.03 -> 530533.2 | H30: 0.06 | I30: =C30+F30 -> 18652850 | J30: =D30+G30-0.01 -> 1119171
A31: 202510 | B31: 商品销售 | C31: 1.9320679e+08 | D31: 25116882 | E31: 0.13 | F31: 5668542.2 | G31: 736910.5 | H31: 0.13 | I31: =C31+F31 -> 1.9887533e+08 | J31: =D31+G31 -> 25853793
B32: 工程建设 | C32: 80723241 | D32: 7265091.8 | E32: 0.09 | F32: -27063652 | G32: -2435728.7 | H32: 0.09 | I32: =C32+F32 -> 53659589 | J32: =D32+G32 -> 4829363
B33: 设计服务 | C33: 39969022 | D33: 2398141.3 | E33: 0.06 | F33: -26693940 | G33: -1601636.4 | H33: 0.06 | I33: =C33+F33 -> 13275081 | J33: =D33+G33 -> 796504.86
A34: 202511 | B34: 商品销售 | C34: 1.0352842e+09 | D34: 1.3458694e+08 | E34: 0.13 | F34: 3.1765623e+08 | G34: 41295310 | H34: 0.13 | I34: =C34+F34 -> 1.3529404e+09 | J34: =D34+G34 -> 1.7588225e+08
B35: 工程建设 | C35: 6040022.1 | D35: 543602.02 | E35: 0.09 | F35: 1.1947254e+08 | G35: 10752529 | H35: 0.09 | I35: =C35+F35 -> 1.2551256e+08 | J35: =D35+G35 -> 11296131
B36: 设计服务 | C36: -28112069 | D36: -1686724.1 | E36: 0.06 | F36: 5400425.7 | G36: 324025.52 | H36: 0.06 | I36: =C36+F36 -> -22711643 | J36: =D36+G36 -> -1362698.6
A37: 202512 | B37: 商品销售 | C37: 取【增值税变动表 】条目=当月利润表主营业务收入（商品销售*的当月开票金额 | D37: 取【增值税变动表 】条目=应交增值税-销项税（商品销售*的当月开票金额 | E37: 取【增值税变动表 】条目中的税率显示 | F37: 取【增值税变动表 】条目=当月利润表主营业务收入（商品销售*的未开票金额 | G37: 取【增值税变动表 】条目=应交增值税-销项税（商品销售*的未开票金额 | H37: 取【增值税变动表 】条目中的税率显示 | I37: ’=C37+F37 | J37: ‘=D37+G37
B38: 工程建设 | C38: 取【增值税变动表 】条目=当月利润表主营业务收入（建安收入*的当月开票金额 | D38: 取【增值税变动表 】条目=应交增值税-销项税（建安收入*的当月开票金额 | E38: 取【增值税变动表 】条目中的税率显示 | F38: 取【增值税变动表 】条目=当月利润表主营业务收入（建安收入*的未开票金额 | G38: 取【增值税变动表 】条目=应交增值税-销项税（建安部分*的未开票金额 | H38: 取【增值税变动表 】条目中的税率显示 | I38: ‘=C38+F38 | J38: ’=D38+G38
B39: 设计服务 | C39: 取【增值税变动表 】条目=当月利润表主营业务收入（设计服务*的当月开票金额 | D39: 取【增值税变动表 】条目=应交增值税-销项税（设计服务*的当月开票金额 | E39: 取【增值税变动表 】条目中的税率显示 | F39: 取【增值税变动表 】条目=当月利润表主营业务收入（设计服务*的未开票金额 | G39: 取【增值税变动表 】条目=应交增值税-销项税（设计服务*的未开票金额 | H39: 取【增值税变动表 】条目中的税率显示 | I39: ’=C39+F39 | J39: ‘=D39+G39

Sheet 项目累计申报
B1: 申报税费汇总表
B2: 上海睿景能源科技有限公司 | M2: 残疾人保证金 | P2: 单位：元
B3: 所属期 | C3: 所得税 | D3: 增值税 | E3: 增值税附加税 | F3: 印花税 | G3: 工会经费 | H3: 房产税 | I3: 个人所得税 | J3: 耕地占用税 | K3: 土地使用税 | L3: 垃圾费 | M3: 水利基金、残疾人保证金 | N3: 税务检查补税 | O3: 契税 | P3: 税款合计 | R3: 在前序税务台账此页的基础上新增本次台账期数据
B4: 45658 | P4: =SUM(C4:O4) -> 0
B5: 45689 | P5: =SUM(C5:O5) -> 0
B6: 45717 | F6: 241059.07 | P6: =SUM(C6:O6) -> 241059.07 | R6: 税目取summary税目配置表
B7: 45748 | P7: =SUM(C7:O7) -> 0
B8: 45778 | P8: =SUM(C8:O8) -> 0
B9: 45809 | C9: 29332502 | F9: 330365.58 | P9: =SUM(C9:O9) -> 29662867
B10: 45839 | M10: 181635.35 | P10: =SUM(C10:O10) -> 181635.35
B11: 45870 | P11: =SUM(C11:O11) -> 0
B12: 45901 | C12: 25579909 | F12: 344819.57 | P12: =SUM(C12:O12) -> 25924728
B13: 45931 | P13: =SUM(C13:O13) -> 0
B14: 45962 | P14: =SUM(C14:O14) -> 0
B15: 45992 | C15: 取【summary表】税种对应实际应纳税额合计 | P15: ‘=SUM(C15:O15)
B16: 合计 | C16: =SUM(C4:C15) -> 54912411 | D16: =SUM(D4:D15) -> 0 | E16: =SUM(E4:E15) -> 0 | F16: =SUM(F4:F15) -> 916244.22 | G16: =SUM(G4:G15) -> 0 | H16: =SUM(H4:H15) -> 0 | I16: =SUM(I4:I15) -> 0 | J16: =SUM(J4:J15) -> 0 | ... O16: =SUM(O4:O15) -> 0 | P16: ’=SUM(C16:O16)

Sheet 项目累计缴纳
B1: 实缴税费汇总表
B2: 上海睿景能源科技有限公司 | M2: 残疾人保证金 | P2: 单位：元
B3: 实际缴纳所属期 | C3: 所得税 | D3: 增值税 | E3: 增值税附加税 | F3: 印花税 | G3: 工会经费 | H3: 房产税 | I3: 个人所得税 | J3: 耕地占用税 | K3: 土地使用税 | L3: 垃圾费 | M3: 水利基金 | N3: 税务检查补税 | O3: 契税 | P3: 实缴税金 | Q3: 申请税金 | R3: 差异 | S3: 原因
B4: 45658 | C4: 3.8001788e+08 | D4: 77264494 | E4: 7,850, 055.95 | F4: 1051983.4 | P4: =SUM(C4:O4) -> 4.5833436e+08 | Q4: 0 | R4: =P4-Q4 -> 4.5833436e+08 | T4: 在前序税务台账此页的基础上新增本次台账期数据
B5: 45689 | P5: =SUM(C5:O5) -> 0 | Q5: 0 | R5: =P5-Q5 -> 0
B6: 45717 | P6: =SUM(C6:O6) -> 0 | Q6: 241059.07
B7: 45748 | F7: 241059.07 | P7: =SUM(C7:O7) -> 241059.07 | Q7: 0 | R7: =P7-Q6 -> 0 | U7: 税目取summary税目配置表
B8: 45778 | P8: =SUM(C8:O8) -> 0 | Q8: 0 | R8: =P8-Q8 -> 0
B9: 45809 | P9: =SUM(C9:O9) -> 0 | Q9: =[113]睿景项目累计申报!P9 -> 29662867 | R9: =P9-Q8 -> 0
B10: 45839 | C10: 29332502 | F10: 330365.58 | P10: =SUM(C10:O10) -> 29662867 | Q10: 0 | R10: =P10-Q9 -> 0
B11: 45870 | P11: =SUM(C11:O11) -> 0 | Q11: 0 | R11: =P11-Q11 -> 0
B12: 45901 | P12: =SUM(C12:O12) -> 0 | Q12: =[113]睿景项目累计申报!P12 -> 25924728 | R12: =P12-Q11 -> 0
B13: 45931 | C13: 25579909 | F13: 344819.57 | P13: =SUM(C13:O13) -> 25924728 | Q13: 0 | R13: =P13-Q12 -> 0
B14: 45962 | P14: =SUM(C14:O14) -> 0 | Q14: 0 | R14: =P14-Q14 -> 0
B15: 45992 | P15: =SUM(C15:O15) -> 0 | Q15: 取【项目累计申报表】台账期税款合计 | R15: =P15-Q15 -> #VALUE!
B16: 合计 | C16: =SUM(C4:C15) -> 4.3493029e+08 | D16: =SUM(D4:D15) -> 77264494 | E16: =SUM(E4:E15) -> 0 | F16: =SUM(F4:F15) -> 1968227.6 | G16: =SUM(G4:G15) -> 0 | H16: =SUM(H4:H15) -> 0 | I16: =SUM(I4:I15) -> 0 | J16: =SUM(J4:J15) -> 0 | ... O16: =SUM(O4:O15) -> 0 | P16: =SUM(C16:O16) -> 5.1416301e+08 | Q16: =SUM(Q4:Q15) -> 55828655 | R16: =SUM(R4:R15) -> #VALUE!

Sheet 印花税明细
A1: 序号 | B1: 税目 | C1: 计税依据 | D1: 税率 | E1: 应纳税额 | F1: 减免税额 | G1: 已缴税额 | H1: 应补（退）税额
A2: 正序填充 | B2: 取【合同印花税明细台账】台账月份所属季度的印花税税目去重填列 | C2: 由此表税目=【合同印花税明细台账】印花税税目，取得【合同印花税明细台账】合同金额字段汇总 | D2: 由此表税目=【合同印花税明细台账】印花税税目，取得【合同印花税明细台账】印花税税率 | E2: ’=C2*D2 | F2: 由此表税目=【合同印花税明细台账】印花税税目，取得【合同印花税明细台账】优惠比例、合同金额字段、印花税税率，计算取得行合同金额*印花税税率*优惠比例的汇总数填列 | G2: 默认为空 | H2: ‘=E2-F2
A3: 1 | B3: 借款合同 | C3: 0 | D3: 5e-05 | E3: 0 | F3: 0 | H3: 0
A4: 2 | B4: 融资租赁合同 | C4: 0 | D4: 5e-05 | E4: 0 | F4: 0 | H4: 0
A5: 3 | B5: 买卖合同 | C5: 3.3248115e+08 | D5: 0.0003 | E5: 99744.345 | F5: 49872.173 | H5: 49872.17
A6: 4 | B6: 承揽合同 | C6: 0 | D6: 0.0003 | E6: 0 | F6: 0 | H6: 0
A7: 5 | B7: 建设工程合同 | C7: 2.8617382e+08 | D7: 0.0003 | E7: 85852.145 | F7: 42926.073 | H7: 42926.07
A8: 6 | B8: 运输合同 | C8: 0 | D8: 0.0003 | E8: 0 | F8: 0 | H8: 0
A9: 7 | B9: 技术合同 | C9: 174528.3 | D9: 0.0003 | E9: 52.35849 | F9: 26.179245 | H9: 26.18
A10: 8 | B10: 租赁合同 | C10: 67129.74 | D10: 0.001 | E10: 67.12974 | F10: 33.56487 | H10: 33.56
A11: 9 | B11: 保管合同 | C11: 0 | D11: 0.001 | E11: 0 | F11: 0 | H11: 0
A12: 10 | B12: 仓储合同 | C12: 0 | D12: 0.001 | E12: 0 | F12: 0 | H12: 0
A13: 11 | B13: 财产保险合同 | C13: 0 | D13: 0.001 | E13: 0 | F13: 0 | H13: 0
A14: 12 | B14: 土地使用权 出让书据 | C14: 0 | D14: 0.0005 | E14: 0 | F14: 0 | H14: 0
... A19: 17 | B19: 证券交易 | C19: 0 | D19: 0.001 | E19: 0 | F19: 0 | H19: 0
B20: 合计 | C20: 6.1889663e+08 | E20: 185715.98 | F20: 92857.989 | G20: 0 | H20: 92857.98

Sheet 收入明细、销项明细、进项明细、所得税明细、其他科目明细
A1: 字段 | B1: 公司代码 | C1: 财政年/阶段 | D1: 凭证日期 | E1: 过账日期 | F1: 凭证类型 | G1: 凭证编号 | H1: 抬头文本 | I1: 行项目号 | J1: 总账科目 | K1: 本币金额 | L1: 本币 | M1: 货币金额 | N1: 凭证货币 | O1: 行文本 | P1: 付款参考 | Q1: 贸易伙伴 | R1: 客户 | S1: 供应商 | T1: 成本中心 | U1: WBS | V1: 参照 | W1: 冲销凭证号 | X1: 采购凭证 | Y1: 参考代码1 | Z1: 分配 | AA1: 用户名
A2: 数据集字段 | B2: company_code | C2: fiscal_year_period | D2: document_date | E2: posting_date_in_the_document | F2: document_type | G2: document_print_number | H2: document_header_text | I2: number_of_line_item_within_accounting_document | J2: account | K2: credit_amount_in_local_currency或者 debit_amount_in_local_currency | L2: currency_key_of_the_local_currency | M2: credit_amount_in_document_currency或者debit_amount_in_document_currency | N2: currency_key_of_the_document_currency | O2: item_text | P2: payment_reference | Q2: company_id_of_trading_partner | R2: customer_number | S2: vendor_number | T2: cost_center | U2: wbs_element | V2: reference | W2: reverse_document_number | X2: purchasing_document_number | Y2: reference_key_1_for_line_item | Z2: assignment | AA2: user_name
A3: 取值逻辑 | J3: 1. 销项明细，科目默认 2221010200 2. 进项明细，科目默认 2221010100、2221010400 3. 所得税明细，科目默认2221050000 4. 收入明细，取开头为6001的科目 5. 其他科目明细，科目=6603020011、6702000010 | K3: 如果debit_credit_indicator=”S”，此字段取debit_amount_in_local_currency字段；如果debit_credit_indicator=”H”，此字段取credit_amount_in_local_currency字段*-1； | M3: 如果debit_credit_indicator=”S”，此字段取debit_amount_in_document_currency字段；如果debit_credit_indicator=”H”，此字段取credit_amount_in_document_currency字段*-1；

Sheet 累计项目税收明细表202512
J1: ='[113]累计项目税收明细表2017-202302'!G355 -> 1.1960885e+10 | K1: ='[113]累计项目税收明细表2017-202302'!H355 -> 1.1569549e+10 | L1: =SUBTOTAL(9,L8:L143) -> 4.42397e+08 | M1: =SUBTOTAL(9,M9:M143) -> 5.4813931e+08 | N1: =SUBTOTAL(9,N8:N143) -> 5.2125169e+08 | O1: =SUBTOTAL(9,O8:O143) -> 5.1244236e+08 | P1: =SUBTOTAL(9,P8:P143) -> 6.3590871e+08 | Q1: =SUBTOTAL(9,Q8:Q143) -> 5.4741284e+08 | R1: =SUBTOTAL(9,R8:R150) -> 3.0901827e+08 | S1: =SUBTOTAL(9,S8:S150) -> 3.4998131e+08 | T1: =SUBTOTAL(9,T8:T157) -> 5.5568377e+08 | U1: =SUBTOTAL(9,U8:U150) -> 5.1789361e+08 | V1: =SUBTOTAL(9,V8:V150) -> 6.7448332e+08 | W1: =SUBTOTAL(9,W8:W150) -> 5.424389e+08 | X1: =SUBTOTAL(9,X8:X150) -> 3.3679561e+08 | Y1: =SUBTOTAL(9,Y8:Y150) -> 4.5653185e+08
B2: 项目类型 | C2: 公司代码 或项目号 | D2: 项目名称 | E2: 类别 | F2: 税率 | G2: 累计收入 | H2: 累计开票 | I2: 未开票收入 | J2: 202403之前月度 收入额小计 | K2: 202403之前月度 开票额小计 | L2: 202403账面收入 | M2: 202403开票 | N2: 202404账面收入 | O2: 202404开票 | P2: 202405账面收入 | Q2: 202405开票 | R2: 202406账面收入 | S2: 202406开票 | T2: 202407账面收入 | U2: 202407开票 | V2: 202408账面收入 | W2: 202408开票 | X2: 202409账面收入 | Y2: 202409开票 | Z2: 202410账面收入 | AA2: 202410开票 | AB2: 202411账面收入 | AC2: 202411开票 | AD2: 202412账面收入 | AE2: 202412开票 | AF2: 202501账面收入 | AG2: 202501开票 | AH2: 202502账面收入 | AI2: 202502开票 | AJ2: 202503账面收入 | AK2: 202503开票 | AL2: 202504账面收入 | AM2: 202504开票 | AN2: 202505账面收入 | AO2: 202505开票 | AP2: 202506账面收入 | AQ2: 202506开票 | AR2: 202507账面收入 | AS2: 202507开票 | AT2: 202508预开票金额 | AU2: 202508账面收入 | AV2: 202508开票 | AW2: 202509账面收入 | AX2: 202509开票 | AY2: 202510账面收入 | AZ2: 202510开票 | BA2: 202510预开票 | BB2: 202510预开票冲回 | BC2: 202511账面收入 | BD2: 202511开票 | BE2: 202511预开票 | BF2: 202511预开票冲回 | BG2: 202512账面收入 | BH2: 202512开票 | BI2: 202512预开票 | BJ2: 202512预开票冲回
D3: 202403之前 各月度数据结转 | E3: 商品销售 | F3: 0.16 | G3: =SUM(J3,L3,N3,P3,R3,T3,V3,X3,Z3) -> 467927.48 | H3: =SUM(K3,M3,O3,Q3) -> 88819830 | I3: =G3-H3 -> -88351903 | J3: 467927.48 | K3: 88819830
E4: 工程施工 | F4: 0.1 | G4: =SUM(J4,L4,N4,P4,R4,T4,V4,X4,Z4) -> -1.2564439e+08 | H4: =SUM(K4,M4,O4,Q4) -> -47524533 | I4: =G4-H4 -> -78119852 | J4: -1.2564439e+08 | K4: -47524533
E5: 商品销售 | F5: 0.13 | G5: =SUM(J5,L5,N5,P5,R5,T5,V5,X5,Z5) -> 6.6085485e+09 | H5: =SUM(K5,M5,O5,Q5) -> 6.2670488e+09 | I5: =G5-H5 -> 3.414997e+08 | J5: 6.6085485e+09 | K5: 6.2670488e+09
E6: 工程施工 | F6: 0.09 | G6: =SUM(J6,L6,N6,P6,R6,T6,V6,X6,Z6) -> 5.0145477e+09 | H6: =SUM(K6,M6,O6,Q6) -> 4.892353e+09 | I6: =G6-H6 -> 1.221947e+08 | J6: 5.0145477e+09 | K6: 4.892353e+09
E7: 设计咨询 | F7: 0.06 | G7: =SUM(J7,L7,N7,P7,R7,T7,V7,X7,Z7) -> 4.6296552e+08 | H7: =SUM(K7,M7,O7,Q7) -> 3.6885177e+08 | I7: =G7-H7 -> 94113747 | J7: 4.6296552e+08 | K7: 3.6885177e+08 | Y7: 0
B8: EPC自建 | C8: 2346 | D8: 安徽宣城郎溪 | E8: 商品销售 | F8: 0.13 | G8: =SUM(J8,L8,N8,P8,R8,T8,V8,X8,Z8,AB8,AD8,AF8,AH8,AJ8,AL8,AN8,AP8,AR8,AU8,AW8,AY8,BC8,BG8) -> 32635696 | H8: =SUM(K8,M8,O8,Q8,S8,U8,W8,Y8,AA8,AC8,AE8,AG8,AI8,AK8,AM8,AO8,AQ8,AS8,AV8,AX8,AZ8,BD8,BH8) -> 37275653 | I8: =G8-H8 -> -4639956.4 | N8: 7575879.3 | O8: 11624470 | P8: 17461283 | Q8: 7575879.3 | R8: 2028030.5 | S8: 10476770 | T8: 184101.94 | V8: 5386401.3 | W8: 0 | X8: 0 | Y8: 0 | AJ8: 0 | AK8: 7598533.8
C9: 2346 | E9: 工程施工 | F9: 0.09 | G9: =SUM(J9,L9,N9,P9,R9,T9,V9,X9,Z9,AB9,AD9,AF9,AH9,AJ9,AL9,AN9,AP9,AR9,AU9,AW9,AY9,BC9,BG9) -> 9498435.8 | H9: =SUM(K9,M9,O9,Q9,S9,U9,W9,Y9,AA9,AC9,AE9,AG9,AI9,AK9,AM9,AO9,AQ9,AS9,AV9,AX9,AZ9,BD9,BH9) -> 19399126 | I9: =G9-H9 -> -9900690.2 | L9: 1044857.3 | N9: 2871503.7 | P9: 1423208.3 | Q9: 15363805 | R9: 2364082.2 | S9: 4035321.1 | T9: 1100229.4 | V9: 470183.49 | W9: 0 | X9: 224371.56 | Y9: 0
C10: 2346 | E10: 设计咨询 | F10: 0.06 | G10: =SUM(J10,L10,N10,P10,R10,T10,V10,X10,Z10,AB10,AD10,AF10,AH10,AJ10,AL10,AN10,AP10,AR10,AU10,AW10,AY10,BC10,BG10) -> 1587499.5 | H10: =SUM(K10,M10,O10,Q10,S10,U10,W10,Y10,AA10,AC10,AE10,AG10,AI10,AK10,AM10,AO10,AQ10,AS10,AV10,AX10,AZ10,BD10,BH10) -> 1604523.2 | I10: =G10-H10 -> -17023.79 | L10: 116896.06 | N10: 170311.43 | P10: 316972.4 | Q10: 1050616 | R10: 634803.18 | S10: 362041.83 | T10: 201873.22 | U10: 45222.28 | V10: 68316.87 | W10: 68316.87 | X10: 44486.8 | Y10: 44486.8 | Z10: 33839.49 | AA10: 33839.49
C11: 安新县阔达有色金属熔炼有限公司 | D11: 安徽宣城郎溪 | E11: 商品销售 | F11: 0.13 | G11: =SUM(J11,L11,N11,P11,R11,T11,V11,X11,Z11,AB11,AD11,AF11,AH11,AJ11,AL11,AN11,AP11,AR11,AU11,AW11,AY11,BC11,BG11) -> 0 | H11: =SUM(K11,M11,O11,Q11,S11,U11,W11,Y11,AA11,AC11,AE11,AG11,AI11,AK11,AM11,AO11,AQ11,AS11,AV11,AX11,AZ11,BD11,BH11) -> 81415.93 | BH11: 81415.93
E12: 工程施工 | F12: 0.09 | G12: =SUM(J12,L12,N12,P12,R12,T12,V12,X12,Z12,AB12,AD12,AF12,AH12,AJ12,AL12,AN12,AP12,AR12,AU12,AW12,AY12,BC12,BG12) -> 0 | H12: =SUM(K12,M12,O12,Q12,S12,U12,W12,Y12,AA12,AC12,AE12,AG12,AI12,AK12,AM12,AO12,AQ12,AS12,AV12,AX12,AZ12,BD12,BH12) -> 0
E13: 设计咨询 | F13: 0.06 | G13: =SUM(J13,L13,N13,P13,R13,T13,V13,X13,Z13,AB13,AD13,AF13,AH13,AJ13,AL13,AN13,AP13,AR13,AU13,AW13,AY13,BC13,BG13) -> 0 | H13: =SUM(K13,M13,O13,Q13,S13,U13,W13,Y13,AA13,AC13,AE13,AG13,AI13,AK13,AM13,AO13,AQ13,AS13,AV13,AX13,AZ13,BD13,BH13) -> 0
B14: EPC自建 | C14: 3660 | D14: 巴彦淖尔 | E14: 商品销售 | F14: 0.13 | G14: =SUM(J14,L14,N14,P14,R14,T14,V14,X14,Z14,AB14,AD14,AF14,AH14,AJ14,AL14,AN14,AP14,AR14,AU14,AW14,AY14,BC14,BG14) -> 8211701.3 | H14: =SUM(K14,M14,O14,Q14,S14,U14,W14,Y14,AA14,AC14,AE14,AG14,AI14,AK14,AM14,AO14,AQ14,AS14,AV14,AX14,AZ14,BD14,BH14) -> 11336364 | I14: =G14-H14 -> -3124662.7 | L14: 8130064.1 | M14: 3124662.6 | N14: 81637.17 | V14: 0 | W14: 0 | X14: 0 | Y14: 8211701.4
C15: 3660 | E15: 工程施工 | F15: 0.09 | G15: =SUM(J15,L15,N15,P15,R15,T15,V15,X15,Z15,AB15,AD15,AF15,AH15,AJ15,AL15,AN15,AP15,AR15,AU15,AW15,AY15,BC15,BG15) -> 4.6214846e+08 | H15: =SUM(K15,M15,O15,Q15,S15,U15,W15,Y15,AA15,AC15,AE15,AG15,AI15,AK15,AM15,AO15,AQ15,AS15,AV15,AX15,AZ15,BD15,BH15) -> 4.6214846e+08 | I15: =G15-H15 -> -0.029999912 | L15: 1.8904657e+08 | M15: 1.8348624e+08 | N15: 2.2018349e+08 | O15: 2.2018349e+08 | P15: 1.9266055e+08 | Q15: 1.9266055e+08 | U15: 3981328.1 | V15: 1239039.6 | W15: 0 | X15: 0 | Y15: 2818045.8 | AD15: -1.4098119e+08 | AE15: 0 | AI15: -1.4098119e+08
C16: 3660 | E16: 设计咨询 | F16: 0.06 | G16: =SUM(J16,L16,N16,P16,R16,T16,V16,X16,Z16,AB16,AD16,AF16,AH16,AJ16,AL16,AN16,AP16,AR16,AU16,AW16,AY16,BC16,BG16) -> 5519384.1 | H16: =SUM(K16,M16,O16,Q16,S16,U16,W16,Y16,AA16,AC16,AE16,AG16,AI16,AK16,AM16,AO16,AQ16,AS16,AV16,AX16,AZ16,BD16,BH16) -> 6976051.5 | I16: =G16-H16 -> -1456667.3 | L16: 5238515.3 | M16: 1456667.3 | N16: -81637.17 | T16: 212735.85 | U16: 4216037.7 | V16: 52152 | W16: 0 | X16: 0 | Y16: 1205728.3 | AD16: 97618.11 | AE16: 97618.11
B17: EPC自建 | C17: 4030 | D17: 定边白兴庄 | E17: 商品销售 | F17: 0.13 | G17: =SUM(J17,L17,N17,P17,R17,T17,V17,X17,Z17,AB17,AD17,AF17,AH17,AJ17,AL17,AN17,AP17,AR17,AU17,AW17,AY17,BC17,BG17) -> 2.0329258e+08 | H17: =SUM(K17,M17,O17,Q17,S17,U17,W17,Y17,AA17,AC17,AE17,AG17,AI17,AK17,AM17,AO17,AQ17,AS17,AV17,AX17,AZ17,BD17,BH17) -> 1.1134199e+08 | I17: =G17-H17 -> 91950591 | N17: 3664601.8 | P17: 222234.5 | R17: 18651916 | S17: 0 | T17: 53556348 | V17: 14543776 | W17: 0 | X17: -9581572.7 | Y17: 8347326.5 | Z17: 32102530 | AA17: 11020813 | AB17: 90132743 | AC17: 91973846
C18: 4030 | E18: 工程施工 | F18: 0.09 | G18: =SUM(J18,L18,N18,P18,R18,T18,V18,X18,Z18,AB18,AD18,AF18,AH18,AJ18,AL18,AN18,AP18,AR18,AU18,AW18,AY18,BC18,BG18) -> 2.1309161e+08 | H18: =SUM(K18,M18,O18,Q18,S18,U18,W18,Y18,AA18,AC18,AE18,AG18,AI18,AK18,AM18,AO18,AQ18,AS18,AV18,AX18,AZ18,BD18,BH18) -> 1.8890447e+08 | I18: =G18-H18 -> 24187141 | L18: 489233.5 | N18: 9211423.6 | O18: 45871560 | P18: 10406006 | R18: 14196013 | S18: 0 | T18: 12344910 | V18: 9578080.4 | W18: 0 | X18: 15013767 | Y18: 18679332 | Z18: 37165437 | AA18: 9429091.5 | AB18: 53132537 | AC18: 63370283 | AD18: 51554199 | AE18: 51554199
C19: 4030 | E19: 设计咨询 | F19: 0.06 | G19: =SUM(J19,L19,N19,P19,R19,T19,V19,X19,Z19,AB19,AD19,AF19,AH19,AJ19,AL19,AN19,AP19,AR19,AU19,AW19,AY19,BC19,BG19) -> 8329405.3 | H19: =SUM(K19,M19,O19,Q19,S19,U19,W19,Y19,AA19,AC19,AE19,AG19,AI19,AK19,AM19,AO19,AQ19,AS19,AV19,AX19,AZ19,BD19,BH19) -> 7940431.8 | I19: =G19-H19 -> 388973.51 | L19: 43891.61 | N19: 685280.75 | P19: 64486.14 | R19: 156301.33 | S19: 60092.57 | T19: 3078319.5 | U19: 60296.37 | V19: =563843.01+91089.15 -> 654932.16 | W19: 91089.15 | X19: 165683.66 | Y19: 4427586 | Z19: 3031830.8 | AA19: 474936.19 | AB19: 448679.26 | AC19: 2826431.5
B20: EPC自建 | C20: 4020 | D20: 定边王家梁 | E20: 商品销售 | F20: 0.13 | G20: =SUM(J20,L20,N20,P20,R20,T20,V20,X20,Z20,AB20,AD20,AF20,AH20,AJ20,AL20,AN20,AP20,AR20,AU20,AW20,AY20,BC20,BG20) -> 1.0538136e+08 | H20: =SUM(K20,M20,O20,Q20,S20,U20,W20,Y20,AA20,AC20,AE20,AG20,AI20,AK20,AM20,AO20,AQ20,AS20,AV20,AX20,AZ20,BD20,BH20) -> 1.0767405e+08 | I20: =G20-H20 -> -2292690.1 | M20: 2292690 | N20: 10422345 | R20: 660150.8 | S20: 0 | T20: 27073953 | V20: 3545901.1 | W20: 13168633 | X20: 11705115 | Y20: 3422302.7 | Z20: 51973899 | AA20: 36816530 | AI20: 51973899
C21: 4020 | E21: 工程施工 | F21: 0.09 | G21: =SUM(J21,L21,N21,P21,R21,T21,V21,X21,Z21,AB21,AD21,AF21,AH21,AJ21,AL21,AN21,AP21,AR21,AU21,AW21,AY21,BC21,BG21) -> 2.9721338e+08 | H21: =SUM(K21,M21,O21,Q21,S21,U21,W21,Y21,AA21,AC21,AE21,AG21,AI21,AK21,AM21,AO21,AQ21,AS21,AV21,AX21,AZ21,BD21,BH21) -> 3.2681651e+08 | I21: =G21-H21 -> -29603135 | L21: 5244190.5 | M21: 29823783 | N21: 13660419 | O21: 1.6430483e+08 | P21: 27909442 | R21: 19309601 | S21: 0 | T21: 12545273 | V21: 7283802.8 | W21: 73424735 | X21: 8064138.7 | Y21: 2271099.1 | Z21: 2.0319651e+08 | AA21: 47672842 | AE21: 9319218.1
C22: 4020 | E22: 设计咨询 | F22: 0.06 | G22: =SUM(J22,L22,N22,P22,R22,T22,V22,X22,Z22,AB22,AD22,AF22,AH22,AJ22,AL22,AN22,AP22,AR22,AU22,AW22,AY22,BC22,BG22) -> 15200557 | H22: =SUM(K22,M22,O22,Q22,S22,U22,W22,Y22,AA22,AC22,AE22,AG22,AI22,AK22,AM22,AO22,AQ22,AS22,AV22,AX22,AZ22,BD22,BH22) -> 29092126 | I22: =G22-H22 -> -13891569 | L22: 387382.3 | M22: 6720925.1 | N22: 1991865.6 | O22: 614275.5 | P22: 1033444.8 | R22: 605451.16 | S22: 60092.57 | T22: 3642158.9 | U22: 60296.37 | V22: =451080.26+91089.15 -> 542169.41 | W22: 14187371 | X22: 453844.04 | Y22: 510396 | Z22: 5695184.2 | AA22: 394528.3 | AD22: 849056.6 | AE22: 5695184.2 | AG22: 849056.6
B23: EPC自建 | C23: 2319 | D23: 定远乘风 | E23: 商品销售 | F23: 0.13 | G23: =SUM(J23,L23,N23,P23,R23,T23,V23,X23,Z23,AB23,AD23,AF23,AH23,AJ23,AL23,AN23,AP23,AR23,AU23,AW23,AY23,BC23,BG23) -> 1.2192612e+08 | H23: =SUM(K23,M23,O23,Q23,S23,U23,W23,Y23,AA23,AC23,AE23,AG23,AI23,AK23,AM23,AO23,AQ23,AS23,AV23,AX23,AZ23,BD23,BH23) -> 1.4448884e+08 | I23: =G23-H23 -> -22562720 | L23: 3184412.9 | P23: 3053970.6 | R23: 1591338.1 | S23: 0 | T23: 28616.54 | U23: 30132373 | V23: 22396948 | W23: 0 | X23: 23544881 | Y23: 0 | Z23: 68125955 | AA23: 54847.11 | AC23: 1.1404155e+08 | AD23: 0 | AE23: 260067.96
C24: 2319 | E24: 工程施工 | F24: 0.09 | G24: =SUM(J24,L24,N24,P24,R24,T24,V24,X24,Z24,AB24,AD24,AF24,AH24,AJ24,AL24,AN24,AP24,AR24,AU24,AW24,AY24,BC24,BG24) -> 4.0298493e+08 | H24: =SUM(K24,M24,O24,Q24,S24,U24,W24,Y24,AA24,AC24,AE24,AG24,AI24,AK24,AM24,AO24,AQ24,AS24,AV24,AX24,AZ24,BD24,BH24) -> 4.7599102e+08 | I24: =G24-H24 -> -73006093 | L24: -493692.65 | N24: 11024685 | P24: 9616720.9 | R24: 15488844 | S24: 0 | T24: 5873943.7 | U24: 1.0864265e+08 | V24: 8786601.5 | W24: 0 | X24: 15887463 | Y24: 0 | Z24: 43577732 | AB24: 2.9396666e+08 | AC24: 74125740 | AD24: -744034.87 | AE24: 2.9322263e+08
C25: 2319 | E25: 设计咨询 | F25: 0.06 | G25: =SUM(J25,L25,N25,P25,R25,T25,V25,X25,Z25,AB25,AD25,AF25,AH25,AJ25,AL25,AN25,AP25,AR25,AU25,AW25,AY25,BC25,BG25) -> 12445292 | H25: =SUM(K25,M25,O25,Q25,S25,U25,W25,Y25,AA25,AC25,AE25,AG25,AI25,AK25,AM25,AO25,AQ25,AS25,AV25,AX25,AZ25,BD25,BH25) -> 25072324 | I25: =G25-H25 -> -12627032 | P25: 572632.47 | R25: 1198794.8 | S25: 60092.57 | T25: 1933105.9 | U25: 15442087 | V25: =2056169.38+91089.15 -> 2147258.5 | W25: -1053820.4 | X25: 1316111 | Y25: 59315.74 | Z25: 5207673.3 | AC25: 10494933 | AF25: 69716.4 | AG25: 69716.4
B26: EPC自建 | C26: 2318 | D26: 定远欣月 | E26: 商品销售 | F26: 0.13 | G26: =SUM(J26,L26,N26,P26,R26,T26,V26,X26,Z26,AB26,AD26,AF26,AH26,AJ26,AL26,AN26,AP26,AR26,AU26,AW26,AY26,BC26,BG26) -> 91048578 | H26: =SUM(K26,M26,O26,Q26,S26,U26,W26,Y26,AA26,AC26,AE26,AG26,AI26,AK26,AM26,AO26,AQ26,AS26,AV26,AX26,AZ26,BD26,BH26) -> 94539002 | I26: =G26-H26 -> -3490424.3 | P26: 18248654 | R26: 14223009 | S26: 0 | T26: 24448246 | U26: 35962087 | V26: 6740165.1 | W26: 0 | X26: -3136198 | Y26: 0 | Z26: 30470275 | AB26: 54427.05 | AC26: 58576915
C27: 2318 | E27: 工程施工 | F27: 0.09 | G27: =SUM(J27,L27,N27,P27,R27,T27,V27,X27,Z27,AB27,AD27,AF27,AH27,AJ27,AL27,AN27,AP27,AR27,AU27,AW27,AY27,BC27,BG27) -> 2.385241e+08 | H27: =SUM(K27,M27,O27,Q27,S27,U27,W27,Y27,AA27,AC27,AE27,AG27,AI27,AK27,AM27,AO27,AQ27,AS27,AV27,AX27,AZ27,BD27,BH27) -> 2.7753196e+08 | I27: =G27-H27 -> -39007863 | L27: -634747.7 | N27: 4893183.6 | P27: 1363532.1 | R27: 7882465.7 | S27: 0 | T27: 3424803.4 | U27: 52512297 | V27: 3477768.1 | W27: 0 | X27: -545268.65 | Y27: 0 | Z27: 17266715 | AB27: 1.5728736e+08 | AC27: 1.8091138e+08 | AD27: 44108287 | AE27: 44108287
C28: 2318 | E28: 设计咨询 | F28: 0.06 | G28: =SUM(J28,L28,N28,P28,R28,T28,V28,X28,Z28,AB28,AD28,AF28,AH28,AJ28,AL28,AN28,AP28,AR28,AU28,AW28,AY28,BC28,BG28) -> 9887422.4 | H28: =SUM(K28,M28,O28,Q28,S28,U28,W28,Y28,AA28,AC28,AE28,AG28,AI28,AK28,AM28,AO28,AQ28,AS28,AV28,AX28,AZ28,BD28,BH28) -> 22107136 | I28: =G28-H28 -> -12219713 | L28: 625546.26 | N28: 721744.48 | P28: 1109241.8 | R28: 848738.92 | S28: 45069.41 | T28: 1125155.6 | U28: 16630790 | V28: =1480911.13+68316.91 -> 1549228 | W28: -935850.35 | X28: 281836.92 | Y28: 44486.75 | Z28: 3625930.4 | AC28: 6322639.7
B29: EPC自建 | C29: 2A50 | D29: 定远独立储能 | E29: 商品销售 | F29: 0.13 | G29: =SUM(J29,L29,N29,P29,R29,T29,V29,X29,Z29,AB29,AD29,AF29,AH29,AJ29,AL29,AN29,AP29,AR29,AU29,AW29,AY29,BC29,BG29) -> 0 | H29: =SUM(K29,M29,O29,Q29,S29,U29,W29,Y29,AA29,AC29,AE29,AG29,AI29,AK29,AM29,AO29,AQ29,AS29,AV29,AX29,AZ29,BD29,BH29) -> 9836350.8 | I29: =G29-H29 -> -9836350.8 | V29: 0 | W29: 0 | X29: 0 | Y29: 0 | Z29: 117923.07 | AH29: -117923.07 | AJ29: 0 | AK29: 9836350.8
C30: 2A50 | E30: 工程施工 | F30: 0.09 | G30: =SUM(J30,L30,N30,P30,R30,T30,V30,X30,Z30,AB30,AD30,AF30,AH30,AJ30,AL30,AN30,AP30,AR30,AU30,AW30,AY30,BC30,BG30) -> 2073641.8 | H30: =SUM(K30,M30,O30,Q30,S30,U30,W30,Y30,AA30,AC30,AE30,AG30,AI30,AK30,AM30,AO30,AQ30,AS30,AV30,AX30,AZ30,BD30,BH30) -> 30988092 | I30: =G30-H30 -> -28914451 | V30: 0 | W30: 0 | X30: 0 | Y30: 0 | Z30: 2073641.8 | AI30: 30988092
C31: 2A50 | E31: 设计咨询 | F31: 0.06 | G31: =SUM(J31,L31,N31,P31,R31,T31,V31,X31,Z31,AB31,AD31,AF31,AH31,AJ31,AL31,AN31,AP31,AR31,AU31,AW31,AY31,BC31,BG31) -> 1726122.2 | H31: =SUM(K31,M31,O31,Q31,S31,U31,W31,Y31,AA31,AC31,AE31,AG31,AI31,AK31,AM31,AO31,AQ31,AS31,AV31,AX31,AZ31,BD31,BH31) -> 8077291.4 | I31: =G31-H31 -> -6351169.2 | L31: 1262584.2 | N31: 112007.19 | Q31: 7725760.7 | U31: 0 | V31: 0 | W31: 0 | X31: 0 | Y31: 0 | Z31: 351530.75 | AJ31: 0 | AK31: 351530.74
B32: EPC自建 | C32: 1080 | D32: 丰宁 | E32: 商品销售 | F32: 0.13 | G32: =SUM(J32,L32,N32,P32,R32,T32,V32,X32,Z32,AB32,AD32,AF32,AH32,AJ32,AL32,AN32,AP32,AR32,AU32,AW32,AY32,BC32,BG32) -> 0 | H32: =SUM(K32,M32,O32,Q32,S32,U32,W32,Y32,AA32,AC32,AE32,AG32,AI32,AK32,AM32,AO32,AQ32,AS32,AV32,AX32,AZ32,BD32,BH32) -> 0 | I32: =G32-H32 -> 0
C33: 1080 | E33: 工程施工 | F33: 0.09 | G33: =SUM(J33,L33,N33,P33,R33,T33,V33,X33,Z33,AB33,AD33,AF33,AH33,AJ33,AL33,AN33,AP33,AR33,AU33,AW33,AY33,BC33,BG33) -> 0 | H33: =SUM(K33,M33,O33,Q33,S33,U33,W33,Y33,AA33,AC33,AE33,AG33,AI33,AK33,AM33,AO33,AQ33,AS33,AV33,AX33,AZ33,BD33,BH33) -> 379237.83 | I33: =G33-H33 -> -379237.83 | AI33: 379237.83
C34: 1080 | E34: 设计咨询 | F34: 0.06 | G34: =SUM(J34,L34,N34,P34,R34,T34,V34,X34,Z34,AB34,AD34,AF34,AH34,AJ34,AL34,AN34,AP34,AR34,AU34,AW34,AY34,BC34,BG34) -> 0 | H34: =SUM(K34,M34,O34,Q34,S34,U34,W34,Y34,AA34,AC34,AE34,AG34,AI34,AK34,AM34,AO34,AQ34,AS34,AV34,AX34,AZ34,BD34,BH34) -> 475794.07 | I34: =G34-H34 -> -475794.07 | AI34: 475794.07
B35: EPC自建 | C35: 1080 | D35: 丰宁二期 | E35: 商品销售 | F35: 0.13 | G35: =SUM(J35,L35,N35,P35,R35,T35,V35,X35,Z35,AB35,AD35,AF35,AH35,AJ35,AL35,AN35,AP35,AR35,AU35,AW35,AY35,BC35,BG35) -> 2.1818304e+08 | H35: =SUM(K35,M35,O35,Q35,S35,U35,W35,Y35,AA35,AC35,AE35,AG35,AI35,AK35,AM35,AO35,AQ35,AS35,AV35,AX35,AZ35,BD35,BH35) -> 2.0772881e+08 | I35: =G35-H35 -> 10454224 | N35: 22944611 | P35: 9632042.6 | Q35: 21162439 | R35: 35911880 | S35: 11414215 | T35: 10896695 | V35: 1.0628981e+08 | W35: 36354351 | X35: 4407911.8 | Y35: 83150389 | Z35: 28100089 | AA35: 27533528 | AE35: 4012784.8 | AI35: 24101106
C36: 1080 | E36: 工程施工 | F36: 0.09 | G36: =SUM(J36,L36,N36,P36,R36,T36,V36,X36,Z36,AB36,AD36,AF36,AH36,AJ36,AL36,AN36,AP36,AR36,AU36,AW36,AY36,BC36,BG36) -> 1.1833155e+09 | H36: =SUM(K36,M36,O36,Q36,S36,U36,W36,Y36,AA36,AC36,AE36,AG36,AI36,AK36,AM36,AO36,AQ36,AS36,AV36,AX36,AZ36,BD36,BH36) -> 1.0976805e+09 | I36: =G36-H36 -> 85635052 | L36: 2011104.1 | N36: 16149385 | P36: 24831319 | R36: 29735687 | S36: 49099875 | T36: 1.5868586e+08 | U36: 1.3761468e+08 | V36: 1.7189511e+08 | W36: 2.0677017e+08 | X36: 1.1730584e+08 | Y36: 1.2733723e+08 | Z36: 75373568 | AA36: 28836197 | AD36: 5.8732768e+08 | AE36: 1.4418091e+08 | AG36: 2.7522936e+08 | AI36: 1.2861208e+08 | AN36: -91743119 | AP36: 91743119
C37: 1080 | E37: 设计咨询 | F37: 0.06 | G37: =SUM(J37,L37,N37,P37,R37,T37,V37,X37,Z37,AB37,AD37,AF37,AH37,AJ37,AL37,AN37,AP37,AR37,AU37,AW37,AY37,BC37,BG37) -> 20771259 | H37: =SUM(K37,M37,O37,Q37,S37,U37,W37,Y37,AA37,AC37,AE37,AG37,AI37,AK37,AM37,AO37,AQ37,AS37,AV37,AX37,AZ37,BD37,BH37) -> 22230481 | I37: =G37-H37 -> -1459221.8 | L37: 439078.6 | N37: 1226790.2 | P37: -113038.25 | Q37: 2831283.8 | R37: 60092.57 | S37: 60092.57 | T37: 472894.22 | U37: 60296.37 | V37: =7294630.9+91089.15 -> 7385720.1 | W37: 684455.55 | X37: 2150705.6 | Y37: 7353946.6 | Z37: 9149015.7 | AA37: 2091389.9 | AE37: 9149015.7
