Workbook
Name \A: #REF!
Name \e: #REF!
Name \p: #REF!
Name \s: #N/A
Name _: #REF!
Name _.xls: #REF!
Name _?: #N/A
Name _??????: #N/A
Name __: #REF!
Name __?: #N/A
Name __??????: #N/A
Name __aaa5: [3]六纺!#REF!
Name __k3: #REF!
Name __sc13: #REF!
Name _00104gz: #REF!
Name _002报表: #REF!
Name _002科目余额表: #REF!
Name _003报表: #REF!
Name _003科目余额表: #REF!
Name _003年12月辅料库: #REF!
Name _01.xls: #REF!
Name _010104501: #REF!
Name _02.xls: #REF!
Name _03.xls: #REF!
Name _1_?: #N/A
Name _11.xls: #REF!
Name _12.xls: #REF!
Name _121.dbf: #REF!
Name _1212002.dbf: #REF!
Name _13: #REF!
Name _17103.dbf: #REF!
Name _171032002.dbf: #REF!
Name _2: #REF!
Name _2_??????: #N/A
Name _2009: #REF!
Name _3¸ß¼ÛÖÜ×ª¼þ_¨º½²Ä¹ý¶É: #REF!
Name _3年12月: #REF!
Name _3年12月后勤库: #REF!
Name _4_04标准价: #REF!
Name _5_20011225: #REF!
Name _55154: #REF!
Name _8未还DB_查询: #REF!
Name _9_12_mo_cost: #REF!
Name _999年12月31日股份应收帐款.dbf: #REF!
Name _aaa5: [3]六纺!#REF!
Name _act411: #REF!
Name _act412: #REF!
Name _act413: #REF!
Name _act414: #REF!
Name _DAT1: #REF!
Name _DAT10: #REF!
Name _DAT11: #REF!
Name _DAT12: #REF!
Name _DAT13: [13]Sheet1!#REF!
Name _DAT14: [13]Sheet1!#REF!
Name _DAT15: [13]Sheet1!#REF!
Name _DAT16: [13]Sheet1!#REF!
Name _DAT2: #REF!
Name _DAT3: #REF!
Name _DAT4: #REF!

Sheet 报税
A1: 1、取自：报税pt（筛选：月份）
A2: 2、核对：已开票收入+未开票收入=账面主营收入
D3: 建安9% | K3: 设备13% | R3: 设计服务6% | Y3: 咨询服务-在建6% | AF3: 咨询服务-在运6% | AM3: 仓储保管6%
A4: 行标签 | B4: 项目代码 | C4: 业务类型 | D4: 成本 | E4: 收入 | F4: 销项 | G4: 已开票收入 | H4: 已开票税额 | I4: 未开票收入 | J4: 未开票税额 | K4: 成本 | L4: 收入 | M4: 销项 | N4: 已开票收入 | O4: 已开票税额 | P4: 未开票收入 | Q4: 未开票税额 | R4: 成本 | S4: 收入 | T4: 销项 | U4: 已开票收入 | V4: 已开票税额 | W4: 未开票收入 | X4: 未开票税额 | Y4: 成本 | Z4: 收入 | AA4: 销项 | AB4: 已开票收入 | AC4: 已开票税额 | AD4: 未开票收入 | AE4: 未开票税额 | AF4: 成本 | AG4: 收入 | AH4: 销项 | AI4: 已开票收入 | AJ4: 已开票税额 | AK4: 未开票收入 | AL4: 未开票税额 | AM4: 收入 | AN4: 销项 | AO4: 已开票收入 | AP4: 已开票税额 | AQ4: 未开票收入 | AR4: 未开票税额
A5: 安徽宣城郎溪 | B5: 2346 | C5: EPC | D5: 531538.49 | G5: =SUMIFS([1]项目开票!C:C,[1]项目开票!B:B,报税!B5,[1]项目开票!A:A,报税!A5) -> 0 | H5: =SUMIFS([1]项目开票!D:D,[1]项目开票!B:B,报税!B5,[1]项目开票!A:A,报税!A5) -> 0 | I5: =E5-G5 -> 0 | J5: =F5-H5 -> 0 | K5: -27787.63 | N5: =SUMIFS([1]项目开票!O:O,[1]项目开票!B:B,报税!B5,[1]项目开票!A:A,报税!A5) -> 0 | O5: =SUMIFS([1]项目开票!P:P,[1]项目开票!B:B,报税!B5,[1]项目开票!A:A,报税!A5) -> 0 | P5: =L5-N5 -> 0 | Q5: =M5-O5 -> 0 | R5: 525720 | U5: =SUMIFS([1]项目开票!F:F,[1]项目开票!B:B,报税!B5,[1]项目开票!A:A,报税!A5) -> 0 | V5: =SUMIFS([1]项目开票!G:G,[1]项目开票!B:B,报税!B5,[1]项目开票!A:A,报税!A5) -> 0 | W5: =S5-U5 -> 0 | X5: =T5-V5 -> 0 | AB5: =SUMIFS([1]项目开票!I:I,[1]项目开票!B:B,报税!B5,[1]项目开票!A:A,报税!A5) -> 0 | AC5: =SUMIFS([1]项目开票!J:J,[1]项目开票!B:B,报税!B5,[1]项目开票!A:A,报税!A5) -> 0 | AD5: =Z5-AB5 -> 0 | AE5: =AA5-AC5 -> 0 | AI5: =SUMIFS([1]项目开票!L:L,[1]项目开票!B:B,报税!B5,[1]项目开票!A:A,报税!A5) -> 0 | AJ5: =SUMIFS([1]项目开票!M:M,[1]项目开票!B:B,报税!B5,[1]项目开票!A:A,报税!A5) -> 0 | AK5: =AG5-AI5 -> 0 | AL5: =AH5-AJ5 -> 0 | AQ5: =AM5-AO5 -> 0 | AR5: =AN5-AP5 -> 0 | AS5: =G5+N5+U5+AB5+AI5+AO5 -> 0
A6: 安徽宣城郎溪 | B6: 安新县阔达有色金属熔炼有限公司 | C6: EPC | G6: =SUMIFS([1]项目开票!C:C,[1]项目开票!B:B,报税!B6,[1]项目开票!A:A,报税!A6) -> 0 | H6: =SUMIFS([1]项目开票!D:D,[1]项目开票!B:B,报税!B6,[1]项目开票!A:A,报税!A6) -> 0 | I6: =E6-G6 -> 0 | J6: =F6-H6 -> 0 | M6: 10584.07 | N6: =SUMIFS([1]项目开票!O:O,[1]项目开票!B:B,报税!B6,[1]项目开票!A:A,报税!A6) -> 81415.93 | O6: =SUMIFS([1]项目开票!P:P,[1]项目开票!B:B,报税!B6,[1]项目开票!A:A,报税!A6) -> 10584.07 | P6: =L6-N6 -> -81415.93 | Q6: =M6-O6 -> 0 | U6: =SUMIFS([1]项目开票!F:F,[1]项目开票!B:B,报税!B6,[1]项目开票!A:A,报税!A6) -> 0 | V6: =SUMIFS([1]项目开票!G:G,[1]项目开票!B:B,报税!B6,[1]项目开票!A:A,报税!A6) -> 0 | W6: =S6-U6 -> 0 | X6: =T6-V6 -> 0 | AB6: =SUMIFS([1]项目开票!I:I,[1]项目开票!B:B,报税!B6,[1]项目开票!A:A,报税!A6) -> 0 | AC6: =SUMIFS([1]项目开票!J:J,[1]项目开票!B:B,报税!B6,[1]项目开票!A:A,报税!A6) -> 0 | AD6: =Z6-AB6 -> 0 | AE6: =AA6-AC6 -> 0 | AI6: =SUMIFS([1]项目开票!L:L,[1]项目开票!B:B,报税!B6,[1]项目开票!A:A,报税!A6) -> 0 | AJ6: =SUMIFS([1]项目开票!M:M,[1]项目开票!B:B,报税!B6,[1]项目开票!A:A,报税!A6) -> 0 | AK6: =AG6-AI6 -> 0 | AL6: =AH6-AJ6 -> 0 | AQ6: =AM6-AO6 -> 0 | AR6: =AN6-AP6 -> 0 | AS6: =G6+N6+U6+AB6+AI6+AO6 -> 81415.93
A7: 内蒙赤峰零碳氢氨-赤峰元宝山 | B7: XC00 | C7: EPC | D7: 165863.18 | E7: 284666.26 | F7: 25619.96 | G7: =SUMIFS([1]项目开票!C:C,[1]项目开票!B:B,报税!B7,[1]项目开票!A:A,报税!A7) -> 0 | H7: =SUMIFS([1]项目开票!D:D,[1]项目开票!B:B,报税!B7,[1]项目开票!A:A,报税!A7) -> 0 | I7: =E7-G7 -> 284666.26 | J7: =F7-H7 -> 25619.96 | N7: =SUMIFS([1]项目开票!O:O,[1]项目开票!B:B,报税!B7,[1]项目开票!A:A,报税!A7) -> 0 | O7: =SUMIFS([1]项目开票!P:P,[1]项目开票!B:B,报税!B7,[1]项目开票!A:A,报税!A7) -> 0 | P7: =L7-N7 -> 0 | Q7: =M7-O7 -> 0 | U7: =SUMIFS([1]项目开票!F:F,[1]项目开票!B:B,报税!B7,[1]项目开票!A:A,报税!A7) -> 0 | V7: =SUMIFS([1]项目开票!G:G,[1]项目开票!B:B,报税!B7,[1]项目开票!A:A,报税!A7) -> 0 | W7: =S7-U7 -> 0 | X7: =T7-V7 -> 0 | AB7: =SUMIFS([1]项目开票!I:I,[1]项目开票!B:B,报税!B7,[1]项目开票!A:A,报税!A7) -> 0 | AC7: =SUMIFS([1]项目开票!J:J,[1]项目开票!B:B,报税!B7,[1]项目开票!A:A,报税!A7) -> 0 | AD7: =Z7-AB7 -> 0 | AE7: =AA7-AC7 -> 0 | AI7: =SUMIFS([1]项目开票!L:L,[1]项目开票!B:B,报税!B7,[1]项目开票!A:A,报税!A7) -> 0 | AJ7: =SUMIFS([1]项目开票!M:M,[1]项目开票!B:B,报税!B7,[1]项目开票!A:A,报税!A7) -> 0 | AK7: =AG7-AI7 -> 0 | AL7: =AH7-AJ7 -> 0 | AQ7: =AM7-AO7 -> 0 | AR7: =AN7-AP7 -> 0 | AS7: =G7+N7+U7+AB7+AI7+AO7 -> 0
A8: 内蒙武川 | B8: 3690 | C8: 已出售 | G8: =SUMIFS([1]项目开票!C:C,[1]项目开票!B:B,报税!B8,[1]项目开票!A:A,报税!A8) -> 0 | H8: =SUMIFS([1]项目开票!D:D,[1]项目开票!B:B,报税!B8,[1]项目开票!A:A,报税!A8) -> 0 | I8: =E8-G8 -> 0 | J8: =F8-H8 -> 0 | N8: =SUMIFS([1]项目开票!O:O,[1]项目开票!B:B,报税!B8,[1]项目开票!A:A,报税!A8) -> 0 | O8: =SUMIFS([1]项目开票!P:P,[1]项目开票!B:B,报税!B8,[1]项目开票!A:A,报税!A8) -> 0 | P8: =L8-N8 -> 0 | Q8: =M8-O8 -> 0 | R8: -23551097 | U8: =SUMIFS([1]项目开票!F:F,[1]项目开票!B:B,报税!B8,[1]项目开票!A:A,报税!A8) -> 0 | V8: =SUMIFS([1]项目开票!G:G,[1]项目开票!B:B,报税!B8,[1]项目开票!A:A,报税!A8) -> 0 | W8: =S8-U8 -> 0 | X8: =T8-V8 -> 0 | AB8: =SUMIFS([1]项目开票!I:I,[1]项目开票!B:B,报税!B8,[1]项目开票!A:A,报税!A8) -> 0 | AC8: =SUMIFS([1]项目开票!J:J,[1]项目开票!B:B,报税!B8,[1]项目开票!A:A,报税!A8) -> 0 | AD8: =Z8-AB8 -> 0 | AE8: =AA8-AC8 -> 0 | AI8: =SUMIFS([1]项目开票!L:L,[1]项目开票!B:B,报税!B8,[1]项目开票!A:A,报税!A8) -> 0 | AJ8: =SUMIFS([1]项目开票!M:M,[1]项目开票!B:B,报税!B8,[1]项目开票!A:A,报税!A8) -> 0 | AK8: =AG8-AI8 -> 0 | AL8: =AH8-AJ8 -> 0 | AQ8: =AM8-AO8 -> 0 | AR8: =AN8-AP8 -> 0 | AS8: =G8+N8+U8+AB8+AI8+AO8 -> 0
A9: 内蒙伊旗风光储 | B9: 4470 | C9: EPC | D9: 5147036 | E9: 5275711.8 | F9: 474814.06 | G9: =SUMIFS([1]项目开票!C:C,[1]项目开票!B:B,报税!B9,[1]项目开票!A:A,报税!A9) -> 0 | H9: =SUMIFS([1]项目开票!D:D,[1]项目开票!B:B,报税!B9,[1]项目开票!A:A,报税!A9) -> 0 | I9: =E9-G9 -> 5275711.8 | J9: =F9-H9 -> 474814.06 | K9: -2001509.9 | L9: -2051547.6 | M9: -266701.21 | N9: =SUMIFS([1]项目开票!O:O,[1]项目开票!B:B,报税!B9,[1]项目开票!A:A,报税!A9) -> 0 | O9: =SUMIFS([1]项目开票!P:P,[1]项目开票!B:B,报税!B9,[1]项目开票!A:A,报税!A9) -> 0 | P9: =L9-N9 -> -2051547.6 | Q9: =M9-O9 -> -266701.21 | R9: 22278469 | S9: 22835430 | T9: 1370125.8 | U9: =SUMIFS([1]项目开票!F:F,[1]项目开票!B:B,报税!B9,[1]项目开票!A:A,报税!A9) -> 0 | V9: =SUMIFS([1]项目开票!G:G,[1]项目开票!B:B,报税!B9,[1]项目开票!A:A,报税!A9) -> 0 | W9: =S9-U9 -> 22835430 | X9: =T9-V9 -> 1370125.8 | AB9: =SUMIFS([1]项目开票!I:I,[1]项目开票!B:B,报税!B9,[1]项目开票!A:A,报税!A9) -> 0 | AC9: =SUMIFS([1]项目开票!J:J,[1]项目开票!B:B,报税!B9,[1]项目开票!A:A,报税!A9) -> 0 | AD9: =Z9-AB9 -> 0 | AE9: =AA9-AC9 -> 0 | AI9: =SUMIFS([1]项目开票!L:L,[1]项目开票!B:B,报税!B9,[1]项目开票!A:A,报税!A9) -> 0 | AJ9: =SUMIFS([1]项目开票!M:M,[1]项目开票!B:B,报税!B9,[1]项目开票!A:A,报税!A9) -> 0 | AK9: =AG9-AI9 -> 0 | AL9: =AH9-AJ9 -> 0 | AQ9: =AM9-AO9 -> 0 | AR9: =AN9-AP9 -> 0 | AS9: =G9+N9+U9+AB9+AI9+AO9 -> 0
A10: 内蒙伊旗风光储 | B10: 甘肃宏宇天成电力工程有限公司 | C10: EPC | G10: =SUMIFS([1]项目开票!C:C,[1]项目开票!B:B,报税!B10,[1]项目开票!A:A,报税!A10) -> 0 | H10: =SUMIFS([1]项目开票!D:D,[1]项目开票!B:B,报税!B10,[1]项目开票!A:A,报税!A10) -> 0 | I10: =E10-G10 -> 0 | J10: =F10-H10 -> 0 | M10: 318672.55 | N10: =SUMIFS([1]项目开票!O:O,[1]项目开票!B:B,报税!B10,[1]项目开票!A:A,报税!A10) -> 2451327.5 | O10: =SUMIFS([1]项目开票!P:P,[1]项目开票!B:B,报税!B10,[1]项目开票!A:A,报税!A10) -> 318672.55 | P10: =L10-N10 -> -2451327.5 | Q10: =M10-O10 -> 0 | U10: =SUMIFS([1]项目开票!F:F,[1]项目开票!B:B,报税!B10,[1]项目开票!A:A,报税!A10) -> 0 | V10: =SUMIFS([1]项目开票!G:G,[1]项目开票!B:B,报税!B10,[1]项目开票!A:A,报税!A10) -> 0 | W10: =S10-U10 -> 0 | X10: =T10-V10 -> 0 | AB10: =SUMIFS([1]项目开票!I:I,[1]项目开票!B:B,报税!B10,[1]项目开票!A:A,报税!A10) -> 0 | AC10: =SUMIFS([1]项目开票!J:J,[1]项目开票!B:B,报税!B10,[1]项目开票!A:A,报税!A10) -> 0 | AD10: =Z10-AB10 -> 0 | AE10: =AA10-AC10 -> 0 | AI10: =SUMIFS([1]项目开票!L:L,[1]项目开票!B:B,报税!B10,[1]项目开票!A:A,报税!A10) -> 0 | AJ10: =SUMIFS([1]项目开票!M:M,[1]项目开票!B:B,报税!B10,[1]项目开票!A:A,报税!A10) -> 0 | AK10: =AG10-AI10 -> 0 | AL10: =AH10-AJ10 -> 0 | AQ10: =AM10-AO10 -> 0 | AR10: =AN10-AP10 -> 0 | AS10: =G10+N10+U10+AB10+AI10+AO10 -> 2451327.5
A11: 内蒙伊旗风光储 | B11: 河间市绿洁再生资源回收有限公司 | C11: EPC | G11: =SUMIFS([1]项目开票!C:C,[1]项目开票!B:B,报税!B11,[1]项目开票!A:A,报税!A11) -> 0 | H11: =SUMIFS([1]项目开票!D:D,[1]项目开票!B:B,报税!B11,[1]项目开票!A:A,报税!A11) -> 0 | I11: =E11-G11 -> 0 | J11: =F11-H11 -> 0 | M11: 47030.16 | N11: =SUMIFS([1]项目开票!O:O,[1]项目开票!B:B,报税!B11,[1]项目开票!A:A,报税!A11) -> 361770.42 | O11: =SUMIFS([1]项目开票!P:P,[1]项目开票!B:B,报税!B11,[1]项目开票!A:A,报税!A11) -> 47030.16 | P11: =L11-N11 -> -361770.42 | Q11: =M11-O11 -> 0 | U11: =SUMIFS([1]项目开票!F:F,[1]项目开票!B:B,报税!B11,[1]项目开票!A:A,报税!A11) -> 0 | V11: =SUMIFS([1]项目开票!G:G,[1]项目开票!B:B,报税!B11,[1]项目开票!A:A,报税!A11) -> 0 | W11: =S11-U11 -> 0 | X11: =T11-V11 -> 0 | AB11: =SUMIFS([1]项目开票!I:I,[1]项目开票!B:B,报税!B11,[1]项目开票!A:A,报税!A11) -> 0 | AC11: =SUMIFS([1]项目开票!J:J,[1]项目开票!B:B,报税!B11,[1]项目开票!A:A,报税!A11) -> 0 | AD11: =Z11-AB11 -> 0 | AE11: =AA11-AC11 -> 0 | AI11: =SUMIFS([1]项目开票!L:L,[1]项目开票!B:B,报税!B11,[1]项目开票!A:A,报税!A11) -> 0 | AJ11: =SUMIFS([1]项目开票!M:M,[1]项目开票!B:B,报税!B11,[1]项目开票!A:A,报税!A11) -> 0 | AK11: =AG11-AI11 -> 0 | AL11: =AH11-AJ11 -> 0 | AQ11: =AM11-AO11 -> 0 | AR11: =AN11-AP11 -> 0 | AS11: =G11+N11+U11+AB11+AI11+AO11 -> 361770.42
A12: 内蒙伊旗风光储-光伏 | B12: 4470 | C12: EPC | D12: 2496504.9 | E12: 2558917.5 | F12: 230302.58 | G12: =SUMIFS([1]项目开票!C:C,[1]项目开票!B:B,报税!B12,[1]项目开票!A:A,报税!A12) -> 0 | H12: =SUMIFS([1]项目开票!D:D,[1]项目开票!B:B,报税!B12,[1]项目开票!A:A,报税!A12) -> 0 | I12: =E12-G12 -> 2558917.5 | J12: =F12-H12 -> 230302.58 | N12: =SUMIFS([1]项目开票!O:O,[1]项目开票!B:B,报税!B12,[1]项目开票!A:A,报税!A12) -> 0 | O12: =SUMIFS([1]项目开票!P:P,[1]项目开票!B:B,报税!B12,[1]项目开票!A:A,报税!A12) -> 0 | P12: =L12-N12 -> 0 | Q12: =M12-O12 -> 0 | R12: 95462.87 | S12: 97849.44 | T12: 5870.97 | U12: =SUMIFS([1]项目开票!F:F,[1]项目开票!B:B,报税!B12,[1]项目开票!A:A,报税!A12) -> 0 | V12: =SUMIFS([1]项目开票!G:G,[1]项目开票!B:B,报税!B12,[1]项目开票!A:A,报税!A12) -> 0 | W12: =S12-U12 -> 97849.44 | X12: =T12-V12 -> 5870.97 | AB12: =SUMIFS([1]项目开票!I:I,[1]项目开票!B:B,报税!B12,[1]项目开票!A:A,报税!A12) -> 0 | AC12: =SUMIFS([1]项目开票!J:J,[1]项目开票!B:B,报税!B12,[1]项目开票!A:A,报税!A12) -> 0 | AD12: =Z12-AB12 -> 0 | AE12: =AA12-AC12 -> 0 | AI12: =SUMIFS([1]项目开票!L:L,[1]项目开票!B:B,报税!B12,[1]项目开票!A:A,报税!A12) -> 0 | AJ12: =SUMIFS([1]项目开票!M:M,[1]项目开票!B:B,报税!B12,[1]项目开票!A:A,报税!A12) -> 0 | AK12: =AG12-AI12 -> 0 | AL12: =AH12-AJ12 -> 0 | AQ12: =AM12-AO12 -> 0 | AR12: =AN12-AP12 -> 0 | AS12: =G12+N12+U12+AB12+AI12+AO12 -> 0
A13: 灵山玖伯一期 | B13: 3307 | C13: 已出售 | G13: =SUMIFS([1]项目开票!C:C,[1]项目开票!B:B,报税!B13,[1]项目开票!A:A,报税!A13) -> 0 | H13: =SUMIFS([1]项目开票!D:D,[1]项目开票!B:B,报税!B13,[1]项目开票!A:A,报税!A13) -> 0 | I13: =E13-G13 -> 0 | J13: =F13-H13 -> 0 | N13: =SUMIFS([1]项目开票!O:O,[1]项目开票!B:B,报税!B13,[1]项目开票!A:A,报税!A13) -> 0 | O13: =SUMIFS([1]项目开票!P:P,[1]项目开票!B:B,报税!B13,[1]项目开票!A:A,报税!A13) -> 0 | P13: =L13-N13 -> 0 | Q13: =M13-O13 -> 0 | R13: 53584.91 | S13: 53584.91 | T13: 3215.09 | U13: =SUMIFS([1]项目开票!F:F,[1]项目开票!B:B,报税!B13,[1]项目开票!A:A,报税!A13) -> 323739.19 | V13: =SUMIFS([1]项目开票!G:G,[1]项目开票!B:B,报税!B13,[1]项目开票!A:A,报税!A13) -> 19424.35 | W13: =S13-U13 -> -270154.28 | X13: =T13-V13 -> -16209.26 | AB13: =SUMIFS([1]项目开票!I:I,[1]项目开票!B:B,报税!B13,[1]项目开票!A:A,报税!A13) -> 0 | AC13: =SUMIFS([1]项目开票!J:J,[1]项目开票!B:B,报税!B13,[1]项目开票!A:A,报税!A13) -> 0 | AD13: =Z13-AB13 -> 0 | AE13: =AA13-AC13 -> 0 | AI13: =SUMIFS([1]项目开票!L:L,[1]项目开票!B:B,报税!B13,[1]项目开票!A:A,报税!A13) -> 0 | AJ13: =SUMIFS([1]项目开票!M:M,[1]项目开票!B:B,报税!B13,[1]项目开票!A:A,报税!A13) -> 0 | AK13: =AG13-AI13 -> 0 | AL13: =AH13-AJ13 -> 0 | AS13: =G13+N13+U13+AB13+AI13+AO13 -> 323739.19
A14: 利豪鸡泽县项目 | B14: 利豪泽风邯郸风力发电有限责任公司 | C14: 对外EPC | G14: =SUMIFS([1]项目开票!C:C,[1]项目开票!B:B,报税!B14,[1]项目开票!A:A,报税!A14) -> 0 | H14: =SUMIFS([1]项目开票!D:D,[1]项目开票!B:B,报税!B14,[1]项目开票!A:A,报税!A14) -> 0 | I14: =E14-G14 -> 0 | J14: =F14-H14 -> 0 | K14: 122417.26 | L14: 132550.47 | M14: 17231.56 | N14: =SUMIFS([1]项目开票!O:O,[1]项目开票!B:B,报税!B14,[1]项目开票!A:A,报税!A14) -> 0 | O14: =SUMIFS([1]项目开票!P:P,[1]项目开票!B:B,报税!B14,[1]项目开票!A:A,报税!A14) -> 0 | P14: =L14-N14 -> 132550.47 | Q14: =M14-O14 -> 17231.56 | R14: 315272.44 | S14: 345134.82 | T14: 20708.09 | U14: =SUMIFS([1]项目开票!F:F,[1]项目开票!B:B,报税!B14,[1]项目开票!A:A,报税!A14) -> 0 | V14: =SUMIFS([1]项目开票!G:G,[1]项目开票!B:B,报税!B14,[1]项目开票!A:A,报税!A14) -> 0 | W14: =S14-U14 -> 345134.82 | X14: =T14-V14 -> 20708.09 | AB14: =SUMIFS([1]项目开票!I:I,[1]项目开票!B:B,报税!B14,[1]项目开票!A:A,报税!A14) -> 0 | AC14: =SUMIFS([1]项目开票!J:J,[1]项目开票!B:B,报税!B14,[1]项目开票!A:A,报税!A14) -> 0 | AD14: =Z14-AB14 -> 0 | AE14: =AA14-AC14 -> 0 | AI14: =SUMIFS([1]项目开票!L:L,[1]项目开票!B:B,报税!B14,[1]项目开票!A:A,报税!A14) -> 0 | AJ14: =SUMIFS([1]项目开票!M:M,[1]项目开票!B:B,报税!B14,[1]项目开票!A:A,报税!A14) -> 0 | AK14: =AG14-AI14 -> 0 | AL14: =AH14-AJ14 -> 0 | AQ14: =AM14-AO14 -> 0 | AR14: =AN14-AP14 -> 0 | AS14: =G14+N14+U14+AB14+AI14+AO14 -> 0
A15: 安徽定远 | B15: 1A00 | C15: 已出售 | D15: 460600 | E15: 472115 | F15: 42490.35 | G15: =SUMIFS([1]项目开票!C:C,[1]项目开票!B:B,报税!B15,[1]项目开票!A:A,报税!A15) -> 472115 | H15: =SUMIFS([1]项目开票!D:D,[1]项目开票!B:B,报税!B15,[1]项目开票!A:A,报税!A15) -> 42490.35 | I15: =E15-G15 -> 0 | J15: =F15-H15 -> 0 | N15: =SUMIFS([1]项目开票!O:O,[1]项目开票!B:B,报税!B15,[1]项目开票!A:A,报税!A15) -> 0 | O15: =SUMIFS([1]项目开票!P:P,[1]项目开票!B:B,报税!B15,[1]项目开票!A:A,报税!A15) -> 0 | P15: =L15-N15 -> 0 | Q15: =M15-O15 -> 0 | U15: =SUMIFS([1]项目开票!F:F,[1]项目开票!B:B,报税!B15,[1]项目开票!A:A,报税!A15) -> 0 | V15: =SUMIFS([1]项目开票!G:G,[1]项目开票!B:B,报税!B15,[1]项目开票!A:A,报税!A15) -> 0 | W15: =S15-U15 -> 0 | X15: =T15-V15 -> 0 | AB15: =SUMIFS([1]项目开票!I:I,[1]项目开票!B:B,报税!B15,[1]项目开票!A:A,报税!A15) -> 0 | AC15: =SUMIFS([1]项目开票!J:J,[1]项目开票!B:B,报税!B15,[1]项目开票!A:A,报税!A15) -> 0 | AD15: =Z15-AB15 -> 0 | AE15: =AA15-AC15 -> 0 | AI15: =SUMIFS([1]项目开票!L:L,[1]项目开票!B:B,报税!B15,[1]项目开票!A:A,报税!A15) -> 0 | AJ15: =SUMIFS([1]项目开票!M:M,[1]项目开票!B:B,报税!B15,[1]项目开票!A:A,报税!A15) -> 0 | AK15: =AG15-AI15 -> 0 | AL15: =AH15-AJ15 -> 0 | AQ15: =AM15-AO15 -> 0 | AR15: =AN15-AP15 -> 0 | AS15: =G15+N15+U15+AB15+AI15+AO15 -> 472115
A16: 内蒙鄂尔多斯分散式 | B16: 4470 | C16: EPC | D16: -0.01 | G16: =SUMIFS([1]项目开票!C:C,[1]项目开票!B:B,报税!B16,[1]项目开票!A:A,报税!A16) -> 0 | H16: =SUMIFS([1]项目开票!D:D,[1]项目开票!B:B,报税!B16,[1]项目开票!A:A,报税!A16) -> 0 | I16: =E16-G16 -> 0 | J16: =F16-H16 -> 0 | N16: =SUMIFS([1]项目开票!O:O,[1]项目开票!B:B,报税!B16,[1]项目开票!A:A,报税!A16) -> 0 | O16: =SUMIFS([1]项目开票!P:P,[1]项目开票!B:B,报税!B16,[1]项目开票!A:A,报税!A16) -> 0 | P16: =L16-N16 -> 0 | Q16: =M16-O16 -> 0 | R16: 3624400.4 | S16: 3715010.5 | T16: 222900.63 | U16: =SUMIFS([1]项目开票!F:F,[1]项目开票!B:B,报税!B16,[1]项目开票!A:A,报税!A16) -> 0 | V16: =SUMIFS([1]项目开票!G:G,[1]项目开票!B:B,报税!B16,[1]项目开票!A:A,报税!A16) -> 0 | W16: =S16-U16 -> 3715010.5 | X16: =T16-V16 -> 222900.63 | AB16: =SUMIFS([1]项目开票!I:I,[1]项目开票!B:B,报税!B16,[1]项目开票!A:A,报税!A16) -> 0 | AC16: =SUMIFS([1]项目开票!J:J,[1]项目开票!B:B,报税!B16,[1]项目开票!A:A,报税!A16) -> 0 | AD16: =Z16-AB16 -> 0 | AE16: =AA16-AC16 -> 0 | AI16: =SUMIFS([1]项目开票!L:L,[1]项目开票!B:B,报税!B16,[1]项目开票!A:A,报税!A16) -> 0 | AJ16: =SUMIFS([1]项目开票!M:M,[1]项目开票!B:B,报税!B16,[1]项目开票!A:A,报税!A16) -> 0 | AK16: =AG16-AI16 -> 0 | AL16: =AH16-AJ16 -> 0 | AQ16: =AM16-AO16 -> 0 | AR16: =AN16-AP16 -> 0 | AS16: =G16+N16+U16+AB16+AI16+AO16 -> 0
A17: 赤峰市风光制氢一体化项目-赤峰翁牛特旗P1-375 | B17: XC00 | C17: EPC | G17: =SUMIFS([1]项目开票!C:C,[1]项目开票!B:B,报税!B17,[1]项目开票!A:A,报税!A17) -> 0 | H17: =SUMIFS([1]项目开票!D:D,[1]项目开票!B:B,报税!B17,[1]项目开票!A:A,报税!A17) -> 0 | I17: =E17-G17 -> 0 | J17: =F17-H17 -> 0 | N17: =SUMIFS([1]项目开票!O:O,[1]项目开票!B:B,报税!B17,[1]项目开票!A:A,报税!A17) -> 0 | O17: =SUMIFS([1]项目开票!P:P,[1]项目开票!B:B,报税!B17,[1]项目开票!A:A,报税!A17) -> 0 | P17: =L17-N17 -> 0 | Q17: =M17-O17 -> 0 | U17: =SUMIFS([1]项目开票!F:F,[1]项目开票!B:B,报税!B17,[1]项目开票!A:A,报税!A17) -> 0 | V17: =SUMIFS([1]项目开票!G:G,[1]项目开票!B:B,报税!B17,[1]项目开票!A:A,报税!A17) -> 0 | W17: =S17-U17 -> 0 | X17: =T17-V17 -> 0 | Y17: 31013.05 | Z17: 31788.38 | AA17: 1907.3 | AB17: =SUMIFS([1]项目开票!I:I,[1]项目开票!B:B,报税!B17,[1]项目开票!A:A,报税!A17) -> 31788.38 | AC17: =SUMIFS([1]项目开票!J:J,[1]项目开票!B:B,报税!B17,[1]项目开票!A:A,报税!A17) -> 1907.3 | AD17: =Z17-AB17 -> 0 | AE17: =AA17-AC17 -> 0 | AI17: =SUMIFS([1]项目开票!L:L,[1]项目开票!B:B,报税!B17,[1]项目开票!A:A,报税!A17) -> 0 | AJ17: =SUMIFS([1]项目开票!M:M,[1]项目开票!B:B,报税!B17,[1]项目开票!A:A,报税!A17) -> 0 | AK17: =AG17-AI17 -> 0 | AL17: =AH17-AJ17 -> 0 | AQ17: =AM17-AO17 -> 0 | AR17: =AN17-AP17 -> 0 | AS17: =G17+N17+U17+AB17+AI17+AO17 -> 31788.38
A18: 民勤共享储能电站 | B18: 3A12 | C18: EPC | D18: -2109767.6 | E18: -2162511.8 | F18: -194626.06 | G18: =SUMIFS([1]项目开票!C:C,[1]项目开票!B:B,报税!B18,[1]项目开票!A:A,报税!A18) -> 0 | H18: =SUMIFS([1]项目开票!D:D,[1]项目开票!B:B,报税!B18,[1]项目开票!A:A,报税!A18) -> 0 | I18: =E18-G18 -> -2162511.8 | J18: =F18-H18 -> -194626.06 | N18: =SUMIFS([1]项目开票!O:O,[1]项目开票!B:B,报税!B18,[1]项目开票!A:A,报税!A18) -> 0 | O18: =SUMIFS([1]项目开票!P:P,[1]项目开票!B:B,报税!B18,[1]项目开票!A:A,报税!A18) -> 0 | P18: =L18-N18 -> 0 | Q18: =M18-O18 -> 0 | R18: 854960.78 | S18: 876334.8 | T18: 52580.09 | U18: =SUMIFS([1]项目开票!F:F,[1]项目开票!B:B,报税!B18,[1]项目开票!A:A,报税!A18) -> 0 | V18: =SUMIFS([1]项目开票!G:G,[1]项目开票!B:B,报税!B18,[1]项目开票!A:A,报税!A18) -> 0 | W18: =S18-U18 -> 876334.8 | X18: =T18-V18 -> 52580.09 | AB18: =SUMIFS([1]项目开票!I:I,[1]项目开票!B:B,报税!B18,[1]项目开票!A:A,报税!A18) -> 0 | AC18: =SUMIFS([1]项目开票!J:J,[1]项目开票!B:B,报税!B18,[1]项目开票!A:A,报税!A18) -> 0 | AD18: =Z18-AB18 -> 0 | AE18: =AA18-AC18 -> 0 | AI18: =SUMIFS([1]项目开票!L:L,[1]项目开票!B:B,报税!B18,[1]项目开票!A:A,报税!A18) -> 0 | AJ18: =SUMIFS([1]项目开票!M:M,[1]项目开票!B:B,报税!B18,[1]项目开票!A:A,报税!A18) -> 0 | AK18: =AG18-AI18 -> 0 | AL18: =AH18-AJ18 -> 0 | AQ18: =AM18-AO18 -> 0 | AR18: =AN18-AP18 -> 0 | AS18: =G18+N18+U18+AB18+AI18+AO18 -> 0
A19: 锡盟苏右100万千瓦/400万千瓦时储能 | B19: 4301 | C19: EPC | D19: 40479053 | E19: 16308117 | F19: 1467730.5 | G19: =SUMIFS([1]项目开票!C:C,[1]项目开票!B:B,报税!B19,[1]项目开票!A:A,报税!A19) -> 0 | H19: =SUMIFS([1]项目开票!D:D,[1]项目开票!B:B,报税!B19,[1]项目开票!A:A,报税!A19) -> 0 | I19: =E19-G19 -> 16308117 | J19: =F19-H19 -> 1467730.5 | K19: 8.6568815e+08 | L19: 8.5109174e+08 | M19: 1.1064193e+08 | N19: =SUMIFS([1]项目开票!O:O,[1]项目开票!B:B,报税!B19,[1]项目开票!A:A,报税!A19) -> 0 | O19: =SUMIFS([1]项目开票!P:P,[1]项目开票!B:B,报税!B19,[1]项目开票!A:A,报税!A19) -> 0 | P19: =L19-N19 -> 8.5109174e+08 | Q19: =M19-O19 -> 1.1064193e+08 | R19: 32786646 | S19: 33410446 | T19: 2004626.8 | U19: =SUMIFS([1]项目开票!F:F,[1]项目开票!B:B,报税!B19,[1]项目开票!A:A,报税!A19) -> 0 | V19: =SUMIFS([1]项目开票!G:G,[1]项目开票!B:B,报税!B19,[1]项目开票!A:A,报税!A19) -> 0 | W19: =S19-U19 -> 33410446 | X19: =T19-V19 -> 2004626.8 | Y19: 29801.75 | Z19: 30546.79 | AA19: 1832.81 | AB19: =SUMIFS([1]项目开票!I:I,[1]项目开票!B:B,报税!B19,[1]项目开票!A:A,报税!A19) -> 30546.79 | AC19: =SUMIFS([1]项目开票!J:J,[1]项目开票!B:B,报税!B19,[1]项目开票!A:A,报税!A19) -> 1832.81 | AD19: =Z19-AB19 -> 0 | AE19: =AA19-AC19 -> 0 | AI19: =SUMIFS([1]项目开票!L:L,[1]项目开票!B:B,报税!B19,[1]项目开票!A:A,报税!A19) -> 0 | AJ19: =SUMIFS([1]项目开票!M:M,[1]项目开票!B:B,报税!B19,[1]项目开票!A:A,报税!A19) -> 0 | AK19: =AG19-AI19 -> 0 | AL19: =AH19-AJ19 -> 0 | AQ19: =AM19-AO19 -> 0 | AR19: =AN19-AP19 -> 0 | AS19: =G19+N19+U19+AB19+AI19+AO19 -> 30546.79
A20: 巴彦淖尔1000MW/4000MWh储能 | B20: 3A17 | C20: EPC | D20: 74809451 | E20: 1.9768947e+08 | F20: 17792052 | G20: =SUMIFS([1]项目开票!C:C,[1]项目开票!B:B,报税!B20,[1]项目开票!A:A,报税!A20) -> 1.859622e+08 | H20: =SUMIFS([1]项目开票!D:D,[1]项目开票!B:B,报税!B20,[1]项目开票!A:A,报税!A20) -> 16736598 | I20: =E20-G20 -> 11727267 | J20: =F20-H20 -> 1055454 | K20: 5.6543495e+08 | L20: 5.6708361e+08 | M20: 73720869 | N20: =SUMIFS([1]项目开票!O:O,[1]项目开票!B:B,报税!B20,[1]项目开票!A:A,报税!A20) -> 0 | O20: =SUMIFS([1]项目开票!P:P,[1]项目开票!B:B,报税!B20,[1]项目开票!A:A,报税!A20) -> 0 | P20: =L20-N20 -> 5.6708361e+08 | Q20: =M20-O20 -> 73720869 | R20: 23806211 | S20: 24044065 | T20: 1442643.9 | U20: =SUMIFS([1]项目开票!F:F,[1]项目开票!B:B,报税!B20,[1]项目开票!A:A,报税!A20) -> 0 | V20: =SUMIFS([1]项目开票!G:G,[1]项目开票!B:B,报税!B20,[1]项目开票!A:A,报税!A20) -> 0 | W20: =S20-U20 -> 24044065 | X20: =T20-V20 -> 1442643.9 | Y20: 29801.75 | Z20: 30546.79 | AA20: 1832.81 | AB20: =SUMIFS([1]项目开票!I:I,[1]项目开票!B:B,报税!B20,[1]项目开票!A:A,报税!A20) -> 30546.79 | AC20: =SUMIFS([1]项目开票!J:J,[1]项目开票!B:B,报税!B20,[1]项目开票!A:A,报税!A20) -> 1832.81 | AD20: =Z20-AB20 -> 0 | AE20: =AA20-AC20 -> 0 | AI20: =SUMIFS([1]项目开票!L:L,[1]项目开票!B:B,报税!B20,[1]项目开票!A:A,报税!A20) -> 0 | AJ20: =SUMIFS([1]项目开票!M:M,[1]项目开票!B:B,报税!B20,[1]项目开票!A:A,报税!A20) -> 0 | AK20: =AG20-AI20 -> 0 | AL20: =AH20-AJ20 -> 0 | AQ20: =AM20-AO20 -> 0 | AR20: =AN20-AP20 -> 0 | AS20: =G20+N20+U20+AB20+AI20+AO20 -> 1.8599275e+08
A21: 陕西佳县 | B21: 3316 | C21: EPC | G21: =SUMIFS([1]项目开票!C:C,[1]项目开票!B:B,报税!B21,[1]项目开票!A:A,报税!A21) -> 0 | H21: =SUMIFS([1]项目开票!D:D,[1]项目开票!B:B,报税!B21,[1]项目开票!A:A,报税!A21) -> 0 | I21: =E21-G21 -> 0 | J21: =F21-H21 -> 0 | N21: =SUMIFS([1]项目开票!O:O,[1]项目开票!B:B,报税!B21,[1]项目开票!A:A,报税!A21) -> 0 | O21: =SUMIFS([1]项目开票!P:P,[1]项目开票!B:B,报税!B21,[1]项目开票!A:A,报税!A21) -> 0 | P21: =L21-N21 -> 0 | Q21: =M21-O21 -> 0 | R21: 619297.69 | S21: 619297.69 | T21: 37157.86 | U21: =SUMIFS([1]项目开票!F:F,[1]项目开票!B:B,报税!B21,[1]项目开票!A:A,报税!A21) -> 0 | V21: =SUMIFS([1]项目开票!G:G,[1]项目开票!B:B,报税!B21,[1]项目开票!A:A,报税!A21) -> 0 | W21: =S21-U21 -> 619297.69 | X21: =T21-V21 -> 37157.86 | Y21: 47683.01 | Z21: 48875.09 | AA21: 2932.51 | AB21: =SUMIFS([1]项目开票!I:I,[1]项目开票!B:B,报税!B21,[1]项目开票!A:A,报税!A21) -> 48875.09 | AC21: =SUMIFS([1]项目开票!J:J,[1]项目开票!B:B,报税!B21,[1]项目开票!A:A,报税!A21) -> 2932.51 | AD21: =Z21-AB21 -> 0 | AE21: =AA21-AC21 -> 0 | AI21: =SUMIFS([1]项目开票!L:L,[1]项目开票!B:B,报税!B21,[1]项目开票!A:A,报税!A21) -> 0 | AJ21: =SUMIFS([1]项目开票!M:M,[1]项目开票!B:B,报税!B21,[1]项目开票!A:A,报税!A21) -> 0 | AK21: =AG21-AI21 -> 0 | AL21: =AH21-AJ21 -> 0 | AQ21: =AM21-AO21 -> 0 | AR21: =AN21-AP21 -> 0 | AS21: =G21+N21+U21+AB21+AI21+AO21 -> 48875.09
A22: 乌海市金湖500kV独立储能电站 | B22: 乌海市远鸿富景新能源科技有限公司 | C22: 对外EPC | D22: 327698.08 | E22: 8550.45 | F22: 769.54 | G22: =SUMIFS([1]项目开票!C:C,[1]项目开票!B:B,报税!B22,[1]项目开票!A:A,报税!A22) -> 0 | H22: =SUMIFS([1]项目开票!D:D,[1]项目开票!B:B,报税!B22,[1]项目开票!A:A,报税!A22) -> 0 | I22: =E22-G22 -> 8550.45 | J22: =F22-H22 -> 769.54 | N22: =SUMIFS([1]项目开票!O:O,[1]项目开票!B:B,报税!B22,[1]项目开票!A:A,报税!A22) -> 0 | O22: =SUMIFS([1]项目开票!P:P,[1]项目开票!B:B,报税!B22,[1]项目开票!A:A,报税!A22) -> 0 | P22: =L22-N22 -> 0 | Q22: =M22-O22 -> 0 | U22: =SUMIFS([1]项目开票!F:F,[1]项目开票!B:B,报税!B22,[1]项目开票!A:A,报税!A22) -> 0 | V22: =SUMIFS([1]项目开票!G:G,[1]项目开票!B:B,报税!B22,[1]项目开票!A:A,报税!A22) -> 0 | W22: =S22-U22 -> 0 | X22: =T22-V22 -> 0 | AB22: =SUMIFS([1]项目开票!I:I,[1]项目开票!B:B,报税!B22,[1]项目开票!A:A,报税!A22) -> 0 | AC22: =SUMIFS([1]项目开票!J:J,[1]项目开票!B:B,报税!B22,[1]项目开票!A:A,报税!A22) -> 0 | AD22: =Z22-AB22 -> 0 | AE22: =AA22-AC22 -> 0 | AI22: =SUMIFS([1]项目开票!L:L,[1]项目开票!B:B,报税!B22,[1]项目开票!A:A,报税!A22) -> 0 | AJ22: =SUMIFS([1]项目开票!M:M,[1]项目开票!B:B,报税!B22,[1]项目开票!A:A,报税!A22) -> 0 | AK22: =AG22-AI22 -> 0 | AL22: =AH22-AJ22 -> 0 | AQ22: =AM22-AO22 -> 0 | AR22: =AN22-AP22 -> 0 | AS22: =G22+N22+U22+AB22+AI22+AO22 -> 0
A23: 射阳样机_远景 | B23: 1000 | C23: EPC | D23: 10067937 | E23: 10823033 | F23: 974072.94 | G23: =SUMIFS([1]项目开票!C:C,[1]项目开票!B:B,报税!B23,[1]项目开票!A:A,报税!A23) -> 10823033 | H23: =SUMIFS([1]项目开票!D:D,[1]项目开票!B:B,报税!B23,[1]项目开票!A:A,报税!A23) -> 974072.94 | I23: =E23-G23 -> 0 | J23: =F23-H23 -> 0 | N23: =SUMIFS([1]项目开票!O:O,[1]项目开票!B:B,报税!B23,[1]项目开票!A:A,报税!A23) -> 0 | O23: =SUMIFS([1]项目开票!P:P,[1]项目开票!B:B,报税!B23,[1]项目开票!A:A,报税!A23) -> 0 | P23: =L23-N23 -> 0 | Q23: =M23-O23 -> 0 | R23: 784711.52 | S23: 843564.88 | T23: 50613.89 | U23: =SUMIFS([1]项目开票!F:F,[1]项目开票!B:B,报税!B23,[1]项目开票!A:A,报税!A23) -> 843564.88 | V23: =SUMIFS([1]项目开票!G:G,[1]项目开票!B:B,报税!B23,[1]项目开票!A:A,报税!A23) -> 50613.89 | W23: =S23-U23 -> 0 | X23: =T23-V23 -> 0 | AB23: =SUMIFS([1]项目开票!I:I,[1]项目开票!B:B,报税!B23,[1]项目开票!A:A,报税!A23) -> 0 | AC23: =SUMIFS([1]项目开票!J:J,[1]项目开票!B:B,报税!B23,[1]项目开票!A:A,报税!A23) -> 0 | AD23: =Z23-AB23 -> 0 | AE23: =AA23-AC23 -> 0 | AI23: =SUMIFS([1]项目开票!L:L,[1]项目开票!B:B,报税!B23,[1]项目开票!A:A,报税!A23) -> 0 | AJ23: =SUMIFS([1]项目开票!M:M,[1]项目开票!B:B,报税!B23,[1]项目开票!A:A,报税!A23) -> 0 | AK23: =AG23-AI23 -> 0 | AL23: =AH23-AJ23 -> 0 | AQ23: =AM23-AO23 -> 0 | AR23: =AN23-AP23 -> 0 | AS23: =G23+N23+U23+AB23+AI23+AO23 -> 11666597
A24: 射阳样机_远景 | B24: 2060 | C24: EPC | D24: 6067157 | E24: 6522193.7 | F24: 586997.45 | G24: =SUMIFS([1]项目开票!C:C,[1]项目开票!B:B,报税!B24,[1]项目开票!A:A,报税!A24) -> 6522193.7 | H24: =SUMIFS([1]项目开票!D:D,[1]项目开票!B:B,报税!B24,[1]项目开票!A:A,报税!A24) -> 586997.45 | I24: =E24-G24 -> 0 | J24: =F24-H24 -> 0 | N24: =SUMIFS([1]项目开票!O:O,[1]项目开票!B:B,报税!B24,[1]项目开票!A:A,报税!A24) -> 0 | O24: =SUMIFS([1]项目开票!P:P,[1]项目开票!B:B,报税!B24,[1]项目开票!A:A,报税!A24) -> 0 | P24: =L24-N24 -> 0 | Q24: =M24-O24 -> 0 | R24: 472792.64 | S24: 508252.09 | T24: 30495.12 | U24: =SUMIFS([1]项目开票!F:F,[1]项目开票!B:B,报税!B24,[1]项目开票!A:A,报税!A24) -> 508252.09 | V24: =SUMIFS([1]项目开票!G:G,[1]项目开票!B:B,报税!B24,[1]项目开票!A:A,报税!A24) -> 30495.12 | W24: =S24-U24 -> 0 | X24: =T24-V24 -> 0 | AB24: =SUMIFS([1]项目开票!I:I,[1]项目开票!B:B,报税!B24,[1]项目开票!A:A,报税!A24) -> 0 | AC24: =SUMIFS([1]项目开票!J:J,[1]项目开票!B:B,报税!B24,[1]项目开票!A:A,报税!A24) -> 0 | AD24: =Z24-AB24 -> 0 | AE24: =AA24-AC24 -> 0 | AI24: =SUMIFS([1]项目开票!L:L,[1]项目开票!B:B,报税!B24,[1]项目开票!A:A,报税!A24) -> 0 | AJ24: =SUMIFS([1]项目开票!M:M,[1]项目开票!B:B,报税!B24,[1]项目开票!A:A,报税!A24) -> 0 | AK24: =AG24-AI24 -> 0 | AL24: =AH24-AJ24 -> 0 | AQ24: =AM24-AO24 -> 0 | AR24: =AN24-AP24 -> 0 | AS24: =G24+N24+U24+AB24+AI24+AO24 -> 7030445.8
A25: 射阳样机_远景 | B25: 2260 | C25: EPC | D25: 4487802.2 | E25: 4824387.3 | F25: 434194.86 | G25: =SUMIFS([1]项目开票!C:C,[1]项目开票!B:B,报税!B25,[1]项目开票!A:A,报税!A25) -> 4824387.3 | H25: =SUMIFS([1]项目开票!D:D,[1]项目开票!B:B,报税!B25,[1]项目开票!A:A,报税!A25) -> 434194.86 | I25: =E25-G25 -> 0 | J25: =F25-H25 -> 0 | N25: =SUMIFS([1]项目开票!O:O,[1]项目开票!B:B,报税!B25,[1]项目开票!A:A,报税!A25) -> 0 | O25: =SUMIFS([1]项目开票!P:P,[1]项目开票!B:B,报税!B25,[1]项目开票!A:A,报税!A25) -> 0 | P25: =L25-N25 -> 0 | Q25: =M25-O25 -> 0 | R25: 472792.64 | S25: 508252.09 | T25: 30495.12 | U25: =SUMIFS([1]项目开票!F:F,[1]项目开票!B:B,报税!B25,[1]项目开票!A:A,报税!A25) -> 508252.09 | V25: =SUMIFS([1]项目开票!G:G,[1]项目开票!B:B,报税!B25,[1]项目开票!A:A,报税!A25) -> 30495.12 | W25: =S25-U25 -> 0 | X25: =T25-V25 -> 0 | AB25: =SUMIFS([1]项目开票!I:I,[1]项目开票!B:B,报税!B25,[1]项目开票!A:A,报税!A25) -> 0 | AC25: =SUMIFS([1]项目开票!J:J,[1]项目开票!B:B,报税!B25,[1]项目开票!A:A,报税!A25) -> 0 | AD25: =Z25-AB25 -> 0 | AE25: =AA25-AC25 -> 0 | AI25: =SUMIFS([1]项目开票!L:L,[1]项目开票!B:B,报税!B25,[1]项目开票!A:A,报税!A25) -> 0 | AJ25: =SUMIFS([1]项目开票!M:M,[1]项目开票!B:B,报税!B25,[1]项目开票!A:A,报税!A25) -> 0 | AK25: =AG25-AI25 -> 0 | AL25: =AH25-AJ25 -> 0 | AQ25: =AM25-AO25 -> 0 | AR25: =AN25-AP25 -> 0 | AS25: =G25+N25+U25+AB25+AI25+AO25 -> 5332639.4
A26: F-001227海伦市东林乡分散式风电场项目场站运维服务 | B26: 海伦京网新能源有限公司 | C26: 后服务收入 | G26: =SUMIFS([1]项目开票!C:C,[1]项目开票!B:B,报税!B26,[1]项目开票!A:A,报税!A26) -> 0 | H26: =SUMIFS([1]项目开票!D:D,[1]项目开票!B:B,报税!B26,[1]项目开票!A:A,报税!A26) -> 0 | I26: =E26-G26 -> 0 | J26: =F26-H26 -> 0 | K26: 10679.25 | L26: 10953.1 | M26: 1423.9 | N26: =SUMIFS([1]项目开票!O:O,[1]项目开票!B:B,报税!B26,[1]项目开票!A:A,报税!A26) -> 0 | O26: =SUMIFS([1]项目开票!P:P,[1]项目开票!B:B,报税!B26,[1]项目开票!A:A,报税!A26) -> 0 | P26: =L26-N26 -> 10953.1 | Q26: =M26-O26 -> 1423.9 | R26: 105136.18 | S26: 107831.98 | T26: 6469.92 | U26: =SUMIFS([1]项目开票!F:F,[1]项目开票!B:B,报税!B26,[1]项目开票!A:A,报税!A26) -> 0 | V26: =SUMIFS([1]项目开票!G:G,[1]项目开票!B:B,报税!B26,[1]项目开票!A:A,报税!A26) -> 0 | W26: =S26-U26 -> 107831.98 | X26: =T26-V26 -> 6469.92 | AB26: =SUMIFS([1]项目开票!I:I,[1]项目开票!B:B,报税!B26,[1]项目开票!A:A,报税!A26) -> 0 | AC26: =SUMIFS([1]项目开票!J:J,[1]项目开票!B:B,报税!B26,[1]项目开票!A:A,报税!A26) -> 0 | AD26: =Z26-AB26 -> 0 | AE26: =AA26-AC26 -> 0 | AI26: =SUMIFS([1]项目开票!L:L,[1]项目开票!B:B,报税!B26,[1]项目开票!A:A,报税!A26) -> 0 | AJ26: =SUMIFS([1]项目开票!M:M,[1]项目开票!B:B,报税!B26,[1]项目开票!A:A,报税!A26) -> 0 | AK26: =AG26-AI26 -> 0 | AL26: =AH26-AJ26 -> 0 | AQ26: =AM26-AO26 -> 0 | AR26: =AN26-AP26 -> 0 | AS26: =G26+N26+U26+AB26+AI26+AO26 -> 0
A27: 贵港桂平一期 | B27: 2056 | C27: EPC | G27: =SUMIFS([1]项目开票!C:C,[1]项目开票!B:B,报税!B27,[1]项目开票!A:A,报税!A27) -> 0 | H27: =SUMIFS([1]项目开票!D:D,[1]项目开票!B:B,报税!B27,[1]项目开票!A:A,报税!A27) -> 0 | I27: =E27-G27 -> 0 | J27: =F27-H27 -> 0 | N27: =SUMIFS([1]项目开票!O:O,[1]项目开票!B:B,报税!B27,[1]项目开票!A:A,报税!A27) -> 0 | O27: =SUMIFS([1]项目开票!P:P,[1]项目开票!B:B,报税!B27,[1]项目开票!A:A,报税!A27) -> 0 | P27: =L27-N27 -> 0 | Q27: =M27-O27 -> 0 | R27: 96855.35 | S27: 96855.35 | T27: 5811.32 | U27: =SUMIFS([1]项目开票!F:F,[1]项目开票!B:B,报税!B27,[1]项目开票!A:A,报税!A27) -> 999308.33 | V27: =SUMIFS([1]项目开票!G:G,[1]项目开票!B:B,报税!B27,[1]项目开票!A:A,报税!A27) -> 59958.51 | W27: =S27-U27 -> -902452.98 | X27: =T27-V27 -> -54147.19 | AB27: =SUMIFS([1]项目开票!I:I,[1]项目开票!B:B,报税!B27,[1]项目开票!A:A,报税!A27) -> 61093.6 | AC27: =SUMIFS([1]项目开票!J:J,[1]项目开票!B:B,报税!B27,[1]项目开票!A:A,报税!A27) -> 3665.62 | AD27: =Z27-AB27 -> -61093.6 | AE27: =AA27-AC27 -> -3665.62 | AI27: =SUMIFS([1]项目开票!L:L,[1]项目开票!B:B,报税!B27,[1]项目开票!A:A,报税!A27) -> 0 | AJ27: =SUMIFS([1]项目开票!M:M,[1]项目开票!B:B,报税!B27,[1]项目开票!A:A,报税!A27) -> 0 | AK27: =AG27-AI27 -> 0 | AL27: =AH27-AJ27 -> 0 | AQ27: =AM27-AO27 -> 0 | AR27: =AN27-AP27 -> 0 | AS27: =G27+N27+U27+AB27+AI27+AO27 -> 1060401.9
A28: FC-000068清池河北沧县浮阳风电场变电运维服务 | B28: 沧县清池新能源有限公司 | C28: 后服务收入 | G28: =SUMIFS([1]项目开票!C:C,[1]项目开票!B:B,报税!B28,[1]项目开票!A:A,报税!A28) -> 0 | H28: =SUMIFS([1]项目开票!D:D,[1]项目开票!B:B,报税!B28,[1]项目开票!A:A,报税!A28) -> 0 | I28: =E28-G28 -> 0 | J28: =F28-H28 -> 0 | N28: =SUMIFS([1]项目开票!O:O,[1]项目开票!B:B,报税!B28,[1]项目开票!A:A,报税!A28) -> 0 | O28: =SUMIFS([1]项目开票!P:P,[1]项目开票!B:B,报税!B28,[1]项目开票!A:A,报税!A28) -> 0 | P28: =L28-N28 -> 0 | Q28: =M28-O28 -> 0 | R28: 733456.66 | S28: 752263.25 | T28: 45135.8 | U28: =SUMIFS([1]项目开票!F:F,[1]项目开票!B:B,报税!B28,[1]项目开票!A:A,报税!A28) -> 0 | V28: =SUMIFS([1]项目开票!G:G,[1]项目开票!B:B,报税!B28,[1]项目开票!A:A,报税!A28) -> 0 | W28: =S28-U28 -> 752263.25 | X28: =T28-V28 -> 45135.8 | AB28: =SUMIFS([1]项目开票!I:I,[1]项目开票!B:B,报税!B28,[1]项目开票!A:A,报税!A28) -> 0 | AC28: =SUMIFS([1]项目开票!J:J,[1]项目开票!B:B,报税!B28,[1]项目开票!A:A,报税!A28) -> 0 | AD28: =Z28-AB28 -> 0 | AE28: =AA28-AC28 -> 0 | AI28: =SUMIFS([1]项目开票!L:L,[1]项目开票!B:B,报税!B28,[1]项目开票!A:A,报税!A28) -> 0 | AJ28: =SUMIFS([1]项目开票!M:M,[1]项目开票!B:B,报税!B28,[1]项目开票!A:A,报税!A28) -> 0 | AK28: =AG28-AI28 -> 0 | AL28: =AH28-AJ28 -> 0 | AS28: =G28+N28+U28+AB28+AI28+AO28 -> 0
A29: 河北沧县开元 | B29: 4620 | C29: EPC | G29: =SUMIFS([1]项目开票!C:C,[1]项目开票!B:B,报税!B29,[1]项目开票!A:A,报税!A29) -> 0 | H29: =SUMIFS([1]项目开票!D:D,[1]项目开票!B:B,报税!B29,[1]项目开票!A:A,报税!A29) -> 0 | I29: =E29-G29 -> 0 | J29: =F29-H29 -> 0 | N29: =SUMIFS([1]项目开票!O:O,[1]项目开票!B:B,报税!B29,[1]项目开票!A:A,报税!A29) -> 0 | O29: =SUMIFS([1]项目开票!P:P,[1]项目开票!B:B,报税!B29,[1]项目开票!A:A,报税!A29) -> 0 | P29: =L29-N29 -> 0 | Q29: =M29-O29 -> 0 | U29: =SUMIFS([1]项目开票!F:F,[1]项目开票!B:B,报税!B29,[1]项目开票!A:A,报税!A29) -> 0 | V29: =SUMIFS([1]项目开票!G:G,[1]项目开票!B:B,报税!B29,[1]项目开票!A:A,报税!A29) -> 0 | W29: =S29-U29 -> 0 | X29: =T29-V29 -> 0 | Y29: 59603.51 | Z29: 61093.6 | AA29: 3665.62 | AB29: =SUMIFS([1]项目开票!I:I,[1]项目开票!B:B,报税!B29,[1]项目开票!A:A,报税!A29) -> 999188.32 | AC29: =SUMIFS([1]项目开票!J:J,[1]项目开票!B:B,报税!B29,[1]项目开票!A:A,报税!A29) -> 59951.3 | AD29: =Z29-AB29 -> -938094.72 | AE29: =AA29-AC29 -> -56285.68 | AI29: =SUMIFS([1]项目开票!L:L,[1]项目开票!B:B,报税!B29,[1]项目开票!A:A,报税!A29) -> 0 | AJ29: =SUMIFS([1]项目开票!M:M,[1]项目开票!B:B,报税!B29,[1]项目开票!A:A,报税!A29) -> 0 | AK29: =AG29-AI29 -> 0 | AL29: =AH29-AJ29 -> 0 | AS29: =G29+N29+U29+AB29+AI29+AO29 -> 999188.32
A30: 民勤三期 | B30: 3397 | C30: EPC | G30: =SUMIFS([1]项目开票!C:C,[1]项目开票!B:B,报税!B30,[1]项目开票!A:A,报税!A30) -> 0 | H30: =SUMIFS([1]项目开票!D:D,[1]项目开票!B:B,报税!B30,[1]项目开票!A:A,报税!A30) -> 0 | I30: =E30-G30 -> 0 | J30: =F30-H30 -> 0 | N30: =SUMIFS([1]项目开票!O:O,[1]项目开票!B:B,报税!B30,[1]项目开票!A:A,报税!A30) -> 0 | O30: =SUMIFS([1]项目开票!P:P,[1]项目开票!B:B,报税!B30,[1]项目开票!A:A,报税!A30) -> 0 | P30: =L30-N30 -> 0 | Q30: =M30-O30 -> 0 | U30: =SUMIFS([1]项目开票!F:F,[1]项目开票!B:B,报税!B30,[1]项目开票!A:A,报税!A30) -> 0 | V30: =SUMIFS([1]项目开票!G:G,[1]项目开票!B:B,报税!B30,[1]项目开票!A:A,报税!A30) -> 0 | W30: =S30-U30 -> 0 | X30: =T30-V30 -> 0 | Y30: 59603.51 | Z30: 61093.6 | AA30: 3665.62 | AB30: =SUMIFS([1]项目开票!I:I,[1]项目开票!B:B,报税!B30,[1]项目开票!A:A,报税!A30) -> 61093.6 | AC30: =SUMIFS([1]项目开票!J:J,[1]项目开票!B:B,报税!B30,[1]项目开票!A:A,报税!A30) -> 3665.62 | AD30: =Z30-AB30 -> 0 | AE30: =AA30-AC30 -> 0 | AI30: =SUMIFS([1]项目开票!L:L,[1]项目开票!B:B,报税!B30,[1]项目开票!A:A,报税!A30) -> 0 | AJ30: =SUMIFS([1]项目开票!M:M,[1]项目开票!B:B,报税!B30,[1]项目开票!A:A,报税!A30) -> 0 | AK30: =AG30-AI30 -> 0 | AL30: =AH30-AJ30 -> 0 | AS30: =G30+N30+U30+AB30+AI30+AO30 -> 61093.6
A31: 锡盟防沙治沙二连浩特市20万kW | B31: 4304 | C31: EPC | G31: =SUMIFS([1]项目开票!C:C,[1]项目开票!B:B,报税!B31,[1]项目开票!A:A,报税!A31) -> 0 | H31: =SUMIFS([1]项目开票!D:D,[1]项目开票!B:B,报税!B31,[1]项目开票!A:A,报税!A31) -> 0 | I31: =E31-G31 -> 0 | J31: =F31-H31 -> 0 | N31: =SUMIFS([1]项目开票!O:O,[1]项目开票!B:B,报税!B31,[1]项目开票!A:A,报税!A31) -> 0 | O31: =SUMIFS([1]项目开票!P:P,[1]项目开票!B:B,报税!B31,[1]项目开票!A:A,报税!A31) -> 0 | P31: =L31-N31 -> 0 | Q31: =M31-O31 -> 0 | U31: =SUMIFS([1]项目开票!F:F,[1]项目开票!B:B,报税!B31,[1]项目开票!A:A,报税!A31) -> 0 | V31: =SUMIFS([1]项目开票!G:G,[1]项目开票!B:B,报税!B31,[1]项目开票!A:A,报税!A31) -> 0 | W31: =S31-U31 -> 0 | X31: =T31-V31 -> 0 | Y31: 47682.81 | Z31: 48874.88 | AA31: 2932.49 | AB31: =SUMIFS([1]项目开票!I:I,[1]项目开票!B:B,报税!B31,[1]项目开票!A:A,报税!A31) -> 586686.32 | AC31: =SUMIFS([1]项目开票!J:J,[1]项目开票!B:B,报税!B31,[1]项目开票!A:A,报税!A31) -> 35201.18 | AD31: =Z31-AB31 -> -537811.44 | AE31: =AA31-AC31 -> -32268.69 | AI31: =SUMIFS([1]项目开票!L:L,[1]项目开票!B:B,报税!B31,[1]项目开票!A:A,报税!A31) -> 0 | AJ31: =SUMIFS([1]项目开票!M:M,[1]项目开票!B:B,报税!B31,[1]项目开票!A:A,报税!A31) -> 0 | AK31: =AG31-AI31 -> 0 | AL31: =AH31-AJ31 -> 0 | AS31: =G31+N31+U31+AB31+AI31+AO31 -> 586686.32
A32: 阿拉善左旗 | B32: 4302 | C32: EPC | G32: =SUMIFS([1]项目开票!C:C,[1]项目开票!B:B,报税!B32,[1]项目开票!A:A,报税!A32) -> 0 | H32: =SUMIFS([1]项目开票!D:D,[1]项目开票!B:B,报税!B32,[1]项目开票!A:A,报税!A32) -> 0 | I32: =E32-G32 -> 0 | J32: =F32-H32 -> 0 | N32: =SUMIFS([1]项目开票!O:O,[1]项目开票!B:B,报税!B32,[1]项目开票!A:A,报税!A32) -> 0 | O32: =SUMIFS([1]项目开票!P:P,[1]项目开票!B:B,报税!B32,[1]项目开票!A:A,报税!A32) -> 0 | P32: =L32-N32 -> 0 | Q32: =M32-O32 -> 0 | U32: =SUMIFS([1]项目开票!F:F,[1]项目开票!B:B,报税!B32,[1]项目开票!A:A,报税!A32) -> 0 | V32: =SUMIFS([1]项目开票!G:G,[1]项目开票!B:B,报税!B32,[1]项目开票!A:A,报税!A32) -> 0 | W32: =S32-U32 -> 0 | X32: =T32-V32 -> 0 | Y32: 59603.51 | Z32: 61093.6 | AA32: 3665.62 | AB32: =SUMIFS([1]项目开票!I:I,[1]项目开票!B:B,报税!B32,[1]项目开票!A:A,报税!A32) -> 61093.6 | AC32: =SUMIFS([1]项目开票!J:J,[1]项目开票!B:B,报税!B32,[1]项目开票!A:A,报税!A32) -> 3665.62 | AD32: =Z32-AB32 -> 0 | AE32: =AA32-AC32 -> 0 | AI32: =SUMIFS([1]项目开票!L:L,[1]项目开票!B:B,报税!B32,[1]项目开票!A:A,报税!A32) -> 0 | AJ32: =SUMIFS([1]项目开票!M:M,[1]项目开票!B:B,报税!B32,[1]项目开票!A:A,报税!A32) -> 0 | AK32: =AG32-AI32 -> 0 | AL32: =AH32-AJ32 -> 0 | AS32: =G32+N32+U32+AB32+AI32+AO32 -> 61093.6
A33: 沧县三期沧县永乐风电场 | B33: 4312 | C33: EPC | G33: =SUMIFS([1]项目开票!C:C,[1]项目开票!B:B,报税!B33,[1]项目开票!A:A,报税!A33) -> 0 | H33: =SUMIFS([1]项目开票!D:D,[1]项目开票!B:B,报税!B33,[1]项目开票!A:A,报税!A33) -> 0 | I33: =E33-G33 -> 0 | J33: =F33-H33 -> 0 | N33: =SUMIFS([1]项目开票!O:O,[1]项目开票!B:B,报税!B33,[1]项目开票!A:A,报税!A33) -> 0 | O33: =SUMIFS([1]项目开票!P:P,[1]项目开票!B:B,报税!B33,[1]项目开票!A:A,报税!A33) -> 0 | P33: =L33-N33 -> 0 | Q33: =M33-O33 -> 0 | U33: =SUMIFS([1]项目开票!F:F,[1]项目开票!B:B,报税!B33,[1]项目开票!A:A,报税!A33) -> 0 | V33: =SUMIFS([1]项目开票!G:G,[1]项目开票!B:B,报税!B33,[1]项目开票!A:A,报税!A33) -> 0 | W33: =S33-U33 -> 0 | X33: =T33-V33 -> 0 | Y33: 59603.51 | Z33: 61093.6 | AA33: 3665.62 | AB33: =SUMIFS([1]项目开票!I:I,[1]项目开票!B:B,报税!B33,[1]项目开票!A:A,报税!A33) -> 409146.79 | AC33: =SUMIFS([1]项目开票!J:J,[1]项目开票!B:B,报税!B33,[1]项目开票!A:A,报税!A33) -> 24548.81 | AD33: =Z33-AB33 -> -348053.19 | AE33: =AA33-AC33 -> -20883.19 | AI33: =SUMIFS([1]项目开票!L:L,[1]项目开票!B:B,报税!B33,[1]项目开票!A:A,报税!A33) -> 0 | AJ33: =SUMIFS([1]项目开票!M:M,[1]项目开票!B:B,报税!B33,[1]项目开票!A:A,报税!A33) -> 0 | AK33: =AG33-AI33 -> 0 | AL33: =AH33-AJ33 -> 0 | AS33: =G33+N33+U33+AB33+AI33+AO33 -> 409146.79
A34: 大业EPC项目 | B34: 山东大业新能源有限公司 | C34: 对外EPC | D34: 1.1209041e+08 | E34: 1.3774398e+08 | F34: 12396958 | G34: =SUMIFS([1]项目开票!C:C,[1]项目开票!B:B,报税!B34,[1]项目开票!A:A,报税!A34) -> 0 | H34: =SUMIFS([1]项目开票!D:D,[1]项目开票!B:B,报税!B34,[1]项目开票!A:A,报税!A34) -> 0 | I34: =E34-G34 -> 1.3774398e+08 | J34: =F34-H34 -> 12396958 | K34: 2.9106224e+08 | L34: 2.9108043e+08 | M34: 37840455 | N34: =SUMIFS([1]项目开票!O:O,[1]项目开票!B:B,报税!B34,[1]项目开票!A:A,报税!A34) -> 0 | O34: =SUMIFS([1]项目开票!P:P,[1]项目开票!B:B,报税!B34,[1]项目开票!A:A,报税!A34) -> 0 | P34: =L34-N34 -> 2.9108043e+08 | Q34: =M34-O34 -> 37840455 | U34: =SUMIFS([1]项目开票!F:F,[1]项目开票!B:B,报税!B34,[1]项目开票!A:A,报税!A34) -> 0 | V34: =SUMIFS([1]项目开票!G:G,[1]项目开票!B:B,报税!B34,[1]项目开票!A:A,报税!A34) -> 0 | W34: =S34-U34 -> 0 | X34: =T34-V34 -> 0 | AB34: =SUMIFS([1]项目开票!I:I,[1]项目开票!B:B,报税!B34,[1]项目开票!A:A,报税!A34) -> 0 | AC34: =SUMIFS([1]项目开票!J:J,[1]项目开票!B:B,报税!B34,[1]项目开票!A:A,报税!A34) -> 0 | AD34: =Z34-AB34 -> 0 | AE34: =AA34-AC34 -> 0 | AI34: =SUMIFS([1]项目开票!L:L,[1]项目开票!B:B,报税!B34,[1]项目开票!A:A,报税!A34) -> 0 | AJ34: =SUMIFS([1]项目开票!M:M,[1]项目开票!B:B,报税!B34,[1]项目开票!A:A,报税!A34) -> 0 | AK34: =AG34-AI34 -> 0 | AL34: =AH34-AJ34 -> 0 | AQ34: =AM34-AO34 -> 0 | AR34: =AN34-AP34 -> 0 | AS34: =G34+N34+U34+AB34+AI34+AO34 -> 0
A35: 滨州二期 | B35: 4313 | C35: EPC | G35: =SUMIFS([1]项目开票!C:C,[1]项目开票!B:B,报税!B35,[1]项目开票!A:A,报税!A35) -> 0 | H35: =SUMIFS([1]项目开票!D:D,[1]项目开票!B:B,报税!B35,[1]项目开票!A:A,报税!A35) -> 0 | I35: =E35-G35 -> 0 | J35: =F35-H35 -> 0 | N35: =SUMIFS([1]项目开票!O:O,[1]项目开票!B:B,报税!B35,[1]项目开票!A:A,报税!A35) -> 0 | O35: =SUMIFS([1]项目开票!P:P,[1]项目开票!B:B,报税!B35,[1]项目开票!A:A,报税!A35) -> 0 | P35: =L35-N35 -> 0 | Q35: =M35-O35 -> 0 | U35: =SUMIFS([1]项目开票!F:F,[1]项目开票!B:B,报税!B35,[1]项目开票!A:A,报税!A35) -> 0 | V35: =SUMIFS([1]项目开票!G:G,[1]项目开票!B:B,报税!B35,[1]项目开票!A:A,报税!A35) -> 0 | W35: =S35-U35 -> 0 | X35: =T35-V35 -> 0 | Y35: 47682.81 | Z35: 48874.88 | AA35: 2932.49 | AB35: =SUMIFS([1]项目开票!I:I,[1]项目开票!B:B,报税!B35,[1]项目开票!A:A,报税!A35) -> 436473.13 | AC35: =SUMIFS([1]项目开票!J:J,[1]项目开票!B:B,报税!B35,[1]项目开票!A:A,报税!A35) -> 26188.39 | AD35: =Z35-AB35 -> -387598.25 | AE35: =AA35-AC35 -> -23255.9 | AI35: =SUMIFS([1]项目开票!L:L,[1]项目开票!B:B,报税!B35,[1]项目开票!A:A,报税!A35) -> 0 | AJ35: =SUMIFS([1]项目开票!M:M,[1]项目开票!B:B,报税!B35,[1]项目开票!A:A,报税!A35) -> 0 | AK35: =AG35-AI35 -> 0 | AL35: =AH35-AJ35 -> 0 | AQ35: =AM35-AO35 -> 0 | AR35: =AN35-AP35 -> 0 | AS35: =G35+N35+U35+AB35+AI35+AO35 -> 436473.13
A36: 广西邕宁百济风电场 | B36: 3403 | C36: EPC | G36: =SUMIFS([1]项目开票!C:C,[1]项目开票!B:B,报税!B36,[1]项目开票!A:A,报税!A36) -> 0 | H36: =SUMIFS([1]项目开票!D:D,[1]项目开票!B:B,报税!B36,[1]项目开票!A:A,报税!A36) -> 0 | I36: =E36-G36 -> 0 | J36: =F36-H36 -> 0 | N36: =SUMIFS([1]项目开票!O:O,[1]项目开票!B:B,报税!B36,[1]项目开票!A:A,报税!A36) -> 0 | O36: =SUMIFS([1]项目开票!P:P,[1]项目开票!B:B,报税!B36,[1]项目开票!A:A,报税!A36) -> 0 | P36: =L36-N36 -> 0 | Q36: =M36-O36 -> 0 | U36: =SUMIFS([1]项目开票!F:F,[1]项目开票!B:B,报税!B36,[1]项目开票!A:A,报税!A36) -> 0 | V36: =SUMIFS([1]项目开票!G:G,[1]项目开票!B:B,报税!B36,[1]项目开票!A:A,报税!A36) -> 0 | W36: =S36-U36 -> 0 | X36: =T36-V36 -> 0 | Y36: 47682.81 | Z36: 48874.88 | AA36: 2932.49 | AB36: =SUMIFS([1]项目开票!I:I,[1]项目开票!B:B,报税!B36,[1]项目开票!A:A,报税!A36) -> 399864.1 | AC36: =SUMIFS([1]项目开票!J:J,[1]项目开票!B:B,报税!B36,[1]项目开票!A:A,报税!A36) -> 23991.85 | AD36: =Z36-AB36 -> -350989.22 | AE36: =AA36-AC36 -> -21059.36 | AI36: =SUMIFS([1]项目开票!L:L,[1]项目开票!B:B,报税!B36,[1]项目开票!A:A,报税!A36) -> 0 | AJ36: =SUMIFS([1]项目开票!M:M,[1]项目开票!B:B,报税!B36,[1]项目开票!A:A,报税!A36) -> 0 | AK36: =AG36-AI36 -> 0 | AL36: =AH36-AJ36 -> 0 | AQ36: =AM36-AO36 -> 0 | AR36: =AN36-AP36 -> 0 | AS36: =G36+N36+U36+AB36+AI36+AO36 -> 399864.1
A37: 广西邕宁那楼中山风电场 | B37: 3398 | C37: EPC | G37: =SUMIFS([1]项目开票!C:C,[1]项目开票!B:B,报税!B37,[1]项目开票!A:A,报税!A37) -> 0 | H37: =SUMIFS([1]项目开票!D:D,[1]项目开票!B:B,报税!B37,[1]项目开票!A:A,报税!A37) -> 0 | I37: =E37-G37 -> 0 | J37: =F37-H37 -> 0 | N37: =SUMIFS([1]项目开票!O:O,[1]项目开票!B:B,报税!B37,[1]项目开票!A:A,报税!A37) -> 0 | O37: =SUMIFS([1]项目开票!P:P,[1]项目开票!B:B,报税!B37,[1]项目开票!A:A,报税!A37) -> 0 | P37: =L37-N37 -> 0 | Q37: =M37-O37 -> 0 | U37: =SUMIFS([1]项目开票!F:F,[1]项目开票!B:B,报税!B37,[1]项目开票!A:A,报税!A37) -> 0 | V37: =SUMIFS([1]项目开票!G:G,[1]项目开票!B:B,报税!B37,[1]项目开票!A:A,报税!A37) -> 0 | W37: =S37-U37 -> 0 | X37: =T37-V37 -> 0 | Y37: 47682.81 | Z37: 48874.88 | AA37: 2932.49 | AB37: =SUMIFS([1]项目开票!I:I,[1]项目开票!B:B,报税!B37,[1]项目开票!A:A,报税!A37) -> 399864.1 | AC37: =SUMIFS([1]项目开票!J:J,[1]项目开票!B:B,报税!B37,[1]项目开票!A:A,报税!A37) -> 23991.85 | AD37: =Z37-AB37 -> -350989.22 | AE37: =AA37-AC37 -> -21059.36 | AI37: =SUMIFS([1]项目开票!L:L,[1]项目开票!B:B,报税!B37,[1]项目开票!A:A,报税!A37) -> 0 | AJ37: =SUMIFS([1]项目开票!M:M,[1]项目开票!B:B,报税!B37,[1]项目开票!A:A,报税!A37) -> 0 | AK37: =AG37-AI37 -> 0 | AL37: =AH37-AJ37 -> 0 | AQ37: =AM37-AO37 -> 0 | AR37: =AN37-AP37 -> 0 | AS37: =G37+N37+U37+AB37+AI37+AO37 -> 399864.1
A38: 广西邕宁中和风电场 | B38: 3402 | C38: EPC | G38: =SUMIFS([1]项目开票!C:C,[1]项目开票!B:B,报税!B38,[1]项目开票!A:A,报税!A38) -> 0 | H38: =SUMIFS([1]项目开票!D:D,[1]项目开票!B:B,报税!B38,[1]项目开票!A:A,报税!A38) -> 0 | I38: =E38-G38 -> 0 | J38: =F38-H38 -> 0 | N38: =SUMIFS([1]项目开票!O:O,[1]项目开票!B:B,报税!B38,[1]项目开票!A:A,报税!A38) -> 0 | O38: =SUMIFS([1]项目开票!P:P,[1]项目开票!B:B,报税!B38,[1]项目开票!A:A,报税!A38) -> 0 | P38: =L38-N38 -> 0 | Q38: =M38-O38 -> 0 | U38: =SUMIFS([1]项目开票!F:F,[1]项目开票!B:B,报税!B38,[1]项目开票!A:A,报税!A38) -> 0 | V38: =SUMIFS([1]项目开票!G:G,[1]项目开票!B:B,报税!B38,[1]项目开票!A:A,报税!A38) -> 0 | W38: =S38-U38 -> 0 | X38: =T38-V38 -> 0 | Y38: 47682.81 | Z38: 48874.88 | AA38: 2932.49 | AB38: =SUMIFS([1]项目开票!I:I,[1]项目开票!B:B,报税!B38,[1]项目开票!A:A,报税!A38) -> 399864.1 | AC38: =SUMIFS([1]项目开票!J:J,[1]项目开票!B:B,报税!B38,[1]项目开票!A:A,报税!A38) -> 23991.85 | AD38: =Z38-AB38 -> -350989.22 | AE38: =AA38-AC38 -> -21059.36 | AI38: =SUMIFS([1]项目开票!L:L,[1]项目开票!B:B,报税!B38,[1]项目开票!A:A,报税!A38) -> 0 | AJ38: =SUMIFS([1]项目开票!M:M,[1]项目开票!B:B,报税!B38,[1]项目开票!A:A,报税!A38) -> 0 | AK38: =AG38-AI38 -> 0 | AL38: =AH38-AJ38 -> 0 | AQ38: =AM38-AO38 -> 0 | AR38: =AN38-AP38 -> 0 | AS38: =G38+N38+U38+AB38+AI38+AO38 -> 399864.1
A39: 四子王旗储能站 | B39: 4317 | C39: EPC | G39: =SUMIFS([1]项目开票!C:C,[1]项目开票!B:B,报税!B39,[1]项目开票!A:A,报税!A39) -> 0 | H39: =SUMIFS([1]项目开票!D:D,[1]项目开票!B:B,报税!B39,[1]项目开票!A:A,报税!A39) -> 0 | I39: =E39-G39 -> 0 | J39: =F39-H39 -> 0 | N39: =SUMIFS([1]项目开票!O:O,[1]项目开票!B:B,报税!B39,[1]项目开票!A:A,报税!A39) -> 0 | O39: =SUMIFS([1]项目开票!P:P,[1]项目开票!B:B,报税!B39,[1]项目开票!A:A,报税!A39) -> 0 | P39: =L39-N39 -> 0 | Q39: =M39-O39 -> 0 | U39: =SUMIFS([1]项目开票!F:F,[1]项目开票!B:B,报税!B39,[1]项目开票!A:A,报税!A39) -> 0 | V39: =SUMIFS([1]项目开票!G:G,[1]项目开票!B:B,报税!B39,[1]项目开票!A:A,报税!A39) -> 0 | W39: =S39-U39 -> 0 | X39: =T39-V39 -> 0 | Y39: 29801.75 | Z39: 29801.75 | AA39: 1788.11 | AB39: =SUMIFS([1]项目开票!I:I,[1]项目开票!B:B,报税!B39,[1]项目开票!A:A,报税!A39) -> 191331.26 | AC39: =SUMIFS([1]项目开票!J:J,[1]项目开票!B:B,报税!B39,[1]项目开票!A:A,报税!A39) -> 11479.88 | AD39: =Z39-AB39 -> -161529.51 | AE39: =AA39-AC39 -> -9691.77 | AI39: =SUMIFS([1]项目开票!L:L,[1]项目开票!B:B,报税!B39,[1]项目开票!A:A,报税!A39) -> 0 | AJ39: =SUMIFS([1]项目开票!M:M,[1]项目开票!B:B,报税!B39,[1]项目开票!A:A,报税!A39) -> 0 | AK39: =AG39-AI39 -> 0 | AL39: =AH39-AJ39 -> 0 | AQ39: =AM39-AO39 -> 0 | AR39: =AN39-AP39 -> 0 | AS39: =G39+N39+U39+AB39+AI39+AO39 -> 191331.26
A40: 白城洮北 | B40: 4650 | C40: EPC | G40: =SUMIFS([1]项目开票!C:C,[1]项目开票!B:B,报税!B40,[1]项目开票!A:A,报税!A40) -> 0 | H40: =SUMIFS([1]项目开票!D:D,[1]项目开票!B:B,报税!B40,[1]项目开票!A:A,报税!A40) -> 0 | I40: =E40-G40 -> 0 | J40: =F40-H40 -> 0 | N40: =SUMIFS([1]项目开票!O:O,[1]项目开票!B:B,报税!B40,[1]项目开票!A:A,报税!A40) -> 0 | O40: =SUMIFS([1]项目开票!P:P,[1]项目开票!B:B,报税!B40,[1]项目开票!A:A,报税!A40) -> 0 | P40: =L40-N40 -> 0 | Q40: =M40-O40 -> 0 | U40: =SUMIFS([1]项目开票!F:F,[1]项目开票!B:B,报税!B40,[1]项目开票!A:A,报税!A40) -> 0 | V40: =SUMIFS([1]项目开票!G:G,[1]项目开票!B:B,报税!B40,[1]项目开票!A:A,报税!A40) -> 0 | W40: =S40-U40 -> 0 | X40: =T40-V40 -> 0 | Y40: 33798.75 | Z40: 34643.72 | AA40: 2078.62 | AB40: =SUMIFS([1]项目开票!I:I,[1]项目开票!B:B,报税!B40,[1]项目开票!A:A,报税!A40) -> 34643.72 | AC40: =SUMIFS([1]项目开票!J:J,[1]项目开票!B:B,报税!B40,[1]项目开票!A:A,报税!A40) -> 2078.62 | AD40: =Z40-AB40 -> 0 | AE40: =AA40-AC40 -> 0 | AI40: =SUMIFS([1]项目开票!L:L,[1]项目开票!B:B,报税!B40,[1]项目开票!A:A,报税!A40) -> 0 | AJ40: =SUMIFS([1]项目开票!M:M,[1]项目开票!B:B,报税!B40,[1]项目开票!A:A,报税!A40) -> 0 | AK40: =AG40-AI40 -> 0 | AL40: =AH40-AJ40 -> 0 | AQ40: =AM40-AO40 -> 0 | AR40: =AN40-AP40 -> 0 | AS40: =G40+N40+U40+AB40+AI40+AO40 -> 34643.72
...
